<?xml version='1.0'?>
<sdf version='1.6'>
    <model name='victor'>
        <allow_auto_disable>true</allow_auto_disable>
        <link name='victor_root'>
            <pose frame=''>0 0 0 0 -0 0</pose>
            <inertial>
                <pose frame=''>0 0 0.3 0 0 0</pose>
                <mass>70.864</mass>
                <inertia>
                    ixx: 17.33333333
                    iyy: 10.66666667
                    izz: 17.33333333
                    <ixx>13</ixx>
                    <ixy>0</ixy>
                    <ixz>0</ixz>
                    <iyy>7</iyy>
                    <iyz>0</iyz>
                    <izz>17</izz>
                </inertia>
            </inertial>
            <kinematic>1</kinematic>
            <visual name='victor_root_fixed_joint_lump__victor_pedestal_visual'>
                <pose frame=''>0 0 0.9245 0 -0 0</pose>
                <geometry>
                    <mesh>
                        <uri>file://victor_description/meshes/baxter_pedestal/pedestal_visual.stl</uri>
                    </mesh>
                </geometry>
            </visual>
            <visual name='victor_root_fixed_joint_lump__victor_base_plate_visual_1'>
                <pose frame=''>0 0 0.863 0 -0 0</pose>
                <geometry>
                    <mesh>
                        <uri>file://victor_description/meshes/torso/torso_visual.stl</uri>
                    </mesh>
                </geometry>
            </visual>
            <visual name='victor_root_fixed_joint_lump__victor_left_arm_link_0_visual_2'>
                <pose frame=''>-0.02 0.138488 1.248 -1.5708 0 -0.785398</pose>
                <geometry>
                    <mesh>
                        <uri>file://victor_description/meshes/iiwa7/visual/link_0.stl</uri>
                    </mesh>
                </geometry>
                <material>
                    <script>
                        <name>Gazebo/Grey</name>
                        <uri>file://media/materials/scripts/gazebo.material</uri>
                    </script>
                </material>
            </visual>
            <visual name='victor_root_fixed_joint_lump__victor_right_arm_link_0_visual_3'>
                <pose frame=''>-0.02 -0.138488 1.248 1.5708 0 0.785398</pose>
                <geometry>
                    <mesh>
                        <uri>file://victor_description/meshes/iiwa7/visual/link_0.stl</uri>
                    </mesh>
                </geometry>
                <material>
                    <script>
                        <name>Gazebo/Grey</name>
                        <uri>file://media/materials/scripts/gazebo.material</uri>
                    </script>
                </material>
            </visual>
        </link>
        <link name='victor_left_arm_link_1'>
            <pose frame=''>0.086066 0.244555 1.248 -1.5708 0 -0.785398</pose>
            <inertial>
                <pose frame=''>0 -0.03 0.12 0 -0 0</pose>
                <mass>3.4525</mass>
                <inertia>
                    <ixx>0.02183</ixx>
                    <ixy>0</ixy>
                    <ixz>0</ixz>
                    <iyy>0.007703</iyy>
                    <iyz>-0.003887</iyz>
                    <izz>0.02083</izz>
                </inertia>
            </inertial>
            <kinematic>1</kinematic>
            <visual name='victor_left_arm_link_1_visual'>
                <pose frame=''>0 0 0.0075 0 -0 0</pose>
                <geometry>
                    <mesh>
                        <uri>file://victor_description/meshes/iiwa7/visual/link_1.stl</uri>
                    </mesh>
                </geometry>
                <material>
                    <script>
                        <name>Gazebo/Orange</name>
                        <uri>file://media/materials/scripts/gazebo.material</uri>
                    </script>
                </material>
            </visual>
        </link>
        <link name='victor_left_arm_link_2'>
            <pose frame=''>0.220416 0.378905 1.248 -3.14159 -0 2.35619</pose>
            <inertial>
                <pose frame=''>0.0003 0.059 0.042 0 -0 0</pose>
                <mass>3.4821</mass>
                <inertia>
                    <ixx>0.02076</ixx>
                    <ixy>0</ixy>
                    <ixz>-0.003626</ixz>
                    <iyy>0.02179</iyy>
                    <iyz>0</iyz>
                    <izz>0.00779</izz>
                </inertia>
            </inertial>
            <kinematic>1</kinematic>
            <visual name='victor_left_arm_link_2_visual'>
                <pose frame=''>0 0 0 0 -0 0</pose>
                <geometry>
                    <mesh>
                        <uri>file://victor_description/meshes/iiwa7/visual/link_2.stl</uri>
                    </mesh>
                </geometry>
                <material>
                    <script>
                        <name>Gazebo/Orange</name>
                        <uri>file://media/materials/scripts/gazebo.material</uri>
                    </script>
                </material>
            </visual>
            <collision name='victor_left_arm_link_2_collision'>
                <max_contacts>4</max_contacts>
                <pose frame=''>0 0 0 0 -0 0</pose>
                <geometry>
                    <mesh>
                        <uri>file://victor_description/meshes/iiwa7/collision/link_2.stl</uri>
                    </mesh>
                </geometry>
                <surface>
                    <friction>
                        <ode>
                            <mu>1</mu>
                            <mu2>1</mu2>
                        </ode>
                    </friction>
                    <contact>
                        <ode>
                            <kp>100000</kp>
                            <kd>1</kd>
                        </ode>
                    </contact>
                </surface>
            </collision>
        </link>
        <link name='victor_left_arm_link_3'>
            <pose frame=''>0.368909 0.527397 1.248 -1.5708 0 -0.785398</pose>
            <inertial>
                <pose frame=''>0 0.03 0.13 0 -0 0</pose>
                <mass>4.05623</mass>
                <inertia>
                    <ixx>0.03204</ixx>
                    <ixy>0</ixy>
                    <ixz>0</ixz>
                    <iyy>0.00972</iyy>
                    <iyz>0.006227</iyz>
                    <izz>0.03042</izz>
                </inertia>
            </inertial>
            <kinematic>1</kinematic>
            <visual name='victor_left_arm_link_3_visual'>
                <pose frame=''>0 0 -0.026 0 -0 0</pose>
                <geometry>
                    <mesh>
                        <uri>file://victor_description/meshes/iiwa7/visual/link_3.stl</uri>
                    </mesh>
                </geometry>
                <material>
                    <script>
                        <name>Gazebo/Orange</name>
                        <uri>file://media/materials/scripts/gazebo.material</uri>
                    </script>
                </material>
            </visual>
            <collision name='victor_left_arm_link_3_collision'>
                <max_contacts>4</max_contacts>
                <pose frame=''>0 0 -0.026 0 -0 0</pose>
                <geometry>
                    <mesh>
                        <uri>file://victor_description/meshes/iiwa7/collision/link_3.stl</uri>
                    </mesh>
                </geometry>
                <surface>
                    <friction>
                        <ode>
                            <mu>1</mu>
                            <mu2>1</mu2>
                        </ode>
                    </friction>
                    <contact>
                        <ode>
                            <kp>100000</kp>
                            <kd>1</kd>
                        </ode>
                    </contact>
                </surface>
            </collision>
        </link>
        <link name='victor_left_arm_link_4'>
            <pose frame=''>0.503259 0.661748 1.248 0 -0 -0.785398</pose>
            <inertial>
                <pose frame=''>0 0.067 0.034 0 -0 0</pose>
                <mass>3.4822</mass>
                <inertia>
                    <ixx>0.02178</ixx>
                    <ixy>0</ixy>
                    <ixz>0</ixz>
                    <iyy>0.02075</iyy>
                    <iyz>-0.003625</iyz>
                    <izz>0.007785</izz>
                </inertia>
            </inertial>
            <kinematic>1</kinematic>
            <visual name='victor_left_arm_link_4_visual'>
                <pose frame=''>0 0 0 0 -0 0</pose>
                <geometry>
                    <mesh>
                        <uri>file://victor_description/meshes/iiwa7/visual/link_4.stl</uri>
                    </mesh>
                </geometry>
                <material>
                    <script>
                        <name>Gazebo/Orange</name>
                        <uri>file://media/materials/scripts/gazebo.material</uri>
                    </script>
                </material>
            </visual>
            <collision name='victor_left_arm_link_4_collision'>
                <max_contacts>4</max_contacts>
                <pose frame=''>0 0 0 0 -0 0</pose>
                <geometry>
                    <mesh>
                        <uri>file://victor_description/meshes/iiwa7/collision/link_4.stl</uri>
                    </mesh>
                </geometry>
                <surface>
                    <friction>
                        <ode>
                            <mu>1</mu>
                            <mu2>1</mu2>
                        </ode>
                    </friction>
                    <contact>
                        <ode>
                            <kp>100000</kp>
                            <kd>1</kd>
                        </ode>
                    </contact>
                </surface>
            </collision>
        </link>
        <link name='victor_left_arm_link_5'>
            <pose frame=''>0.651751 0.81024 1.248 1.5708 -0 2.35619</pose>
            <inertial>
                <pose frame=''>0.0001 0.021 0.076 0 -0 0</pose>
                <mass>2.1633</mass>
                <inertia>
                    <ixx>0.01287</ixx>
                    <ixy>0</ixy>
                    <ixz>0</ixz>
                    <iyy>0.005708</iyy>
                    <iyz>-0.003946</iyz>
                    <izz>0.01112</izz>
                </inertia>
            </inertial>
            <kinematic>1</kinematic>
            <visual name='victor_left_arm_link_5_visual'>
                <pose frame=''>0 0 -0.026 0 -0 0</pose>
                <geometry>
                    <mesh>
                        <uri>file://victor_description/meshes/iiwa7/visual/link_5.stl</uri>
                    </mesh>
                </geometry>
                <material>
                    <script>
                        <name>Gazebo/Orange</name>
                        <uri>file://media/materials/scripts/gazebo.material</uri>
                    </script>
                </material>
            </visual>
            <collision name='victor_left_arm_link_5_collision'>
                <max_contacts>4</max_contacts>
                <pose frame=''>0 0 -0.026 0 -0 0</pose>
                <geometry>
                    <mesh>
                        <uri>file://victor_description/meshes/iiwa7/collision/link_5.stl</uri>
                    </mesh>
                </geometry>
                <surface>
                    <friction>
                        <ode>
                            <mu>1</mu>
                            <mu2>1</mu2>
                        </ode>
                    </friction>
                    <contact>
                        <ode>
                            <kp>100000</kp>
                            <kd>1</kd>
                        </ode>
                    </contact>
                </surface>
            </collision>
        </link>
        <link name='victor_left_arm_link_6'>
            <pose frame=''>0.786102 0.94459 1.3087 -3.14159 -0 2.35619</pose>
            <inertial>
                <pose frame=''>0 0.0006 0.0004 0 -0 0</pose>
                <mass>2.3466</mass>
                <inertia>
                    <ixx>0.006509</ixx>
                    <ixy>0</ixy>
                    <ixz>0</ixz>
                    <iyy>0.006259</iyy>
                    <iyz>0.00031891</iyz>
                    <izz>0.004527</izz>
                </inertia>
            </inertial>
            <kinematic>1</kinematic>
            <visual name='victor_left_arm_link_6_visual'>
                <pose frame=''>0 0 0 0 -0 0</pose>
                <geometry>
                    <mesh>
                        <uri>file://victor_description/meshes/iiwa7/visual/link_6.stl</uri>
                    </mesh>
                </geometry>
                <material>
                    <script>
                        <name>Gazebo/Orange</name>
                        <uri>file://media/materials/scripts/gazebo.material</uri>
                    </script>
                </material>
            </visual>
            <collision name='victor_left_arm_link_6_collision'>
                <max_contacts>4</max_contacts>
                <pose frame=''>0 0 0 0 -0 0</pose>
                <geometry>
                    <mesh>
                        <uri>file://victor_description/meshes/iiwa7/collision/link_6.stl</uri>
                    </mesh>
                </geometry>
                <surface>
                    <friction>
                        <ode>
                            <mu>1</mu>
                            <mu2>1</mu2>
                        </ode>
                    </friction>
                    <contact>
                        <ode>
                            <kp>100000</kp>
                            <kd>1</kd>
                        </ode>
                    </contact>
                </surface>
            </collision>
        </link>
        <link name='victor_left_arm_link_7'>
            <pose frame=''>0.843377 1.00187 1.248 -1.5708 0 -0.785398</pose>
            <inertial>
                <pose frame=''>0.003068 0.003068 0.052213 0 -0 0</pose>
                <mass>5.129</mass>
                <inertia>
                    <ixx>0.0450335</ixx>
                    <ixy>0.000391923</ixy>
                    <ixz>-0.00127372</ixz>
                    <iyy>0.0450435</iyy>
                    <iyz>-0.00127372</iyz>
                    <izz>0.0232706</izz>
                </inertia>
            </inertial>
            <kinematic>1</kinematic>
            <visual name='victor_left_arm_link_7_visual'>
                <pose frame=''>0 0 -0.0005 0 -0 0</pose>
                <geometry>
                    <mesh>
                        <uri>file://victor_description/meshes/iiwa7/visual/link_7_electric.stl</uri>
                    </mesh>
                </geometry>
                <material>
                    <script>
                        <name>Gazebo/Grey</name>
                        <uri>file://media/materials/scripts/gazebo.material</uri>
                    </script>
                </material>
            </visual>
            <visual name='victor_left_arm_link_7_fixed_joint_lump__victor_left_gripper_mounting_bracket_visual_1'>
                <pose frame=''>0 0 0.045 0 -0 0</pose>
                <geometry>
                    <mesh>
                        <uri>file://victor_description/meshes/robotiq_3finger/kuka_to_palm_connectors_visual.stl</uri>
                    </mesh>
                </geometry>
            </visual>
            <visual name='victor_left_arm_link_7_fixed_joint_lump__victor_left_gripper_palm_visual_2'>
                <pose frame=''>0 0 0.07205 0 -0 0.785398</pose>
                <geometry>
                    <mesh>
                        <uri>file://victor_description/meshes/robotiq_3finger/palm_visual.stl</uri>
                    </mesh>
                </geometry>
            </visual>
            <visual name='victor_left_arm_link_7_fixed_joint_lump__victor_left_gripper_fingerA_base_visual_3'>
                <pose frame=''>0.015733 0.015733 0.133169 0 -0 0.785398</pose>
                <geometry>
                    <mesh>
                        <uri>file://victor_description/meshes/robotiq_3finger/finger_link1_base_visual.stl</uri>
                    </mesh>
                </geometry>
                <material>
                    <script>
                        <uri>__default__</uri>
                        <name>__default__</name>
                    </script>
                </material>
            </visual>
            <collision name='victor_left_arm_link_7_collision'>
                <max_contacts>4</max_contacts>
                <pose frame=''>0 0 -0.0005 0 -0 0</pose>
                <geometry>
                    <mesh>
                        <uri>file://victor_description/meshes/iiwa7/collision/link_7_electric.stl</uri>
                    </mesh>
                </geometry>
                <surface>
                    <friction>
                        <ode>
                            <mu>1</mu>
                            <mu2>1</mu2>
                        </ode>
                    </friction>
                    <contact>
                        <ode>
                            <kp>100000</kp>
                            <kd>1</kd>
                        </ode>
                    </contact>
                </surface>
            </collision>
            <collision name='victor_left_arm_link_7_fixed_joint_lump__victor_left_gripper_mounting_bracket_collision_1'>
                <max_contacts>4</max_contacts>
                <pose frame=''>0 0 0.045 0 -0 0</pose>
                <geometry>
                    <mesh>
                        <uri>file://victor_description/meshes/robotiq_3finger/kuka_to_palm_connectors_collision.stl
                        </uri>
                    </mesh>
                </geometry>
                <surface>
                    <friction>
                        <ode>
                            <mu>1</mu>
                            <mu2>1</mu2>
                        </ode>
                    </friction>
                    <contact>
                        <ode>
                            <kp>1e+13</kp>
                            <kd>1</kd>
                        </ode>
                    </contact>
                </surface>
            </collision>
            <collision name='victor_left_arm_link_7_fixed_joint_lump__victor_left_gripper_palm_collision_2'>
                <max_contacts>4</max_contacts>
                <pose frame=''>0 0 0.07205 0 -0 0.785398</pose>
                <geometry>
                    <mesh>
                        <uri>file://victor_description/meshes/robotiq_3finger/palm_collision.stl</uri>
                    </mesh>
                </geometry>
                <surface>
                    <friction>
                        <ode>
                            <mu>1</mu>
                            <mu2>1</mu2>
                        </ode>
                    </friction>
                    <contact>
                        <ode>
                            <kp>1e+13</kp>
                            <kd>1</kd>
                        </ode>
                    </contact>
                </surface>
            </collision>
            <collision name='victor_left_arm_link_7_fixed_joint_lump__victor_left_gripper_fingerA_base_collision_3'>
                <max_contacts>4</max_contacts>
                <pose frame=''>0.015733 0.015733 0.133169 0 -0 0.785398</pose>
                <geometry>
                    <mesh>
                        <uri>file://victor_description/meshes/robotiq_3finger/finger_link1_base_visual.stl</uri>
                    </mesh>
                </geometry>
                <surface>
                    <friction>
                        <ode>
                            <mu>1</mu>
                            <mu2>1</mu2>
                        </ode>
                    </friction>
                    <contact>
                        <ode>
                            <kp>100000</kp>
                            <kd>1</kd>
                        </ode>
                    </contact>
                </surface>
            </collision>
        </link>
        <link name='victor_left_gripper_fingerA_dist'>
            <pose frame=''>1.05749 1.11685 1.1779 -1.74273 0.770319 -1.02978</pose>
            <inertial>
                <pose frame=''>0 0 0 0 -0 0</pose>
                <mass>1</mass>
                <inertia>
                    <ixx>0.01</ixx>
                    <ixy>0</ixy>
                    <ixz>0</ixz>
                    <iyy>0.01</iyy>
                    <iyz>0</iyz>
                    <izz>0.01</izz>
                </inertia>
            </inertial>
            <kinematic>1</kinematic>
            <visual name='victor_left_gripper_fingerA_dist_visual'>
                <pose frame=''>0 0 0 0 -0 0</pose>
                <geometry>
                    <mesh>
                        <uri>file://victor_description/meshes/robotiq_3finger/finger_link4_dist_visual.stl</uri>
                    </mesh>
                </geometry>
                <material>
                    <script>
                        <uri>__default__</uri>
                        <name>__default__</name>
                    </script>
                </material>
            </visual>
            <collision name='victor_left_gripper_fingerA_dist_collision'>
                <max_contacts>4</max_contacts>
                <pose frame=''>0 0 0 0 -0 0</pose>
                <geometry>
                    <mesh>
                        <uri>file://victor_description/meshes/robotiq_3finger/finger_link4_dist_collision.stl</uri>
                    </mesh>
                </geometry>
                <surface>
                    <friction>
                        <ode>
                            <mu>1</mu>
                            <mu2>1</mu2>
                        </ode>
                    </friction>
                    <contact>
                        <ode>
                            <kp>100000</kp>
                            <kd>1</kd>
                        </ode>
                    </contact>
                </surface>
            </collision>
        </link>
        <link name='victor_left_gripper_fingerA_med'>
            <pose frame=''>1.0245 1.10571 1.19335 -2.09156 0.617781 -1.56589</pose>
            <inertial>
                <pose frame=''>0 0 0 0 -0 0</pose>
                <mass>1</mass>
                <inertia>
                    <ixx>0.01</ixx>
                    <ixy>0</ixy>
                    <ixz>0</ixz>
                    <iyy>0.01</iyy>
                    <iyz>0</iyz>
                    <izz>0.01</izz>
                </inertia>
            </inertial>
            <kinematic>1</kinematic>
            <visual name='victor_left_gripper_fingerA_med_visual'>
                <pose frame=''>0 0 0 0 -0 0</pose>
                <geometry>
                    <mesh>
                        <uri>file://victor_description/meshes/robotiq_3finger/finger_link3_med_visual.stl</uri>
                    </mesh>
                </geometry>
                <material>
                    <script>
                        <uri>__default__</uri>
                        <name>__default__</name>
                    </script>
                </material>
            </visual>
            <collision name='victor_left_gripper_fingerA_med_collision'>
                <max_contacts>4</max_contacts>
                <pose frame=''>0 0 0 0 -0 0</pose>
                <geometry>
                    <mesh>
                        <uri>file://victor_description/meshes/robotiq_3finger/finger_link3_med_collision.stl</uri>
                    </mesh>
                </geometry>
                <surface>
                    <friction>
                        <ode>
                            <mu>1</mu>
                            <mu2>1</mu2>
                        </ode>
                    </friction>
                    <contact>
                        <ode>
                            <kp>100000</kp>
                            <kd>1</kd>
                        </ode>
                    </contact>
                </surface>
            </collision>
        </link>
        <link name='victor_left_gripper_fingerA_prox'>
            <pose frame=''>0.975005 1.08899 1.21653 -2.09156 0.617781 -1.56589</pose>
            <inertial>
                <pose frame=''>0 0 0 0 -0 0</pose>
                <mass>1</mass>
                <inertia>
                    <ixx>0.01</ixx>
                    <ixy>0</ixy>
                    <ixz>0</ixz>
                    <iyy>0.01</iyy>
                    <iyz>0</iyz>
                    <izz>0.01</izz>
                </inertia>
            </inertial>
            <kinematic>1</kinematic>
            <visual name='victor_left_gripper_fingerA_prox_visual'>
                <pose frame=''>0 0 0 0 -0 0</pose>
                <geometry>
                    <mesh>
                        <uri>file://victor_description/meshes/robotiq_3finger/finger_link2_prox_visual.stl</uri>
                    </mesh>
                </geometry>
                <material>
                    <script>
                        <uri>__default__</uri>
                        <name>__default__</name>
                    </script>
                </material>
            </visual>
            <collision name='victor_left_gripper_fingerA_prox_collision'>
                <max_contacts>4</max_contacts>
                <pose frame=''>0 0 0 0 -0 0</pose>
                <geometry>
                    <mesh>
                        <uri>file://victor_description/meshes/robotiq_3finger/finger_link2_prox_collision.stl</uri>
                    </mesh>
                </geometry>
                <surface>
                    <friction>
                        <ode>
                            <mu>1</mu>
                            <mu2>1</mu2>
                        </ode>
                    </friction>
                    <contact>
                        <ode>
                            <kp>100000</kp>
                            <kd>1</kd>
                        </ode>
                    </contact>
                </surface>
            </collision>
        </link>
        <link name='victor_left_gripper_fingerB_base'>
            <pose frame=''>0.908135 1.12544 1.23795 1.5708 -0.785398 2.35619</pose>
            <inertial>
                <pose frame=''>0 0 0 0 -0 0</pose>
                <mass>1</mass>
                <inertia>
                    <ixx>0.01</ixx>
                    <ixy>0</ixy>
                    <ixz>0</ixz>
                    <iyy>0.01</iyy>
                    <iyz>0</iyz>
                    <izz>0.01</izz>
                </inertia>
            </inertial>
            <kinematic>1</kinematic>
            <visual name='victor_left_gripper_fingerB_base_visual'>
                <pose frame=''>0 0 0 0 -0 0</pose>
                <geometry>
                    <mesh>
                        <uri>file://victor_description/meshes/robotiq_3finger/finger_link1_base_visual.stl</uri>
                    </mesh>
                </geometry>
                <material>
                    <script>
                        <uri>__default__</uri>
                        <name>__default__</name>
                    </script>
                </material>
            </visual>
            <collision name='victor_left_gripper_fingerB_base_collision'>
                <max_contacts>4</max_contacts>
                <pose frame=''>0 0 0 0 -0 0</pose>
                <geometry>
                    <mesh>
                        <uri>file://victor_description/meshes/robotiq_3finger/finger_link1_base_visual.stl</uri>
                    </mesh>
                </geometry>
                <surface>
                    <friction>
                        <ode>
                            <mu>1</mu>
                            <mu2>1</mu2>
                        </ode>
                    </friction>
                    <contact>
                        <ode>
                            <kp>100000</kp>
                            <kd>1</kd>
                        </ode>
                    </contact>
                </surface>
            </collision>
        </link>
        <link name='victor_left_gripper_fingerB_dist'>
            <pose frame=''>0.940077 1.23426 1.29232 1.39886 -0.770319 2.60057</pose>
            <inertial>
                <pose frame=''>0 0 0 0 -0 0</pose>
                <mass>1</mass>
                <inertia>
                    <ixx>0.01</ixx>
                    <ixy>0</ixy>
                    <ixz>0</ixz>
                    <iyy>0.01</iyy>
                    <iyz>0</iyz>
                    <izz>0.01</izz>
                </inertia>
            </inertial>
            <kinematic>1</kinematic>
            <visual name='victor_left_gripper_fingerB_dist_visual'>
                <pose frame=''>0 0 0 0 -0 0</pose>
                <geometry>
                    <mesh>
                        <uri>file://victor_description/meshes/robotiq_3finger/finger_link4_dist_visual.stl</uri>
                    </mesh>
                </geometry>
                <material>
                    <script>
                        <uri>__default__</uri>
                        <name>__default__</name>
                    </script>
                </material>
            </visual>
            <collision name='victor_left_gripper_fingerB_dist_collision'>
                <max_contacts>4</max_contacts>
                <pose frame=''>0 0 0 0 -0 0</pose>
                <geometry>
                    <mesh>
                        <uri>file://victor_description/meshes/robotiq_3finger/finger_link4_dist_collision.stl</uri>
                    </mesh>
                </geometry>
                <surface>
                    <friction>
                        <ode>
                            <mu>1</mu>
                            <mu2>1</mu2>
                        </ode>
                    </friction>
                    <contact>
                        <ode>
                            <kp>100000</kp>
                            <kd>1</kd>
                        </ode>
                    </contact>
                </surface>
            </collision>
        </link>
        <link name='victor_left_gripper_fingerB_med'>
            <pose frame=''>0.928936 1.20127 1.27686 1.05003 -0.617781 3.13669</pose>
            <inertial>
                <pose frame=''>0 0 0 0 -0 0</pose>
                <mass>1</mass>
                <inertia>
                    <ixx>0.01</ixx>
                    <ixy>0</ixy>
                    <ixz>0</ixz>
                    <iyy>0.01</iyy>
                    <iyz>0</iyz>
                    <izz>0.01</izz>
                </inertia>
            </inertial>
            <kinematic>1</kinematic>
            <visual name='victor_left_gripper_fingerB_med_visual'>
                <pose frame=''>0 0 0 0 -0 0</pose>
                <geometry>
                    <mesh>
                        <uri>file://victor_description/meshes/robotiq_3finger/finger_link3_med_visual.stl</uri>
                    </mesh>
                </geometry>
                <material>
                    <script>
                        <uri>__default__</uri>
                        <name>__default__</name>
                    </script>
                </material>
            </visual>
            <collision name='victor_left_gripper_fingerB_med_collision'>
                <max_contacts>4</max_contacts>
                <pose frame=''>0 0 0 0 -0 0</pose>
                <geometry>
                    <mesh>
                        <uri>file://victor_description/meshes/robotiq_3finger/finger_link3_med_collision.stl</uri>
                    </mesh>
                </geometry>
                <surface>
                    <friction>
                        <ode>
                            <mu>1</mu>
                            <mu2>1</mu2>
                        </ode>
                    </friction>
                    <contact>
                        <ode>
                            <kp>100000</kp>
                            <kd>1</kd>
                        </ode>
                    </contact>
                </surface>
            </collision>
        </link>
        <link name='victor_left_gripper_fingerB_prox'>
            <pose frame=''>0.912223 1.15177 1.25368 1.05003 -0.617781 3.13669</pose>
            <inertial>
                <pose frame=''>0 0 0 0 -0 0</pose>
                <mass>1</mass>
                <inertia>
                    <ixx>0.01</ixx>
                    <ixy>0</ixy>
                    <ixz>0</ixz>
                    <iyy>0.01</iyy>
                    <iyz>0</iyz>
                    <izz>0.01</izz>
                </inertia>
            </inertial>
            <kinematic>1</kinematic>
            <visual name='victor_left_gripper_fingerB_prox_visual'>
                <pose frame=''>0 0 0 0 -0 0</pose>
                <geometry>
                    <mesh>
                        <uri>file://victor_description/meshes/robotiq_3finger/finger_link2_prox_visual.stl</uri>
                    </mesh>
                </geometry>
                <material>
                    <script>
                        <uri>__default__</uri>
                        <name>__default__</name>
                    </script>
                </material>
            </visual>
            <collision name='victor_left_gripper_fingerB_prox_collision'>
                <max_contacts>4</max_contacts>
                <pose frame=''>0 0 0 0 -0 0</pose>
                <geometry>
                    <mesh>
                        <uri>file://victor_description/meshes/robotiq_3finger/finger_link2_prox_collision.stl</uri>
                    </mesh>
                </geometry>
                <surface>
                    <friction>
                        <ode>
                            <mu>1</mu>
                            <mu2>1</mu2>
                        </ode>
                    </friction>
                    <contact>
                        <ode>
                            <kp>100000</kp>
                            <kd>1</kd>
                        </ode>
                    </contact>
                </surface>
            </collision>
        </link>
        <link name='victor_left_gripper_fingerC_base'>
            <pose frame=''>0.944648 1.08892 1.28959 1.5708 -0.785398 2.35619</pose>
            <inertial>
                <pose frame=''>0 0 0 0 -0 0</pose>
                <mass>1</mass>
                <inertia>
                    <ixx>0.01</ixx>
                    <ixy>0</ixy>
                    <ixz>0</ixz>
                    <iyy>0.01</iyy>
                    <iyz>0</iyz>
                    <izz>0.01</izz>
                </inertia>
            </inertial>
            <kinematic>1</kinematic>
            <visual name='victor_left_gripper_fingerC_base_visual'>
                <pose frame=''>0 0 0 0 -0 0</pose>
                <geometry>
                    <mesh>
                        <uri>file://victor_description/meshes/robotiq_3finger/finger_link1_base_visual.stl</uri>
                    </mesh>
                </geometry>
            </visual>
            <collision name='victor_left_gripper_fingerC_base_collision'>
                <max_contacts>4</max_contacts>
                <pose frame=''>0 0 0 0 -0 0</pose>
                <geometry>
                    <mesh>
                        <uri>file://victor_description/meshes/robotiq_3finger/finger_link1_base_visual.stl</uri>
                    </mesh>
                </geometry>
                <surface>
                    <friction>
                        <ode>
                            <mu>1</mu>
                            <mu2>1</mu2>
                        </ode>
                    </friction>
                    <contact>
                        <ode>
                            <kp>1e+13</kp>
                            <kd>1</kd>
                        </ode>
                    </contact>
                </surface>
            </collision>
        </link>
        <link name='victor_left_gripper_fingerC_dist'>
            <pose frame=''>0.97659 1.19775 1.34395 1.39886 -0.770319 2.60057</pose>
            <inertial>
                <pose frame=''>0 0 0 0 -0 0</pose>
                <mass>1</mass>
                <inertia>
                    <ixx>0.01</ixx>
                    <ixy>0</ixy>
                    <ixz>0</ixz>
                    <iyy>0.01</iyy>
                    <iyz>0</iyz>
                    <izz>0.01</izz>
                </inertia>
            </inertial>
            <kinematic>1</kinematic>
            <visual name='victor_left_gripper_fingerC_dist_visual'>
                <pose frame=''>0 0 0 0 -0 0</pose>
                <geometry>
                    <mesh>
                        <uri>file://victor_description/meshes/robotiq_3finger/finger_link4_dist_visual.stl</uri>
                    </mesh>
                </geometry>
            </visual>
            <collision name='victor_left_gripper_fingerC_dist_collision'>
                <max_contacts>4</max_contacts>
                <pose frame=''>0 0 0 0 -0 0</pose>
                <geometry>
                    <mesh>
                        <uri>file://victor_description/meshes/robotiq_3finger/finger_link4_dist_collision.stl</uri>
                    </mesh>
                </geometry>
                <surface>
                    <friction>
                        <ode>
                            <mu>1</mu>
                            <mu2>1</mu2>
                        </ode>
                    </friction>
                    <contact>
                        <ode>
                            <kp>1e+13</kp>
                            <kd>1</kd>
                        </ode>
                    </contact>
                </surface>
            </collision>
        </link>
        <link name='victor_left_gripper_fingerC_med'>
            <pose frame=''>0.965448 1.16476 1.3285 1.05003 -0.617781 3.13669</pose>
            <inertial>
                <pose frame=''>0 0 0 0 -0 0</pose>
                <mass>1</mass>
                <inertia>
                    <ixx>0.01</ixx>
                    <ixy>0</ixy>
                    <ixz>0</ixz>
                    <iyy>0.01</iyy>
                    <iyz>0</iyz>
                    <izz>0.01</izz>
                </inertia>
            </inertial>
            <kinematic>1</kinematic>
            <visual name='victor_left_gripper_fingerC_med_visual'>
                <pose frame=''>0 0 0 0 -0 0</pose>
                <geometry>
                    <mesh>
                        <uri>file://victor_description/meshes/robotiq_3finger/finger_link3_med_visual.stl</uri>
                    </mesh>
                </geometry>
            </visual>
            <collision name='victor_left_gripper_fingerC_med_collision'>
                <max_contacts>4</max_contacts>
                <pose frame=''>0 0 0 0 -0 0</pose>
                <geometry>
                    <mesh>
                        <uri>file://victor_description/meshes/robotiq_3finger/finger_link3_med_collision.stl</uri>
                    </mesh>
                </geometry>
                <surface>
                    <friction>
                        <ode>
                            <mu>1</mu>
                            <mu2>1</mu2>
                        </ode>
                    </friction>
                    <contact>
                        <ode>
                            <kp>1e+13</kp>
                            <kd>1</kd>
                        </ode>
                    </contact>
                </surface>
            </collision>
        </link>
        <link name='victor_left_gripper_fingerC_prox'>
            <pose frame=''>0.948735 1.11526 1.30532 1.05003 -0.617781 3.13669</pose>
            <inertial>
                <pose frame=''>0 0 0 0 -0 0</pose>
                <mass>1</mass>
                <inertia>
                    <ixx>0.01</ixx>
                    <ixy>0</ixy>
                    <ixz>0</ixz>
                    <iyy>0.01</iyy>
                    <iyz>0</iyz>
                    <izz>0.01</izz>
                </inertia>
            </inertial>
            <kinematic>1</kinematic>
            <visual name='victor_left_gripper_fingerC_prox_visual'>
                <pose frame=''>0 0 0 0 -0 0</pose>
                <geometry>
                    <mesh>
                        <uri>file://victor_description/meshes/robotiq_3finger/finger_link2_prox_visual.stl</uri>
                    </mesh>
                </geometry>
            </visual>
            <collision name='victor_left_gripper_fingerC_prox_collision'>
                <max_contacts>4</max_contacts>
                <pose frame=''>0 0 0 0 -0 0</pose>
                <geometry>
                    <mesh>
                        <uri>file://victor_description/meshes/robotiq_3finger/finger_link2_prox_collision.stl</uri>
                    </mesh>
                </geometry>
                <surface>
                    <friction>
                        <ode>
                            <mu>1</mu>
                            <mu2>1</mu2>
                        </ode>
                    </friction>
                    <contact>
                        <ode>
                            <kp>1e+13</kp>
                            <kd>1</kd>
                        </ode>
                    </contact>
                </surface>
            </collision>
        </link>
        <link name='victor_right_arm_link_1'>
            <pose frame=''>0.086066 -0.244555 1.248 1.5708 0 0.785398</pose>
            <inertial>
                <pose frame=''>0 -0.03 0.12 0 -0 0</pose>
                <mass>3.4525</mass>
                <inertia>
                    <ixx>0.02183</ixx>
                    <ixy>0</ixy>
                    <ixz>0</ixz>
                    <iyy>0.007703</iyy>
                    <iyz>-0.003887</iyz>
                    <izz>0.02083</izz>
                </inertia>
            </inertial>
            <kinematic>1</kinematic>
            <visual name='victor_right_arm_link_1_visual'>
                <pose frame=''>0 0 0.0075 0 -0 0</pose>
                <geometry>
                    <mesh>
                        <uri>file://victor_description/meshes/iiwa7/visual/link_1.stl</uri>
                    </mesh>
                </geometry>
                <material>
                    <script>
                        <name>Gazebo/Orange</name>
                        <uri>file://media/materials/scripts/gazebo.material</uri>
                    </script>
                </material>
            </visual>
        </link>
        <link name='victor_right_arm_link_2'>
            <pose frame=''>0.220416 -0.378905 1.248 -0 -0 -2.35619</pose>
            <inertial>
                <pose frame=''>0.0003 0.059 0.042 0 -0 0</pose>
                <mass>3.4821</mass>
                <inertia>
                    <ixx>0.02076</ixx>
                    <ixy>0</ixy>
                    <ixz>-0.003626</ixz>
                    <iyy>0.02179</iyy>
                    <iyz>0</iyz>
                    <izz>0.00779</izz>
                </inertia>
            </inertial>
            <kinematic>1</kinematic>
            <visual name='victor_right_arm_link_2_visual'>
                <pose frame=''>0 0 0 0 -0 0</pose>
                <geometry>
                    <mesh>
                        <uri>file://victor_description/meshes/iiwa7/visual/link_2.stl</uri>
                    </mesh>
                </geometry>
                <material>
                    <script>
                        <name>Gazebo/Orange</name>
                        <uri>file://media/materials/scripts/gazebo.material</uri>
                    </script>
                </material>
            </visual>
            <collision name='victor_right_arm_link_2_collision'>
                <max_contacts>4</max_contacts>
                <pose frame=''>0 0 0 0 -0 0</pose>
                <geometry>
                    <mesh>
                        <uri>file://victor_description/meshes/iiwa7/collision/link_2.stl</uri>
                    </mesh>
                </geometry>
                <surface>
                    <friction>
                        <ode>
                            <mu>1</mu>
                            <mu2>1</mu2>
                        </ode>
                    </friction>
                    <contact>
                        <ode>
                            <kp>100000</kp>
                            <kd>1</kd>
                        </ode>
                    </contact>
                </surface>
            </collision>
        </link>
        <link name='victor_right_arm_link_3'>
            <pose frame=''>0.368909 -0.527397 1.248 1.5708 0 0.785398</pose>
            <inertial>
                <pose frame=''>0 0.03 0.13 0 -0 0</pose>
                <mass>4.05623</mass>
                <inertia>
                    <ixx>0.03204</ixx>
                    <ixy>0</ixy>
                    <ixz>0</ixz>
                    <iyy>0.00972</iyy>
                    <iyz>0.006227</iyz>
                    <izz>0.03042</izz>
                </inertia>
            </inertial>
            <kinematic>1</kinematic>
            <visual name='victor_right_arm_link_3_visual'>
                <pose frame=''>0 0 -0.026 0 -0 0</pose>
                <geometry>
                    <mesh>
                        <uri>file://victor_description/meshes/iiwa7/visual/link_3.stl</uri>
                    </mesh>
                </geometry>
                <material>
                    <script>
                        <name>Gazebo/Orange</name>
                        <uri>file://media/materials/scripts/gazebo.material</uri>
                    </script>
                </material>
            </visual>
            <collision name='victor_right_arm_link_3_collision'>
                <max_contacts>4</max_contacts>
                <pose frame=''>0 0 -0.026 0 -0 0</pose>
                <geometry>
                    <mesh>
                        <uri>file://victor_description/meshes/iiwa7/collision/link_3.stl</uri>
                    </mesh>
                </geometry>
                <surface>
                    <friction>
                        <ode>
                            <mu>1</mu>
                            <mu2>1</mu2>
                        </ode>
                    </friction>
                    <contact>
                        <ode>
                            <kp>100000</kp>
                            <kd>1</kd>
                        </ode>
                    </contact>
                </surface>
            </collision>
        </link>
        <link name='victor_right_arm_link_4'>
            <pose frame=''>0.503259 -0.661748 1.248 -3.14159 -0 0.785398</pose>
            <inertial>
                <pose frame=''>0 0.067 0.034 0 -0 0</pose>
                <mass>3.4822</mass>
                <inertia>
                    <ixx>0.02178</ixx>
                    <ixy>0</ixy>
                    <ixz>0</ixz>
                    <iyy>0.02075</iyy>
                    <iyz>-0.003625</iyz>
                    <izz>0.007785</izz>
                </inertia>
            </inertial>
            <kinematic>1</kinematic>
            <visual name='victor_right_arm_link_4_visual'>
                <pose frame=''>0 0 0 0 -0 0</pose>
                <geometry>
                    <mesh>
                        <uri>file://victor_description/meshes/iiwa7/visual/link_4.stl</uri>
                    </mesh>
                </geometry>
                <material>
                    <script>
                        <name>Gazebo/Orange</name>
                        <uri>file://media/materials/scripts/gazebo.material</uri>
                    </script>
                </material>
            </visual>
            <collision name='victor_right_arm_link_4_collision'>
                <max_contacts>4</max_contacts>
                <pose frame=''>0 0 0 0 -0 0</pose>
                <geometry>
                    <mesh>
                        <uri>file://victor_description/meshes/iiwa7/collision/link_4.stl</uri>
                    </mesh>
                </geometry>
                <surface>
                    <friction>
                        <ode>
                            <mu>1</mu>
                            <mu2>1</mu2>
                        </ode>
                    </friction>
                    <contact>
                        <ode>
                            <kp>100000</kp>
                            <kd>1</kd>
                        </ode>
                    </contact>
                </surface>
            </collision>
        </link>
        <link name='victor_right_arm_link_5'>
            <pose frame=''>0.651751 -0.81024 1.248 -1.5708 -0 -2.35619</pose>
            <inertial>
                <pose frame=''>0.0001 0.021 0.076 0 -0 0</pose>
                <mass>2.1633</mass>
                <inertia>
                    <ixx>0.01287</ixx>
                    <ixy>0</ixy>
                    <ixz>0</ixz>
                    <iyy>0.005708</iyy>
                    <iyz>-0.003946</iyz>
                    <izz>0.01112</izz>
                </inertia>
            </inertial>
            <kinematic>1</kinematic>
            <visual name='victor_right_arm_link_5_visual'>
                <pose frame=''>0 0 -0.026 0 -0 0</pose>
                <geometry>
                    <mesh>
                        <uri>file://victor_description/meshes/iiwa7/visual/link_5.stl</uri>
                    </mesh>
                </geometry>
                <material>
                    <script>
                        <name>Gazebo/Orange</name>
                        <uri>file://media/materials/scripts/gazebo.material</uri>
                    </script>
                </material>
            </visual>
            <collision name='victor_right_arm_link_5_collision'>
                <max_contacts>4</max_contacts>
                <pose frame=''>0 0 -0.026 0 -0 0</pose>
                <geometry>
                    <mesh>
                        <uri>file://victor_description/meshes/iiwa7/collision/link_5.stl</uri>
                    </mesh>
                </geometry>
                <surface>
                    <friction>
                        <ode>
                            <mu>1</mu>
                            <mu2>1</mu2>
                        </ode>
                    </friction>
                    <contact>
                        <ode>
                            <kp>100000</kp>
                            <kd>1</kd>
                        </ode>
                    </contact>
                </surface>
            </collision>
        </link>
        <link name='victor_right_arm_link_6'>
            <pose frame=''>0.786102 -0.94459 1.1873 -0 -0 -2.35619</pose>
            <inertial>
                <pose frame=''>0 0.0006 0.0004 0 -0 0</pose>
                <mass>2.3466</mass>
                <inertia>
                    <ixx>0.006509</ixx>
                    <ixy>0</ixy>
                    <ixz>0</ixz>
                    <iyy>0.006259</iyy>
                    <iyz>0.00031891</iyz>
                    <izz>0.004527</izz>
                </inertia>
            </inertial>
            <kinematic>1</kinematic>
            <visual name='victor_right_arm_link_6_visual'>
                <pose frame=''>0 0 0 0 -0 0</pose>
                <geometry>
                    <mesh>
                        <uri>file://victor_description/meshes/iiwa7/visual/link_6.stl</uri>
                    </mesh>
                </geometry>
                <material>
                    <script>
                        <name>Gazebo/Orange</name>
                        <uri>file://media/materials/scripts/gazebo.material</uri>
                    </script>
                </material>
            </visual>
            <collision name='victor_right_arm_link_6_collision'>
                <max_contacts>4</max_contacts>
                <pose frame=''>0 0 0 0 -0 0</pose>
                <geometry>
                    <mesh>
                        <uri>file://victor_description/meshes/iiwa7/collision/link_6.stl</uri>
                    </mesh>
                </geometry>
                <surface>
                    <friction>
                        <ode>
                            <mu>1</mu>
                            <mu2>1</mu2>
                        </ode>
                    </friction>
                    <contact>
                        <ode>
                            <kp>100000</kp>
                            <kd>1</kd>
                        </ode>
                    </contact>
                </surface>
            </collision>
        </link>
        <link name='victor_right_arm_link_7'>
            <pose frame=''>0.843377 -1.00187 1.248 1.5708 0 0.785398</pose>
            <inertial>
                <pose frame=''>0.003068 0.003068 0.052213 0 -0 0</pose>
                <mass>5.129</mass>
                <inertia>
                    <ixx>0.0450335</ixx>
                    <ixy>0.000391923</ixy>
                    <ixz>-0.00127372</ixz>
                    <iyy>0.0450435</iyy>
                    <iyz>-0.00127372</iyz>
                    <izz>0.0232706</izz>
                </inertia>
            </inertial>
            <kinematic>1</kinematic>
            <visual name='victor_right_arm_link_7_visual'>
                <pose frame=''>0 0 -0.0005 0 -0 0</pose>
                <geometry>
                    <mesh>
                        <uri>file://victor_description/meshes/iiwa7/visual/link_7_electric.stl</uri>
                    </mesh>
                </geometry>
                <material>
                    <script>
                        <name>Gazebo/Grey</name>
                        <uri>file://media/materials/scripts/gazebo.material</uri>
                    </script>
                </material>
            </visual>
            <visual name='victor_right_arm_link_7_fixed_joint_lump__victor_right_gripper_mounting_bracket_visual_1'>
                <pose frame=''>0 0 0.045 0 -0 0</pose>
                <geometry>
                    <mesh>
                        <uri>file://victor_description/meshes/robotiq_3finger/kuka_to_palm_connectors_visual.stl</uri>
                    </mesh>
                </geometry>
            </visual>
            <visual name='victor_right_arm_link_7_fixed_joint_lump__victor_right_gripper_palm_visual_2'>
                <pose frame=''>0 0 0.07205 0 -0 0.785398</pose>
                <geometry>
                    <mesh>
                        <uri>file://victor_description/meshes/robotiq_3finger/palm_visual.stl</uri>
                    </mesh>
                </geometry>
            </visual>
            <visual name='victor_right_arm_link_7_fixed_joint_lump__victor_right_gripper_fingerA_base_visual_3'>
                <pose frame=''>0.015733 0.015733 0.133169 0 -0 0.785398</pose>
                <geometry>
                    <mesh>
                        <uri>file://victor_description/meshes/robotiq_3finger/finger_link1_base_visual.stl</uri>
                    </mesh>
                </geometry>
                <material>
                    <script>
                        <uri>__default__</uri>
                        <name>__default__</name>
                    </script>
                </material>
            </visual>
            <collision name='victor_right_arm_link_7_collision'>
                <max_contacts>4</max_contacts>
                <pose frame=''>0 0 -0.0005 0 -0 0</pose>
                <geometry>
                    <mesh>
                        <uri>file://victor_description/meshes/iiwa7/collision/link_7_electric.stl</uri>
                    </mesh>
                </geometry>
                <surface>
                    <friction>
                        <ode>
                            <mu>1</mu>
                            <mu2>1</mu2>
                        </ode>
                    </friction>
                    <contact>
                        <ode>
                            <kp>100000</kp>
                            <kd>1</kd>
                        </ode>
                    </contact>
                </surface>
            </collision>
            <collision name='victor_right_arm_link_7_fixed_joint_lump__victor_right_gripper_mounting_bracket_collision_1'>
                <max_contacts>4</max_contacts>
                <pose frame=''>0 0 0.045 0 -0 0</pose>
                <geometry>
                    <mesh>
                        <uri>file://victor_description/meshes/robotiq_3finger/kuka_to_palm_connectors_collision.stl
                        </uri>
                    </mesh>
                </geometry>
                <surface>
                    <friction>
                        <ode>
                            <mu>1</mu>
                            <mu2>1</mu2>
                        </ode>
                    </friction>
                    <contact>
                        <ode>
                            <kp>1e+13</kp>
                            <kd>1</kd>
                        </ode>
                    </contact>
                </surface>
            </collision>
            <collision name='victor_right_arm_link_7_fixed_joint_lump__victor_right_gripper_palm_collision_2'>
                <max_contacts>4</max_contacts>
                <pose frame=''>0 0 0.07205 0 -0 0.785398</pose>
                <geometry>
                    <mesh>
                        <uri>file://victor_description/meshes/robotiq_3finger/palm_collision.stl</uri>
                    </mesh>
                </geometry>
                <surface>
                    <friction>
                        <ode>
                            <mu>1</mu>
                            <mu2>1</mu2>
                        </ode>
                    </friction>
                    <contact>
                        <ode>
                            <kp>1e+13</kp>
                            <kd>1</kd>
                        </ode>
                    </contact>
                </surface>
            </collision>
            <collision name='victor_right_arm_link_7_fixed_joint_lump__victor_right_gripper_fingerA_base_collision_3'>
                <max_contacts>4</max_contacts>
                <pose frame=''>0.015733 0.015733 0.133169 0 -0 0.785398</pose>
                <geometry>
                    <mesh>
                        <uri>file://victor_description/meshes/robotiq_3finger/finger_link1_base_visual.stl</uri>
                    </mesh>
                </geometry>
                <surface>
                    <friction>
                        <ode>
                            <mu>1</mu>
                            <mu2>1</mu2>
                        </ode>
                    </friction>
                    <contact>
                        <ode>
                            <kp>100000</kp>
                            <kd>1</kd>
                        </ode>
                    </contact>
                </surface>
            </collision>
        </link>
        <link name='victor_right_gripper_fingerA_dist'>
            <pose frame=''>1.05749 -1.11685 1.3181 1.39886 -0.770319 1.02978</pose>
            <inertial>
                <pose frame=''>0 0 0 0 -0 0</pose>
                <mass>1</mass>
                <inertia>
                    <ixx>0.01</ixx>
                    <ixy>0</ixy>
                    <ixz>0</ixz>
                    <iyy>0.01</iyy>
                    <iyz>0</iyz>
                    <izz>0.01</izz>
                </inertia>
            </inertial>
            <kinematic>1</kinematic>
            <visual name='victor_right_gripper_fingerA_dist_visual'>
                <pose frame=''>0 0 0 0 -0 0</pose>
                <geometry>
                    <mesh>
                        <uri>file://victor_description/meshes/robotiq_3finger/finger_link4_dist_visual.stl</uri>
                    </mesh>
                </geometry>
                <material>
                    <script>
                        <uri>__default__</uri>
                        <name>__default__</name>
                    </script>
                </material>
            </visual>
            <collision name='victor_right_gripper_fingerA_dist_collision'>
                <max_contacts>4</max_contacts>
                <pose frame=''>0 0 0 0 -0 0</pose>
                <geometry>
                    <mesh>
                        <uri>file://victor_description/meshes/robotiq_3finger/finger_link4_dist_collision.stl</uri>
                    </mesh>
                </geometry>
                <surface>
                    <friction>
                        <ode>
                            <mu>1</mu>
                            <mu2>1</mu2>
                        </ode>
                    </friction>
                    <contact>
                        <ode>
                            <kp>100000</kp>
                            <kd>1</kd>
                        </ode>
                    </contact>
                </surface>
            </collision>
        </link>
        <link name='victor_right_gripper_fingerA_med'>
            <pose frame=''>1.0245 -1.10571 1.30265 1.05003 -0.617781 1.56589</pose>
            <inertial>
                <pose frame=''>0 0 0 0 -0 0</pose>
                <mass>1</mass>
                <inertia>
                    <ixx>0.01</ixx>
                    <ixy>0</ixy>
                    <ixz>0</ixz>
                    <iyy>0.01</iyy>
                    <iyz>0</iyz>
                    <izz>0.01</izz>
                </inertia>
            </inertial>
            <kinematic>1</kinematic>
            <visual name='victor_right_gripper_fingerA_med_visual'>
                <pose frame=''>0 0 0 0 -0 0</pose>
                <geometry>
                    <mesh>
                        <uri>file://victor_description/meshes/robotiq_3finger/finger_link3_med_visual.stl</uri>
                    </mesh>
                </geometry>
                <material>
                    <script>
                        <uri>__default__</uri>
                        <name>__default__</name>
                    </script>
                </material>
            </visual>
            <collision name='victor_right_gripper_fingerA_med_collision'>
                <max_contacts>4</max_contacts>
                <pose frame=''>0 0 0 0 -0 0</pose>
                <geometry>
                    <mesh>
                        <uri>file://victor_description/meshes/robotiq_3finger/finger_link3_med_collision.stl</uri>
                    </mesh>
                </geometry>
                <surface>
                    <friction>
                        <ode>
                            <mu>1</mu>
                            <mu2>1</mu2>
                        </ode>
                    </friction>
                    <contact>
                        <ode>
                            <kp>100000</kp>
                            <kd>1</kd>
                        </ode>
                    </contact>
                </surface>
            </collision>
        </link>
        <link name='victor_right_gripper_fingerA_prox'>
            <pose frame=''>0.975005 -1.08899 1.27947 1.05003 -0.617781 1.56589</pose>
            <inertial>
                <pose frame=''>0 0 0 0 -0 0</pose>
                <mass>1</mass>
                <inertia>
                    <ixx>0.01</ixx>
                    <ixy>0</ixy>
                    <ixz>0</ixz>
                    <iyy>0.01</iyy>
                    <iyz>0</iyz>
                    <izz>0.01</izz>
                </inertia>
            </inertial>
            <kinematic>1</kinematic>
            <visual name='victor_right_gripper_fingerA_prox_visual'>
                <pose frame=''>0 0 0 0 -0 0</pose>
                <geometry>
                    <mesh>
                        <uri>file://victor_description/meshes/robotiq_3finger/finger_link2_prox_visual.stl</uri>
                    </mesh>
                </geometry>
                <material>
                    <script>
                        <uri>__default__</uri>
                        <name>__default__</name>
                    </script>
                </material>
            </visual>
            <collision name='victor_right_gripper_fingerA_prox_collision'>
                <max_contacts>4</max_contacts>
                <pose frame=''>0 0 0 0 -0 0</pose>
                <geometry>
                    <mesh>
                        <uri>file://victor_description/meshes/robotiq_3finger/finger_link2_prox_collision.stl</uri>
                    </mesh>
                </geometry>
                <surface>
                    <friction>
                        <ode>
                            <mu>1</mu>
                            <mu2>1</mu2>
                        </ode>
                    </friction>
                    <contact>
                        <ode>
                            <kp>100000</kp>
                            <kd>1</kd>
                        </ode>
                    </contact>
                </surface>
            </collision>
        </link>
        <link name='victor_right_gripper_fingerB_base'>
            <pose frame=''>0.908135 -1.12544 1.25805 -1.5708 0.785398 -2.35619</pose>
            <inertial>
                <pose frame=''>0 0 0 0 -0 0</pose>
                <mass>1</mass>
                <inertia>
                    <ixx>0.01</ixx>
                    <ixy>0</ixy>
                    <ixz>0</ixz>
                    <iyy>0.01</iyy>
                    <iyz>0</iyz>
                    <izz>0.01</izz>
                </inertia>
            </inertial>
            <kinematic>1</kinematic>
            <visual name='victor_right_gripper_fingerB_base_visual'>
                <pose frame=''>0 0 0 0 -0 0</pose>
                <geometry>
                    <mesh>
                        <uri>file://victor_description/meshes/robotiq_3finger/finger_link1_base_visual.stl</uri>
                    </mesh>
                </geometry>
                <material>
                    <script>
                        <uri>__default__</uri>
                        <name>__default__</name>
                    </script>
                </material>
            </visual>
            <collision name='victor_right_gripper_fingerB_base_collision'>
                <max_contacts>4</max_contacts>
                <pose frame=''>0 0 0 0 -0 0</pose>
                <geometry>
                    <mesh>
                        <uri>file://victor_description/meshes/robotiq_3finger/finger_link1_base_visual.stl</uri>
                    </mesh>
                </geometry>
                <surface>
                    <friction>
                        <ode>
                            <mu>1</mu>
                            <mu2>1</mu2>
                        </ode>
                    </friction>
                    <contact>
                        <ode>
                            <kp>100000</kp>
                            <kd>1</kd>
                        </ode>
                    </contact>
                </surface>
            </collision>
        </link>
        <link name='victor_right_gripper_fingerB_dist'>
            <pose frame=''>0.940077 -1.23426 1.20368 -1.74273 0.770319 -2.60057</pose>
            <inertial>
                <pose frame=''>0 0 0 0 -0 0</pose>
                <mass>1</mass>
                <inertia>
                    <ixx>0.01</ixx>
                    <ixy>0</ixy>
                    <ixz>0</ixz>
                    <iyy>0.01</iyy>
                    <iyz>0</iyz>
                    <izz>0.01</izz>
                </inertia>
            </inertial>
            <kinematic>1</kinematic>
            <visual name='victor_right_gripper_fingerB_dist_visual'>
                <pose frame=''>0 0 0 0 -0 0</pose>
                <geometry>
                    <mesh>
                        <uri>file://victor_description/meshes/robotiq_3finger/finger_link4_dist_visual.stl</uri>
                    </mesh>
                </geometry>
                <material>
                    <script>
                        <uri>__default__</uri>
                        <name>__default__</name>
                    </script>
                </material>
            </visual>
            <collision name='victor_right_gripper_fingerB_dist_collision'>
                <max_contacts>4</max_contacts>
                <pose frame=''>0 0 0 0 -0 0</pose>
                <geometry>
                    <mesh>
                        <uri>file://victor_description/meshes/robotiq_3finger/finger_link4_dist_collision.stl</uri>
                    </mesh>
                </geometry>
                <surface>
                    <friction>
                        <ode>
                            <mu>1</mu>
                            <mu2>1</mu2>
                        </ode>
                    </friction>
                    <contact>
                        <ode>
                            <kp>100000</kp>
                            <kd>1</kd>
                        </ode>
                    </contact>
                </surface>
            </collision>
        </link>
        <link name='victor_right_gripper_fingerB_med'>
            <pose frame=''>0.928936 -1.20127 1.21914 -2.09156 0.617781 -3.13669</pose>
            <inertial>
                <pose frame=''>0 0 0 0 -0 0</pose>
                <mass>1</mass>
                <inertia>
                    <ixx>0.01</ixx>
                    <ixy>0</ixy>
                    <ixz>0</ixz>
                    <iyy>0.01</iyy>
                    <iyz>0</iyz>
                    <izz>0.01</izz>
                </inertia>
            </inertial>
            <kinematic>1</kinematic>
            <visual name='victor_right_gripper_fingerB_med_visual'>
                <pose frame=''>0 0 0 0 -0 0</pose>
                <geometry>
                    <mesh>
                        <uri>file://victor_description/meshes/robotiq_3finger/finger_link3_med_visual.stl</uri>
                    </mesh>
                </geometry>
                <material>
                    <script>
                        <uri>__default__</uri>
                        <name>__default__</name>
                    </script>
                </material>
            </visual>
            <collision name='victor_right_gripper_fingerB_med_collision'>
                <max_contacts>4</max_contacts>
                <pose frame=''>0 0 0 0 -0 0</pose>
                <geometry>
                    <mesh>
                        <uri>file://victor_description/meshes/robotiq_3finger/finger_link3_med_collision.stl</uri>
                    </mesh>
                </geometry>
                <surface>
                    <friction>
                        <ode>
                            <mu>1</mu>
                            <mu2>1</mu2>
                        </ode>
                    </friction>
                    <contact>
                        <ode>
                            <kp>100000</kp>
                            <kd>1</kd>
                        </ode>
                    </contact>
                </surface>
            </collision>
        </link>
        <link name='victor_right_gripper_fingerB_prox'>
            <pose frame=''>0.912223 -1.15177 1.24232 -2.09156 0.617781 -3.13669</pose>
            <inertial>
                <pose frame=''>0 0 0 0 -0 0</pose>
                <mass>1</mass>
                <inertia>
                    <ixx>0.01</ixx>
                    <ixy>0</ixy>
                    <ixz>0</ixz>
                    <iyy>0.01</iyy>
                    <iyz>0</iyz>
                    <izz>0.01</izz>
                </inertia>
            </inertial>
            <kinematic>1</kinematic>
            <visual name='victor_right_gripper_fingerB_prox_visual'>
                <pose frame=''>0 0 0 0 -0 0</pose>
                <geometry>
                    <mesh>
                        <uri>file://victor_description/meshes/robotiq_3finger/finger_link2_prox_visual.stl</uri>
                    </mesh>
                </geometry>
                <material>
                    <script>
                        <uri>__default__</uri>
                        <name>__default__</name>
                    </script>
                </material>
            </visual>
            <collision name='victor_right_gripper_fingerB_prox_collision'>
                <max_contacts>4</max_contacts>
                <pose frame=''>0 0 0 0 -0 0</pose>
                <geometry>
                    <mesh>
                        <uri>file://victor_description/meshes/robotiq_3finger/finger_link2_prox_collision.stl</uri>
                    </mesh>
                </geometry>
                <surface>
                    <friction>
                        <ode>
                            <mu>1</mu>
                            <mu2>1</mu2>
                        </ode>
                    </friction>
                    <contact>
                        <ode>
                            <kp>100000</kp>
                            <kd>1</kd>
                        </ode>
                    </contact>
                </surface>
            </collision>
        </link>
        <link name='victor_right_gripper_fingerC_base'>
            <pose frame=''>0.944648 -1.08892 1.20641 -1.5708 0.785398 -2.35619</pose>
            <inertial>
                <pose frame=''>0 0 0 0 -0 0</pose>
                <mass>1</mass>
                <inertia>
                    <ixx>0.01</ixx>
                    <ixy>0</ixy>
                    <ixz>0</ixz>
                    <iyy>0.01</iyy>
                    <iyz>0</iyz>
                    <izz>0.01</izz>
                </inertia>
            </inertial>
            <kinematic>1</kinematic>
            <visual name='victor_right_gripper_fingerC_base_visual'>
                <pose frame=''>0 0 0 0 -0 0</pose>
                <geometry>
                    <mesh>
                        <uri>file://victor_description/meshes/robotiq_3finger/finger_link1_base_visual.stl</uri>
                    </mesh>
                </geometry>
            </visual>
            <collision name='victor_right_gripper_fingerC_base_collision'>
                <max_contacts>4</max_contacts>
                <pose frame=''>0 0 0 0 -0 0</pose>
                <geometry>
                    <mesh>
                        <uri>file://victor_description/meshes/robotiq_3finger/finger_link1_base_visual.stl</uri>
                    </mesh>
                </geometry>
                <surface>
                    <friction>
                        <ode>
                            <mu>1</mu>
                            <mu2>1</mu2>
                        </ode>
                    </friction>
                    <contact>
                        <ode>
                            <kp>1e+13</kp>
                            <kd>1</kd>
                        </ode>
                    </contact>
                </surface>
            </collision>
        </link>
        <link name='victor_right_gripper_fingerC_dist'>
            <pose frame=''>0.97659 -1.19775 1.15205 -1.74273 0.770319 -2.60057</pose>
            <inertial>
                <pose frame=''>0 0 0 0 -0 0</pose>
                <mass>1</mass>
                <inertia>
                    <ixx>0.01</ixx>
                    <ixy>0</ixy>
                    <ixz>0</ixz>
                    <iyy>0.01</iyy>
                    <iyz>0</iyz>
                    <izz>0.01</izz>
                </inertia>
            </inertial>
            <kinematic>1</kinematic>
            <visual name='victor_right_gripper_fingerC_dist_visual'>
                <pose frame=''>0 0 0 0 -0 0</pose>
                <geometry>
                    <mesh>
                        <uri>file://victor_description/meshes/robotiq_3finger/finger_link4_dist_visual.stl</uri>
                    </mesh>
                </geometry>
            </visual>
            <collision name='victor_right_gripper_fingerC_dist_collision'>
                <max_contacts>4</max_contacts>
                <pose frame=''>0 0 0 0 -0 0</pose>
                <geometry>
                    <mesh>
                        <uri>file://victor_description/meshes/robotiq_3finger/finger_link4_dist_collision.stl</uri>
                    </mesh>
                </geometry>
                <surface>
                    <friction>
                        <ode>
                            <mu>1</mu>
                            <mu2>1</mu2>
                        </ode>
                    </friction>
                    <contact>
                        <ode>
                            <kp>1e+13</kp>
                            <kd>1</kd>
                        </ode>
                    </contact>
                </surface>
            </collision>
        </link>
        <link name='victor_right_gripper_fingerC_med'>
            <pose frame=''>0.965448 -1.16476 1.1675 -2.09156 0.617781 -3.13669</pose>
            <inertial>
                <pose frame=''>0 0 0 0 -0 0</pose>
                <mass>1</mass>
                <inertia>
                    <ixx>0.01</ixx>
                    <ixy>0</ixy>
                    <ixz>0</ixz>
                    <iyy>0.01</iyy>
                    <iyz>0</iyz>
                    <izz>0.01</izz>
                </inertia>
            </inertial>
            <kinematic>1</kinematic>
            <visual name='victor_right_gripper_fingerC_med_visual'>
                <pose frame=''>0 0 0 0 -0 0</pose>
                <geometry>
                    <mesh>
                        <uri>file://victor_description/meshes/robotiq_3finger/finger_link3_med_visual.stl</uri>
                    </mesh>
                </geometry>
            </visual>
            <collision name='victor_right_gripper_fingerC_med_collision'>
                <max_contacts>4</max_contacts>
                <pose frame=''>0 0 0 0 -0 0</pose>
                <geometry>
                    <mesh>
                        <uri>file://victor_description/meshes/robotiq_3finger/finger_link3_med_collision.stl</uri>
                    </mesh>
                </geometry>
                <surface>
                    <friction>
                        <ode>
                            <mu>1</mu>
                            <mu2>1</mu2>
                        </ode>
                    </friction>
                    <contact>
                        <ode>
                            <kp>1e+13</kp>
                            <kd>1</kd>
                        </ode>
                    </contact>
                </surface>
            </collision>
        </link>
        <link name='victor_right_gripper_fingerC_prox'>
            <pose frame=''>0.948735 -1.11526 1.19068 -2.09156 0.617781 -3.13669</pose>
            <inertial>
                <pose frame=''>0 0 0 0 -0 0</pose>
                <mass>1</mass>
                <inertia>
                    <ixx>0.01</ixx>
                    <ixy>0</ixy>
                    <ixz>0</ixz>
                    <iyy>0.01</iyy>
                    <iyz>0</iyz>
                    <izz>0.01</izz>
                </inertia>
            </inertial>
            <kinematic>1</kinematic>
            <visual name='victor_right_gripper_fingerC_prox_visual'>
                <pose frame=''>0 0 0 0 -0 0</pose>
                <geometry>
                    <mesh>
                        <uri>file://victor_description/meshes/robotiq_3finger/finger_link2_prox_visual.stl</uri>
                    </mesh>
                </geometry>
            </visual>
            <collision name='victor_right_gripper_fingerC_prox_collision'>
                <max_contacts>4</max_contacts>
                <pose frame=''>0 0 0 0 -0 0</pose>
                <geometry>
                    <mesh>
                        <uri>file://victor_description/meshes/robotiq_3finger/finger_link2_prox_collision.stl</uri>
                    </mesh>
                </geometry>
                <surface>
                    <friction>
                        <ode>
                            <mu>1</mu>
                            <mu2>1</mu2>
                        </ode>
                    </friction>
                    <contact>
                        <ode>
                            <kp>1e+13</kp>
                            <kd>1</kd>
                        </ode>
                    </contact>
                </surface>
            </collision>
        </link>
        <joint name='victor_left_arm_joint_1' type='revolute'>
            <parent>victor_root</parent>
            <child>victor_left_arm_link_1</child>
            <pose frame=''>0 0 0 0 -0 0</pose>
            <axis>
                <xyz>0.707107 0.707107 -0</xyz>
                <use_parent_model_frame>1</use_parent_model_frame>
                <limit>
                    <lower>-2.96706</lower>
                    <upper>2.96706</upper>
                </limit>
                <dynamics>
                    <damping>0.5</damping>
                    <friction>0</friction>
                </dynamics>
            </axis>
            <physics>
                <ode>
                    <limit>
                    </limit>
                </ode>
            </physics>
        </joint>
        <joint name='victor_left_arm_joint_2' type='revolute'>
            <parent>victor_left_arm_link_1</parent>
            <child>victor_left_arm_link_2</child>
            <pose frame=''>0 0 0 0 -0 0</pose>
            <axis>
                <xyz>-0 0 -1</xyz>
                <use_parent_model_frame>1</use_parent_model_frame>
                <limit>
                    <lower>-2.0944</lower>
                    <upper>2.0944</upper>
                </limit>
                <dynamics>
                    <damping>0.5</damping>
                    <friction>0</friction>
                </dynamics>
            </axis>
            <physics>
                <ode>
                    <limit>
                    </limit>
                </ode>
            </physics>
        </joint>
        <joint name='victor_left_arm_joint_3' type='revolute'>
            <parent>victor_left_arm_link_2</parent>
            <child>victor_left_arm_link_3</child>
            <pose frame=''>0 0 0 0 -0 0</pose>
            <axis>
                <xyz>0.707107 0.707107 -0</xyz>
                <use_parent_model_frame>1</use_parent_model_frame>
                <limit>
                    <lower>-2.96706</lower>
                    <upper>2.96706</upper>
                </limit>
                <dynamics>
                    <damping>0.5</damping>
                    <friction>0</friction>
                </dynamics>
            </axis>
            <physics>
                <ode>
                    <limit>
                    </limit>
                </ode>
            </physics>
        </joint>
        <joint name='victor_left_arm_joint_4' type='revolute'>
            <parent>victor_left_arm_link_3</parent>
            <child>victor_left_arm_link_4</child>
            <pose frame=''>0 0 0 0 -0 0</pose>
            <axis>
                <xyz>0 0 1</xyz>
                <use_parent_model_frame>1</use_parent_model_frame>
                <limit>
                    <lower>-2.0944</lower>
                    <upper>2.0944</upper>
                </limit>
                <dynamics>
                    <damping>0.5</damping>
                    <friction>0</friction>
                </dynamics>
            </axis>
            <physics>
                <ode>
                    <limit>
                    </limit>
                </ode>
            </physics>
        </joint>
        <joint name='victor_left_arm_joint_5' type='revolute'>
            <parent>victor_left_arm_link_4</parent>
            <child>victor_left_arm_link_5</child>
            <pose frame=''>0 0 0 0 -0 0</pose>
            <axis>
                <xyz>0.707107 0.707107 -0</xyz>
                <use_parent_model_frame>1</use_parent_model_frame>
                <limit>
                    <lower>-2.96706</lower>
                    <upper>2.96706</upper>
                </limit>
                <dynamics>
                    <damping>0.5</damping>
                    <friction>0</friction>
                </dynamics>
            </axis>
            <physics>
                <ode>
                    <limit>
                    </limit>
                </ode>
            </physics>
        </joint>
        <joint name='victor_left_arm_joint_6' type='revolute'>
            <parent>victor_left_arm_link_5</parent>
            <child>victor_left_arm_link_6</child>
            <pose frame=''>0 0 0 0 -0 0</pose>
            <axis>
                <xyz>-0 -0 -1</xyz>
                <use_parent_model_frame>1</use_parent_model_frame>
                <limit>
                    <lower>-2.0944</lower>
                    <upper>2.0944</upper>
                </limit>
                <dynamics>
                    <damping>0.5</damping>
                    <friction>0</friction>
                </dynamics>
            </axis>
            <physics>
                <ode>
                    <limit>
                    </limit>
                </ode>
            </physics>
        </joint>
        <joint name='victor_left_arm_joint_7' type='revolute'>
            <parent>victor_left_arm_link_6</parent>
            <child>victor_left_arm_link_7</child>
            <pose frame=''>0 0 0 0 -0 0</pose>
            <axis>
                <xyz>0.707107 0.707107 -0</xyz>
                <use_parent_model_frame>1</use_parent_model_frame>
                <limit>
                    <lower>-3.05433</lower>
                    <upper>3.05433</upper>
                </limit>
                <dynamics>
                    <damping>0.5</damping>
                    <friction>0</friction>
                </dynamics>
            </axis>
            <physics>
                <ode>
                    <limit>
                    </limit>
                </ode>
            </physics>
        </joint>
        <joint name='victor_left_gripper_fingerA_joint_2' type='revolute'>
            <parent>victor_left_arm_link_7</parent>
            <child>victor_left_gripper_fingerA_prox</child>
            <pose frame=''>0 0 0 0 -0 0</pose>
            <axis>
                <initial_position>0.7</initial_position>
                <xyz>0.5 -0.5 0.707107</xyz>
                <use_parent_model_frame>1</use_parent_model_frame>
                <limit>
                    <lower>0</lower>
                    <upper>1.22173</upper>
                </limit>
                <dynamics>
                    <damping>0.5</damping>
                    <friction>0</friction>
                </dynamics>
            </axis>
            <physics>
                <ode>
                    <limit>
                    </limit>
                </ode>
            </physics>
        </joint>
        <joint name='victor_left_gripper_fingerA_joint_3' type='revolute'>
            <parent>victor_left_gripper_fingerA_prox</parent>
            <child>victor_left_gripper_fingerA_med</child>
            <pose frame=''>0 0 0 0 -0 0</pose>
            <axis>
                <xyz>0.5 -0.5 0.707107</xyz>
                <use_parent_model_frame>1</use_parent_model_frame>
                <limit>
                    <lower>-1</lower>
                    <upper>1</upper>
                </limit>
                <dynamics>
                    <damping>0.5</damping>
                    <friction>0</friction>
                </dynamics>
            </axis>
            <physics>
                <ode>
                    <limit>
                    </limit>
                </ode>
            </physics>
        </joint>
        <joint name='victor_left_gripper_fingerA_joint_4' type='revolute'>
            <parent>victor_left_gripper_fingerA_med</parent>
            <child>victor_left_gripper_fingerA_dist</child>
            <pose frame=''>0 0 0 0 -0 0</pose>
            <axis>
                <xyz>0.5 -0.5 0.707107</xyz>
                <use_parent_model_frame>1</use_parent_model_frame>
                <limit>
                    <lower>-1</lower>
                    <upper>1</upper>
                </limit>
                <dynamics>
                    <damping>0.5</damping>
                    <friction>0</friction>
                </dynamics>
            </axis>
            <physics>
                <ode>
                    <limit>
                    </limit>
                </ode>
            </physics>
        </joint>
        <joint name='victor_left_gripper_fingerB_joint_2' type='revolute'>
            <parent>victor_left_gripper_fingerB_base</parent>
            <child>victor_left_gripper_fingerB_prox</child>
            <pose frame=''>0 0 0 0 -0 0</pose>
            <axis>
                <initial_position>0.7</initial_position>
                <xyz>-0.5 0.5 -0.707107</xyz>
                <use_parent_model_frame>1</use_parent_model_frame>
                <limit>
                    <lower>0</lower>
                    <upper>1.22173</upper>
                </limit>
                <dynamics>
                    <damping>0.5</damping>
                    <friction>0</friction>
                </dynamics>
            </axis>
            <physics>
                <ode>
                    <limit>
                    </limit>
                </ode>
            </physics>
        </joint>
        <joint name='victor_left_gripper_fingerB_joint_3' type='revolute'>
            <parent>victor_left_gripper_fingerB_prox</parent>
            <child>victor_left_gripper_fingerB_med</child>
            <pose frame=''>0 0 0 0 -0 0</pose>
            <axis>
                <xyz>-0.5 0.5 -0.707107</xyz>
                <use_parent_model_frame>1</use_parent_model_frame>
                <limit>
                    <lower>-1</lower>
                    <upper>1</upper>
                </limit>
                <dynamics>
                    <damping>0.5</damping>
                    <friction>0</friction>
                </dynamics>
            </axis>
            <physics>
                <ode>
                    <limit>
                    </limit>
                </ode>
            </physics>
        </joint>
        <joint name='victor_left_gripper_fingerB_joint_4' type='revolute'>
            <parent>victor_left_gripper_fingerB_med</parent>
            <child>victor_left_gripper_fingerB_dist</child>
            <pose frame=''>0 0 0 0 -0 0</pose>
            <axis>
                <xyz>-0.5 0.5 -0.707107</xyz>
                <use_parent_model_frame>1</use_parent_model_frame>
                <limit>
                    <lower>-1</lower>
                    <upper>1</upper>
                </limit>
                <dynamics>
                    <damping>0.5</damping>
                    <friction>0</friction>
                </dynamics>
            </axis>
            <physics>
                <ode>
                    <limit>
                    </limit>
                </ode>
            </physics>
        </joint>
        <joint name='victor_left_gripper_fingerB_knuckle' type='revolute'>
            <parent>victor_left_arm_link_7</parent>
            <child>victor_left_gripper_fingerB_base</child>
            <pose frame=''>0 0 0 0 -0 0</pose>
            <axis>
                <xyz>0.5 -0.5 -0.707107</xyz>
                <use_parent_model_frame>1</use_parent_model_frame>
                <limit>
                    <lower>-0.279253</lower>
                    <upper>0.174533</upper>
                </limit>
                <dynamics>
                    <damping>0.5</damping>
                    <friction>0</friction>
                </dynamics>
            </axis>
            <physics>
                <ode>
                    <limit>
                    </limit>
                </ode>
            </physics>
        </joint>
        <joint name='victor_left_gripper_fingerC_joint_2' type='revolute'>
            <parent>victor_left_gripper_fingerC_base</parent>
            <child>victor_left_gripper_fingerC_prox</child>
            <pose frame=''>0 0 0 0 -0 0</pose>
            <axis>
                <initial_position>0.7</initial_position>
                <xyz>-0.5 0.5 -0.707107</xyz>
                <use_parent_model_frame>1</use_parent_model_frame>
                <limit>
                    <lower>0</lower>
                    <upper>1.22173</upper>
                </limit>
                <dynamics>
                    <damping>0.5</damping>
                    <friction>0</friction>
                </dynamics>
            </axis>
            <physics>
                <ode>
                    <limit>
                    </limit>
                </ode>
            </physics>
        </joint>
        <joint name='victor_left_gripper_fingerC_joint_3' type='revolute'>
            <parent>victor_left_gripper_fingerC_prox</parent>
            <child>victor_left_gripper_fingerC_med</child>
            <pose frame=''>0 0 0 0 -0 0</pose>
            <axis>
                <xyz>-0.5 0.5 -0.707107</xyz>
                <use_parent_model_frame>1</use_parent_model_frame>
                <limit>
                    <lower>-1</lower>
                    <upper>1</upper>
                </limit>
                <dynamics>
                    <damping>0.5</damping>
                    <friction>0</friction>
                </dynamics>
            </axis>
            <physics>
                <ode>
                    <limit>
                    </limit>
                </ode>
            </physics>
        </joint>
        <joint name='victor_left_gripper_fingerC_joint_4' type='revolute'>
            <parent>victor_left_gripper_fingerC_med</parent>
            <child>victor_left_gripper_fingerC_dist</child>
            <pose frame=''>0 0 0 0 -0 0</pose>
            <axis>
                <xyz>-0.5 0.5 -0.707107</xyz>
                <use_parent_model_frame>1</use_parent_model_frame>
                <limit>
                    <lower>-1</lower>
                    <upper>1</upper>
                </limit>
                <dynamics>
                    <damping>0.5</damping>
                    <friction>0</friction>
                </dynamics>
            </axis>
            <physics>
                <ode>
                    <limit>
                    </limit>
                </ode>
            </physics>
        </joint>
        <joint name='victor_left_gripper_fingerC_knuckle' type='revolute'>
            <parent>victor_left_arm_link_7</parent>
            <child>victor_left_gripper_fingerC_base</child>
            <pose frame=''>0 0 0 0 -0 0</pose>
            <axis>
                <xyz>-0.5 0.5 0.707107</xyz>
                <use_parent_model_frame>1</use_parent_model_frame>
                <limit>
                    <lower>-0.279253</lower>
                    <upper>0.174533</upper>
                </limit>
                <dynamics>
                    <damping>0.5</damping>
                    <friction>0</friction>
                </dynamics>
            </axis>
            <physics>
                <ode>
                    <limit>
                    </limit>
                </ode>
            </physics>
        </joint>
        <joint name='victor_right_arm_joint_1' type='revolute'>
            <parent>victor_root</parent>
            <child>victor_right_arm_link_1</child>
            <pose frame=''>0 0 0 0 -0 0</pose>
            <axis>
                <xyz>0.707107 -0.707107 -0</xyz>
                <use_parent_model_frame>1</use_parent_model_frame>
                <limit>
                    <lower>-2.96706</lower>
                    <upper>2.96706</upper>
                </limit>
                <dynamics>
                    <damping>0.5</damping>
                    <friction>0</friction>
                </dynamics>
            </axis>
            <physics>
                <ode>
                    <limit>
                    </limit>
                </ode>
            </physics>
        </joint>
        <joint name='victor_right_arm_joint_2' type='revolute'>
            <parent>victor_right_arm_link_1</parent>
            <child>victor_right_arm_link_2</child>
            <pose frame=''>0 0 0 0 -0 0</pose>
            <axis>
                <xyz>0 -0 1</xyz>
                <use_parent_model_frame>1</use_parent_model_frame>
                <limit>
                    <lower>-2.0944</lower>
                    <upper>2.0944</upper>
                </limit>
                <dynamics>
                    <damping>0.5</damping>
                    <friction>0</friction>
                </dynamics>
            </axis>
            <physics>
                <ode>
                    <limit>
                    </limit>
                </ode>
            </physics>
        </joint>
        <joint name='victor_right_arm_joint_3' type='revolute'>
            <parent>victor_right_arm_link_2</parent>
            <child>victor_right_arm_link_3</child>
            <pose frame=''>0 0 0 0 -0 0</pose>
            <axis>
                <xyz>0.707107 -0.707107 -0</xyz>
                <use_parent_model_frame>1</use_parent_model_frame>
                <limit>
                    <lower>-2.96706</lower>
                    <upper>2.96706</upper>
                </limit>
                <dynamics>
                    <damping>0.5</damping>
                    <friction>0</friction>
                </dynamics>
            </axis>
            <physics>
                <ode>
                    <limit>
                    </limit>
                </ode>
            </physics>
        </joint>
        <joint name='victor_right_arm_joint_4' type='revolute'>
            <parent>victor_right_arm_link_3</parent>
            <child>victor_right_arm_link_4</child>
            <pose frame=''>0 0 0 0 -0 0</pose>
            <axis>
                <xyz>-0 0 -1</xyz>
                <use_parent_model_frame>1</use_parent_model_frame>
                <limit>
                    <lower>-2.0944</lower>
                    <upper>2.0944</upper>
                </limit>
                <dynamics>
                    <damping>0.5</damping>
                    <friction>0</friction>
                </dynamics>
            </axis>
            <physics>
                <ode>
                    <limit>
                    </limit>
                </ode>
            </physics>
        </joint>
        <joint name='victor_right_arm_joint_5' type='revolute'>
            <parent>victor_right_arm_link_4</parent>
            <child>victor_right_arm_link_5</child>
            <pose frame=''>0 0 0 0 -0 0</pose>
            <axis>
                <xyz>0.707107 -0.707107 0</xyz>
                <use_parent_model_frame>1</use_parent_model_frame>
                <limit>
                    <lower>-2.96706</lower>
                    <upper>2.96706</upper>
                </limit>
                <dynamics>
                    <damping>0.5</damping>
                    <friction>0</friction>
                </dynamics>
            </axis>
            <physics>
                <ode>
                    <limit>
                    </limit>
                </ode>
            </physics>
        </joint>
        <joint name='victor_right_arm_joint_6' type='revolute'>
            <parent>victor_right_arm_link_5</parent>
            <child>victor_right_arm_link_6</child>
            <pose frame=''>0 0 0 0 -0 0</pose>
            <axis>
                <xyz>-0 -0 1</xyz>
                <use_parent_model_frame>1</use_parent_model_frame>
                <limit>
                    <lower>-2.0944</lower>
                    <upper>2.0944</upper>
                </limit>
                <dynamics>
                    <damping>0.5</damping>
                    <friction>0</friction>
                </dynamics>
            </axis>
            <physics>
                <ode>
                    <limit>
                    </limit>
                </ode>
            </physics>
        </joint>
        <joint name='victor_right_arm_joint_7' type='revolute'>
            <parent>victor_right_arm_link_6</parent>
            <child>victor_right_arm_link_7</child>
            <pose frame=''>0 0 0 0 -0 0</pose>
            <axis>
                <xyz>0.707107 -0.707107 -0</xyz>
                <use_parent_model_frame>1</use_parent_model_frame>
                <limit>
                    <lower>-3.05433</lower>
                    <upper>3.05433</upper>
                </limit>
                <dynamics>
                    <damping>0.5</damping>
                    <friction>0</friction>
                </dynamics>
            </axis>
            <physics>
                <ode>
                    <limit>
                    </limit>
                </ode>
            </physics>
        </joint>
        <joint name='victor_right_gripper_fingerA_joint_2' type='revolute'>
            <parent>victor_right_arm_link_7</parent>
            <child>victor_right_gripper_fingerA_prox</child>
            <pose frame=''>0 0 0 0 -0 0</pose>
            <axis>
                <initial_position>0.7</initial_position>
                <xyz>0.5 0.5 -0.707107</xyz>
                <use_parent_model_frame>1</use_parent_model_frame>
                <limit>
                    <lower>0</lower>
                    <upper>1.22173</upper>
                </limit>
                <dynamics>
                    <damping>0.5</damping>
                    <friction>0</friction>
                </dynamics>
            </axis>
            <physics>
                <ode>
                    <limit>
                    </limit>
                </ode>
            </physics>
        </joint>
        <joint name='victor_right_gripper_fingerA_joint_3' type='revolute'>
            <parent>victor_right_gripper_fingerA_prox</parent>
            <child>victor_right_gripper_fingerA_med</child>
            <pose frame=''>0 0 0 0 -0 0</pose>
            <axis>
                <xyz>0.5 0.5 -0.707107</xyz>
                <use_parent_model_frame>1</use_parent_model_frame>
                <limit>
                    <lower>-1</lower>
                    <upper>1</upper>
                </limit>
                <dynamics>
                    <damping>0.5</damping>
                    <friction>0</friction>
                </dynamics>
            </axis>
            <physics>
                <ode>
                    <limit>
                    </limit>
                </ode>
            </physics>
        </joint>
        <joint name='victor_right_gripper_fingerA_joint_4' type='revolute'>
            <parent>victor_right_gripper_fingerA_med</parent>
            <child>victor_right_gripper_fingerA_dist</child>
            <pose frame=''>0 0 0 0 -0 0</pose>
            <axis>
                <xyz>0.5 0.5 -0.707107</xyz>
                <use_parent_model_frame>1</use_parent_model_frame>
                <limit>
                    <lower>-1</lower>
                    <upper>1</upper>
                </limit>
                <dynamics>
                    <damping>0.5</damping>
                    <friction>0</friction>
                </dynamics>
            </axis>
            <physics>
                <ode>
                    <limit>
                    </limit>
                </ode>
            </physics>
        </joint>
        <joint name='victor_right_gripper_fingerB_joint_2' type='revolute'>
            <parent>victor_right_gripper_fingerB_base</parent>
            <child>victor_right_gripper_fingerB_prox</child>
            <pose frame=''>0 0 0 0 -0 0</pose>
            <axis>
                <initial_position>0.7</initial_position>
                <xyz>-0.5 -0.5 0.707107</xyz>
                <use_parent_model_frame>1</use_parent_model_frame>
                <limit>
                    <lower>0</lower>
                    <upper>1.22173</upper>
                </limit>
                <dynamics>
                    <damping>0.5</damping>
                    <friction>0</friction>
                </dynamics>
            </axis>
            <physics>
                <ode>
                    <limit>
                    </limit>
                </ode>
            </physics>
        </joint>
        <joint name='victor_right_gripper_fingerB_joint_3' type='revolute'>
            <parent>victor_right_gripper_fingerB_prox</parent>
            <child>victor_right_gripper_fingerB_med</child>
            <pose frame=''>0 0 0 0 -0 0</pose>
            <axis>
                <xyz>-0.5 -0.5 0.707107</xyz>
                <use_parent_model_frame>1</use_parent_model_frame>
                <limit>
                    <lower>-1</lower>
                    <upper>1</upper>
                </limit>
                <dynamics>
                    <damping>0.5</damping>
                    <friction>0</friction>
                </dynamics>
            </axis>
            <physics>
                <ode>
                    <limit>
                    </limit>
                </ode>
            </physics>
        </joint>
        <joint name='victor_right_gripper_fingerB_joint_4' type='revolute'>
            <parent>victor_right_gripper_fingerB_med</parent>
            <child>victor_right_gripper_fingerB_dist</child>
            <pose frame=''>0 0 0 0 -0 0</pose>
            <axis>
                <xyz>-0.5 -0.5 0.707107</xyz>
                <use_parent_model_frame>1</use_parent_model_frame>
                <limit>
                    <lower>-1</lower>
                    <upper>1</upper>
                </limit>
                <dynamics>
                    <damping>0.5</damping>
                    <friction>0</friction>
                </dynamics>
            </axis>
            <physics>
                <ode>
                    <limit>
                    </limit>
                </ode>
            </physics>
        </joint>
        <joint name='victor_right_gripper_fingerB_knuckle' type='revolute'>
            <parent>victor_right_arm_link_7</parent>
            <child>victor_right_gripper_fingerB_base</child>
            <pose frame=''>0 0 0 0 -0 0</pose>
            <axis>
                <xyz>0.5 0.5 0.707107</xyz>
                <use_parent_model_frame>1</use_parent_model_frame>
                <limit>
                    <lower>-0.279253</lower>
                    <upper>0.174533</upper>
                </limit>
                <dynamics>
                    <damping>0.5</damping>
                    <friction>0</friction>
                </dynamics>
            </axis>
            <physics>
                <ode>
                    <limit>
                    </limit>
                </ode>
            </physics>
        </joint>
        <joint name='victor_right_gripper_fingerC_joint_2' type='revolute'>
            <parent>victor_right_gripper_fingerC_base</parent>
            <child>victor_right_gripper_fingerC_prox</child>
            <pose frame=''>0 0 0 0 -0 0</pose>
            <axis>
                <initial_position>0.7</initial_position>
                <xyz>-0.5 -0.5 0.707107</xyz>
                <use_parent_model_frame>1</use_parent_model_frame>
                <limit>
                    <lower>0</lower>
                    <upper>1.22173</upper>
                </limit>
                <dynamics>
                    <damping>0.5</damping>
                    <friction>0</friction>
                </dynamics>
            </axis>
            <physics>
                <ode>
                    <limit>
                    </limit>
                </ode>
            </physics>
        </joint>
        <joint name='victor_right_gripper_fingerC_joint_3' type='revolute'>
            <parent>victor_right_gripper_fingerC_prox</parent>
            <child>victor_right_gripper_fingerC_med</child>
            <pose frame=''>0 0 0 0 -0 0</pose>
            <axis>
                <xyz>-0.5 -0.5 0.707107</xyz>
                <use_parent_model_frame>1</use_parent_model_frame>
                <limit>
                    <lower>-1</lower>
                    <upper>1</upper>
                </limit>
                <dynamics>
                    <damping>0.5</damping>
                    <friction>0</friction>
                </dynamics>
            </axis>
            <physics>
                <ode>
                    <limit>
                    </limit>
                </ode>
            </physics>
        </joint>
        <joint name='victor_right_gripper_fingerC_joint_4' type='revolute'>
            <parent>victor_right_gripper_fingerC_med</parent>
            <child>victor_right_gripper_fingerC_dist</child>
            <pose frame=''>0 0 0 0 -0 0</pose>
            <axis>
                <xyz>-0.5 -0.5 0.707107</xyz>
                <use_parent_model_frame>1</use_parent_model_frame>
                <limit>
                    <lower>-1</lower>
                    <upper>1</upper>
                </limit>
                <dynamics>
                    <damping>0.5</damping>
                    <friction>0</friction>
                </dynamics>
            </axis>
            <physics>
                <ode>
                    <limit>
                    </limit>
                </ode>
            </physics>
        </joint>
        <joint name='victor_right_gripper_fingerC_knuckle' type='revolute'>
            <parent>victor_right_arm_link_7</parent>
            <child>victor_right_gripper_fingerC_base</child>
            <pose frame=''>0 0 0 0 -0 0</pose>
            <axis>
                <xyz>-0.5 -0.5 -0.707107</xyz>
                <use_parent_model_frame>1</use_parent_model_frame>
                <limit>
                    <lower>-0.279253</lower>
                    <upper>0.174533</upper>
                </limit>
                <dynamics>
                    <damping>0.5</damping>
                    <friction>0</friction>
                </dynamics>
            </axis>
            <physics>
                <ode>
                    <limit>
                    </limit>
                </ode>
            </physics>
        </joint>
        <plugin name='kinematic_victor' filename='libkinematic_victor_plugin.so'>
            <arm name="left">
                <initial_positions> -1.39626, 0.5759586531581284, 1.9, -1.3089969389957472, 9.947598300641403e-14, 0.733038285837619, -0.2617993877991509</initial_positions>
            </arm>
            <arm name="right">
                <initial_positions> -1.74533, -0.5759586531581287, -1.9, 1.3089969389957465, -1.9539925233402755e-14, -0.7330382858376183, 1.8325957145940466 </initial_positions>
            </arm>
            <max_dist_between_gripper_and_link_scale_factor>1.1</max_dist_between_gripper_and_link_scale_factor>
        </plugin>
    </model>
</sdf>
