
<sdf version="1.6">
    <model name="link_bot">
        <pose frame="">0 0 0 0 0 0</pose>
        
        <link name="link_1">
        <pose frame="">0.015 0 0 3.14159 -1.57079 3.14159</pose>
        <inertial>
            <pose frame="">0 0 0 0 0 0</pose>
            <mass>0.03
            </mass>
            <inertia>
                <ixx>2.7299999999999997e-06
                </ixx>
                <ixy>0</ixy>
                <ixz>0</ixz>
                <iyy>2.7299999999999997e-06
                </iyy>
                <iyz>0</iyz>
                <izz>9.600000000000001e-07
                </izz>
            </inertia>
        </inertial>
        <collision name="link_1_collision">
            <pose frame="">0 0 0 0 0 0</pose>
            <geometry>
                <cylinder>
                    <length>0.03</length>
                    <radius>0.008</radius>
                </cylinder>
            </geometry>
            <surface>
                <friction>
                    <ode>
                        <mu>0.20</mu>
                        <mu2>0.20</mu2>
                    </ode>
                </friction>
                <contact>
                    <ode>
                        <kp>1e15</kp>
                        <kd>1e13</kd>
                    </ode>
                </contact>
            </surface>
        </collision>

        <collision name="link_1_collision_ball1">
            <pose frame="">0 0 0.015 0 0 0</pose>
            <geometry>
                <sphere>
                    <radius>0.008</radius>
                </sphere>
            </geometry>
            <surface>
                <friction>
                    <ode>
                        <mu>0.20</mu>
                        <mu2>0.20</mu2>
                    </ode>
                </friction>
                <contact>
                    <ode>
                        <kp>1e15</kp>
                        <kd>1e13</kd>
                    </ode>
                </contact>
            </surface>
        </collision>

        <collision name="link_1_collision_ball2">
            <pose frame="">0 0 -0.015 0 0 0</pose>
            <geometry>
                <sphere>
                    <radius>0.008</radius>
                </sphere>
            </geometry>
            <surface>
                <friction>
                    <ode>
                        <mu>0.20</mu>
                        <mu2>0.20</mu2>
                    </ode>
                </friction>
                <contact>
                    <ode>
                        <kp>1e15</kp>
                        <kd>1e13</kd>
                    </ode>
                </contact>
            </surface>
        </collision>



        <visual name="link_1_visual">
            <cast_shadows>0</cast_shadows>
            <pose frame="">0 0 0 0 0 0</pose>
            <geometry>
                <cylinder>
                    <length>0.03
                    </length>
                    <radius>0.008
                    </radius>
                </cylinder>
            </geometry>
            <material>
                <script>
                    <name>Gazebo/Orange </name>
                    <uri>file://media/materials/scripts/gazebo.material</uri>
                </script>
            </material>
        </visual>
        <self_collide>1</self_collide>
        </link>
        
        <link name="link_2">
        <pose frame="">0.045 0 0 3.14159 -1.57079 3.14159</pose>
        <inertial>
            <pose frame="">0 0 0 0 0 0</pose>
            <mass>0.03
            </mass>
            <inertia>
                <ixx>2.7299999999999997e-06
                </ixx>
                <ixy>0</ixy>
                <ixz>0</ixz>
                <iyy>2.7299999999999997e-06
                </iyy>
                <iyz>0</iyz>
                <izz>9.600000000000001e-07
                </izz>
            </inertia>
        </inertial>
        <collision name="link_2_collision">
            <pose frame="">0 0 0 0 0 0</pose>
            <geometry>
                <cylinder>
                    <length>0.03</length>
                    <radius>0.008</radius>
                </cylinder>
            </geometry>
            <surface>
                <friction>
                    <ode>
                        <mu>0.20</mu>
                        <mu2>0.20</mu2>
                    </ode>
                </friction>
                <contact>
                    <ode>
                        <kp>1e15</kp>
                        <kd>1e13</kd>
                    </ode>
                </contact>
            </surface>
        </collision>

        <collision name="link_2_collision_ball1">
            <pose frame="">0 0 0.015 0 0 0</pose>
            <geometry>
                <sphere>
                    <radius>0.008</radius>
                </sphere>
            </geometry>
            <surface>
                <friction>
                    <ode>
                        <mu>0.20</mu>
                        <mu2>0.20</mu2>
                    </ode>
                </friction>
                <contact>
                    <ode>
                        <kp>1e15</kp>
                        <kd>1e13</kd>
                    </ode>
                </contact>
            </surface>
        </collision>

        <collision name="link_2_collision_ball2">
            <pose frame="">0 0 -0.015 0 0 0</pose>
            <geometry>
                <sphere>
                    <radius>0.008</radius>
                </sphere>
            </geometry>
            <surface>
                <friction>
                    <ode>
                        <mu>0.20</mu>
                        <mu2>0.20</mu2>
                    </ode>
                </friction>
                <contact>
                    <ode>
                        <kp>1e15</kp>
                        <kd>1e13</kd>
                    </ode>
                </contact>
            </surface>
        </collision>



        <visual name="link_2_visual">
            <cast_shadows>0</cast_shadows>
            <pose frame="">0 0 0 0 0 0</pose>
            <geometry>
                <cylinder>
                    <length>0.03
                    </length>
                    <radius>0.008
                    </radius>
                </cylinder>
            </geometry>
            <material>
                <script>
                    <name>Gazebo/Yellow </name>
                    <uri>file://media/materials/scripts/gazebo.material</uri>
                </script>
            </material>
        </visual>
        <self_collide>1</self_collide>
        </link>
        
        <link name="link_3">
        <pose frame="">0.075 0 0 3.14159 -1.57079 3.14159</pose>
        <inertial>
            <pose frame="">0 0 0 0 0 0</pose>
            <mass>0.03
            </mass>
            <inertia>
                <ixx>2.7299999999999997e-06
                </ixx>
                <ixy>0</ixy>
                <ixz>0</ixz>
                <iyy>2.7299999999999997e-06
                </iyy>
                <iyz>0</iyz>
                <izz>9.600000000000001e-07
                </izz>
            </inertia>
        </inertial>
        <collision name="link_3_collision">
            <pose frame="">0 0 0 0 0 0</pose>
            <geometry>
                <cylinder>
                    <length>0.03</length>
                    <radius>0.008</radius>
                </cylinder>
            </geometry>
            <surface>
                <friction>
                    <ode>
                        <mu>0.20</mu>
                        <mu2>0.20</mu2>
                    </ode>
                </friction>
                <contact>
                    <ode>
                        <kp>1e15</kp>
                        <kd>1e13</kd>
                    </ode>
                </contact>
            </surface>
        </collision>

        <collision name="link_3_collision_ball1">
            <pose frame="">0 0 0.015 0 0 0</pose>
            <geometry>
                <sphere>
                    <radius>0.008</radius>
                </sphere>
            </geometry>
            <surface>
                <friction>
                    <ode>
                        <mu>0.20</mu>
                        <mu2>0.20</mu2>
                    </ode>
                </friction>
                <contact>
                    <ode>
                        <kp>1e15</kp>
                        <kd>1e13</kd>
                    </ode>
                </contact>
            </surface>
        </collision>

        <collision name="link_3_collision_ball2">
            <pose frame="">0 0 -0.015 0 0 0</pose>
            <geometry>
                <sphere>
                    <radius>0.008</radius>
                </sphere>
            </geometry>
            <surface>
                <friction>
                    <ode>
                        <mu>0.20</mu>
                        <mu2>0.20</mu2>
                    </ode>
                </friction>
                <contact>
                    <ode>
                        <kp>1e15</kp>
                        <kd>1e13</kd>
                    </ode>
                </contact>
            </surface>
        </collision>



        <visual name="link_3_visual">
            <cast_shadows>0</cast_shadows>
            <pose frame="">0 0 0 0 0 0</pose>
            <geometry>
                <cylinder>
                    <length>0.03
                    </length>
                    <radius>0.008
                    </radius>
                </cylinder>
            </geometry>
            <material>
                <script>
                    <name>Gazebo/Green </name>
                    <uri>file://media/materials/scripts/gazebo.material</uri>
                </script>
            </material>
        </visual>
        <self_collide>1</self_collide>
        </link>
        
        <link name="link_4">
        <pose frame="">0.105 0 0 3.14159 -1.57079 3.14159</pose>
        <inertial>
            <pose frame="">0 0 0 0 0 0</pose>
            <mass>0.03
            </mass>
            <inertia>
                <ixx>2.7299999999999997e-06
                </ixx>
                <ixy>0</ixy>
                <ixz>0</ixz>
                <iyy>2.7299999999999997e-06
                </iyy>
                <iyz>0</iyz>
                <izz>9.600000000000001e-07
                </izz>
            </inertia>
        </inertial>
        <collision name="link_4_collision">
            <pose frame="">0 0 0 0 0 0</pose>
            <geometry>
                <cylinder>
                    <length>0.03</length>
                    <radius>0.008</radius>
                </cylinder>
            </geometry>
            <surface>
                <friction>
                    <ode>
                        <mu>0.20</mu>
                        <mu2>0.20</mu2>
                    </ode>
                </friction>
                <contact>
                    <ode>
                        <kp>1e15</kp>
                        <kd>1e13</kd>
                    </ode>
                </contact>
            </surface>
        </collision>

        <collision name="link_4_collision_ball1">
            <pose frame="">0 0 0.015 0 0 0</pose>
            <geometry>
                <sphere>
                    <radius>0.008</radius>
                </sphere>
            </geometry>
            <surface>
                <friction>
                    <ode>
                        <mu>0.20</mu>
                        <mu2>0.20</mu2>
                    </ode>
                </friction>
                <contact>
                    <ode>
                        <kp>1e15</kp>
                        <kd>1e13</kd>
                    </ode>
                </contact>
            </surface>
        </collision>

        <collision name="link_4_collision_ball2">
            <pose frame="">0 0 -0.015 0 0 0</pose>
            <geometry>
                <sphere>
                    <radius>0.008</radius>
                </sphere>
            </geometry>
            <surface>
                <friction>
                    <ode>
                        <mu>0.20</mu>
                        <mu2>0.20</mu2>
                    </ode>
                </friction>
                <contact>
                    <ode>
                        <kp>1e15</kp>
                        <kd>1e13</kd>
                    </ode>
                </contact>
            </surface>
        </collision>



        <visual name="link_4_visual">
            <cast_shadows>0</cast_shadows>
            <pose frame="">0 0 0 0 0 0</pose>
            <geometry>
                <cylinder>
                    <length>0.03
                    </length>
                    <radius>0.008
                    </radius>
                </cylinder>
            </geometry>
            <material>
                <script>
                    <name>Gazebo/Blue </name>
                    <uri>file://media/materials/scripts/gazebo.material</uri>
                </script>
            </material>
        </visual>
        <self_collide>1</self_collide>
        </link>
        
        <link name="link_5">
        <pose frame="">0.135 0 0 3.14159 -1.57079 3.14159</pose>
        <inertial>
            <pose frame="">0 0 0 0 0 0</pose>
            <mass>0.03
            </mass>
            <inertia>
                <ixx>2.7299999999999997e-06
                </ixx>
                <ixy>0</ixy>
                <ixz>0</ixz>
                <iyy>2.7299999999999997e-06
                </iyy>
                <iyz>0</iyz>
                <izz>9.600000000000001e-07
                </izz>
            </inertia>
        </inertial>
        <collision name="link_5_collision">
            <pose frame="">0 0 0 0 0 0</pose>
            <geometry>
                <cylinder>
                    <length>0.03</length>
                    <radius>0.008</radius>
                </cylinder>
            </geometry>
            <surface>
                <friction>
                    <ode>
                        <mu>0.20</mu>
                        <mu2>0.20</mu2>
                    </ode>
                </friction>
                <contact>
                    <ode>
                        <kp>1e15</kp>
                        <kd>1e13</kd>
                    </ode>
                </contact>
            </surface>
        </collision>

        <collision name="link_5_collision_ball1">
            <pose frame="">0 0 0.015 0 0 0</pose>
            <geometry>
                <sphere>
                    <radius>0.008</radius>
                </sphere>
            </geometry>
            <surface>
                <friction>
                    <ode>
                        <mu>0.20</mu>
                        <mu2>0.20</mu2>
                    </ode>
                </friction>
                <contact>
                    <ode>
                        <kp>1e15</kp>
                        <kd>1e13</kd>
                    </ode>
                </contact>
            </surface>
        </collision>

        <collision name="link_5_collision_ball2">
            <pose frame="">0 0 -0.015 0 0 0</pose>
            <geometry>
                <sphere>
                    <radius>0.008</radius>
                </sphere>
            </geometry>
            <surface>
                <friction>
                    <ode>
                        <mu>0.20</mu>
                        <mu2>0.20</mu2>
                    </ode>
                </friction>
                <contact>
                    <ode>
                        <kp>1e15</kp>
                        <kd>1e13</kd>
                    </ode>
                </contact>
            </surface>
        </collision>



        <visual name="link_5_visual">
            <cast_shadows>0</cast_shadows>
            <pose frame="">0 0 0 0 0 0</pose>
            <geometry>
                <cylinder>
                    <length>0.03
                    </length>
                    <radius>0.008
                    </radius>
                </cylinder>
            </geometry>
            <material>
                <script>
                    <name>Gazebo/Purple </name>
                    <uri>file://media/materials/scripts/gazebo.material</uri>
                </script>
            </material>
        </visual>
        <self_collide>1</self_collide>
        </link>
        
        <link name="link_6">
        <pose frame="">0.16499999999999998 0 0 3.14159 -1.57079 3.14159</pose>
        <inertial>
            <pose frame="">0 0 0 0 0 0</pose>
            <mass>0.03
            </mass>
            <inertia>
                <ixx>2.7299999999999997e-06
                </ixx>
                <ixy>0</ixy>
                <ixz>0</ixz>
                <iyy>2.7299999999999997e-06
                </iyy>
                <iyz>0</iyz>
                <izz>9.600000000000001e-07
                </izz>
            </inertia>
        </inertial>
        <collision name="link_6_collision">
            <pose frame="">0 0 0 0 0 0</pose>
            <geometry>
                <cylinder>
                    <length>0.03</length>
                    <radius>0.008</radius>
                </cylinder>
            </geometry>
            <surface>
                <friction>
                    <ode>
                        <mu>0.20</mu>
                        <mu2>0.20</mu2>
                    </ode>
                </friction>
                <contact>
                    <ode>
                        <kp>1e15</kp>
                        <kd>1e13</kd>
                    </ode>
                </contact>
            </surface>
        </collision>

        <collision name="link_6_collision_ball1">
            <pose frame="">0 0 0.015 0 0 0</pose>
            <geometry>
                <sphere>
                    <radius>0.008</radius>
                </sphere>
            </geometry>
            <surface>
                <friction>
                    <ode>
                        <mu>0.20</mu>
                        <mu2>0.20</mu2>
                    </ode>
                </friction>
                <contact>
                    <ode>
                        <kp>1e15</kp>
                        <kd>1e13</kd>
                    </ode>
                </contact>
            </surface>
        </collision>

        <collision name="link_6_collision_ball2">
            <pose frame="">0 0 -0.015 0 0 0</pose>
            <geometry>
                <sphere>
                    <radius>0.008</radius>
                </sphere>
            </geometry>
            <surface>
                <friction>
                    <ode>
                        <mu>0.20</mu>
                        <mu2>0.20</mu2>
                    </ode>
                </friction>
                <contact>
                    <ode>
                        <kp>1e15</kp>
                        <kd>1e13</kd>
                    </ode>
                </contact>
            </surface>
        </collision>



        <visual name="link_6_visual">
            <cast_shadows>0</cast_shadows>
            <pose frame="">0 0 0 0 0 0</pose>
            <geometry>
                <cylinder>
                    <length>0.03
                    </length>
                    <radius>0.008
                    </radius>
                </cylinder>
            </geometry>
            <material>
                <script>
                    <name>Gazebo/White </name>
                    <uri>file://media/materials/scripts/gazebo.material</uri>
                </script>
            </material>
        </visual>
        <self_collide>1</self_collide>
        </link>
        
        <link name="link_7">
        <pose frame="">0.195 0 0 3.14159 -1.57079 3.14159</pose>
        <inertial>
            <pose frame="">0 0 0 0 0 0</pose>
            <mass>0.03
            </mass>
            <inertia>
                <ixx>2.7299999999999997e-06
                </ixx>
                <ixy>0</ixy>
                <ixz>0</ixz>
                <iyy>2.7299999999999997e-06
                </iyy>
                <iyz>0</iyz>
                <izz>9.600000000000001e-07
                </izz>
            </inertia>
        </inertial>
        <collision name="link_7_collision">
            <pose frame="">0 0 0 0 0 0</pose>
            <geometry>
                <cylinder>
                    <length>0.03</length>
                    <radius>0.008</radius>
                </cylinder>
            </geometry>
            <surface>
                <friction>
                    <ode>
                        <mu>0.20</mu>
                        <mu2>0.20</mu2>
                    </ode>
                </friction>
                <contact>
                    <ode>
                        <kp>1e15</kp>
                        <kd>1e13</kd>
                    </ode>
                </contact>
            </surface>
        </collision>

        <collision name="link_7_collision_ball1">
            <pose frame="">0 0 0.015 0 0 0</pose>
            <geometry>
                <sphere>
                    <radius>0.008</radius>
                </sphere>
            </geometry>
            <surface>
                <friction>
                    <ode>
                        <mu>0.20</mu>
                        <mu2>0.20</mu2>
                    </ode>
                </friction>
                <contact>
                    <ode>
                        <kp>1e15</kp>
                        <kd>1e13</kd>
                    </ode>
                </contact>
            </surface>
        </collision>

        <collision name="link_7_collision_ball2">
            <pose frame="">0 0 -0.015 0 0 0</pose>
            <geometry>
                <sphere>
                    <radius>0.008</radius>
                </sphere>
            </geometry>
            <surface>
                <friction>
                    <ode>
                        <mu>0.20</mu>
                        <mu2>0.20</mu2>
                    </ode>
                </friction>
                <contact>
                    <ode>
                        <kp>1e15</kp>
                        <kd>1e13</kd>
                    </ode>
                </contact>
            </surface>
        </collision>



        <visual name="link_7_visual">
            <cast_shadows>0</cast_shadows>
            <pose frame="">0 0 0 0 0 0</pose>
            <geometry>
                <cylinder>
                    <length>0.03
                    </length>
                    <radius>0.008
                    </radius>
                </cylinder>
            </geometry>
            <material>
                <script>
                    <name>Gazebo/Black </name>
                    <uri>file://media/materials/scripts/gazebo.material</uri>
                </script>
            </material>
        </visual>
        <self_collide>1</self_collide>
        </link>
        
        <link name="link_8">
        <pose frame="">0.22499999999999998 0 0 3.14159 -1.57079 3.14159</pose>
        <inertial>
            <pose frame="">0 0 0 0 0 0</pose>
            <mass>0.03
            </mass>
            <inertia>
                <ixx>2.7299999999999997e-06
                </ixx>
                <ixy>0</ixy>
                <ixz>0</ixz>
                <iyy>2.7299999999999997e-06
                </iyy>
                <iyz>0</iyz>
                <izz>9.600000000000001e-07
                </izz>
            </inertia>
        </inertial>
        <collision name="link_8_collision">
            <pose frame="">0 0 0 0 0 0</pose>
            <geometry>
                <cylinder>
                    <length>0.03</length>
                    <radius>0.008</radius>
                </cylinder>
            </geometry>
            <surface>
                <friction>
                    <ode>
                        <mu>0.20</mu>
                        <mu2>0.20</mu2>
                    </ode>
                </friction>
                <contact>
                    <ode>
                        <kp>1e15</kp>
                        <kd>1e13</kd>
                    </ode>
                </contact>
            </surface>
        </collision>

        <collision name="link_8_collision_ball1">
            <pose frame="">0 0 0.015 0 0 0</pose>
            <geometry>
                <sphere>
                    <radius>0.008</radius>
                </sphere>
            </geometry>
            <surface>
                <friction>
                    <ode>
                        <mu>0.20</mu>
                        <mu2>0.20</mu2>
                    </ode>
                </friction>
                <contact>
                    <ode>
                        <kp>1e15</kp>
                        <kd>1e13</kd>
                    </ode>
                </contact>
            </surface>
        </collision>

        <collision name="link_8_collision_ball2">
            <pose frame="">0 0 -0.015 0 0 0</pose>
            <geometry>
                <sphere>
                    <radius>0.008</radius>
                </sphere>
            </geometry>
            <surface>
                <friction>
                    <ode>
                        <mu>0.20</mu>
                        <mu2>0.20</mu2>
                    </ode>
                </friction>
                <contact>
                    <ode>
                        <kp>1e15</kp>
                        <kd>1e13</kd>
                    </ode>
                </contact>
            </surface>
        </collision>



        <visual name="link_8_visual">
            <cast_shadows>0</cast_shadows>
            <pose frame="">0 0 0 0 0 0</pose>
            <geometry>
                <cylinder>
                    <length>0.03
                    </length>
                    <radius>0.008
                    </radius>
                </cylinder>
            </geometry>
            <material>
                <script>
                    <name>Gazebo/Red </name>
                    <uri>file://media/materials/scripts/gazebo.material</uri>
                </script>
            </material>
        </visual>
        <self_collide>1</self_collide>
        </link>
        
        <link name="link_9">
        <pose frame="">0.255 0 0 3.14159 -1.57079 3.14159</pose>
        <inertial>
            <pose frame="">0 0 0 0 0 0</pose>
            <mass>0.03
            </mass>
            <inertia>
                <ixx>2.7299999999999997e-06
                </ixx>
                <ixy>0</ixy>
                <ixz>0</ixz>
                <iyy>2.7299999999999997e-06
                </iyy>
                <iyz>0</iyz>
                <izz>9.600000000000001e-07
                </izz>
            </inertia>
        </inertial>
        <collision name="link_9_collision">
            <pose frame="">0 0 0 0 0 0</pose>
            <geometry>
                <cylinder>
                    <length>0.03</length>
                    <radius>0.008</radius>
                </cylinder>
            </geometry>
            <surface>
                <friction>
                    <ode>
                        <mu>0.20</mu>
                        <mu2>0.20</mu2>
                    </ode>
                </friction>
                <contact>
                    <ode>
                        <kp>1e15</kp>
                        <kd>1e13</kd>
                    </ode>
                </contact>
            </surface>
        </collision>

        <collision name="link_9_collision_ball1">
            <pose frame="">0 0 0.015 0 0 0</pose>
            <geometry>
                <sphere>
                    <radius>0.008</radius>
                </sphere>
            </geometry>
            <surface>
                <friction>
                    <ode>
                        <mu>0.20</mu>
                        <mu2>0.20</mu2>
                    </ode>
                </friction>
                <contact>
                    <ode>
                        <kp>1e15</kp>
                        <kd>1e13</kd>
                    </ode>
                </contact>
            </surface>
        </collision>

        <collision name="link_9_collision_ball2">
            <pose frame="">0 0 -0.015 0 0 0</pose>
            <geometry>
                <sphere>
                    <radius>0.008</radius>
                </sphere>
            </geometry>
            <surface>
                <friction>
                    <ode>
                        <mu>0.20</mu>
                        <mu2>0.20</mu2>
                    </ode>
                </friction>
                <contact>
                    <ode>
                        <kp>1e15</kp>
                        <kd>1e13</kd>
                    </ode>
                </contact>
            </surface>
        </collision>



        <visual name="link_9_visual">
            <cast_shadows>0</cast_shadows>
            <pose frame="">0 0 0 0 0 0</pose>
            <geometry>
                <cylinder>
                    <length>0.03
                    </length>
                    <radius>0.008
                    </radius>
                </cylinder>
            </geometry>
            <material>
                <script>
                    <name>Gazebo/Orange </name>
                    <uri>file://media/materials/scripts/gazebo.material</uri>
                </script>
            </material>
        </visual>
        <self_collide>1</self_collide>
        </link>
        
        <link name="link_10">
        <pose frame="">0.28500000000000003 0 0 3.14159 -1.57079 3.14159</pose>
        <inertial>
            <pose frame="">0 0 0 0 0 0</pose>
            <mass>0.03
            </mass>
            <inertia>
                <ixx>2.7299999999999997e-06
                </ixx>
                <ixy>0</ixy>
                <ixz>0</ixz>
                <iyy>2.7299999999999997e-06
                </iyy>
                <iyz>0</iyz>
                <izz>9.600000000000001e-07
                </izz>
            </inertia>
        </inertial>
        <collision name="link_10_collision">
            <pose frame="">0 0 0 0 0 0</pose>
            <geometry>
                <cylinder>
                    <length>0.03</length>
                    <radius>0.008</radius>
                </cylinder>
            </geometry>
            <surface>
                <friction>
                    <ode>
                        <mu>0.20</mu>
                        <mu2>0.20</mu2>
                    </ode>
                </friction>
                <contact>
                    <ode>
                        <kp>1e15</kp>
                        <kd>1e13</kd>
                    </ode>
                </contact>
            </surface>
        </collision>

        <collision name="link_10_collision_ball1">
            <pose frame="">0 0 0.015 0 0 0</pose>
            <geometry>
                <sphere>
                    <radius>0.008</radius>
                </sphere>
            </geometry>
            <surface>
                <friction>
                    <ode>
                        <mu>0.20</mu>
                        <mu2>0.20</mu2>
                    </ode>
                </friction>
                <contact>
                    <ode>
                        <kp>1e15</kp>
                        <kd>1e13</kd>
                    </ode>
                </contact>
            </surface>
        </collision>

        <collision name="link_10_collision_ball2">
            <pose frame="">0 0 -0.015 0 0 0</pose>
            <geometry>
                <sphere>
                    <radius>0.008</radius>
                </sphere>
            </geometry>
            <surface>
                <friction>
                    <ode>
                        <mu>0.20</mu>
                        <mu2>0.20</mu2>
                    </ode>
                </friction>
                <contact>
                    <ode>
                        <kp>1e15</kp>
                        <kd>1e13</kd>
                    </ode>
                </contact>
            </surface>
        </collision>



        <visual name="link_10_visual">
            <cast_shadows>0</cast_shadows>
            <pose frame="">0 0 0 0 0 0</pose>
            <geometry>
                <cylinder>
                    <length>0.03
                    </length>
                    <radius>0.008
                    </radius>
                </cylinder>
            </geometry>
            <material>
                <script>
                    <name>Gazebo/Yellow </name>
                    <uri>file://media/materials/scripts/gazebo.material</uri>
                </script>
            </material>
        </visual>
        <self_collide>1</self_collide>
        </link>
        
        
        <joint name="joint_1" type="universal">
            <child>link_2</child>
            <parent>link_1</parent>
            <pose>0 0 0.015 0 0 0 </pose>
            <axis>
                <xyz>0 0 1</xyz>
                <limit>
                    <lower>-2.0</lower>
                    <upper>2.0</upper>
                </limit>
                <dynamics>
                    <damping>0.001</damping>
                    <friction>0.002</friction>
                </dynamics>
                <use_parent_model_frame>1</use_parent_model_frame>
            </axis>
            <axis2>
                <xyz>0 1 0</xyz>
                <limit>
                    <lower>-2.0</lower>
                    <upper>2.0</upper>
                </limit>
                <dynamics>
                    <damping>0.001</damping>
                    <friction>0.002</friction>
                </dynamics>
                <use_parent_model_frame>1</use_parent_model_frame>
            </axis2>
            <physics>
                <ode>
                </ode>
            </physics>
        </joint>
        
        <joint name="joint_2" type="universal">
            <child>link_3</child>
            <parent>link_2</parent>
            <pose>0 0 0.015 0 0 0 </pose>
            <axis>
                <xyz>0 0 1</xyz>
                <limit>
                    <lower>-2.0</lower>
                    <upper>2.0</upper>
                </limit>
                <dynamics>
                    <damping>0.001</damping>
                    <friction>0.002</friction>
                </dynamics>
                <use_parent_model_frame>1</use_parent_model_frame>
            </axis>
            <axis2>
                <xyz>0 1 0</xyz>
                <limit>
                    <lower>-2.0</lower>
                    <upper>2.0</upper>
                </limit>
                <dynamics>
                    <damping>0.001</damping>
                    <friction>0.002</friction>
                </dynamics>
                <use_parent_model_frame>1</use_parent_model_frame>
            </axis2>
            <physics>
                <ode>
                </ode>
            </physics>
        </joint>
        
        <joint name="joint_3" type="universal">
            <child>link_4</child>
            <parent>link_3</parent>
            <pose>0 0 0.015 0 0 0 </pose>
            <axis>
                <xyz>0 0 1</xyz>
                <limit>
                    <lower>-2.0</lower>
                    <upper>2.0</upper>
                </limit>
                <dynamics>
                    <damping>0.001</damping>
                    <friction>0.002</friction>
                </dynamics>
                <use_parent_model_frame>1</use_parent_model_frame>
            </axis>
            <axis2>
                <xyz>0 1 0</xyz>
                <limit>
                    <lower>-2.0</lower>
                    <upper>2.0</upper>
                </limit>
                <dynamics>
                    <damping>0.001</damping>
                    <friction>0.002</friction>
                </dynamics>
                <use_parent_model_frame>1</use_parent_model_frame>
            </axis2>
            <physics>
                <ode>
                </ode>
            </physics>
        </joint>
        
        <joint name="joint_4" type="universal">
            <child>link_5</child>
            <parent>link_4</parent>
            <pose>0 0 0.015 0 0 0 </pose>
            <axis>
                <xyz>0 0 1</xyz>
                <limit>
                    <lower>-2.0</lower>
                    <upper>2.0</upper>
                </limit>
                <dynamics>
                    <damping>0.001</damping>
                    <friction>0.002</friction>
                </dynamics>
                <use_parent_model_frame>1</use_parent_model_frame>
            </axis>
            <axis2>
                <xyz>0 1 0</xyz>
                <limit>
                    <lower>-2.0</lower>
                    <upper>2.0</upper>
                </limit>
                <dynamics>
                    <damping>0.001</damping>
                    <friction>0.002</friction>
                </dynamics>
                <use_parent_model_frame>1</use_parent_model_frame>
            </axis2>
            <physics>
                <ode>
                </ode>
            </physics>
        </joint>
        
        <joint name="joint_5" type="universal">
            <child>link_6</child>
            <parent>link_5</parent>
            <pose>0 0 0.015 0 0 0 </pose>
            <axis>
                <xyz>0 0 1</xyz>
                <limit>
                    <lower>-2.0</lower>
                    <upper>2.0</upper>
                </limit>
                <dynamics>
                    <damping>0.001</damping>
                    <friction>0.002</friction>
                </dynamics>
                <use_parent_model_frame>1</use_parent_model_frame>
            </axis>
            <axis2>
                <xyz>0 1 0</xyz>
                <limit>
                    <lower>-2.0</lower>
                    <upper>2.0</upper>
                </limit>
                <dynamics>
                    <damping>0.001</damping>
                    <friction>0.002</friction>
                </dynamics>
                <use_parent_model_frame>1</use_parent_model_frame>
            </axis2>
            <physics>
                <ode>
                </ode>
            </physics>
        </joint>
        
        <joint name="joint_6" type="universal">
            <child>link_7</child>
            <parent>link_6</parent>
            <pose>0 0 0.015 0 0 0 </pose>
            <axis>
                <xyz>0 0 1</xyz>
                <limit>
                    <lower>-2.0</lower>
                    <upper>2.0</upper>
                </limit>
                <dynamics>
                    <damping>0.001</damping>
                    <friction>0.002</friction>
                </dynamics>
                <use_parent_model_frame>1</use_parent_model_frame>
            </axis>
            <axis2>
                <xyz>0 1 0</xyz>
                <limit>
                    <lower>-2.0</lower>
                    <upper>2.0</upper>
                </limit>
                <dynamics>
                    <damping>0.001</damping>
                    <friction>0.002</friction>
                </dynamics>
                <use_parent_model_frame>1</use_parent_model_frame>
            </axis2>
            <physics>
                <ode>
                </ode>
            </physics>
        </joint>
        
        <joint name="joint_7" type="universal">
            <child>link_8</child>
            <parent>link_7</parent>
            <pose>0 0 0.015 0 0 0 </pose>
            <axis>
                <xyz>0 0 1</xyz>
                <limit>
                    <lower>-2.0</lower>
                    <upper>2.0</upper>
                </limit>
                <dynamics>
                    <damping>0.001</damping>
                    <friction>0.002</friction>
                </dynamics>
                <use_parent_model_frame>1</use_parent_model_frame>
            </axis>
            <axis2>
                <xyz>0 1 0</xyz>
                <limit>
                    <lower>-2.0</lower>
                    <upper>2.0</upper>
                </limit>
                <dynamics>
                    <damping>0.001</damping>
                    <friction>0.002</friction>
                </dynamics>
                <use_parent_model_frame>1</use_parent_model_frame>
            </axis2>
            <physics>
                <ode>
                </ode>
            </physics>
        </joint>
        
        <joint name="joint_8" type="universal">
            <child>link_9</child>
            <parent>link_8</parent>
            <pose>0 0 0.015 0 0 0 </pose>
            <axis>
                <xyz>0 0 1</xyz>
                <limit>
                    <lower>-2.0</lower>
                    <upper>2.0</upper>
                </limit>
                <dynamics>
                    <damping>0.001</damping>
                    <friction>0.002</friction>
                </dynamics>
                <use_parent_model_frame>1</use_parent_model_frame>
            </axis>
            <axis2>
                <xyz>0 1 0</xyz>
                <limit>
                    <lower>-2.0</lower>
                    <upper>2.0</upper>
                </limit>
                <dynamics>
                    <damping>0.001</damping>
                    <friction>0.002</friction>
                </dynamics>
                <use_parent_model_frame>1</use_parent_model_frame>
            </axis2>
            <physics>
                <ode>
                </ode>
            </physics>
        </joint>
        
        <joint name="joint_9" type="universal">
            <child>link_10</child>
            <parent>link_9</parent>
            <pose>0 0 0.015 0 0 0 </pose>
            <axis>
                <xyz>0 0 1</xyz>
                <limit>
                    <lower>-2.0</lower>
                    <upper>2.0</upper>
                </limit>
                <dynamics>
                    <damping>0.001</damping>
                    <friction>0.002</friction>
                </dynamics>
                <use_parent_model_frame>1</use_parent_model_frame>
            </axis>
            <axis2>
                <xyz>0 1 0</xyz>
                <limit>
                    <lower>-2.0</lower>
                    <upper>2.0</upper>
                </limit>
                <dynamics>
                    <damping>0.001</damping>
                    <friction>0.002</friction>
                </dynamics>
                <use_parent_model_frame>1</use_parent_model_frame>
            </axis2>
            <physics>
                <ode>
                </ode>
            </physics>
        </joint>
        
        <link name='gripper1'>
            <pose frame=''>0.3 0 0 0 0 0 </pose>
            <inertial>
                <pose frame=''>0 0 0 0 0 0</pose>
                <mass>0.1</mass>
                <inertia>
                    <ixx>0.0001</ixx>
                    <ixy>0</ixy>
                    <ixz>0</ixz>
                    <iyy>0.0001</iyy>
                    <iyz>0</iyz>
                    <izz>0.001</izz>
                </inertia>
            </inertial>
            <collision name='gripper1_collision'>
                <pose frame=''>0 0 0 0 0 0</pose>
                <geometry>
                    <sphere>
                        <radius>0.008 </radius>
                    </sphere>
                </geometry>
                <surface>
                    <friction>
                        <ode>
                            <mu>0.0</mu>
                            <mu2>0.0</mu2>
                        </ode>
                    </friction>
                    <contact>
                        <ode>
                        </ode>
                    </contact>
                </surface>
            </collision>
            <visual name='gripper1_visual'>
                <cast_shadows>0</cast_shadows>
                <pose frame=''>0 0 0 0 0 0</pose>
                <geometry>
                    <sphere>
                        <radius>0.008
                        </radius>
                    </sphere>
                </geometry>
                <material>
                    <script>
                        <name>Gazebo/Blue</name>
                        <uri>file://media/materials/scripts/gazebo.material</uri>
                    </script>
                </material>
            </visual>
            <self_collide>1</self_collide>
            <kinematic>true</kinematic>
        </link>
        <joint name="gripper1_joint" type="universal">
            <child>gripper1</child>
            <parent>link_10</parent>
            <pose>0 0 0 0 0 0</pose>
            <axis>
                <xyz>0 0 1</xyz>
                <dynamics>
                    <damping>0.001</damping>
                    <friction>0.002</friction>
                </dynamics>
            </axis>
            <axis2>
                <xyz>0 1 0</xyz>
                <dynamics>
                    <damping>0.001</damping>
                    <friction>0.002</friction>
                </dynamics>
            </axis2>
        </joint>
        <link name='gripper2'>
            <pose frame=''>0 0 0 0 0 0 </pose>
            <inertial>
                <pose frame=''>0 0 0 0 0 0</pose>
                <mass>0.1</mass>
                <inertia>
                    <ixx>0.0001</ixx>
                    <ixy>0</ixy>
                    <ixz>0</ixz>
                    <iyy>0.0001</iyy>
                    <iyz>0</iyz>
                    <izz>0.001</izz>
                </inertia>
            </inertial>
            <collision name='gripper2_collision'>
                <pose frame=''>0 0 0 0 0 0</pose>
                <geometry>
                    <sphere>
                        <radius>0.008 </radius>
                    </sphere>
                </geometry>
                <surface>
                    <friction>
                        <ode>
                            <mu>0.0</mu>
                            <mu2>0.0</mu2>
                        </ode>
                    </friction>
                    <contact>
                        <ode>
                        </ode>
                    </contact>
                </surface>
            </collision>
            <visual name='gripper2_visual'>
                <cast_shadows>0</cast_shadows>
                <pose frame=''>0 0 0 0 0 0</pose>
                <geometry>
                    <sphere>
                        <radius>0.008
                        </radius>
                    </sphere>
                </geometry>
                <material>
                    <script>
                        <name>Gazebo/Red</name>
                        <uri>file://media/materials/scripts/gazebo.material</uri>
                    </script>
                </material>
            </visual>
            <self_collide>1</self_collide>
            <kinematic>true</kinematic>
        </link>
        <joint name="gripper2_joint" type="universal">
            <child>gripper2</child>
            <parent>link_1</parent>
            <pose>0 0 0 0 0 0</pose>
            <axis>
                <xyz>0 0 1</xyz>
                <dynamics>
                    <damping>0.001</damping>
                    <friction>0.002</friction>
                </dynamics>
            </axis>
            <axis2>
                <xyz>0 1 0</xyz>
                <dynamics>
                    <damping>0.001</damping>
                    <friction>0.002</friction>
                </dynamics>
            </axis2>
        </joint>
        <plugin name='rope_plugin' filename='librope_plugin.so'>
            <num_links>10</num_links>
            <rope_length>0.3</rope_length>
        </plugin>
        <plugin name='dual_gripper_plugin' filename='libdual_gripper_plugin.so'>
            <object_name>gripper</object_name>
        </plugin>
    </model>
</sdf>
