
<sdf version="1.6">
    <model name="link_bot">
        <pose frame="">0 0 0 0 0 0</pose>
        
        <link name="link_1">
            <pose frame="">0.01 0 0 3.14159 -1.57079 3.14159</pose>
            <inertial>
                <pose frame="">0 0 0 0 0 0</pose>
                <mass>0.02
                </mass>
                <inertia>
                    <ixx>9.866666666666668e-07
                    </ixx>
                    <ixy>0</ixy>
                    <ixz>0</ixz>
                    <iyy>9.866666666666668e-07
                    </iyy>
                    <iyz>0</iyz>
                    <izz>6.4e-07
                    </izz>
                </inertia>
            </inertial>
            <collision name="link_1_collision">
                <pose frame="">0 0 0 0 0 0</pose>
                <geometry>
                    <cylinder>
                        <length>0.02</length>
                        <radius>0.008</radius>
                    </cylinder>
                </geometry>
                <surface>
                    <friction>
                        <ode>
                            <mu>0.20</mu>
                            <mu2>0.20</mu2>
                        </ode>
                    </friction>
                    <contact>
                        <ode>
                            <kp>1e15</kp>
                            <kd>1e13</kd>
                        </ode>
                    </contact>
                </surface>
            </collision>

            <collision name="link_1_collision_ball1">
                <pose frame="">0 0 0.01 0 0 0</pose>
                <geometry>
                    <sphere>
                        <radius>0.008</radius>
                    </sphere>
                </geometry>
                <surface>
                    <friction>
                        <ode>
                            <mu>0.20</mu>
                            <mu2>0.20</mu2>
                        </ode>
                    </friction>
                    <contact>
                        <ode>
                            <kp>1e15</kp>
                            <kd>1e13</kd>
                        </ode>
                    </contact>
                </surface>
            </collision>

            <collision name="link_1_collision_ball2">
                <pose frame="">0 0 -0.01 0 0 0</pose>
                <geometry>
                    <sphere>
                        <radius>0.008</radius>
                    </sphere>
                </geometry>
                <surface>
                    <friction>
                        <ode>
                            <mu>0.20</mu>
                            <mu2>0.20</mu2>
                        </ode>
                    </friction>
                    <contact>
                        <ode>
                            <kp>1e15</kp>
                            <kd>1e13</kd>
                        </ode>
                    </contact>
                </surface>
            </collision>

            <visual name="link_1_visual">
                <cast_shadows>0</cast_shadows>
                <pose frame="">0 0 0 0 0 0</pose>
                <geometry>
                    <cylinder>
                        <length>0.02
                        </length>
                        <radius>0.008
                        </radius>
                    </cylinder>
                </geometry>
                <material>
                    <script>
                        <name>Gazebo/Orange </name>
                        <uri>file://media/materials/scripts/gazebo.material</uri>
                    </script>
                </material>
            </visual>
            <self_collide>1</self_collide>
        </link>
        
        <link name="link_2">
            <pose frame="">0.03 0 0 3.14159 -1.57079 3.14159</pose>
            <inertial>
                <pose frame="">0 0 0 0 0 0</pose>
                <mass>0.02
                </mass>
                <inertia>
                    <ixx>9.866666666666668e-07
                    </ixx>
                    <ixy>0</ixy>
                    <ixz>0</ixz>
                    <iyy>9.866666666666668e-07
                    </iyy>
                    <iyz>0</iyz>
                    <izz>6.4e-07
                    </izz>
                </inertia>
            </inertial>
            <collision name="link_2_collision">
                <pose frame="">0 0 0 0 0 0</pose>
                <geometry>
                    <cylinder>
                        <length>0.02</length>
                        <radius>0.008</radius>
                    </cylinder>
                </geometry>
                <surface>
                    <friction>
                        <ode>
                            <mu>0.20</mu>
                            <mu2>0.20</mu2>
                        </ode>
                    </friction>
                    <contact>
                        <ode>
                            <kp>1e15</kp>
                            <kd>1e13</kd>
                        </ode>
                    </contact>
                </surface>
            </collision>

            <collision name="link_2_collision_ball1">
                <pose frame="">0 0 0.01 0 0 0</pose>
                <geometry>
                    <sphere>
                        <radius>0.008</radius>
                    </sphere>
                </geometry>
                <surface>
                    <friction>
                        <ode>
                            <mu>0.20</mu>
                            <mu2>0.20</mu2>
                        </ode>
                    </friction>
                    <contact>
                        <ode>
                            <kp>1e15</kp>
                            <kd>1e13</kd>
                        </ode>
                    </contact>
                </surface>
            </collision>

            <collision name="link_2_collision_ball2">
                <pose frame="">0 0 -0.01 0 0 0</pose>
                <geometry>
                    <sphere>
                        <radius>0.008</radius>
                    </sphere>
                </geometry>
                <surface>
                    <friction>
                        <ode>
                            <mu>0.20</mu>
                            <mu2>0.20</mu2>
                        </ode>
                    </friction>
                    <contact>
                        <ode>
                            <kp>1e15</kp>
                            <kd>1e13</kd>
                        </ode>
                    </contact>
                </surface>
            </collision>

            <visual name="link_2_visual">
                <cast_shadows>0</cast_shadows>
                <pose frame="">0 0 0 0 0 0</pose>
                <geometry>
                    <cylinder>
                        <length>0.02
                        </length>
                        <radius>0.008
                        </radius>
                    </cylinder>
                </geometry>
                <material>
                    <script>
                        <name>Gazebo/Yellow </name>
                        <uri>file://media/materials/scripts/gazebo.material</uri>
                    </script>
                </material>
            </visual>
            <self_collide>1</self_collide>
        </link>
        
        <link name="link_3">
            <pose frame="">0.05 0 0 3.14159 -1.57079 3.14159</pose>
            <inertial>
                <pose frame="">0 0 0 0 0 0</pose>
                <mass>0.02
                </mass>
                <inertia>
                    <ixx>9.866666666666668e-07
                    </ixx>
                    <ixy>0</ixy>
                    <ixz>0</ixz>
                    <iyy>9.866666666666668e-07
                    </iyy>
                    <iyz>0</iyz>
                    <izz>6.4e-07
                    </izz>
                </inertia>
            </inertial>
            <collision name="link_3_collision">
                <pose frame="">0 0 0 0 0 0</pose>
                <geometry>
                    <cylinder>
                        <length>0.02</length>
                        <radius>0.008</radius>
                    </cylinder>
                </geometry>
                <surface>
                    <friction>
                        <ode>
                            <mu>0.20</mu>
                            <mu2>0.20</mu2>
                        </ode>
                    </friction>
                    <contact>
                        <ode>
                            <kp>1e15</kp>
                            <kd>1e13</kd>
                        </ode>
                    </contact>
                </surface>
            </collision>

            <collision name="link_3_collision_ball1">
                <pose frame="">0 0 0.01 0 0 0</pose>
                <geometry>
                    <sphere>
                        <radius>0.008</radius>
                    </sphere>
                </geometry>
                <surface>
                    <friction>
                        <ode>
                            <mu>0.20</mu>
                            <mu2>0.20</mu2>
                        </ode>
                    </friction>
                    <contact>
                        <ode>
                            <kp>1e15</kp>
                            <kd>1e13</kd>
                        </ode>
                    </contact>
                </surface>
            </collision>

            <collision name="link_3_collision_ball2">
                <pose frame="">0 0 -0.01 0 0 0</pose>
                <geometry>
                    <sphere>
                        <radius>0.008</radius>
                    </sphere>
                </geometry>
                <surface>
                    <friction>
                        <ode>
                            <mu>0.20</mu>
                            <mu2>0.20</mu2>
                        </ode>
                    </friction>
                    <contact>
                        <ode>
                            <kp>1e15</kp>
                            <kd>1e13</kd>
                        </ode>
                    </contact>
                </surface>
            </collision>

            <visual name="link_3_visual">
                <cast_shadows>0</cast_shadows>
                <pose frame="">0 0 0 0 0 0</pose>
                <geometry>
                    <cylinder>
                        <length>0.02
                        </length>
                        <radius>0.008
                        </radius>
                    </cylinder>
                </geometry>
                <material>
                    <script>
                        <name>Gazebo/Green </name>
                        <uri>file://media/materials/scripts/gazebo.material</uri>
                    </script>
                </material>
            </visual>
            <self_collide>1</self_collide>
        </link>
        
        <link name="link_4">
            <pose frame="">0.06999999999999999 0 0 3.14159 -1.57079 3.14159</pose>
            <inertial>
                <pose frame="">0 0 0 0 0 0</pose>
                <mass>0.02
                </mass>
                <inertia>
                    <ixx>9.866666666666668e-07
                    </ixx>
                    <ixy>0</ixy>
                    <ixz>0</ixz>
                    <iyy>9.866666666666668e-07
                    </iyy>
                    <iyz>0</iyz>
                    <izz>6.4e-07
                    </izz>
                </inertia>
            </inertial>
            <collision name="link_4_collision">
                <pose frame="">0 0 0 0 0 0</pose>
                <geometry>
                    <cylinder>
                        <length>0.02</length>
                        <radius>0.008</radius>
                    </cylinder>
                </geometry>
                <surface>
                    <friction>
                        <ode>
                            <mu>0.20</mu>
                            <mu2>0.20</mu2>
                        </ode>
                    </friction>
                    <contact>
                        <ode>
                            <kp>1e15</kp>
                            <kd>1e13</kd>
                        </ode>
                    </contact>
                </surface>
            </collision>

            <collision name="link_4_collision_ball1">
                <pose frame="">0 0 0.01 0 0 0</pose>
                <geometry>
                    <sphere>
                        <radius>0.008</radius>
                    </sphere>
                </geometry>
                <surface>
                    <friction>
                        <ode>
                            <mu>0.20</mu>
                            <mu2>0.20</mu2>
                        </ode>
                    </friction>
                    <contact>
                        <ode>
                            <kp>1e15</kp>
                            <kd>1e13</kd>
                        </ode>
                    </contact>
                </surface>
            </collision>

            <collision name="link_4_collision_ball2">
                <pose frame="">0 0 -0.01 0 0 0</pose>
                <geometry>
                    <sphere>
                        <radius>0.008</radius>
                    </sphere>
                </geometry>
                <surface>
                    <friction>
                        <ode>
                            <mu>0.20</mu>
                            <mu2>0.20</mu2>
                        </ode>
                    </friction>
                    <contact>
                        <ode>
                            <kp>1e15</kp>
                            <kd>1e13</kd>
                        </ode>
                    </contact>
                </surface>
            </collision>

            <visual name="link_4_visual">
                <cast_shadows>0</cast_shadows>
                <pose frame="">0 0 0 0 0 0</pose>
                <geometry>
                    <cylinder>
                        <length>0.02
                        </length>
                        <radius>0.008
                        </radius>
                    </cylinder>
                </geometry>
                <material>
                    <script>
                        <name>Gazebo/Blue </name>
                        <uri>file://media/materials/scripts/gazebo.material</uri>
                    </script>
                </material>
            </visual>
            <self_collide>1</self_collide>
        </link>
        
        <link name="link_5">
            <pose frame="">0.09 0 0 3.14159 -1.57079 3.14159</pose>
            <inertial>
                <pose frame="">0 0 0 0 0 0</pose>
                <mass>0.02
                </mass>
                <inertia>
                    <ixx>9.866666666666668e-07
                    </ixx>
                    <ixy>0</ixy>
                    <ixz>0</ixz>
                    <iyy>9.866666666666668e-07
                    </iyy>
                    <iyz>0</iyz>
                    <izz>6.4e-07
                    </izz>
                </inertia>
            </inertial>
            <collision name="link_5_collision">
                <pose frame="">0 0 0 0 0 0</pose>
                <geometry>
                    <cylinder>
                        <length>0.02</length>
                        <radius>0.008</radius>
                    </cylinder>
                </geometry>
                <surface>
                    <friction>
                        <ode>
                            <mu>0.20</mu>
                            <mu2>0.20</mu2>
                        </ode>
                    </friction>
                    <contact>
                        <ode>
                            <kp>1e15</kp>
                            <kd>1e13</kd>
                        </ode>
                    </contact>
                </surface>
            </collision>

            <collision name="link_5_collision_ball1">
                <pose frame="">0 0 0.01 0 0 0</pose>
                <geometry>
                    <sphere>
                        <radius>0.008</radius>
                    </sphere>
                </geometry>
                <surface>
                    <friction>
                        <ode>
                            <mu>0.20</mu>
                            <mu2>0.20</mu2>
                        </ode>
                    </friction>
                    <contact>
                        <ode>
                            <kp>1e15</kp>
                            <kd>1e13</kd>
                        </ode>
                    </contact>
                </surface>
            </collision>

            <collision name="link_5_collision_ball2">
                <pose frame="">0 0 -0.01 0 0 0</pose>
                <geometry>
                    <sphere>
                        <radius>0.008</radius>
                    </sphere>
                </geometry>
                <surface>
                    <friction>
                        <ode>
                            <mu>0.20</mu>
                            <mu2>0.20</mu2>
                        </ode>
                    </friction>
                    <contact>
                        <ode>
                            <kp>1e15</kp>
                            <kd>1e13</kd>
                        </ode>
                    </contact>
                </surface>
            </collision>

            <visual name="link_5_visual">
                <cast_shadows>0</cast_shadows>
                <pose frame="">0 0 0 0 0 0</pose>
                <geometry>
                    <cylinder>
                        <length>0.02
                        </length>
                        <radius>0.008
                        </radius>
                    </cylinder>
                </geometry>
                <material>
                    <script>
                        <name>Gazebo/Purple </name>
                        <uri>file://media/materials/scripts/gazebo.material</uri>
                    </script>
                </material>
            </visual>
            <self_collide>1</self_collide>
        </link>
        
        <link name="link_6">
            <pose frame="">0.11 0 0 3.14159 -1.57079 3.14159</pose>
            <inertial>
                <pose frame="">0 0 0 0 0 0</pose>
                <mass>0.02
                </mass>
                <inertia>
                    <ixx>9.866666666666668e-07
                    </ixx>
                    <ixy>0</ixy>
                    <ixz>0</ixz>
                    <iyy>9.866666666666668e-07
                    </iyy>
                    <iyz>0</iyz>
                    <izz>6.4e-07
                    </izz>
                </inertia>
            </inertial>
            <collision name="link_6_collision">
                <pose frame="">0 0 0 0 0 0</pose>
                <geometry>
                    <cylinder>
                        <length>0.02</length>
                        <radius>0.008</radius>
                    </cylinder>
                </geometry>
                <surface>
                    <friction>
                        <ode>
                            <mu>0.20</mu>
                            <mu2>0.20</mu2>
                        </ode>
                    </friction>
                    <contact>
                        <ode>
                            <kp>1e15</kp>
                            <kd>1e13</kd>
                        </ode>
                    </contact>
                </surface>
            </collision>

            <collision name="link_6_collision_ball1">
                <pose frame="">0 0 0.01 0 0 0</pose>
                <geometry>
                    <sphere>
                        <radius>0.008</radius>
                    </sphere>
                </geometry>
                <surface>
                    <friction>
                        <ode>
                            <mu>0.20</mu>
                            <mu2>0.20</mu2>
                        </ode>
                    </friction>
                    <contact>
                        <ode>
                            <kp>1e15</kp>
                            <kd>1e13</kd>
                        </ode>
                    </contact>
                </surface>
            </collision>

            <collision name="link_6_collision_ball2">
                <pose frame="">0 0 -0.01 0 0 0</pose>
                <geometry>
                    <sphere>
                        <radius>0.008</radius>
                    </sphere>
                </geometry>
                <surface>
                    <friction>
                        <ode>
                            <mu>0.20</mu>
                            <mu2>0.20</mu2>
                        </ode>
                    </friction>
                    <contact>
                        <ode>
                            <kp>1e15</kp>
                            <kd>1e13</kd>
                        </ode>
                    </contact>
                </surface>
            </collision>

            <visual name="link_6_visual">
                <cast_shadows>0</cast_shadows>
                <pose frame="">0 0 0 0 0 0</pose>
                <geometry>
                    <cylinder>
                        <length>0.02
                        </length>
                        <radius>0.008
                        </radius>
                    </cylinder>
                </geometry>
                <material>
                    <script>
                        <name>Gazebo/White </name>
                        <uri>file://media/materials/scripts/gazebo.material</uri>
                    </script>
                </material>
            </visual>
            <self_collide>1</self_collide>
        </link>
        
        <link name="link_7">
            <pose frame="">0.13 0 0 3.14159 -1.57079 3.14159</pose>
            <inertial>
                <pose frame="">0 0 0 0 0 0</pose>
                <mass>0.02
                </mass>
                <inertia>
                    <ixx>9.866666666666668e-07
                    </ixx>
                    <ixy>0</ixy>
                    <ixz>0</ixz>
                    <iyy>9.866666666666668e-07
                    </iyy>
                    <iyz>0</iyz>
                    <izz>6.4e-07
                    </izz>
                </inertia>
            </inertial>
            <collision name="link_7_collision">
                <pose frame="">0 0 0 0 0 0</pose>
                <geometry>
                    <cylinder>
                        <length>0.02</length>
                        <radius>0.008</radius>
                    </cylinder>
                </geometry>
                <surface>
                    <friction>
                        <ode>
                            <mu>0.20</mu>
                            <mu2>0.20</mu2>
                        </ode>
                    </friction>
                    <contact>
                        <ode>
                            <kp>1e15</kp>
                            <kd>1e13</kd>
                        </ode>
                    </contact>
                </surface>
            </collision>

            <collision name="link_7_collision_ball1">
                <pose frame="">0 0 0.01 0 0 0</pose>
                <geometry>
                    <sphere>
                        <radius>0.008</radius>
                    </sphere>
                </geometry>
                <surface>
                    <friction>
                        <ode>
                            <mu>0.20</mu>
                            <mu2>0.20</mu2>
                        </ode>
                    </friction>
                    <contact>
                        <ode>
                            <kp>1e15</kp>
                            <kd>1e13</kd>
                        </ode>
                    </contact>
                </surface>
            </collision>

            <collision name="link_7_collision_ball2">
                <pose frame="">0 0 -0.01 0 0 0</pose>
                <geometry>
                    <sphere>
                        <radius>0.008</radius>
                    </sphere>
                </geometry>
                <surface>
                    <friction>
                        <ode>
                            <mu>0.20</mu>
                            <mu2>0.20</mu2>
                        </ode>
                    </friction>
                    <contact>
                        <ode>
                            <kp>1e15</kp>
                            <kd>1e13</kd>
                        </ode>
                    </contact>
                </surface>
            </collision>

            <visual name="link_7_visual">
                <cast_shadows>0</cast_shadows>
                <pose frame="">0 0 0 0 0 0</pose>
                <geometry>
                    <cylinder>
                        <length>0.02
                        </length>
                        <radius>0.008
                        </radius>
                    </cylinder>
                </geometry>
                <material>
                    <script>
                        <name>Gazebo/Black </name>
                        <uri>file://media/materials/scripts/gazebo.material</uri>
                    </script>
                </material>
            </visual>
            <self_collide>1</self_collide>
        </link>
        
        <link name="link_8">
            <pose frame="">0.15000000000000002 0 0 3.14159 -1.57079 3.14159</pose>
            <inertial>
                <pose frame="">0 0 0 0 0 0</pose>
                <mass>0.02
                </mass>
                <inertia>
                    <ixx>9.866666666666668e-07
                    </ixx>
                    <ixy>0</ixy>
                    <ixz>0</ixz>
                    <iyy>9.866666666666668e-07
                    </iyy>
                    <iyz>0</iyz>
                    <izz>6.4e-07
                    </izz>
                </inertia>
            </inertial>
            <collision name="link_8_collision">
                <pose frame="">0 0 0 0 0 0</pose>
                <geometry>
                    <cylinder>
                        <length>0.02</length>
                        <radius>0.008</radius>
                    </cylinder>
                </geometry>
                <surface>
                    <friction>
                        <ode>
                            <mu>0.20</mu>
                            <mu2>0.20</mu2>
                        </ode>
                    </friction>
                    <contact>
                        <ode>
                            <kp>1e15</kp>
                            <kd>1e13</kd>
                        </ode>
                    </contact>
                </surface>
            </collision>

            <collision name="link_8_collision_ball1">
                <pose frame="">0 0 0.01 0 0 0</pose>
                <geometry>
                    <sphere>
                        <radius>0.008</radius>
                    </sphere>
                </geometry>
                <surface>
                    <friction>
                        <ode>
                            <mu>0.20</mu>
                            <mu2>0.20</mu2>
                        </ode>
                    </friction>
                    <contact>
                        <ode>
                            <kp>1e15</kp>
                            <kd>1e13</kd>
                        </ode>
                    </contact>
                </surface>
            </collision>

            <collision name="link_8_collision_ball2">
                <pose frame="">0 0 -0.01 0 0 0</pose>
                <geometry>
                    <sphere>
                        <radius>0.008</radius>
                    </sphere>
                </geometry>
                <surface>
                    <friction>
                        <ode>
                            <mu>0.20</mu>
                            <mu2>0.20</mu2>
                        </ode>
                    </friction>
                    <contact>
                        <ode>
                            <kp>1e15</kp>
                            <kd>1e13</kd>
                        </ode>
                    </contact>
                </surface>
            </collision>

            <visual name="link_8_visual">
                <cast_shadows>0</cast_shadows>
                <pose frame="">0 0 0 0 0 0</pose>
                <geometry>
                    <cylinder>
                        <length>0.02
                        </length>
                        <radius>0.008
                        </radius>
                    </cylinder>
                </geometry>
                <material>
                    <script>
                        <name>Gazebo/Red </name>
                        <uri>file://media/materials/scripts/gazebo.material</uri>
                    </script>
                </material>
            </visual>
            <self_collide>1</self_collide>
        </link>
        
        <link name="link_9">
            <pose frame="">0.17 0 0 3.14159 -1.57079 3.14159</pose>
            <inertial>
                <pose frame="">0 0 0 0 0 0</pose>
                <mass>0.02
                </mass>
                <inertia>
                    <ixx>9.866666666666668e-07
                    </ixx>
                    <ixy>0</ixy>
                    <ixz>0</ixz>
                    <iyy>9.866666666666668e-07
                    </iyy>
                    <iyz>0</iyz>
                    <izz>6.4e-07
                    </izz>
                </inertia>
            </inertial>
            <collision name="link_9_collision">
                <pose frame="">0 0 0 0 0 0</pose>
                <geometry>
                    <cylinder>
                        <length>0.02</length>
                        <radius>0.008</radius>
                    </cylinder>
                </geometry>
                <surface>
                    <friction>
                        <ode>
                            <mu>0.20</mu>
                            <mu2>0.20</mu2>
                        </ode>
                    </friction>
                    <contact>
                        <ode>
                            <kp>1e15</kp>
                            <kd>1e13</kd>
                        </ode>
                    </contact>
                </surface>
            </collision>

            <collision name="link_9_collision_ball1">
                <pose frame="">0 0 0.01 0 0 0</pose>
                <geometry>
                    <sphere>
                        <radius>0.008</radius>
                    </sphere>
                </geometry>
                <surface>
                    <friction>
                        <ode>
                            <mu>0.20</mu>
                            <mu2>0.20</mu2>
                        </ode>
                    </friction>
                    <contact>
                        <ode>
                            <kp>1e15</kp>
                            <kd>1e13</kd>
                        </ode>
                    </contact>
                </surface>
            </collision>

            <collision name="link_9_collision_ball2">
                <pose frame="">0 0 -0.01 0 0 0</pose>
                <geometry>
                    <sphere>
                        <radius>0.008</radius>
                    </sphere>
                </geometry>
                <surface>
                    <friction>
                        <ode>
                            <mu>0.20</mu>
                            <mu2>0.20</mu2>
                        </ode>
                    </friction>
                    <contact>
                        <ode>
                            <kp>1e15</kp>
                            <kd>1e13</kd>
                        </ode>
                    </contact>
                </surface>
            </collision>

            <visual name="link_9_visual">
                <cast_shadows>0</cast_shadows>
                <pose frame="">0 0 0 0 0 0</pose>
                <geometry>
                    <cylinder>
                        <length>0.02
                        </length>
                        <radius>0.008
                        </radius>
                    </cylinder>
                </geometry>
                <material>
                    <script>
                        <name>Gazebo/Orange </name>
                        <uri>file://media/materials/scripts/gazebo.material</uri>
                    </script>
                </material>
            </visual>
            <self_collide>1</self_collide>
        </link>
        
        <link name="link_10">
            <pose frame="">0.19 0 0 3.14159 -1.57079 3.14159</pose>
            <inertial>
                <pose frame="">0 0 0 0 0 0</pose>
                <mass>0.02
                </mass>
                <inertia>
                    <ixx>9.866666666666668e-07
                    </ixx>
                    <ixy>0</ixy>
                    <ixz>0</ixz>
                    <iyy>9.866666666666668e-07
                    </iyy>
                    <iyz>0</iyz>
                    <izz>6.4e-07
                    </izz>
                </inertia>
            </inertial>
            <collision name="link_10_collision">
                <pose frame="">0 0 0 0 0 0</pose>
                <geometry>
                    <cylinder>
                        <length>0.02</length>
                        <radius>0.008</radius>
                    </cylinder>
                </geometry>
                <surface>
                    <friction>
                        <ode>
                            <mu>0.20</mu>
                            <mu2>0.20</mu2>
                        </ode>
                    </friction>
                    <contact>
                        <ode>
                            <kp>1e15</kp>
                            <kd>1e13</kd>
                        </ode>
                    </contact>
                </surface>
            </collision>

            <collision name="link_10_collision_ball1">
                <pose frame="">0 0 0.01 0 0 0</pose>
                <geometry>
                    <sphere>
                        <radius>0.008</radius>
                    </sphere>
                </geometry>
                <surface>
                    <friction>
                        <ode>
                            <mu>0.20</mu>
                            <mu2>0.20</mu2>
                        </ode>
                    </friction>
                    <contact>
                        <ode>
                            <kp>1e15</kp>
                            <kd>1e13</kd>
                        </ode>
                    </contact>
                </surface>
            </collision>

            <collision name="link_10_collision_ball2">
                <pose frame="">0 0 -0.01 0 0 0</pose>
                <geometry>
                    <sphere>
                        <radius>0.008</radius>
                    </sphere>
                </geometry>
                <surface>
                    <friction>
                        <ode>
                            <mu>0.20</mu>
                            <mu2>0.20</mu2>
                        </ode>
                    </friction>
                    <contact>
                        <ode>
                            <kp>1e15</kp>
                            <kd>1e13</kd>
                        </ode>
                    </contact>
                </surface>
            </collision>

            <visual name="link_10_visual">
                <cast_shadows>0</cast_shadows>
                <pose frame="">0 0 0 0 0 0</pose>
                <geometry>
                    <cylinder>
                        <length>0.02
                        </length>
                        <radius>0.008
                        </radius>
                    </cylinder>
                </geometry>
                <material>
                    <script>
                        <name>Gazebo/Yellow </name>
                        <uri>file://media/materials/scripts/gazebo.material</uri>
                    </script>
                </material>
            </visual>
            <self_collide>1</self_collide>
        </link>
        
        <link name="link_11">
            <pose frame="">0.21000000000000002 0 0 3.14159 -1.57079 3.14159</pose>
            <inertial>
                <pose frame="">0 0 0 0 0 0</pose>
                <mass>0.02
                </mass>
                <inertia>
                    <ixx>9.866666666666668e-07
                    </ixx>
                    <ixy>0</ixy>
                    <ixz>0</ixz>
                    <iyy>9.866666666666668e-07
                    </iyy>
                    <iyz>0</iyz>
                    <izz>6.4e-07
                    </izz>
                </inertia>
            </inertial>
            <collision name="link_11_collision">
                <pose frame="">0 0 0 0 0 0</pose>
                <geometry>
                    <cylinder>
                        <length>0.02</length>
                        <radius>0.008</radius>
                    </cylinder>
                </geometry>
                <surface>
                    <friction>
                        <ode>
                            <mu>0.20</mu>
                            <mu2>0.20</mu2>
                        </ode>
                    </friction>
                    <contact>
                        <ode>
                            <kp>1e15</kp>
                            <kd>1e13</kd>
                        </ode>
                    </contact>
                </surface>
            </collision>

            <collision name="link_11_collision_ball1">
                <pose frame="">0 0 0.01 0 0 0</pose>
                <geometry>
                    <sphere>
                        <radius>0.008</radius>
                    </sphere>
                </geometry>
                <surface>
                    <friction>
                        <ode>
                            <mu>0.20</mu>
                            <mu2>0.20</mu2>
                        </ode>
                    </friction>
                    <contact>
                        <ode>
                            <kp>1e15</kp>
                            <kd>1e13</kd>
                        </ode>
                    </contact>
                </surface>
            </collision>

            <collision name="link_11_collision_ball2">
                <pose frame="">0 0 -0.01 0 0 0</pose>
                <geometry>
                    <sphere>
                        <radius>0.008</radius>
                    </sphere>
                </geometry>
                <surface>
                    <friction>
                        <ode>
                            <mu>0.20</mu>
                            <mu2>0.20</mu2>
                        </ode>
                    </friction>
                    <contact>
                        <ode>
                            <kp>1e15</kp>
                            <kd>1e13</kd>
                        </ode>
                    </contact>
                </surface>
            </collision>

            <visual name="link_11_visual">
                <cast_shadows>0</cast_shadows>
                <pose frame="">0 0 0 0 0 0</pose>
                <geometry>
                    <cylinder>
                        <length>0.02
                        </length>
                        <radius>0.008
                        </radius>
                    </cylinder>
                </geometry>
                <material>
                    <script>
                        <name>Gazebo/Green </name>
                        <uri>file://media/materials/scripts/gazebo.material</uri>
                    </script>
                </material>
            </visual>
            <self_collide>1</self_collide>
        </link>
        
        <link name="link_12">
            <pose frame="">0.23 0 0 3.14159 -1.57079 3.14159</pose>
            <inertial>
                <pose frame="">0 0 0 0 0 0</pose>
                <mass>0.02
                </mass>
                <inertia>
                    <ixx>9.866666666666668e-07
                    </ixx>
                    <ixy>0</ixy>
                    <ixz>0</ixz>
                    <iyy>9.866666666666668e-07
                    </iyy>
                    <iyz>0</iyz>
                    <izz>6.4e-07
                    </izz>
                </inertia>
            </inertial>
            <collision name="link_12_collision">
                <pose frame="">0 0 0 0 0 0</pose>
                <geometry>
                    <cylinder>
                        <length>0.02</length>
                        <radius>0.008</radius>
                    </cylinder>
                </geometry>
                <surface>
                    <friction>
                        <ode>
                            <mu>0.20</mu>
                            <mu2>0.20</mu2>
                        </ode>
                    </friction>
                    <contact>
                        <ode>
                            <kp>1e15</kp>
                            <kd>1e13</kd>
                        </ode>
                    </contact>
                </surface>
            </collision>

            <collision name="link_12_collision_ball1">
                <pose frame="">0 0 0.01 0 0 0</pose>
                <geometry>
                    <sphere>
                        <radius>0.008</radius>
                    </sphere>
                </geometry>
                <surface>
                    <friction>
                        <ode>
                            <mu>0.20</mu>
                            <mu2>0.20</mu2>
                        </ode>
                    </friction>
                    <contact>
                        <ode>
                            <kp>1e15</kp>
                            <kd>1e13</kd>
                        </ode>
                    </contact>
                </surface>
            </collision>

            <collision name="link_12_collision_ball2">
                <pose frame="">0 0 -0.01 0 0 0</pose>
                <geometry>
                    <sphere>
                        <radius>0.008</radius>
                    </sphere>
                </geometry>
                <surface>
                    <friction>
                        <ode>
                            <mu>0.20</mu>
                            <mu2>0.20</mu2>
                        </ode>
                    </friction>
                    <contact>
                        <ode>
                            <kp>1e15</kp>
                            <kd>1e13</kd>
                        </ode>
                    </contact>
                </surface>
            </collision>

            <visual name="link_12_visual">
                <cast_shadows>0</cast_shadows>
                <pose frame="">0 0 0 0 0 0</pose>
                <geometry>
                    <cylinder>
                        <length>0.02
                        </length>
                        <radius>0.008
                        </radius>
                    </cylinder>
                </geometry>
                <material>
                    <script>
                        <name>Gazebo/Blue </name>
                        <uri>file://media/materials/scripts/gazebo.material</uri>
                    </script>
                </material>
            </visual>
            <self_collide>1</self_collide>
        </link>
        
        <link name="link_13">
            <pose frame="">0.25 0 0 3.14159 -1.57079 3.14159</pose>
            <inertial>
                <pose frame="">0 0 0 0 0 0</pose>
                <mass>0.02
                </mass>
                <inertia>
                    <ixx>9.866666666666668e-07
                    </ixx>
                    <ixy>0</ixy>
                    <ixz>0</ixz>
                    <iyy>9.866666666666668e-07
                    </iyy>
                    <iyz>0</iyz>
                    <izz>6.4e-07
                    </izz>
                </inertia>
            </inertial>
            <collision name="link_13_collision">
                <pose frame="">0 0 0 0 0 0</pose>
                <geometry>
                    <cylinder>
                        <length>0.02</length>
                        <radius>0.008</radius>
                    </cylinder>
                </geometry>
                <surface>
                    <friction>
                        <ode>
                            <mu>0.20</mu>
                            <mu2>0.20</mu2>
                        </ode>
                    </friction>
                    <contact>
                        <ode>
                            <kp>1e15</kp>
                            <kd>1e13</kd>
                        </ode>
                    </contact>
                </surface>
            </collision>

            <collision name="link_13_collision_ball1">
                <pose frame="">0 0 0.01 0 0 0</pose>
                <geometry>
                    <sphere>
                        <radius>0.008</radius>
                    </sphere>
                </geometry>
                <surface>
                    <friction>
                        <ode>
                            <mu>0.20</mu>
                            <mu2>0.20</mu2>
                        </ode>
                    </friction>
                    <contact>
                        <ode>
                            <kp>1e15</kp>
                            <kd>1e13</kd>
                        </ode>
                    </contact>
                </surface>
            </collision>

            <collision name="link_13_collision_ball2">
                <pose frame="">0 0 -0.01 0 0 0</pose>
                <geometry>
                    <sphere>
                        <radius>0.008</radius>
                    </sphere>
                </geometry>
                <surface>
                    <friction>
                        <ode>
                            <mu>0.20</mu>
                            <mu2>0.20</mu2>
                        </ode>
                    </friction>
                    <contact>
                        <ode>
                            <kp>1e15</kp>
                            <kd>1e13</kd>
                        </ode>
                    </contact>
                </surface>
            </collision>

            <visual name="link_13_visual">
                <cast_shadows>0</cast_shadows>
                <pose frame="">0 0 0 0 0 0</pose>
                <geometry>
                    <cylinder>
                        <length>0.02
                        </length>
                        <radius>0.008
                        </radius>
                    </cylinder>
                </geometry>
                <material>
                    <script>
                        <name>Gazebo/Purple </name>
                        <uri>file://media/materials/scripts/gazebo.material</uri>
                    </script>
                </material>
            </visual>
            <self_collide>1</self_collide>
        </link>
        
        <link name="link_14">
            <pose frame="">0.27 0 0 3.14159 -1.57079 3.14159</pose>
            <inertial>
                <pose frame="">0 0 0 0 0 0</pose>
                <mass>0.02
                </mass>
                <inertia>
                    <ixx>9.866666666666668e-07
                    </ixx>
                    <ixy>0</ixy>
                    <ixz>0</ixz>
                    <iyy>9.866666666666668e-07
                    </iyy>
                    <iyz>0</iyz>
                    <izz>6.4e-07
                    </izz>
                </inertia>
            </inertial>
            <collision name="link_14_collision">
                <pose frame="">0 0 0 0 0 0</pose>
                <geometry>
                    <cylinder>
                        <length>0.02</length>
                        <radius>0.008</radius>
                    </cylinder>
                </geometry>
                <surface>
                    <friction>
                        <ode>
                            <mu>0.20</mu>
                            <mu2>0.20</mu2>
                        </ode>
                    </friction>
                    <contact>
                        <ode>
                            <kp>1e15</kp>
                            <kd>1e13</kd>
                        </ode>
                    </contact>
                </surface>
            </collision>

            <collision name="link_14_collision_ball1">
                <pose frame="">0 0 0.01 0 0 0</pose>
                <geometry>
                    <sphere>
                        <radius>0.008</radius>
                    </sphere>
                </geometry>
                <surface>
                    <friction>
                        <ode>
                            <mu>0.20</mu>
                            <mu2>0.20</mu2>
                        </ode>
                    </friction>
                    <contact>
                        <ode>
                            <kp>1e15</kp>
                            <kd>1e13</kd>
                        </ode>
                    </contact>
                </surface>
            </collision>

            <collision name="link_14_collision_ball2">
                <pose frame="">0 0 -0.01 0 0 0</pose>
                <geometry>
                    <sphere>
                        <radius>0.008</radius>
                    </sphere>
                </geometry>
                <surface>
                    <friction>
                        <ode>
                            <mu>0.20</mu>
                            <mu2>0.20</mu2>
                        </ode>
                    </friction>
                    <contact>
                        <ode>
                            <kp>1e15</kp>
                            <kd>1e13</kd>
                        </ode>
                    </contact>
                </surface>
            </collision>

            <visual name="link_14_visual">
                <cast_shadows>0</cast_shadows>
                <pose frame="">0 0 0 0 0 0</pose>
                <geometry>
                    <cylinder>
                        <length>0.02
                        </length>
                        <radius>0.008
                        </radius>
                    </cylinder>
                </geometry>
                <material>
                    <script>
                        <name>Gazebo/White </name>
                        <uri>file://media/materials/scripts/gazebo.material</uri>
                    </script>
                </material>
            </visual>
            <self_collide>1</self_collide>
        </link>
        
        <link name="link_15">
            <pose frame="">0.29000000000000004 0 0 3.14159 -1.57079 3.14159</pose>
            <inertial>
                <pose frame="">0 0 0 0 0 0</pose>
                <mass>0.02
                </mass>
                <inertia>
                    <ixx>9.866666666666668e-07
                    </ixx>
                    <ixy>0</ixy>
                    <ixz>0</ixz>
                    <iyy>9.866666666666668e-07
                    </iyy>
                    <iyz>0</iyz>
                    <izz>6.4e-07
                    </izz>
                </inertia>
            </inertial>
            <collision name="link_15_collision">
                <pose frame="">0 0 0 0 0 0</pose>
                <geometry>
                    <cylinder>
                        <length>0.02</length>
                        <radius>0.008</radius>
                    </cylinder>
                </geometry>
                <surface>
                    <friction>
                        <ode>
                            <mu>0.20</mu>
                            <mu2>0.20</mu2>
                        </ode>
                    </friction>
                    <contact>
                        <ode>
                            <kp>1e15</kp>
                            <kd>1e13</kd>
                        </ode>
                    </contact>
                </surface>
            </collision>

            <collision name="link_15_collision_ball1">
                <pose frame="">0 0 0.01 0 0 0</pose>
                <geometry>
                    <sphere>
                        <radius>0.008</radius>
                    </sphere>
                </geometry>
                <surface>
                    <friction>
                        <ode>
                            <mu>0.20</mu>
                            <mu2>0.20</mu2>
                        </ode>
                    </friction>
                    <contact>
                        <ode>
                            <kp>1e15</kp>
                            <kd>1e13</kd>
                        </ode>
                    </contact>
                </surface>
            </collision>

            <collision name="link_15_collision_ball2">
                <pose frame="">0 0 -0.01 0 0 0</pose>
                <geometry>
                    <sphere>
                        <radius>0.008</radius>
                    </sphere>
                </geometry>
                <surface>
                    <friction>
                        <ode>
                            <mu>0.20</mu>
                            <mu2>0.20</mu2>
                        </ode>
                    </friction>
                    <contact>
                        <ode>
                            <kp>1e15</kp>
                            <kd>1e13</kd>
                        </ode>
                    </contact>
                </surface>
            </collision>

            <visual name="link_15_visual">
                <cast_shadows>0</cast_shadows>
                <pose frame="">0 0 0 0 0 0</pose>
                <geometry>
                    <cylinder>
                        <length>0.02
                        </length>
                        <radius>0.008
                        </radius>
                    </cylinder>
                </geometry>
                <material>
                    <script>
                        <name>Gazebo/Black </name>
                        <uri>file://media/materials/scripts/gazebo.material</uri>
                    </script>
                </material>
            </visual>
            <self_collide>1</self_collide>
        </link>
        
        
        <joint name="joint_1" type="universal">
            <child>link_2</child>
            <parent>link_1</parent>
            <pose>0 0 0.01 0 0 0 </pose>
            <axis>
                <xyz>0 0 1</xyz>
                <dynamics>
                    <damping>0.0005</damping>
                    <friction>0.0</friction>
                </dynamics>
                <use_parent_model_frame>1</use_parent_model_frame>
            </axis>
            <axis2>
                <xyz>0 1 0</xyz>
                <dynamics>
                    <damping>0.0005</damping>
                    <friction>0.0</friction>
                </dynamics>
                <use_parent_model_frame>1</use_parent_model_frame>
            </axis2>
            <physics>
                <ode>
                    <cfm>0.001</cfm>
                    <implicit_spring_damper>1</implicit_spring_damper>
                </ode>
            </physics>
        </joint>
        
        <joint name="joint_2" type="universal">
            <child>link_3</child>
            <parent>link_2</parent>
            <pose>0 0 0.01 0 0 0 </pose>
            <axis>
                <xyz>0 0 1</xyz>
                <dynamics>
                    <damping>0.0005</damping>
                    <friction>0.0</friction>
                </dynamics>
                <use_parent_model_frame>1</use_parent_model_frame>
            </axis>
            <axis2>
                <xyz>0 1 0</xyz>
                <dynamics>
                    <damping>0.0005</damping>
                    <friction>0.0</friction>
                </dynamics>
                <use_parent_model_frame>1</use_parent_model_frame>
            </axis2>
            <physics>
                <ode>
                    <cfm>0.001</cfm>
                    <implicit_spring_damper>1</implicit_spring_damper>
                </ode>
            </physics>
        </joint>
        
        <joint name="joint_3" type="universal">
            <child>link_4</child>
            <parent>link_3</parent>
            <pose>0 0 0.01 0 0 0 </pose>
            <axis>
                <xyz>0 0 1</xyz>
                <dynamics>
                    <damping>0.0005</damping>
                    <friction>0.0</friction>
                </dynamics>
                <use_parent_model_frame>1</use_parent_model_frame>
            </axis>
            <axis2>
                <xyz>0 1 0</xyz>
                <dynamics>
                    <damping>0.0005</damping>
                    <friction>0.0</friction>
                </dynamics>
                <use_parent_model_frame>1</use_parent_model_frame>
            </axis2>
            <physics>
                <ode>
                    <cfm>0.001</cfm>
                    <implicit_spring_damper>1</implicit_spring_damper>
                </ode>
            </physics>
        </joint>
        
        <joint name="joint_4" type="universal">
            <child>link_5</child>
            <parent>link_4</parent>
            <pose>0 0 0.01 0 0 0 </pose>
            <axis>
                <xyz>0 0 1</xyz>
                <dynamics>
                    <damping>0.0005</damping>
                    <friction>0.0</friction>
                </dynamics>
                <use_parent_model_frame>1</use_parent_model_frame>
            </axis>
            <axis2>
                <xyz>0 1 0</xyz>
                <dynamics>
                    <damping>0.0005</damping>
                    <friction>0.0</friction>
                </dynamics>
                <use_parent_model_frame>1</use_parent_model_frame>
            </axis2>
            <physics>
                <ode>
                    <cfm>0.001</cfm>
                    <implicit_spring_damper>1</implicit_spring_damper>
                </ode>
            </physics>
        </joint>
        
        <joint name="joint_5" type="universal">
            <child>link_6</child>
            <parent>link_5</parent>
            <pose>0 0 0.01 0 0 0 </pose>
            <axis>
                <xyz>0 0 1</xyz>
                <dynamics>
                    <damping>0.0005</damping>
                    <friction>0.0</friction>
                </dynamics>
                <use_parent_model_frame>1</use_parent_model_frame>
            </axis>
            <axis2>
                <xyz>0 1 0</xyz>
                <dynamics>
                    <damping>0.0005</damping>
                    <friction>0.0</friction>
                </dynamics>
                <use_parent_model_frame>1</use_parent_model_frame>
            </axis2>
            <physics>
                <ode>
                    <cfm>0.001</cfm>
                    <implicit_spring_damper>1</implicit_spring_damper>
                </ode>
            </physics>
        </joint>
        
        <joint name="joint_6" type="universal">
            <child>link_7</child>
            <parent>link_6</parent>
            <pose>0 0 0.01 0 0 0 </pose>
            <axis>
                <xyz>0 0 1</xyz>
                <dynamics>
                    <damping>0.0005</damping>
                    <friction>0.0</friction>
                </dynamics>
                <use_parent_model_frame>1</use_parent_model_frame>
            </axis>
            <axis2>
                <xyz>0 1 0</xyz>
                <dynamics>
                    <damping>0.0005</damping>
                    <friction>0.0</friction>
                </dynamics>
                <use_parent_model_frame>1</use_parent_model_frame>
            </axis2>
            <physics>
                <ode>
                    <cfm>0.001</cfm>
                    <implicit_spring_damper>1</implicit_spring_damper>
                </ode>
            </physics>
        </joint>
        
        <joint name="joint_7" type="universal">
            <child>link_8</child>
            <parent>link_7</parent>
            <pose>0 0 0.01 0 0 0 </pose>
            <axis>
                <xyz>0 0 1</xyz>
                <dynamics>
                    <damping>0.0005</damping>
                    <friction>0.0</friction>
                </dynamics>
                <use_parent_model_frame>1</use_parent_model_frame>
            </axis>
            <axis2>
                <xyz>0 1 0</xyz>
                <dynamics>
                    <damping>0.0005</damping>
                    <friction>0.0</friction>
                </dynamics>
                <use_parent_model_frame>1</use_parent_model_frame>
            </axis2>
            <physics>
                <ode>
                    <cfm>0.001</cfm>
                    <implicit_spring_damper>1</implicit_spring_damper>
                </ode>
            </physics>
        </joint>
        
        <joint name="joint_8" type="universal">
            <child>link_9</child>
            <parent>link_8</parent>
            <pose>0 0 0.01 0 0 0 </pose>
            <axis>
                <xyz>0 0 1</xyz>
                <dynamics>
                    <damping>0.0005</damping>
                    <friction>0.0</friction>
                </dynamics>
                <use_parent_model_frame>1</use_parent_model_frame>
            </axis>
            <axis2>
                <xyz>0 1 0</xyz>
                <dynamics>
                    <damping>0.0005</damping>
                    <friction>0.0</friction>
                </dynamics>
                <use_parent_model_frame>1</use_parent_model_frame>
            </axis2>
            <physics>
                <ode>
                    <cfm>0.001</cfm>
                    <implicit_spring_damper>1</implicit_spring_damper>
                </ode>
            </physics>
        </joint>
        
        <joint name="joint_9" type="universal">
            <child>link_10</child>
            <parent>link_9</parent>
            <pose>0 0 0.01 0 0 0 </pose>
            <axis>
                <xyz>0 0 1</xyz>
                <dynamics>
                    <damping>0.0005</damping>
                    <friction>0.0</friction>
                </dynamics>
                <use_parent_model_frame>1</use_parent_model_frame>
            </axis>
            <axis2>
                <xyz>0 1 0</xyz>
                <dynamics>
                    <damping>0.0005</damping>
                    <friction>0.0</friction>
                </dynamics>
                <use_parent_model_frame>1</use_parent_model_frame>
            </axis2>
            <physics>
                <ode>
                    <cfm>0.001</cfm>
                    <implicit_spring_damper>1</implicit_spring_damper>
                </ode>
            </physics>
        </joint>
        
        <joint name="joint_10" type="universal">
            <child>link_11</child>
            <parent>link_10</parent>
            <pose>0 0 0.01 0 0 0 </pose>
            <axis>
                <xyz>0 0 1</xyz>
                <dynamics>
                    <damping>0.0005</damping>
                    <friction>0.0</friction>
                </dynamics>
                <use_parent_model_frame>1</use_parent_model_frame>
            </axis>
            <axis2>
                <xyz>0 1 0</xyz>
                <dynamics>
                    <damping>0.0005</damping>
                    <friction>0.0</friction>
                </dynamics>
                <use_parent_model_frame>1</use_parent_model_frame>
            </axis2>
            <physics>
                <ode>
                    <cfm>0.001</cfm>
                    <implicit_spring_damper>1</implicit_spring_damper>
                </ode>
            </physics>
        </joint>
        
        <joint name="joint_11" type="universal">
            <child>link_12</child>
            <parent>link_11</parent>
            <pose>0 0 0.01 0 0 0 </pose>
            <axis>
                <xyz>0 0 1</xyz>
                <dynamics>
                    <damping>0.0005</damping>
                    <friction>0.0</friction>
                </dynamics>
                <use_parent_model_frame>1</use_parent_model_frame>
            </axis>
            <axis2>
                <xyz>0 1 0</xyz>
                <dynamics>
                    <damping>0.0005</damping>
                    <friction>0.0</friction>
                </dynamics>
                <use_parent_model_frame>1</use_parent_model_frame>
            </axis2>
            <physics>
                <ode>
                    <cfm>0.001</cfm>
                    <implicit_spring_damper>1</implicit_spring_damper>
                </ode>
            </physics>
        </joint>
        
        <joint name="joint_12" type="universal">
            <child>link_13</child>
            <parent>link_12</parent>
            <pose>0 0 0.01 0 0 0 </pose>
            <axis>
                <xyz>0 0 1</xyz>
                <dynamics>
                    <damping>0.0005</damping>
                    <friction>0.0</friction>
                </dynamics>
                <use_parent_model_frame>1</use_parent_model_frame>
            </axis>
            <axis2>
                <xyz>0 1 0</xyz>
                <dynamics>
                    <damping>0.0005</damping>
                    <friction>0.0</friction>
                </dynamics>
                <use_parent_model_frame>1</use_parent_model_frame>
            </axis2>
            <physics>
                <ode>
                    <cfm>0.001</cfm>
                    <implicit_spring_damper>1</implicit_spring_damper>
                </ode>
            </physics>
        </joint>
        
        <joint name="joint_13" type="universal">
            <child>link_14</child>
            <parent>link_13</parent>
            <pose>0 0 0.01 0 0 0 </pose>
            <axis>
                <xyz>0 0 1</xyz>
                <dynamics>
                    <damping>0.0005</damping>
                    <friction>0.0</friction>
                </dynamics>
                <use_parent_model_frame>1</use_parent_model_frame>
            </axis>
            <axis2>
                <xyz>0 1 0</xyz>
                <dynamics>
                    <damping>0.0005</damping>
                    <friction>0.0</friction>
                </dynamics>
                <use_parent_model_frame>1</use_parent_model_frame>
            </axis2>
            <physics>
                <ode>
                    <cfm>0.001</cfm>
                    <implicit_spring_damper>1</implicit_spring_damper>
                </ode>
            </physics>
        </joint>
        
        <joint name="joint_14" type="universal">
            <child>link_15</child>
            <parent>link_14</parent>
            <pose>0 0 0.01 0 0 0 </pose>
            <axis>
                <xyz>0 0 1</xyz>
                <dynamics>
                    <damping>0.0005</damping>
                    <friction>0.0</friction>
                </dynamics>
                <use_parent_model_frame>1</use_parent_model_frame>
            </axis>
            <axis2>
                <xyz>0 1 0</xyz>
                <dynamics>
                    <damping>0.0005</damping>
                    <friction>0.0</friction>
                </dynamics>
                <use_parent_model_frame>1</use_parent_model_frame>
            </axis2>
            <physics>
                <ode>
                    <cfm>0.001</cfm>
                    <implicit_spring_damper>1</implicit_spring_damper>
                </ode>
            </physics>
        </joint>
        
        <link name='gripper1'>
            <pose frame=''>0.3 0 0 0 0 0 </pose>
            <inertial>
                <pose frame=''>0 0 0 0 0 0</pose>
                <mass>0.1</mass>
                <inertia>
                    <ixx>0.0001</ixx>
                    <ixy>0</ixy>
                    <ixz>0</ixz>
                    <iyy>0.0001</iyy>
                    <iyz>0</iyz>
                    <izz>0.001</izz>
                </inertia>
            </inertial>
            <collision name='gripper1_collision'>
                <pose frame=''>0 0 0 0 0 0</pose>
                <geometry>
                    <sphere>
                        <radius>0.008 </radius>
                    </sphere>
                </geometry>
                <surface>
                    <friction>
                        <ode>
                            <mu>0.0</mu>
                            <mu2>0.0</mu2>
                        </ode>
                    </friction>
                    <contact>
                        <ode>
                        </ode>
                    </contact>
                </surface>
            </collision>
            <visual name='gripper1_visual'>
                <cast_shadows>0</cast_shadows>
                <pose frame=''>0 0 0 0 0 0</pose>
                <geometry>
                    <sphere>
                        <radius>0.008
                        </radius>
                    </sphere>
                </geometry>
                <material>
                    <script>
                        <name>Gazebo/Blue</name>
                        <uri>file://media/materials/scripts/gazebo.material</uri>
                    </script>
                </material>
            </visual>

            <self_collide>1</self_collide>
            <kinematic>true</kinematic>
        </link>
        <joint name="gripper1_joint" type="universal">
            <child>gripper1</child>
            <parent>link_15</parent>
            <pose>0 0 0 0 0 0</pose>
            <axis>
                <xyz>0 0 1</xyz>
                <dynamics>
                    <damping>0.0005</damping>
                    <friction>0.0</friction>
                </dynamics>
            </axis>
            <axis2>
                <xyz>0 1 0</xyz>
                <dynamics>
                    <damping>0.0005</damping>
                    <friction>0.0</friction>
                </dynamics>
            </axis2>
        </joint>
        <link name='gripper2'>
            <pose frame=''>0 0 0 0 0 0 </pose>
            <inertial>
                <pose frame=''>0 0 0 0 0 0</pose>
                <mass>0.1</mass>
                <inertia>
                    <ixx>0.0001</ixx>
                    <ixy>0</ixy>
                    <ixz>0</ixz>
                    <iyy>0.0001</iyy>
                    <iyz>0</iyz>
                    <izz>0.001</izz>
                </inertia>
            </inertial>
            <collision name='gripper2_collision'>
                <pose frame=''>0 0 0 0 0 0</pose>
                <geometry>
                    <sphere>
                        <radius>0.008 </radius>
                    </sphere>
                </geometry>
                <surface>
                    <friction>
                        <ode>
                            <mu>0.0</mu>
                            <mu2>0.0</mu2>
                        </ode>
                    </friction>
                    <contact>
                        <ode>
                        </ode>
                    </contact>
                </surface>
            </collision>
            <visual name='gripper2_visual'>
                <cast_shadows>0</cast_shadows>
                <pose frame=''>0 0 0 0 0 0</pose>
                <geometry>
                    <sphere>
                        <radius>0.008</radius>
                    </sphere>
                </geometry>
                <material>
                    <script>
                        <name>Gazebo/Red</name>
                        <uri>file://media/materials/scripts/gazebo.material</uri>
                    </script>
                </material>
            </visual>
            <self_collide>1</self_collide>
            <kinematic>true</kinematic>
        </link>
        <joint name="gripper2_joint" type="universal">
            <child>gripper2</child>
            <parent>link_1</parent>
            <pose>0 0 0 0 0 0</pose>
            <axis>
                <xyz>0 0 1</xyz>
                <dynamics>
                    <damping>0.0005</damping>
                    <friction>0.0</friction>
                </dynamics>
            </axis>
            <axis2>
                <xyz>0 1 0</xyz>
                <dynamics>
                    <damping>0.0005</damping>
                    <friction>0.0</friction>
                </dynamics>
            </axis2>
        </joint>
        <plugin name='rope_plugin' filename='librope_plugin.so'>
            <num_links>15</num_links>
            <rope_length>0.3</rope_length>
        </plugin>
        <plugin name='dual_gripper_plugin' filename='libdual_gripper_plugin.so'>
        </plugin>
    </model>
</sdf>
