
<sdf version="1.6">
    <model name="link_bot">
        <pose frame="">0 0 0.01 0 0 0</pose>
        
        <link name="rope_link_1">
        <pose frame="">0.05 0 0 3.14159 -1.57079 3.14159</pose>
        <inertial>
            <pose frame="">0.025 0 0 0 0 0</pose>
            <mass>0.05</mass>
            <inertia>
                <ixx>1.5416666666666668e-05</ixx>
                <ixy>0</ixy>
                <ixz>0</ixz>
                <iyy>1.5416666666666668e-05</iyy>
                <iyz>0</iyz>
                <izz>1.0e-05</izz>
            </inertia>
        </inertial>
        <collision name="link_1_collision">
            <pose frame="">0 0 0 0 0 0</pose>
            <geometry>
                <box>
                    <size>0.04000000000000001 0.04000000000000001 0.02</size>
                </box>
            </geometry>
            <surface>
                <friction>
                    <ode>
                        <mu>0.10</mu>
                        <mu2>0.10</mu2>
                    </ode>
                </friction>
                <contact>
                    <ode>
                        <kp>1e15</kp>
                        <kd>1e13</kd>
                    </ode>
                </contact>
            </surface>
        </collision>

        <visual name="link_1_visual">
            <cast_shadows>0</cast_shadows>
            <pose frame="">0 0 0 0 0 0</pose>
            <geometry>
                <cylinder>
                    <length>0.05</length>
                    <radius>0.02</radius>
                </cylinder>
            </geometry>
            <material>
                <script>
                    <name>Gazebo/Red</name>
                    <uri>file://media/materials/scripts/gazebo.material</uri>
                </script>
            </material>
        </visual>
        <self_collide>1</self_collide>
        </link>
        
        <link name="rope_link_2">
        <pose frame="">0.1 0 0 3.14159 -1.57079 3.14159</pose>
        <inertial>
            <pose frame="">0.025 0 0 0 0 0</pose>
            <mass>0.05</mass>
            <inertia>
                <ixx>1.5416666666666668e-05</ixx>
                <ixy>0</ixy>
                <ixz>0</ixz>
                <iyy>1.5416666666666668e-05</iyy>
                <iyz>0</iyz>
                <izz>1.0e-05</izz>
            </inertia>
        </inertial>
        <collision name="link_2_collision">
            <pose frame="">0 0 0 0 0 0</pose>
            <geometry>
                <box>
                    <size>0.04000000000000001 0.04000000000000001 0.02</size>
                </box>
            </geometry>
            <surface>
                <friction>
                    <ode>
                        <mu>0.10</mu>
                        <mu2>0.10</mu2>
                    </ode>
                </friction>
                <contact>
                    <ode>
                        <kp>1e15</kp>
                        <kd>1e13</kd>
                    </ode>
                </contact>
            </surface>
        </collision>

        <visual name="link_2_visual">
            <cast_shadows>0</cast_shadows>
            <pose frame="">0 0 0 0 0 0</pose>
            <geometry>
                <cylinder>
                    <length>0.05</length>
                    <radius>0.02</radius>
                </cylinder>
            </geometry>
            <material>
                <script>
                    <name>Gazebo/Red</name>
                    <uri>file://media/materials/scripts/gazebo.material</uri>
                </script>
            </material>
        </visual>
        <self_collide>1</self_collide>
        </link>
        
        <link name="rope_link_3">
        <pose frame="">0.15000000000000002 0 0 3.14159 -1.57079 3.14159</pose>
        <inertial>
            <pose frame="">0.025 0 0 0 0 0</pose>
            <mass>0.05</mass>
            <inertia>
                <ixx>1.5416666666666668e-05</ixx>
                <ixy>0</ixy>
                <ixz>0</ixz>
                <iyy>1.5416666666666668e-05</iyy>
                <iyz>0</iyz>
                <izz>1.0e-05</izz>
            </inertia>
        </inertial>
        <collision name="link_3_collision">
            <pose frame="">0 0 0 0 0 0</pose>
            <geometry>
                <box>
                    <size>0.04000000000000001 0.04000000000000001 0.02</size>
                </box>
            </geometry>
            <surface>
                <friction>
                    <ode>
                        <mu>0.10</mu>
                        <mu2>0.10</mu2>
                    </ode>
                </friction>
                <contact>
                    <ode>
                        <kp>1e15</kp>
                        <kd>1e13</kd>
                    </ode>
                </contact>
            </surface>
        </collision>

        <visual name="link_3_visual">
            <cast_shadows>0</cast_shadows>
            <pose frame="">0 0 0 0 0 0</pose>
            <geometry>
                <cylinder>
                    <length>0.05</length>
                    <radius>0.02</radius>
                </cylinder>
            </geometry>
            <material>
                <script>
                    <name>Gazebo/Red</name>
                    <uri>file://media/materials/scripts/gazebo.material</uri>
                </script>
            </material>
        </visual>
        <self_collide>1</self_collide>
        </link>
        
        <link name="rope_link_4">
        <pose frame="">0.2 0 0 3.14159 -1.57079 3.14159</pose>
        <inertial>
            <pose frame="">0.025 0 0 0 0 0</pose>
            <mass>0.05</mass>
            <inertia>
                <ixx>1.5416666666666668e-05</ixx>
                <ixy>0</ixy>
                <ixz>0</ixz>
                <iyy>1.5416666666666668e-05</iyy>
                <iyz>0</iyz>
                <izz>1.0e-05</izz>
            </inertia>
        </inertial>
        <collision name="link_4_collision">
            <pose frame="">0 0 0 0 0 0</pose>
            <geometry>
                <box>
                    <size>0.04000000000000001 0.04000000000000001 0.02</size>
                </box>
            </geometry>
            <surface>
                <friction>
                    <ode>
                        <mu>0.10</mu>
                        <mu2>0.10</mu2>
                    </ode>
                </friction>
                <contact>
                    <ode>
                        <kp>1e15</kp>
                        <kd>1e13</kd>
                    </ode>
                </contact>
            </surface>
        </collision>

        <visual name="link_4_visual">
            <cast_shadows>0</cast_shadows>
            <pose frame="">0 0 0 0 0 0</pose>
            <geometry>
                <cylinder>
                    <length>0.05</length>
                    <radius>0.02</radius>
                </cylinder>
            </geometry>
            <material>
                <script>
                    <name>Gazebo/Red</name>
                    <uri>file://media/materials/scripts/gazebo.material</uri>
                </script>
            </material>
        </visual>
        <self_collide>1</self_collide>
        </link>
        
        <link name="rope_link_5">
        <pose frame="">0.25 0 0 3.14159 -1.57079 3.14159</pose>
        <inertial>
            <pose frame="">0.025 0 0 0 0 0</pose>
            <mass>0.05</mass>
            <inertia>
                <ixx>1.5416666666666668e-05</ixx>
                <ixy>0</ixy>
                <ixz>0</ixz>
                <iyy>1.5416666666666668e-05</iyy>
                <iyz>0</iyz>
                <izz>1.0e-05</izz>
            </inertia>
        </inertial>
        <collision name="link_5_collision">
            <pose frame="">0 0 0 0 0 0</pose>
            <geometry>
                <box>
                    <size>0.04000000000000001 0.04000000000000001 0.02</size>
                </box>
            </geometry>
            <surface>
                <friction>
                    <ode>
                        <mu>0.10</mu>
                        <mu2>0.10</mu2>
                    </ode>
                </friction>
                <contact>
                    <ode>
                        <kp>1e15</kp>
                        <kd>1e13</kd>
                    </ode>
                </contact>
            </surface>
        </collision>

        <visual name="link_5_visual">
            <cast_shadows>0</cast_shadows>
            <pose frame="">0 0 0 0 0 0</pose>
            <geometry>
                <cylinder>
                    <length>0.05</length>
                    <radius>0.02</radius>
                </cylinder>
            </geometry>
            <material>
                <script>
                    <name>Gazebo/Red</name>
                    <uri>file://media/materials/scripts/gazebo.material</uri>
                </script>
            </material>
        </visual>
        <self_collide>1</self_collide>
        </link>
        
        <link name="rope_link_6">
        <pose frame="">0.30000000000000004 0 0 3.14159 -1.57079 3.14159</pose>
        <inertial>
            <pose frame="">0.025 0 0 0 0 0</pose>
            <mass>0.05</mass>
            <inertia>
                <ixx>1.5416666666666668e-05</ixx>
                <ixy>0</ixy>
                <ixz>0</ixz>
                <iyy>1.5416666666666668e-05</iyy>
                <iyz>0</iyz>
                <izz>1.0e-05</izz>
            </inertia>
        </inertial>
        <collision name="link_6_collision">
            <pose frame="">0 0 0 0 0 0</pose>
            <geometry>
                <box>
                    <size>0.04000000000000001 0.04000000000000001 0.02</size>
                </box>
            </geometry>
            <surface>
                <friction>
                    <ode>
                        <mu>0.10</mu>
                        <mu2>0.10</mu2>
                    </ode>
                </friction>
                <contact>
                    <ode>
                        <kp>1e15</kp>
                        <kd>1e13</kd>
                    </ode>
                </contact>
            </surface>
        </collision>

        <visual name="link_6_visual">
            <cast_shadows>0</cast_shadows>
            <pose frame="">0 0 0 0 0 0</pose>
            <geometry>
                <cylinder>
                    <length>0.05</length>
                    <radius>0.02</radius>
                </cylinder>
            </geometry>
            <material>
                <script>
                    <name>Gazebo/Red</name>
                    <uri>file://media/materials/scripts/gazebo.material</uri>
                </script>
            </material>
        </visual>
        <self_collide>1</self_collide>
        </link>
        
        <link name="rope_link_7">
        <pose frame="">0.35000000000000003 0 0 3.14159 -1.57079 3.14159</pose>
        <inertial>
            <pose frame="">0.025 0 0 0 0 0</pose>
            <mass>0.05</mass>
            <inertia>
                <ixx>1.5416666666666668e-05</ixx>
                <ixy>0</ixy>
                <ixz>0</ixz>
                <iyy>1.5416666666666668e-05</iyy>
                <iyz>0</iyz>
                <izz>1.0e-05</izz>
            </inertia>
        </inertial>
        <collision name="link_7_collision">
            <pose frame="">0 0 0 0 0 0</pose>
            <geometry>
                <box>
                    <size>0.04000000000000001 0.04000000000000001 0.02</size>
                </box>
            </geometry>
            <surface>
                <friction>
                    <ode>
                        <mu>0.10</mu>
                        <mu2>0.10</mu2>
                    </ode>
                </friction>
                <contact>
                    <ode>
                        <kp>1e15</kp>
                        <kd>1e13</kd>
                    </ode>
                </contact>
            </surface>
        </collision>

        <visual name="link_7_visual">
            <cast_shadows>0</cast_shadows>
            <pose frame="">0 0 0 0 0 0</pose>
            <geometry>
                <cylinder>
                    <length>0.05</length>
                    <radius>0.02</radius>
                </cylinder>
            </geometry>
            <material>
                <script>
                    <name>Gazebo/Red</name>
                    <uri>file://media/materials/scripts/gazebo.material</uri>
                </script>
            </material>
        </visual>
        <self_collide>1</self_collide>
        </link>
        
        <link name="rope_link_8">
        <pose frame="">0.4 0 0 3.14159 -1.57079 3.14159</pose>
        <inertial>
            <pose frame="">0.025 0 0 0 0 0</pose>
            <mass>0.05</mass>
            <inertia>
                <ixx>1.5416666666666668e-05</ixx>
                <ixy>0</ixy>
                <ixz>0</ixz>
                <iyy>1.5416666666666668e-05</iyy>
                <iyz>0</iyz>
                <izz>1.0e-05</izz>
            </inertia>
        </inertial>
        <collision name="link_8_collision">
            <pose frame="">0 0 0 0 0 0</pose>
            <geometry>
                <box>
                    <size>0.04000000000000001 0.04000000000000001 0.02</size>
                </box>
            </geometry>
            <surface>
                <friction>
                    <ode>
                        <mu>0.10</mu>
                        <mu2>0.10</mu2>
                    </ode>
                </friction>
                <contact>
                    <ode>
                        <kp>1e15</kp>
                        <kd>1e13</kd>
                    </ode>
                </contact>
            </surface>
        </collision>

        <visual name="link_8_visual">
            <cast_shadows>0</cast_shadows>
            <pose frame="">0 0 0 0 0 0</pose>
            <geometry>
                <cylinder>
                    <length>0.05</length>
                    <radius>0.02</radius>
                </cylinder>
            </geometry>
            <material>
                <script>
                    <name>Gazebo/Red</name>
                    <uri>file://media/materials/scripts/gazebo.material</uri>
                </script>
            </material>
        </visual>
        <self_collide>1</self_collide>
        </link>
        
        <link name="rope_link_9">
        <pose frame="">0.45 0 0 3.14159 -1.57079 3.14159</pose>
        <inertial>
            <pose frame="">0.025 0 0 0 0 0</pose>
            <mass>0.05</mass>
            <inertia>
                <ixx>1.5416666666666668e-05</ixx>
                <ixy>0</ixy>
                <ixz>0</ixz>
                <iyy>1.5416666666666668e-05</iyy>
                <iyz>0</iyz>
                <izz>1.0e-05</izz>
            </inertia>
        </inertial>
        <collision name="link_9_collision">
            <pose frame="">0 0 0 0 0 0</pose>
            <geometry>
                <box>
                    <size>0.04000000000000001 0.04000000000000001 0.02</size>
                </box>
            </geometry>
            <surface>
                <friction>
                    <ode>
                        <mu>0.10</mu>
                        <mu2>0.10</mu2>
                    </ode>
                </friction>
                <contact>
                    <ode>
                        <kp>1e15</kp>
                        <kd>1e13</kd>
                    </ode>
                </contact>
            </surface>
        </collision>

        <visual name="link_9_visual">
            <cast_shadows>0</cast_shadows>
            <pose frame="">0 0 0 0 0 0</pose>
            <geometry>
                <cylinder>
                    <length>0.05</length>
                    <radius>0.02</radius>
                </cylinder>
            </geometry>
            <material>
                <script>
                    <name>Gazebo/Red</name>
                    <uri>file://media/materials/scripts/gazebo.material</uri>
                </script>
            </material>
        </visual>
        <self_collide>1</self_collide>
        </link>
        
        <link name="rope_link_10">
        <pose frame="">0.5 0 0 3.14159 -1.57079 3.14159</pose>
        <inertial>
            <pose frame="">0.025 0 0 0 0 0</pose>
            <mass>0.05</mass>
            <inertia>
                <ixx>1.5416666666666668e-05</ixx>
                <ixy>0</ixy>
                <ixz>0</ixz>
                <iyy>1.5416666666666668e-05</iyy>
                <iyz>0</iyz>
                <izz>1.0e-05</izz>
            </inertia>
        </inertial>
        <collision name="link_10_collision">
            <pose frame="">0 0 0 0 0 0</pose>
            <geometry>
                <box>
                    <size>0.04000000000000001 0.04000000000000001 0.02</size>
                </box>
            </geometry>
            <surface>
                <friction>
                    <ode>
                        <mu>0.10</mu>
                        <mu2>0.10</mu2>
                    </ode>
                </friction>
                <contact>
                    <ode>
                        <kp>1e15</kp>
                        <kd>1e13</kd>
                    </ode>
                </contact>
            </surface>
        </collision>

        <visual name="link_10_visual">
            <cast_shadows>0</cast_shadows>
            <pose frame="">0 0 0 0 0 0</pose>
            <geometry>
                <cylinder>
                    <length>0.05</length>
                    <radius>0.02</radius>
                </cylinder>
            </geometry>
            <material>
                <script>
                    <name>Gazebo/Red</name>
                    <uri>file://media/materials/scripts/gazebo.material</uri>
                </script>
            </material>
        </visual>
        <self_collide>1</self_collide>
        </link>
        
        
        <joint name="joint_1" type="revolute">
            <child>rope_link_2</child>
            <parent>rope_link_1</parent>
            <pose>0 0 0.025 0 0 0</pose>
            <axis>
                <xyz>0 0 1</xyz>
                <limit>
                    <lower>-2.8</lower>
                    <upper>2.8</upper>
                    <effort>10</effort>
                    <velocity>5</velocity>
                </limit>
                <dynamics>
                    <damping>0.0</damping>
                    <friction>0</friction>
                </dynamics>
                <use_parent_model_frame>1</use_parent_model_frame>
            </axis>
            <physics>
                <ode>
                    <cfm>0.0001</cfm>
                    <implicit_spring_damper>1</implicit_spring_damper>
                </ode>
            </physics>
        </joint>
        
        <joint name="joint_2" type="revolute">
            <child>rope_link_3</child>
            <parent>rope_link_2</parent>
            <pose>0 0 0.025 0 0 0</pose>
            <axis>
                <xyz>0 0 1</xyz>
                <limit>
                    <lower>-2.8</lower>
                    <upper>2.8</upper>
                    <effort>10</effort>
                    <velocity>5</velocity>
                </limit>
                <dynamics>
                    <damping>0.0</damping>
                    <friction>0</friction>
                </dynamics>
                <use_parent_model_frame>1</use_parent_model_frame>
            </axis>
            <physics>
                <ode>
                    <cfm>0.0001</cfm>
                    <implicit_spring_damper>1</implicit_spring_damper>
                </ode>
            </physics>
        </joint>
        
        <joint name="joint_3" type="revolute">
            <child>rope_link_4</child>
            <parent>rope_link_3</parent>
            <pose>0 0 0.025 0 0 0</pose>
            <axis>
                <xyz>0 0 1</xyz>
                <limit>
                    <lower>-2.8</lower>
                    <upper>2.8</upper>
                    <effort>10</effort>
                    <velocity>5</velocity>
                </limit>
                <dynamics>
                    <damping>0.0</damping>
                    <friction>0</friction>
                </dynamics>
                <use_parent_model_frame>1</use_parent_model_frame>
            </axis>
            <physics>
                <ode>
                    <cfm>0.0001</cfm>
                    <implicit_spring_damper>1</implicit_spring_damper>
                </ode>
            </physics>
        </joint>
        
        <joint name="joint_4" type="revolute">
            <child>rope_link_5</child>
            <parent>rope_link_4</parent>
            <pose>0 0 0.025 0 0 0</pose>
            <axis>
                <xyz>0 0 1</xyz>
                <limit>
                    <lower>-2.8</lower>
                    <upper>2.8</upper>
                    <effort>10</effort>
                    <velocity>5</velocity>
                </limit>
                <dynamics>
                    <damping>0.0</damping>
                    <friction>0</friction>
                </dynamics>
                <use_parent_model_frame>1</use_parent_model_frame>
            </axis>
            <physics>
                <ode>
                    <cfm>0.0001</cfm>
                    <implicit_spring_damper>1</implicit_spring_damper>
                </ode>
            </physics>
        </joint>
        
        <joint name="joint_5" type="revolute">
            <child>rope_link_6</child>
            <parent>rope_link_5</parent>
            <pose>0 0 0.025 0 0 0</pose>
            <axis>
                <xyz>0 0 1</xyz>
                <limit>
                    <lower>-2.8</lower>
                    <upper>2.8</upper>
                    <effort>10</effort>
                    <velocity>5</velocity>
                </limit>
                <dynamics>
                    <damping>0.0</damping>
                    <friction>0</friction>
                </dynamics>
                <use_parent_model_frame>1</use_parent_model_frame>
            </axis>
            <physics>
                <ode>
                    <cfm>0.0001</cfm>
                    <implicit_spring_damper>1</implicit_spring_damper>
                </ode>
            </physics>
        </joint>
        
        <joint name="joint_6" type="revolute">
            <child>rope_link_7</child>
            <parent>rope_link_6</parent>
            <pose>0 0 0.025 0 0 0</pose>
            <axis>
                <xyz>0 0 1</xyz>
                <limit>
                    <lower>-2.8</lower>
                    <upper>2.8</upper>
                    <effort>10</effort>
                    <velocity>5</velocity>
                </limit>
                <dynamics>
                    <damping>0.0</damping>
                    <friction>0</friction>
                </dynamics>
                <use_parent_model_frame>1</use_parent_model_frame>
            </axis>
            <physics>
                <ode>
                    <cfm>0.0001</cfm>
                    <implicit_spring_damper>1</implicit_spring_damper>
                </ode>
            </physics>
        </joint>
        
        <joint name="joint_7" type="revolute">
            <child>rope_link_8</child>
            <parent>rope_link_7</parent>
            <pose>0 0 0.025 0 0 0</pose>
            <axis>
                <xyz>0 0 1</xyz>
                <limit>
                    <lower>-2.8</lower>
                    <upper>2.8</upper>
                    <effort>10</effort>
                    <velocity>5</velocity>
                </limit>
                <dynamics>
                    <damping>0.0</damping>
                    <friction>0</friction>
                </dynamics>
                <use_parent_model_frame>1</use_parent_model_frame>
            </axis>
            <physics>
                <ode>
                    <cfm>0.0001</cfm>
                    <implicit_spring_damper>1</implicit_spring_damper>
                </ode>
            </physics>
        </joint>
        
        <joint name="joint_8" type="revolute">
            <child>rope_link_9</child>
            <parent>rope_link_8</parent>
            <pose>0 0 0.025 0 0 0</pose>
            <axis>
                <xyz>0 0 1</xyz>
                <limit>
                    <lower>-2.8</lower>
                    <upper>2.8</upper>
                    <effort>10</effort>
                    <velocity>5</velocity>
                </limit>
                <dynamics>
                    <damping>0.0</damping>
                    <friction>0</friction>
                </dynamics>
                <use_parent_model_frame>1</use_parent_model_frame>
            </axis>
            <physics>
                <ode>
                    <cfm>0.0001</cfm>
                    <implicit_spring_damper>1</implicit_spring_damper>
                </ode>
            </physics>
        </joint>
        
        <joint name="joint_9" type="revolute">
            <child>rope_link_10</child>
            <parent>rope_link_9</parent>
            <pose>0 0 0.025 0 0 0</pose>
            <axis>
                <xyz>0 0 1</xyz>
                <limit>
                    <lower>-2.8</lower>
                    <upper>2.8</upper>
                    <effort>10</effort>
                    <velocity>5</velocity>
                </limit>
                <dynamics>
                    <damping>0.0</damping>
                    <friction>0</friction>
                </dynamics>
                <use_parent_model_frame>1</use_parent_model_frame>
            </axis>
            <physics>
                <ode>
                    <cfm>0.0001</cfm>
                    <implicit_spring_damper>1</implicit_spring_damper>
                </ode>
            </physics>
        </joint>
        
        <link name='head'>
        <pose frame=''>0.525 0 0 0 0 0 </pose>
        <inertial>
            <pose frame=''>0 0 0 0 0 0</pose>
            <mass>0.1</mass>
            <inertia>
                <ixx>0.0001</ixx>
                <ixy>0</ixy>
                <ixz>0</ixz>
                <iyy>0.0001</iyy>
                <iyz>0</iyz>
                <izz>0.001</izz>
            </inertia>
        </inertial>
        <collision name='head_collision'>
            <pose frame=''>0 0 0 0 0 0</pose>
            <geometry>
                <sphere>
                    <radius>0.02 </radius>
                </sphere>
            </geometry>
            <surface>
                <contact>
                    <ode>
                        <kp>1e15</kp>
                        <kd>1e13</kd>
                    </ode>
                </contact>
                <friction>
                    <ode>
                        <mu>0.10</mu>
                        <mu2>0.10</mu2>
                    </ode>
                </friction>
            </surface>
        </collision>
        <visual name='head_visual'>
            <cast_shadows>0</cast_shadows>
            <pose frame=''>0 0 0 0 0 0</pose>
            <geometry>
                <sphere>
                    <radius>0.02</radius>
                </sphere>
            </geometry>
            <material>
                <script>
                    <name>Gazebo/Red</name>
                    <uri>file://media/materials/scripts/gazebo.material</uri>
                </script>
            </material>
        </visual>
        <self_collide>1</self_collide>
        </link>
        <joint name="head_joint" type="revolute">
            <child>head</child>
            <parent>rope_link_10</parent>
            <pose>0 0 0 0 0 0</pose>
            <axis>
                <xyz>0 0 1</xyz>
                <dynamics>
                    <damping>0.0</damping>
                    <friction>0.0</friction>
                </dynamics>
            </axis>
            <physics>
                <ode>
                    <cfm>0.0005</cfm>
                    <implicit_spring_damper>1</implicit_spring_damper>
                </ode>
            </physics>
        </joint>
        <plugin name='rope_plugin' filename='librope_plugin.so'>
            <num_links>10</num_links>
            <rope_length>0.5</rope_length>
        </plugin>
        <plugin name='position_3d_plugin' filename='libposition_3d_plugin.so'>
            <object_name>gripper</object_name>
            <gravity_compensation>true</gravity_compensation>
            <kP_pos>5</kP_pos>
            <kD_pos>0.0</kD_pos>
            <kP_vel>200.0</kP_vel>
            <kI_vel>0.05</kI_vel>
            <kD_vel>0.0</kD_vel>
            <max_force>2.0</max_force>
            <max_vel>0.15</max_vel>
            <kP_rot>0.0</kP_rot>
            <kI_rot>0.0</kI_rot>
            <kD_rot>0.0</kD_rot>
            <kP_rot_vel>0.0</kP_rot_vel>
            <kI_rot_vel>0.0</kI_rot_vel>
            <kD_rot_vel>0.0</kD_rot_vel>
            <max_torque>0.0</max_torque>
            <max_rot_vel>0.0</max_rot_vel>
            <link>head</link>
        </plugin>
    </model>
</sdf>
