<sdf version='1.6'>
    <model name='link_bot'>
        <link name='link_1'>
            <pose frame=''>0 0 0 0 -0 0</pose>
            <inertial>
                <pose frame=''>0.11 0 0 0 -0 0</pose>
                <mass>0.25</mass>
                <inertia>
                    <ixx>6.66667e-05</ixx>
                    <ixy>0</ixy>
                    <ixz>0</ixz>
                    <iyy>0.00113542</iyy>
                    <iyz>0</iyz>
                    <izz>0.00113542</izz>
                </inertia>
            </inertial>
            <collision name='link_1_collision'>
                <pose frame=''>0.11 0 0 3.14159 -1.57079 3.14159</pose>
                <geometry>
                    <box>
                        <size>0.04 0.04 0.22</size>
                    </box>
                </geometry>
                <surface>
                    <friction>
                        <ode>
                            <mu>0.15</mu>
                            <mu2>0.15</mu2>
                        </ode>
                    </friction>
                </surface>
                <max_contacts>20</max_contacts>
            </collision>
            <visual name='link_1_visual'>
                <cast_shadows>0</cast_shadows>
                <pose frame=''>0.11 0 0 3.14159 -1.57079 3.14159</pose>
                <geometry>
                    <cylinder>
                        <length>0.24</length>
                        <radius>0.02</radius>
                    </cylinder>
                </geometry>
                <material>
                    <script>
                        <name>Gazebo/Green</name>
                        <uri>file://media/materials/scripts/gazebo.material</uri>
                    </script>
                </material>
            </visual>
            <self_collide>1</self_collide>
        </link>
        <link name='link_2'>
            <pose frame=''>0.23 0 0 0 -0 0</pose>
            <inertial>
                <pose frame=''>0.11 0 0 0 -0 0</pose>
                <mass>0.25</mass>
                <inertia>
                    <ixx>6.66667e-05</ixx>
                    <ixy>0</ixy>
                    <ixz>0</ixz>
                    <iyy>0.00113542</iyy>
                    <iyz>0</iyz>
                    <izz>0.00113542</izz>
                </inertia>
            </inertial>
            <collision name='link_2_collision'>
                <pose frame=''>0.11 0 0 3.14159 -1.57079 3.14159</pose>
                <geometry>
                    <box>
                        <size>0.04 0.04 0.22</size>
                    </box>
                </geometry>
                <surface>
                    <friction>
                        <ode>
                            <mu>0.15</mu>
                            <mu2>0.15</mu2>
                        </ode>
                    </friction>
                </surface>
                <max_contacts>20</max_contacts>
            </collision>
            <visual name='link_2_visual'>
                <cast_shadows>0</cast_shadows>
                <pose frame=''>0.11 0 0 3.14159 -1.57079 3.14159</pose>
                <geometry>
                    <cylinder>
                        <length>0.24</length>
                        <radius>0.02</radius>
                    </cylinder>
                </geometry>
                <material>
                    <script>
                        <name>Gazebo/Black</name>
                        <uri>file://media/materials/scripts/gazebo.material</uri>
                    </script>
                </material>
            </visual>
            <self_collide>1</self_collide>
            <sensor name='link_2_contact' type='contact'>
                <contact>
                    <collision>link_2_collision</collision>
                    <topic>__default_topic__</topic>
                </contact>
            </sensor>
        </link>
        <joint name='joint_1' type='revolute'>
            <child>link_2</child>
            <parent>link_1</parent>
            <axis>
                <xyz>0 0 1</xyz>
                <limit>
                    <lower>-3</lower>
                    <upper>3</upper>
                    <effort>10</effort>
                    <velocity>5</velocity>
                </limit>
                <dynamics>
                    <damping>1</damping>
                    <friction>0</friction>
                </dynamics>
                <use_parent_model_frame>1</use_parent_model_frame>
            </axis>
        </joint>
        <link name='head'>
            <pose frame=''>0.46 0 0 0 -0 0</pose>
            <inertial>
                <pose frame=''>0 0 0 0 -0 0</pose>
                <mass>0.1</mass>
                <inertia>
                    <ixx>0.0001</ixx>
                    <ixy>0</ixy>
                    <ixz>0</ixz>
                    <iyy>0.0001</iyy>
                    <iyz>0</iyz>
                    <izz>0.001</izz>
                </inertia>
            </inertial>
            <collision name='head_collision'>
                <pose frame=''>0 0 0 0 -0 0</pose>
                <geometry>
                    <sphere>
                        <radius>0.02</radius>
                    </sphere>
                </geometry>
                <surface>
                    <friction>
                        <ode>
                            <mu>0.15</mu>
                            <mu2>0.15</mu2>
                        </ode>
                    </friction>
                </surface>
                <max_contacts>20</max_contacts>
            </collision>
            <visual name='head_visual'>
                <cast_shadows>0</cast_shadows>
                <pose frame=''>0 0 0 0 -0 0</pose>
                <geometry>
                    <sphere>
                        <radius>0.02</radius>
                    </sphere>
                </geometry>
                <material>
                    <script>
                        <name>Gazebo/Yellow</name>
                        <uri>file://media/materials/scripts/gazebo.material</uri>
                    </script>
                </material>
            </visual>
            <self_collide>1</self_collide>
            <sensor name='head_contact' type='contact'>
                <contact>
                    <collision>head_collision</collision>
                    <topic>__default_topic__</topic>
                </contact>
            </sensor>
        </link>
        <joint name='head_joint' type='revolute'>
            <child>head</child>
            <parent>link_2</parent>
            <axis>
                <xyz>0 0 1</xyz>
                <limit>
                    <lower>-3</lower>
                    <upper>3</upper>
                    <effort>10</effort>
                    <velocity>5</velocity>
                </limit>
                <dynamics>
                    <damping>1</damping>
                    <friction>0</friction>
                </dynamics>
                <use_parent_model_frame>1</use_parent_model_frame>
            </axis>
            <physics>
                <ode>
                    <limit>
                        <cfm>0</cfm>
                        <erp>0.2</erp>
                    </limit>
                </ode>
            </physics>
        </joint>
        <link name='tail'>
            <pose frame=''>-0.02 0 0 0 -0 0</pose>
            <inertial>
                <pose frame=''>0 0 0 0 -0 0</pose>
                <mass>0.1</mass>
                <inertia>
                    <ixx>0.0001</ixx>
                    <ixy>0</ixy>
                    <ixz>0</ixz>
                    <iyy>0.0001</iyy>
                    <iyz>0</iyz>
                    <izz>0.001</izz>
                </inertia>
            </inertial>
            <collision name='tail_collision'>
                <pose frame=''>0 0 0 0 -0 0</pose>
                <geometry>
                    <sphere>
                        <radius>0.02</radius>
                    </sphere>
                </geometry>
                <surface>
                    <friction>
                        <ode>
                            <mu>0.15</mu>
                            <mu2>0.15</mu2>
                        </ode>
                    </friction>
                </surface>
                <max_contacts>20</max_contacts>
            </collision>
            <visual name='tail_visual'>
                <cast_shadows>0</cast_shadows>
                <pose frame=''>0 0 0 0 -0 0</pose>
                <geometry>
                    <sphere>
                        <radius>0.02</radius>
                    </sphere>
                </geometry>
                <material>
                    <script>
                        <name>Gazebo/Orange</name>
                        <uri>file://media/materials/scripts/gazebo.material</uri>
                    </script>
                </material>
            </visual>
            <self_collide>1</self_collide>
        </link>
        <joint name='tail_joint' type='revolute'>
            <child>tail</child>
            <parent>link_1</parent>
            <axis>
                <xyz>0 0 1</xyz>
                <limit>
                    <lower>-3</lower>
                    <upper>3</upper>
                    <effort>10</effort>
                    <velocity>5</velocity>
                </limit>
                <dynamics>
                    <damping>1</damping>
                    <friction>0</friction>
                </dynamics>
                <use_parent_model_frame>1</use_parent_model_frame>
            </axis>
        </joint>
        <static>0</static>
        <plugin name='multi_link_bot_model_plugin' filename='libmulti_link_bot_model_plugin.so'>
            <kP_pos>50</kP_pos>
            <kI_pos>0.001</kI_pos>
            <kD_pos>0.0</kD_pos>
            <kP_vel>75.0</kP_vel>
            <kI_vel>0.0</kI_vel>
            <kD_vel>0.0</kD_vel>
            <gripper1_link>head</gripper1_link>
        </plugin>
        <pose frame=''>-0.45 0 0.01 0 -0 0</pose>
    </model>
</sdf>
