






<?xml version="1.0"?>
<robot name="link_bot">
    
    <link name="link_0">
        <visual>
            <origin rpy="0 -1.5707 0" xyz="0.06142857142857142 0 0"/>
            <geometry>
                <cylinder length="0.14285714285714285" radius="0.02"/>
            </geometry>
        </visual>
        <collision>
            <origin rpy="0 -1.5707 0" xyz="0.06142857142857142 0 0"/>
            <geometry>
                <box size="0.04 0.04 0.12285714285714285"/>
            </geometry>
            <surface>
                <contact>
                    <ode>
                        <max_vel>0.00</max_vel>
                        <min_depth>0.01</min_depth>
                    </ode>
                </contact>
            </surface>
        </collision>
        <inertial>
            <mass value="1.4285714285714286"/>
            <inertia ixx="3.333" ixy="0" ixz="0" iyy="0" iyz="0" izz="3.333"/>
            <origin rpy="0 0 0" xyz="0.13285714285714284 0 0"/>
        </inertial>
    </link>
    
    <link name="link_1">
        <visual>
            <origin rpy="0 -1.5707 0" xyz="0.06142857142857142 0 0"/>
            <geometry>
                <cylinder length="0.14285714285714285" radius="0.02"/>
            </geometry>
        </visual>
        <collision>
            <origin rpy="0 -1.5707 0" xyz="0.06142857142857142 0 0"/>
            <geometry>
                <box size="0.04 0.04 0.12285714285714285"/>
            </geometry>
            <surface>
                <contact>
                    <ode>
                        <max_vel>0.00</max_vel>
                        <min_depth>0.01</min_depth>
                    </ode>
                </contact>
            </surface>
        </collision>
        <inertial>
            <mass value="1.4285714285714286"/>
            <inertia ixx="3.333" ixy="0" ixz="0" iyy="0" iyz="0" izz="3.333"/>
            <origin rpy="0 0 0" xyz="0.13285714285714284 0 0"/>
        </inertial>
    </link>
    
    <link name="link_2">
        <visual>
            <origin rpy="0 -1.5707 0" xyz="0.06142857142857142 0 0"/>
            <geometry>
                <cylinder length="0.14285714285714285" radius="0.02"/>
            </geometry>
        </visual>
        <collision>
            <origin rpy="0 -1.5707 0" xyz="0.06142857142857142 0 0"/>
            <geometry>
                <box size="0.04 0.04 0.12285714285714285"/>
            </geometry>
            <surface>
                <contact>
                    <ode>
                        <max_vel>0.00</max_vel>
                        <min_depth>0.01</min_depth>
                    </ode>
                </contact>
            </surface>
        </collision>
        <inertial>
            <mass value="1.4285714285714286"/>
            <inertia ixx="3.333" ixy="0" ixz="0" iyy="0" iyz="0" izz="3.333"/>
            <origin rpy="0 0 0" xyz="0.13285714285714284 0 0"/>
        </inertial>
    </link>
    
    <link name="link_3">
        <visual>
            <origin rpy="0 -1.5707 0" xyz="0.06142857142857142 0 0"/>
            <geometry>
                <cylinder length="0.14285714285714285" radius="0.02"/>
            </geometry>
        </visual>
        <collision>
            <origin rpy="0 -1.5707 0" xyz="0.06142857142857142 0 0"/>
            <geometry>
                <box size="0.04 0.04 0.12285714285714285"/>
            </geometry>
            <surface>
                <contact>
                    <ode>
                        <max_vel>0.00</max_vel>
                        <min_depth>0.01</min_depth>
                    </ode>
                </contact>
            </surface>
        </collision>
        <inertial>
            <mass value="1.4285714285714286"/>
            <inertia ixx="3.333" ixy="0" ixz="0" iyy="0" iyz="0" izz="3.333"/>
            <origin rpy="0 0 0" xyz="0.13285714285714284 0 0"/>
        </inertial>
    </link>
    
    <link name="link_4">
        <visual>
            <origin rpy="0 -1.5707 0" xyz="0.06142857142857142 0 0"/>
            <geometry>
                <cylinder length="0.14285714285714285" radius="0.02"/>
            </geometry>
        </visual>
        <collision>
            <origin rpy="0 -1.5707 0" xyz="0.06142857142857142 0 0"/>
            <geometry>
                <box size="0.04 0.04 0.12285714285714285"/>
            </geometry>
            <surface>
                <contact>
                    <ode>
                        <max_vel>0.00</max_vel>
                        <min_depth>0.01</min_depth>
                    </ode>
                </contact>
            </surface>
        </collision>
        <inertial>
            <mass value="1.4285714285714286"/>
            <inertia ixx="3.333" ixy="0" ixz="0" iyy="0" iyz="0" izz="3.333"/>
            <origin rpy="0 0 0" xyz="0.13285714285714284 0 0"/>
        </inertial>
    </link>
    
    <link name="link_5">
        <visual>
            <origin rpy="0 -1.5707 0" xyz="0.06142857142857142 0 0"/>
            <geometry>
                <cylinder length="0.14285714285714285" radius="0.02"/>
            </geometry>
        </visual>
        <collision>
            <origin rpy="0 -1.5707 0" xyz="0.06142857142857142 0 0"/>
            <geometry>
                <box size="0.04 0.04 0.12285714285714285"/>
            </geometry>
            <surface>
                <contact>
                    <ode>
                        <max_vel>0.00</max_vel>
                        <min_depth>0.01</min_depth>
                    </ode>
                </contact>
            </surface>
        </collision>
        <inertial>
            <mass value="1.4285714285714286"/>
            <inertia ixx="3.333" ixy="0" ixz="0" iyy="0" iyz="0" izz="3.333"/>
            <origin rpy="0 0 0" xyz="0.13285714285714284 0 0"/>
        </inertial>
    </link>
    
    <link name="link_6">
        <visual>
            <origin rpy="0 -1.5707 0" xyz="0.06142857142857142 0 0"/>
            <geometry>
                <cylinder length="0.14285714285714285" radius="0.02"/>
            </geometry>
        </visual>
        <collision>
            <origin rpy="0 -1.5707 0" xyz="0.06142857142857142 0 0"/>
            <geometry>
                <box size="0.04 0.04 0.12285714285714285"/>
            </geometry>
            <surface>
                <contact>
                    <ode>
                        <max_vel>0.00</max_vel>
                        <min_depth>0.01</min_depth>
                    </ode>
                </contact>
            </surface>
        </collision>
        <inertial>
            <mass value="1.4285714285714286"/>
            <inertia ixx="3.333" ixy="0" ixz="0" iyy="0" iyz="0" izz="3.333"/>
            <origin rpy="0 0 0" xyz="0.13285714285714284 0 0"/>
        </inertial>
    </link>
    
    <link name="link_7">
        <visual>
            <origin rpy="0 -1.5707 0" xyz="0.06142857142857142 0 0"/>
            <geometry>
                <cylinder length="0.14285714285714285" radius="0.02"/>
            </geometry>
        </visual>
        <collision>
            <origin rpy="0 -1.5707 0" xyz="0.06142857142857142 0 0"/>
            <geometry>
                <box size="0.04 0.04 0.12285714285714285"/>
            </geometry>
            <surface>
                <contact>
                    <ode>
                        <max_vel>0.00</max_vel>
                        <min_depth>0.01</min_depth>
                    </ode>
                </contact>
            </surface>
        </collision>
        <inertial>
            <mass value="1.4285714285714286"/>
            <inertia ixx="3.333" ixy="0" ixz="0" iyy="0" iyz="0" izz="3.333"/>
            <origin rpy="0 0 0" xyz="0.13285714285714284 0 0"/>
        </inertial>
    </link>
    

    <link name="head">
        <visual>
            <origin rpy="0 0 0" xyz="0 0 0"/>
            <geometry>
                <sphere radius="0.02"/>
            </geometry>
        </visual>
        <collision name="head">
            <origin rpy="0 0 0" xyz="0 0 0"/>
            <geometry>
                <box size="0.02 0.02 0.02"/>
            </geometry>
        </collision>
        <inertial>
            <mass value="0.1"/>
            <origin rpy="0 0 0" xyz="0 0 0"/>
            <inertia ixx="0.0004" ixy="0" ixz="0" iyy="0.0004" iyz="0" izz="0.004"/>
        </inertial>
    </link>

    
    <joint name="joint_0" type="revolute">
        <parent link="link_0"/>
        <child link="link_1"/>
        <origin xyz="0.13285714285714284 0 0"/>
        <axis xyz="0 0 1"/>
        <limit lower="-3" upper="3" effort="10" velocity="1"/>
        <dynamics damping="1" friction="0.0"/>
    </joint>
    
    <joint name="joint_1" type="revolute">
        <parent link="link_1"/>
        <child link="link_2"/>
        <origin xyz="0.13285714285714284 0 0"/>
        <axis xyz="0 0 1"/>
        <limit lower="-3" upper="3" effort="10" velocity="1"/>
        <dynamics damping="1" friction="0.0"/>
    </joint>
    
    <joint name="joint_2" type="revolute">
        <parent link="link_2"/>
        <child link="link_3"/>
        <origin xyz="0.13285714285714284 0 0"/>
        <axis xyz="0 0 1"/>
        <limit lower="-3" upper="3" effort="10" velocity="1"/>
        <dynamics damping="1" friction="0.0"/>
    </joint>
    
    <joint name="joint_3" type="revolute">
        <parent link="link_3"/>
        <child link="link_4"/>
        <origin xyz="0.13285714285714284 0 0"/>
        <axis xyz="0 0 1"/>
        <limit lower="-3" upper="3" effort="10" velocity="1"/>
        <dynamics damping="1" friction="0.0"/>
    </joint>
    
    <joint name="joint_4" type="revolute">
        <parent link="link_4"/>
        <child link="link_5"/>
        <origin xyz="0.13285714285714284 0 0"/>
        <axis xyz="0 0 1"/>
        <limit lower="-3" upper="3" effort="10" velocity="1"/>
        <dynamics damping="1" friction="0.0"/>
    </joint>
    
    <joint name="joint_5" type="revolute">
        <parent link="link_5"/>
        <child link="link_6"/>
        <origin xyz="0.13285714285714284 0 0"/>
        <axis xyz="0 0 1"/>
        <limit lower="-3" upper="3" effort="10" velocity="1"/>
        <dynamics damping="1" friction="0.0"/>
    </joint>
    
    <joint name="joint_6" type="revolute">
        <parent link="link_6"/>
        <child link="link_7"/>
        <origin xyz="0.13285714285714284 0 0"/>
        <axis xyz="0 0 1"/>
        <limit lower="-3" upper="3" effort="10" velocity="1"/>
        <dynamics damping="1" friction="0.0"/>
    </joint>
    

    <joint name="head_joint" type="revolute">
        <parent link="link_7"/>
        <child link="head"/>
        <origin xyz="0.13285714285714284 0 0"/>
        <axis xyz="0 0 1"/>
        <limit lower="-3" upper="3" effort="10" velocity="1"/>
        <dynamics damping="1.0" friction="0.0"/>
    </joint>

    
    <gazebo reference="link_0">
        <self_collide>true</self_collide>
    </gazebo>
    
    <gazebo reference="link_1">
        <self_collide>true</self_collide>
    </gazebo>
    
    <gazebo reference="link_2">
        <self_collide>true</self_collide>
    </gazebo>
    
    <gazebo reference="link_3">
        <self_collide>true</self_collide>
    </gazebo>
    
    <gazebo reference="link_4">
        <self_collide>true</self_collide>
    </gazebo>
    
    <gazebo reference="link_5">
        <self_collide>true</self_collide>
    </gazebo>
    
    <gazebo reference="link_6">
        <self_collide>true</self_collide>
    </gazebo>
    
    <gazebo reference="link_7">
        <self_collide>true</self_collide>
    </gazebo>
    
    <gazebo reference="head">
        <self_collide>true</self_collide>
    </gazebo>

    <gazebo reference="tail">
        <mu1>0.4</mu1>
        <mu2>0.4</mu2>
        <material>Gazebo/Gray</material>
    </gazebo>
    <gazebo reference="mid">
        <mu1>0.4</mu1>
        <mu2>0.4</mu2>
        <material>Gazebo/Green</material>
    </gazebo>
    <gazebo reference="head">
        <mu1>0.4</mu1>
        <mu2>0.4</mu2>
        <material>Gazebo/Blue</material>
        <sensor name='my_contact' type='contact'>
            <contact>
                <collision>head_collision</collision>
            </contact>
            <plugin name="head_gazebo_ros_bumper_controller" filename="libgazebo_ros_bumper.so">
                <alwaysOn>true</alwaysOn>
                <updateRate>5</updateRate>
                <bumperTopicName>head_contact</bumperTopicName>
            </plugin>
        </sensor>
    </gazebo>
    <gazebo>
        <plugin name="linkbot_model_plugin" filename="liblinkbot_model_plugin.so">
            <kP>600.0</kP>
            <kI>10.0</kI>
            <kD>1.0</kD>
            <action_scale>1</action_scale>
        </plugin>
        <plugin name="gazebo_ros_control" filename="libgazebo_ros_control.so">
            <legacyModeNS>false</legacyModeNS>
            <robotNamespace>link_bot</robotNamespace>
        </plugin>
    </gazebo>
</robot>
