







<?xml version="1.0" ?>
<sdf version="1.5">
  <model name="rope">
    <pose>0 0 0.1 0 0 0</pose>
    
        <link name="sphere_0">
          <pose>0.100000 0.000000 0.000000 0.000000 -0.000000 0.000000</pose>
          <inertial>
            <pose>0.000000 0.000000 0.000000 0.000000 -0.000000 0.000000</pose>
            <mass>0.100000</mass>
            <inertia>
              <ixx>0.010000</ixx>
              <ixy>0.000000</ixy>
              <ixz>0.000000</ixz>
              <iyy>0.010000</iyy>
              <iyz>0.000000</iyz>
              <izz>0.010000</izz>
            </inertia>
          </inertial>
          <collision name="sphere_0_collision">
            <pose>0.000000 0.000000 0.000000 0.000000 -0.000000 0.000000</pose>
            <geometry>
              <sphere>
                <radius>0.025</radius>
              </sphere>
            </geometry>
          </collision>
          <visual name="sphere_0_vis">
            <pose>0.000000 0.000000 0.000000 0.000000 -0.000000 0.000000</pose>
            <geometry>
              <sphere>
                <radius>0.025</radius>
              </sphere>
            </geometry>
          </visual>
          <velocity_decay />
        </link>
        <link name="link_0">
          <pose>0.100000 0.000000 0.000000 0.000000 -0.000000 0.000000</pose>
          <inertial>
            <pose>0.000000 0.000000 0.000000 0.000000 -0.000000 0.000000</pose>
            <mass>0.100000</mass>
            <inertia>
              <ixx>0.010000</ixx>
              <ixy>0.000000</ixy>
              <ixz>0.000000</ixz>
              <iyy>0.010000</iyy>
              <iyz>0.000000</iyz>
              <izz>0.010000</izz>
            </inertia>
          </inertial>
          <collision name="link_0_collision">
            <pose>0.100000 0.000000 0.000000 0.000000 1.570790 0.000000</pose>
            <geometry>
              <cylinder>
                <length>0.2</length>
                <radius>0.025</radius>
              </cylinder>
            </geometry>
          </collision>
          <visual name="link_0_vis">
            <pose>0.100000 0.000000 0.000000 0.000000 1.570790 0.000000</pose>
            <geometry>
              <cylinder>
                <length>0.2</length>
                <radius>00.025</radius>
              </cylinder>
            </geometry>
          </visual>
          <velocity_decay />
        </link>
    
        <link name="sphere_1">
          <pose>0.100000 0.000000 0.000000 0.000000 -0.000000 0.000000</pose>
          <inertial>
            <pose>0.000000 0.000000 0.000000 0.000000 -0.000000 0.000000</pose>
            <mass>0.100000</mass>
            <inertia>
              <ixx>0.010000</ixx>
              <ixy>0.000000</ixy>
              <ixz>0.000000</ixz>
              <iyy>0.010000</iyy>
              <iyz>0.000000</iyz>
              <izz>0.010000</izz>
            </inertia>
          </inertial>
          <collision name="sphere_1_collision">
            <pose>0.000000 0.000000 0.000000 0.000000 -0.000000 0.000000</pose>
            <geometry>
              <sphere>
                <radius>0.025</radius>
              </sphere>
            </geometry>
          </collision>
          <visual name="sphere_1_vis">
            <pose>0.000000 0.000000 0.000000 0.000000 -0.000000 0.000000</pose>
            <geometry>
              <sphere>
                <radius>0.025</radius>
              </sphere>
            </geometry>
          </visual>
          <velocity_decay />
        </link>
        <link name="link_1">
          <pose>0.100000 0.000000 0.000000 0.000000 -0.000000 0.000000</pose>
          <inertial>
            <pose>0.000000 0.000000 0.000000 0.000000 -0.000000 0.000000</pose>
            <mass>0.100000</mass>
            <inertia>
              <ixx>0.010000</ixx>
              <ixy>0.000000</ixy>
              <ixz>0.000000</ixz>
              <iyy>0.010000</iyy>
              <iyz>0.000000</iyz>
              <izz>0.010000</izz>
            </inertia>
          </inertial>
          <collision name="link_1_collision">
            <pose>0.100000 0.000000 0.000000 0.000000 1.570790 0.000000</pose>
            <geometry>
              <cylinder>
                <length>0.2</length>
                <radius>0.025</radius>
              </cylinder>
            </geometry>
          </collision>
          <visual name="link_1_vis">
            <pose>0.100000 0.000000 0.000000 0.000000 1.570790 0.000000</pose>
            <geometry>
              <cylinder>
                <length>0.2</length>
                <radius>00.025</radius>
              </cylinder>
            </geometry>
          </visual>
          <velocity_decay />
        </link>
    
        <link name="sphere_2">
          <pose>0.100000 0.000000 0.000000 0.000000 -0.000000 0.000000</pose>
          <inertial>
            <pose>0.000000 0.000000 0.000000 0.000000 -0.000000 0.000000</pose>
            <mass>0.100000</mass>
            <inertia>
              <ixx>0.010000</ixx>
              <ixy>0.000000</ixy>
              <ixz>0.000000</ixz>
              <iyy>0.010000</iyy>
              <iyz>0.000000</iyz>
              <izz>0.010000</izz>
            </inertia>
          </inertial>
          <collision name="sphere_2_collision">
            <pose>0.000000 0.000000 0.000000 0.000000 -0.000000 0.000000</pose>
            <geometry>
              <sphere>
                <radius>0.025</radius>
              </sphere>
            </geometry>
          </collision>
          <visual name="sphere_2_vis">
            <pose>0.000000 0.000000 0.000000 0.000000 -0.000000 0.000000</pose>
            <geometry>
              <sphere>
                <radius>0.025</radius>
              </sphere>
            </geometry>
          </visual>
          <velocity_decay />
        </link>
        <link name="link_2">
          <pose>0.100000 0.000000 0.000000 0.000000 -0.000000 0.000000</pose>
          <inertial>
            <pose>0.000000 0.000000 0.000000 0.000000 -0.000000 0.000000</pose>
            <mass>0.100000</mass>
            <inertia>
              <ixx>0.010000</ixx>
              <ixy>0.000000</ixy>
              <ixz>0.000000</ixz>
              <iyy>0.010000</iyy>
              <iyz>0.000000</iyz>
              <izz>0.010000</izz>
            </inertia>
          </inertial>
          <collision name="link_2_collision">
            <pose>0.100000 0.000000 0.000000 0.000000 1.570790 0.000000</pose>
            <geometry>
              <cylinder>
                <length>0.2</length>
                <radius>0.025</radius>
              </cylinder>
            </geometry>
          </collision>
          <visual name="link_2_vis">
            <pose>0.100000 0.000000 0.000000 0.000000 1.570790 0.000000</pose>
            <geometry>
              <cylinder>
                <length>0.2</length>
                <radius>00.025</radius>
              </cylinder>
            </geometry>
          </visual>
          <velocity_decay />
        </link>
    
        <link name="sphere_3">
          <pose>0.100000 0.000000 0.000000 0.000000 -0.000000 0.000000</pose>
          <inertial>
            <pose>0.000000 0.000000 0.000000 0.000000 -0.000000 0.000000</pose>
            <mass>0.100000</mass>
            <inertia>
              <ixx>0.010000</ixx>
              <ixy>0.000000</ixy>
              <ixz>0.000000</ixz>
              <iyy>0.010000</iyy>
              <iyz>0.000000</iyz>
              <izz>0.010000</izz>
            </inertia>
          </inertial>
          <collision name="sphere_3_collision">
            <pose>0.000000 0.000000 0.000000 0.000000 -0.000000 0.000000</pose>
            <geometry>
              <sphere>
                <radius>0.025</radius>
              </sphere>
            </geometry>
          </collision>
          <visual name="sphere_3_vis">
            <pose>0.000000 0.000000 0.000000 0.000000 -0.000000 0.000000</pose>
            <geometry>
              <sphere>
                <radius>0.025</radius>
              </sphere>
            </geometry>
          </visual>
          <velocity_decay />
        </link>
        <link name="link_3">
          <pose>0.100000 0.000000 0.000000 0.000000 -0.000000 0.000000</pose>
          <inertial>
            <pose>0.000000 0.000000 0.000000 0.000000 -0.000000 0.000000</pose>
            <mass>0.100000</mass>
            <inertia>
              <ixx>0.010000</ixx>
              <ixy>0.000000</ixy>
              <ixz>0.000000</ixz>
              <iyy>0.010000</iyy>
              <iyz>0.000000</iyz>
              <izz>0.010000</izz>
            </inertia>
          </inertial>
          <collision name="link_3_collision">
            <pose>0.100000 0.000000 0.000000 0.000000 1.570790 0.000000</pose>
            <geometry>
              <cylinder>
                <length>0.2</length>
                <radius>0.025</radius>
              </cylinder>
            </geometry>
          </collision>
          <visual name="link_3_vis">
            <pose>0.100000 0.000000 0.000000 0.000000 1.570790 0.000000</pose>
            <geometry>
              <cylinder>
                <length>0.2</length>
                <radius>00.025</radius>
              </cylinder>
            </geometry>
          </visual>
          <velocity_decay />
        </link>
    
        <link name="sphere_4">
          <pose>0.100000 0.000000 0.000000 0.000000 -0.000000 0.000000</pose>
          <inertial>
            <pose>0.000000 0.000000 0.000000 0.000000 -0.000000 0.000000</pose>
            <mass>0.100000</mass>
            <inertia>
              <ixx>0.010000</ixx>
              <ixy>0.000000</ixy>
              <ixz>0.000000</ixz>
              <iyy>0.010000</iyy>
              <iyz>0.000000</iyz>
              <izz>0.010000</izz>
            </inertia>
          </inertial>
          <collision name="sphere_4_collision">
            <pose>0.000000 0.000000 0.000000 0.000000 -0.000000 0.000000</pose>
            <geometry>
              <sphere>
                <radius>0.025</radius>
              </sphere>
            </geometry>
          </collision>
          <visual name="sphere_4_vis">
            <pose>0.000000 0.000000 0.000000 0.000000 -0.000000 0.000000</pose>
            <geometry>
              <sphere>
                <radius>0.025</radius>
              </sphere>
            </geometry>
          </visual>
          <velocity_decay />
        </link>
        <link name="link_4">
          <pose>0.100000 0.000000 0.000000 0.000000 -0.000000 0.000000</pose>
          <inertial>
            <pose>0.000000 0.000000 0.000000 0.000000 -0.000000 0.000000</pose>
            <mass>0.100000</mass>
            <inertia>
              <ixx>0.010000</ixx>
              <ixy>0.000000</ixy>
              <ixz>0.000000</ixz>
              <iyy>0.010000</iyy>
              <iyz>0.000000</iyz>
              <izz>0.010000</izz>
            </inertia>
          </inertial>
          <collision name="link_4_collision">
            <pose>0.100000 0.000000 0.000000 0.000000 1.570790 0.000000</pose>
            <geometry>
              <cylinder>
                <length>0.2</length>
                <radius>0.025</radius>
              </cylinder>
            </geometry>
          </collision>
          <visual name="link_4_vis">
            <pose>0.100000 0.000000 0.000000 0.000000 1.570790 0.000000</pose>
            <geometry>
              <cylinder>
                <length>0.2</length>
                <radius>00.025</radius>
              </cylinder>
            </geometry>
          </visual>
          <velocity_decay />
        </link>
    
        <link name="sphere_5">
          <pose>0.100000 0.000000 0.000000 0.000000 -0.000000 0.000000</pose>
          <inertial>
            <pose>0.000000 0.000000 0.000000 0.000000 -0.000000 0.000000</pose>
            <mass>0.100000</mass>
            <inertia>
              <ixx>0.010000</ixx>
              <ixy>0.000000</ixy>
              <ixz>0.000000</ixz>
              <iyy>0.010000</iyy>
              <iyz>0.000000</iyz>
              <izz>0.010000</izz>
            </inertia>
          </inertial>
          <collision name="sphere_5_collision">
            <pose>0.000000 0.000000 0.000000 0.000000 -0.000000 0.000000</pose>
            <geometry>
              <sphere>
                <radius>0.025</radius>
              </sphere>
            </geometry>
          </collision>
          <visual name="sphere_5_vis">
            <pose>0.000000 0.000000 0.000000 0.000000 -0.000000 0.000000</pose>
            <geometry>
              <sphere>
                <radius>0.025</radius>
              </sphere>
            </geometry>
          </visual>
          <velocity_decay />
        </link>
        <link name="link_5">
          <pose>0.100000 0.000000 0.000000 0.000000 -0.000000 0.000000</pose>
          <inertial>
            <pose>0.000000 0.000000 0.000000 0.000000 -0.000000 0.000000</pose>
            <mass>0.100000</mass>
            <inertia>
              <ixx>0.010000</ixx>
              <ixy>0.000000</ixy>
              <ixz>0.000000</ixz>
              <iyy>0.010000</iyy>
              <iyz>0.000000</iyz>
              <izz>0.010000</izz>
            </inertia>
          </inertial>
          <collision name="link_5_collision">
            <pose>0.100000 0.000000 0.000000 0.000000 1.570790 0.000000</pose>
            <geometry>
              <cylinder>
                <length>0.2</length>
                <radius>0.025</radius>
              </cylinder>
            </geometry>
          </collision>
          <visual name="link_5_vis">
            <pose>0.100000 0.000000 0.000000 0.000000 1.570790 0.000000</pose>
            <geometry>
              <cylinder>
                <length>0.2</length>
                <radius>00.025</radius>
              </cylinder>
            </geometry>
          </visual>
          <velocity_decay />
        </link>
    
        <link name="sphere_6">
          <pose>0.100000 0.000000 0.000000 0.000000 -0.000000 0.000000</pose>
          <inertial>
            <pose>0.000000 0.000000 0.000000 0.000000 -0.000000 0.000000</pose>
            <mass>0.100000</mass>
            <inertia>
              <ixx>0.010000</ixx>
              <ixy>0.000000</ixy>
              <ixz>0.000000</ixz>
              <iyy>0.010000</iyy>
              <iyz>0.000000</iyz>
              <izz>0.010000</izz>
            </inertia>
          </inertial>
          <collision name="sphere_6_collision">
            <pose>0.000000 0.000000 0.000000 0.000000 -0.000000 0.000000</pose>
            <geometry>
              <sphere>
                <radius>0.025</radius>
              </sphere>
            </geometry>
          </collision>
          <visual name="sphere_6_vis">
            <pose>0.000000 0.000000 0.000000 0.000000 -0.000000 0.000000</pose>
            <geometry>
              <sphere>
                <radius>0.025</radius>
              </sphere>
            </geometry>
          </visual>
          <velocity_decay />
        </link>
        <link name="link_6">
          <pose>0.100000 0.000000 0.000000 0.000000 -0.000000 0.000000</pose>
          <inertial>
            <pose>0.000000 0.000000 0.000000 0.000000 -0.000000 0.000000</pose>
            <mass>0.100000</mass>
            <inertia>
              <ixx>0.010000</ixx>
              <ixy>0.000000</ixy>
              <ixz>0.000000</ixz>
              <iyy>0.010000</iyy>
              <iyz>0.000000</iyz>
              <izz>0.010000</izz>
            </inertia>
          </inertial>
          <collision name="link_6_collision">
            <pose>0.100000 0.000000 0.000000 0.000000 1.570790 0.000000</pose>
            <geometry>
              <cylinder>
                <length>0.2</length>
                <radius>0.025</radius>
              </cylinder>
            </geometry>
          </collision>
          <visual name="link_6_vis">
            <pose>0.100000 0.000000 0.000000 0.000000 1.570790 0.000000</pose>
            <geometry>
              <cylinder>
                <length>0.2</length>
                <radius>00.025</radius>
              </cylinder>
            </geometry>
          </visual>
          <velocity_decay />
        </link>
    
        <link name="sphere_7">
          <pose>0.100000 0.000000 0.000000 0.000000 -0.000000 0.000000</pose>
          <inertial>
            <pose>0.000000 0.000000 0.000000 0.000000 -0.000000 0.000000</pose>
            <mass>0.100000</mass>
            <inertia>
              <ixx>0.010000</ixx>
              <ixy>0.000000</ixy>
              <ixz>0.000000</ixz>
              <iyy>0.010000</iyy>
              <iyz>0.000000</iyz>
              <izz>0.010000</izz>
            </inertia>
          </inertial>
          <collision name="sphere_7_collision">
            <pose>0.000000 0.000000 0.000000 0.000000 -0.000000 0.000000</pose>
            <geometry>
              <sphere>
                <radius>0.025</radius>
              </sphere>
            </geometry>
          </collision>
          <visual name="sphere_7_vis">
            <pose>0.000000 0.000000 0.000000 0.000000 -0.000000 0.000000</pose>
            <geometry>
              <sphere>
                <radius>0.025</radius>
              </sphere>
            </geometry>
          </visual>
          <velocity_decay />
        </link>
        <link name="link_7">
          <pose>0.100000 0.000000 0.000000 0.000000 -0.000000 0.000000</pose>
          <inertial>
            <pose>0.000000 0.000000 0.000000 0.000000 -0.000000 0.000000</pose>
            <mass>0.100000</mass>
            <inertia>
              <ixx>0.010000</ixx>
              <ixy>0.000000</ixy>
              <ixz>0.000000</ixz>
              <iyy>0.010000</iyy>
              <iyz>0.000000</iyz>
              <izz>0.010000</izz>
            </inertia>
          </inertial>
          <collision name="link_7_collision">
            <pose>0.100000 0.000000 0.000000 0.000000 1.570790 0.000000</pose>
            <geometry>
              <cylinder>
                <length>0.2</length>
                <radius>0.025</radius>
              </cylinder>
            </geometry>
          </collision>
          <visual name="link_7_vis">
            <pose>0.100000 0.000000 0.000000 0.000000 1.570790 0.000000</pose>
            <geometry>
              <cylinder>
                <length>0.2</length>
                <radius>00.025</radius>
              </cylinder>
            </geometry>
          </visual>
          <velocity_decay />
        </link>
    
        <link name="sphere_8">
          <pose>0.100000 0.000000 0.000000 0.000000 -0.000000 0.000000</pose>
          <inertial>
            <pose>0.000000 0.000000 0.000000 0.000000 -0.000000 0.000000</pose>
            <mass>0.100000</mass>
            <inertia>
              <ixx>0.010000</ixx>
              <ixy>0.000000</ixy>
              <ixz>0.000000</ixz>
              <iyy>0.010000</iyy>
              <iyz>0.000000</iyz>
              <izz>0.010000</izz>
            </inertia>
          </inertial>
          <collision name="sphere_8_collision">
            <pose>0.000000 0.000000 0.000000 0.000000 -0.000000 0.000000</pose>
            <geometry>
              <sphere>
                <radius>0.025</radius>
              </sphere>
            </geometry>
          </collision>
          <visual name="sphere_8_vis">
            <pose>0.000000 0.000000 0.000000 0.000000 -0.000000 0.000000</pose>
            <geometry>
              <sphere>
                <radius>0.025</radius>
              </sphere>
            </geometry>
          </visual>
          <velocity_decay />
        </link>
        <link name="link_8">
          <pose>0.100000 0.000000 0.000000 0.000000 -0.000000 0.000000</pose>
          <inertial>
            <pose>0.000000 0.000000 0.000000 0.000000 -0.000000 0.000000</pose>
            <mass>0.100000</mass>
            <inertia>
              <ixx>0.010000</ixx>
              <ixy>0.000000</ixy>
              <ixz>0.000000</ixz>
              <iyy>0.010000</iyy>
              <iyz>0.000000</iyz>
              <izz>0.010000</izz>
            </inertia>
          </inertial>
          <collision name="link_8_collision">
            <pose>0.100000 0.000000 0.000000 0.000000 1.570790 0.000000</pose>
            <geometry>
              <cylinder>
                <length>0.2</length>
                <radius>0.025</radius>
              </cylinder>
            </geometry>
          </collision>
          <visual name="link_8_vis">
            <pose>0.100000 0.000000 0.000000 0.000000 1.570790 0.000000</pose>
            <geometry>
              <cylinder>
                <length>0.2</length>
                <radius>00.025</radius>
              </cylinder>
            </geometry>
          </visual>
          <velocity_decay />
        </link>
    
        <link name="sphere_9">
          <pose>0.100000 0.000000 0.000000 0.000000 -0.000000 0.000000</pose>
          <inertial>
            <pose>0.000000 0.000000 0.000000 0.000000 -0.000000 0.000000</pose>
            <mass>0.100000</mass>
            <inertia>
              <ixx>0.010000</ixx>
              <ixy>0.000000</ixy>
              <ixz>0.000000</ixz>
              <iyy>0.010000</iyy>
              <iyz>0.000000</iyz>
              <izz>0.010000</izz>
            </inertia>
          </inertial>
          <collision name="sphere_9_collision">
            <pose>0.000000 0.000000 0.000000 0.000000 -0.000000 0.000000</pose>
            <geometry>
              <sphere>
                <radius>0.025</radius>
              </sphere>
            </geometry>
          </collision>
          <visual name="sphere_9_vis">
            <pose>0.000000 0.000000 0.000000 0.000000 -0.000000 0.000000</pose>
            <geometry>
              <sphere>
                <radius>0.025</radius>
              </sphere>
            </geometry>
          </visual>
          <velocity_decay />
        </link>
        <link name="link_9">
          <pose>0.100000 0.000000 0.000000 0.000000 -0.000000 0.000000</pose>
          <inertial>
            <pose>0.000000 0.000000 0.000000 0.000000 -0.000000 0.000000</pose>
            <mass>0.100000</mass>
            <inertia>
              <ixx>0.010000</ixx>
              <ixy>0.000000</ixy>
              <ixz>0.000000</ixz>
              <iyy>0.010000</iyy>
              <iyz>0.000000</iyz>
              <izz>0.010000</izz>
            </inertia>
          </inertial>
          <collision name="link_9_collision">
            <pose>0.100000 0.000000 0.000000 0.000000 1.570790 0.000000</pose>
            <geometry>
              <cylinder>
                <length>0.2</length>
                <radius>0.025</radius>
              </cylinder>
            </geometry>
          </collision>
          <visual name="link_9_vis">
            <pose>0.100000 0.000000 0.000000 0.000000 1.570790 0.000000</pose>
            <geometry>
              <cylinder>
                <length>0.2</length>
                <radius>00.025</radius>
              </cylinder>
            </geometry>
          </visual>
          <velocity_decay />
        </link>
    
        <link name="sphere_10">
          <pose>0.100000 0.000000 0.000000 0.000000 -0.000000 0.000000</pose>
          <inertial>
            <pose>0.000000 0.000000 0.000000 0.000000 -0.000000 0.000000</pose>
            <mass>0.100000</mass>
            <inertia>
              <ixx>0.010000</ixx>
              <ixy>0.000000</ixy>
              <ixz>0.000000</ixz>
              <iyy>0.010000</iyy>
              <iyz>0.000000</iyz>
              <izz>0.010000</izz>
            </inertia>
          </inertial>
          <collision name="sphere_10_collision">
            <pose>0.000000 0.000000 0.000000 0.000000 -0.000000 0.000000</pose>
            <geometry>
              <sphere>
                <radius>0.025</radius>
              </sphere>
            </geometry>
          </collision>
          <visual name="sphere_10_vis">
            <pose>0.000000 0.000000 0.000000 0.000000 -0.000000 0.000000</pose>
            <geometry>
              <sphere>
                <radius>0.025</radius>
              </sphere>
            </geometry>
          </visual>
          <velocity_decay />
        </link>
        <link name="link_10">
          <pose>0.100000 0.000000 0.000000 0.000000 -0.000000 0.000000</pose>
          <inertial>
            <pose>0.000000 0.000000 0.000000 0.000000 -0.000000 0.000000</pose>
            <mass>0.100000</mass>
            <inertia>
              <ixx>0.010000</ixx>
              <ixy>0.000000</ixy>
              <ixz>0.000000</ixz>
              <iyy>0.010000</iyy>
              <iyz>0.000000</iyz>
              <izz>0.010000</izz>
            </inertia>
          </inertial>
          <collision name="link_10_collision">
            <pose>0.100000 0.000000 0.000000 0.000000 1.570790 0.000000</pose>
            <geometry>
              <cylinder>
                <length>0.2</length>
                <radius>0.025</radius>
              </cylinder>
            </geometry>
          </collision>
          <visual name="link_10_vis">
            <pose>0.100000 0.000000 0.000000 0.000000 1.570790 0.000000</pose>
            <geometry>
              <cylinder>
                <length>0.2</length>
                <radius>00.025</radius>
              </cylinder>
            </geometry>
          </visual>
          <velocity_decay />
        </link>
    
        <link name="sphere_11">
          <pose>0.100000 0.000000 0.000000 0.000000 -0.000000 0.000000</pose>
          <inertial>
            <pose>0.000000 0.000000 0.000000 0.000000 -0.000000 0.000000</pose>
            <mass>0.100000</mass>
            <inertia>
              <ixx>0.010000</ixx>
              <ixy>0.000000</ixy>
              <ixz>0.000000</ixz>
              <iyy>0.010000</iyy>
              <iyz>0.000000</iyz>
              <izz>0.010000</izz>
            </inertia>
          </inertial>
          <collision name="sphere_11_collision">
            <pose>0.000000 0.000000 0.000000 0.000000 -0.000000 0.000000</pose>
            <geometry>
              <sphere>
                <radius>0.025</radius>
              </sphere>
            </geometry>
          </collision>
          <visual name="sphere_11_vis">
            <pose>0.000000 0.000000 0.000000 0.000000 -0.000000 0.000000</pose>
            <geometry>
              <sphere>
                <radius>0.025</radius>
              </sphere>
            </geometry>
          </visual>
          <velocity_decay />
        </link>
        <link name="link_11">
          <pose>0.100000 0.000000 0.000000 0.000000 -0.000000 0.000000</pose>
          <inertial>
            <pose>0.000000 0.000000 0.000000 0.000000 -0.000000 0.000000</pose>
            <mass>0.100000</mass>
            <inertia>
              <ixx>0.010000</ixx>
              <ixy>0.000000</ixy>
              <ixz>0.000000</ixz>
              <iyy>0.010000</iyy>
              <iyz>0.000000</iyz>
              <izz>0.010000</izz>
            </inertia>
          </inertial>
          <collision name="link_11_collision">
            <pose>0.100000 0.000000 0.000000 0.000000 1.570790 0.000000</pose>
            <geometry>
              <cylinder>
                <length>0.2</length>
                <radius>0.025</radius>
              </cylinder>
            </geometry>
          </collision>
          <visual name="link_11_vis">
            <pose>0.100000 0.000000 0.000000 0.000000 1.570790 0.000000</pose>
            <geometry>
              <cylinder>
                <length>0.2</length>
                <radius>00.025</radius>
              </cylinder>
            </geometry>
          </visual>
          <velocity_decay />
        </link>
    
        <link name="sphere_12">
          <pose>0.100000 0.000000 0.000000 0.000000 -0.000000 0.000000</pose>
          <inertial>
            <pose>0.000000 0.000000 0.000000 0.000000 -0.000000 0.000000</pose>
            <mass>0.100000</mass>
            <inertia>
              <ixx>0.010000</ixx>
              <ixy>0.000000</ixy>
              <ixz>0.000000</ixz>
              <iyy>0.010000</iyy>
              <iyz>0.000000</iyz>
              <izz>0.010000</izz>
            </inertia>
          </inertial>
          <collision name="sphere_12_collision">
            <pose>0.000000 0.000000 0.000000 0.000000 -0.000000 0.000000</pose>
            <geometry>
              <sphere>
                <radius>0.025</radius>
              </sphere>
            </geometry>
          </collision>
          <visual name="sphere_12_vis">
            <pose>0.000000 0.000000 0.000000 0.000000 -0.000000 0.000000</pose>
            <geometry>
              <sphere>
                <radius>0.025</radius>
              </sphere>
            </geometry>
          </visual>
          <velocity_decay />
        </link>
        <link name="link_12">
          <pose>0.100000 0.000000 0.000000 0.000000 -0.000000 0.000000</pose>
          <inertial>
            <pose>0.000000 0.000000 0.000000 0.000000 -0.000000 0.000000</pose>
            <mass>0.100000</mass>
            <inertia>
              <ixx>0.010000</ixx>
              <ixy>0.000000</ixy>
              <ixz>0.000000</ixz>
              <iyy>0.010000</iyy>
              <iyz>0.000000</iyz>
              <izz>0.010000</izz>
            </inertia>
          </inertial>
          <collision name="link_12_collision">
            <pose>0.100000 0.000000 0.000000 0.000000 1.570790 0.000000</pose>
            <geometry>
              <cylinder>
                <length>0.2</length>
                <radius>0.025</radius>
              </cylinder>
            </geometry>
          </collision>
          <visual name="link_12_vis">
            <pose>0.100000 0.000000 0.000000 0.000000 1.570790 0.000000</pose>
            <geometry>
              <cylinder>
                <length>0.2</length>
                <radius>00.025</radius>
              </cylinder>
            </geometry>
          </visual>
          <velocity_decay />
        </link>
    
        <link name="sphere_13">
          <pose>0.100000 0.000000 0.000000 0.000000 -0.000000 0.000000</pose>
          <inertial>
            <pose>0.000000 0.000000 0.000000 0.000000 -0.000000 0.000000</pose>
            <mass>0.100000</mass>
            <inertia>
              <ixx>0.010000</ixx>
              <ixy>0.000000</ixy>
              <ixz>0.000000</ixz>
              <iyy>0.010000</iyy>
              <iyz>0.000000</iyz>
              <izz>0.010000</izz>
            </inertia>
          </inertial>
          <collision name="sphere_13_collision">
            <pose>0.000000 0.000000 0.000000 0.000000 -0.000000 0.000000</pose>
            <geometry>
              <sphere>
                <radius>0.025</radius>
              </sphere>
            </geometry>
          </collision>
          <visual name="sphere_13_vis">
            <pose>0.000000 0.000000 0.000000 0.000000 -0.000000 0.000000</pose>
            <geometry>
              <sphere>
                <radius>0.025</radius>
              </sphere>
            </geometry>
          </visual>
          <velocity_decay />
        </link>
        <link name="link_13">
          <pose>0.100000 0.000000 0.000000 0.000000 -0.000000 0.000000</pose>
          <inertial>
            <pose>0.000000 0.000000 0.000000 0.000000 -0.000000 0.000000</pose>
            <mass>0.100000</mass>
            <inertia>
              <ixx>0.010000</ixx>
              <ixy>0.000000</ixy>
              <ixz>0.000000</ixz>
              <iyy>0.010000</iyy>
              <iyz>0.000000</iyz>
              <izz>0.010000</izz>
            </inertia>
          </inertial>
          <collision name="link_13_collision">
            <pose>0.100000 0.000000 0.000000 0.000000 1.570790 0.000000</pose>
            <geometry>
              <cylinder>
                <length>0.2</length>
                <radius>0.025</radius>
              </cylinder>
            </geometry>
          </collision>
          <visual name="link_13_vis">
            <pose>0.100000 0.000000 0.000000 0.000000 1.570790 0.000000</pose>
            <geometry>
              <cylinder>
                <length>0.2</length>
                <radius>00.025</radius>
              </cylinder>
            </geometry>
          </visual>
          <velocity_decay />
        </link>
    
        <link name="sphere_14">
          <pose>0.100000 0.000000 0.000000 0.000000 -0.000000 0.000000</pose>
          <inertial>
            <pose>0.000000 0.000000 0.000000 0.000000 -0.000000 0.000000</pose>
            <mass>0.100000</mass>
            <inertia>
              <ixx>0.010000</ixx>
              <ixy>0.000000</ixy>
              <ixz>0.000000</ixz>
              <iyy>0.010000</iyy>
              <iyz>0.000000</iyz>
              <izz>0.010000</izz>
            </inertia>
          </inertial>
          <collision name="sphere_14_collision">
            <pose>0.000000 0.000000 0.000000 0.000000 -0.000000 0.000000</pose>
            <geometry>
              <sphere>
                <radius>0.025</radius>
              </sphere>
            </geometry>
          </collision>
          <visual name="sphere_14_vis">
            <pose>0.000000 0.000000 0.000000 0.000000 -0.000000 0.000000</pose>
            <geometry>
              <sphere>
                <radius>0.025</radius>
              </sphere>
            </geometry>
          </visual>
          <velocity_decay />
        </link>
        <link name="link_14">
          <pose>0.100000 0.000000 0.000000 0.000000 -0.000000 0.000000</pose>
          <inertial>
            <pose>0.000000 0.000000 0.000000 0.000000 -0.000000 0.000000</pose>
            <mass>0.100000</mass>
            <inertia>
              <ixx>0.010000</ixx>
              <ixy>0.000000</ixy>
              <ixz>0.000000</ixz>
              <iyy>0.010000</iyy>
              <iyz>0.000000</iyz>
              <izz>0.010000</izz>
            </inertia>
          </inertial>
          <collision name="link_14_collision">
            <pose>0.100000 0.000000 0.000000 0.000000 1.570790 0.000000</pose>
            <geometry>
              <cylinder>
                <length>0.2</length>
                <radius>0.025</radius>
              </cylinder>
            </geometry>
          </collision>
          <visual name="link_14_vis">
            <pose>0.100000 0.000000 0.000000 0.000000 1.570790 0.000000</pose>
            <geometry>
              <cylinder>
                <length>0.2</length>
                <radius>00.025</radius>
              </cylinder>
            </geometry>
          </visual>
          <velocity_decay />
        </link>
    
        <link name="sphere_15">
          <pose>0.100000 0.000000 0.000000 0.000000 -0.000000 0.000000</pose>
          <inertial>
            <pose>0.000000 0.000000 0.000000 0.000000 -0.000000 0.000000</pose>
            <mass>0.100000</mass>
            <inertia>
              <ixx>0.010000</ixx>
              <ixy>0.000000</ixy>
              <ixz>0.000000</ixz>
              <iyy>0.010000</iyy>
              <iyz>0.000000</iyz>
              <izz>0.010000</izz>
            </inertia>
          </inertial>
          <collision name="sphere_15_collision">
            <pose>0.000000 0.000000 0.000000 0.000000 -0.000000 0.000000</pose>
            <geometry>
              <sphere>
                <radius>0.025</radius>
              </sphere>
            </geometry>
          </collision>
          <visual name="sphere_15_vis">
            <pose>0.000000 0.000000 0.000000 0.000000 -0.000000 0.000000</pose>
            <geometry>
              <sphere>
                <radius>0.025</radius>
              </sphere>
            </geometry>
          </visual>
          <velocity_decay />
        </link>
        <link name="link_15">
          <pose>0.100000 0.000000 0.000000 0.000000 -0.000000 0.000000</pose>
          <inertial>
            <pose>0.000000 0.000000 0.000000 0.000000 -0.000000 0.000000</pose>
            <mass>0.100000</mass>
            <inertia>
              <ixx>0.010000</ixx>
              <ixy>0.000000</ixy>
              <ixz>0.000000</ixz>
              <iyy>0.010000</iyy>
              <iyz>0.000000</iyz>
              <izz>0.010000</izz>
            </inertia>
          </inertial>
          <collision name="link_15_collision">
            <pose>0.100000 0.000000 0.000000 0.000000 1.570790 0.000000</pose>
            <geometry>
              <cylinder>
                <length>0.2</length>
                <radius>0.025</radius>
              </cylinder>
            </geometry>
          </collision>
          <visual name="link_15_vis">
            <pose>0.100000 0.000000 0.000000 0.000000 1.570790 0.000000</pose>
            <geometry>
              <cylinder>
                <length>0.2</length>
                <radius>00.025</radius>
              </cylinder>
            </geometry>
          </visual>
          <velocity_decay />
        </link>
    
        <link name="sphere_16">
          <pose>0.100000 0.000000 0.000000 0.000000 -0.000000 0.000000</pose>
          <inertial>
            <pose>0.000000 0.000000 0.000000 0.000000 -0.000000 0.000000</pose>
            <mass>0.100000</mass>
            <inertia>
              <ixx>0.010000</ixx>
              <ixy>0.000000</ixy>
              <ixz>0.000000</ixz>
              <iyy>0.010000</iyy>
              <iyz>0.000000</iyz>
              <izz>0.010000</izz>
            </inertia>
          </inertial>
          <collision name="sphere_16_collision">
            <pose>0.000000 0.000000 0.000000 0.000000 -0.000000 0.000000</pose>
            <geometry>
              <sphere>
                <radius>0.025</radius>
              </sphere>
            </geometry>
          </collision>
          <visual name="sphere_16_vis">
            <pose>0.000000 0.000000 0.000000 0.000000 -0.000000 0.000000</pose>
            <geometry>
              <sphere>
                <radius>0.025</radius>
              </sphere>
            </geometry>
          </visual>
          <velocity_decay />
        </link>
        <link name="link_16">
          <pose>0.100000 0.000000 0.000000 0.000000 -0.000000 0.000000</pose>
          <inertial>
            <pose>0.000000 0.000000 0.000000 0.000000 -0.000000 0.000000</pose>
            <mass>0.100000</mass>
            <inertia>
              <ixx>0.010000</ixx>
              <ixy>0.000000</ixy>
              <ixz>0.000000</ixz>
              <iyy>0.010000</iyy>
              <iyz>0.000000</iyz>
              <izz>0.010000</izz>
            </inertia>
          </inertial>
          <collision name="link_16_collision">
            <pose>0.100000 0.000000 0.000000 0.000000 1.570790 0.000000</pose>
            <geometry>
              <cylinder>
                <length>0.2</length>
                <radius>0.025</radius>
              </cylinder>
            </geometry>
          </collision>
          <visual name="link_16_vis">
            <pose>0.100000 0.000000 0.000000 0.000000 1.570790 0.000000</pose>
            <geometry>
              <cylinder>
                <length>0.2</length>
                <radius>00.025</radius>
              </cylinder>
            </geometry>
          </visual>
          <velocity_decay />
        </link>
    
        <link name="sphere_17">
          <pose>0.100000 0.000000 0.000000 0.000000 -0.000000 0.000000</pose>
          <inertial>
            <pose>0.000000 0.000000 0.000000 0.000000 -0.000000 0.000000</pose>
            <mass>0.100000</mass>
            <inertia>
              <ixx>0.010000</ixx>
              <ixy>0.000000</ixy>
              <ixz>0.000000</ixz>
              <iyy>0.010000</iyy>
              <iyz>0.000000</iyz>
              <izz>0.010000</izz>
            </inertia>
          </inertial>
          <collision name="sphere_17_collision">
            <pose>0.000000 0.000000 0.000000 0.000000 -0.000000 0.000000</pose>
            <geometry>
              <sphere>
                <radius>0.025</radius>
              </sphere>
            </geometry>
          </collision>
          <visual name="sphere_17_vis">
            <pose>0.000000 0.000000 0.000000 0.000000 -0.000000 0.000000</pose>
            <geometry>
              <sphere>
                <radius>0.025</radius>
              </sphere>
            </geometry>
          </visual>
          <velocity_decay />
        </link>
        <link name="link_17">
          <pose>0.100000 0.000000 0.000000 0.000000 -0.000000 0.000000</pose>
          <inertial>
            <pose>0.000000 0.000000 0.000000 0.000000 -0.000000 0.000000</pose>
            <mass>0.100000</mass>
            <inertia>
              <ixx>0.010000</ixx>
              <ixy>0.000000</ixy>
              <ixz>0.000000</ixz>
              <iyy>0.010000</iyy>
              <iyz>0.000000</iyz>
              <izz>0.010000</izz>
            </inertia>
          </inertial>
          <collision name="link_17_collision">
            <pose>0.100000 0.000000 0.000000 0.000000 1.570790 0.000000</pose>
            <geometry>
              <cylinder>
                <length>0.2</length>
                <radius>0.025</radius>
              </cylinder>
            </geometry>
          </collision>
          <visual name="link_17_vis">
            <pose>0.100000 0.000000 0.000000 0.000000 1.570790 0.000000</pose>
            <geometry>
              <cylinder>
                <length>0.2</length>
                <radius>00.025</radius>
              </cylinder>
            </geometry>
          </visual>
          <velocity_decay />
        </link>
    
        <link name="sphere_18">
          <pose>0.100000 0.000000 0.000000 0.000000 -0.000000 0.000000</pose>
          <inertial>
            <pose>0.000000 0.000000 0.000000 0.000000 -0.000000 0.000000</pose>
            <mass>0.100000</mass>
            <inertia>
              <ixx>0.010000</ixx>
              <ixy>0.000000</ixy>
              <ixz>0.000000</ixz>
              <iyy>0.010000</iyy>
              <iyz>0.000000</iyz>
              <izz>0.010000</izz>
            </inertia>
          </inertial>
          <collision name="sphere_18_collision">
            <pose>0.000000 0.000000 0.000000 0.000000 -0.000000 0.000000</pose>
            <geometry>
              <sphere>
                <radius>0.025</radius>
              </sphere>
            </geometry>
          </collision>
          <visual name="sphere_18_vis">
            <pose>0.000000 0.000000 0.000000 0.000000 -0.000000 0.000000</pose>
            <geometry>
              <sphere>
                <radius>0.025</radius>
              </sphere>
            </geometry>
          </visual>
          <velocity_decay />
        </link>
        <link name="link_18">
          <pose>0.100000 0.000000 0.000000 0.000000 -0.000000 0.000000</pose>
          <inertial>
            <pose>0.000000 0.000000 0.000000 0.000000 -0.000000 0.000000</pose>
            <mass>0.100000</mass>
            <inertia>
              <ixx>0.010000</ixx>
              <ixy>0.000000</ixy>
              <ixz>0.000000</ixz>
              <iyy>0.010000</iyy>
              <iyz>0.000000</iyz>
              <izz>0.010000</izz>
            </inertia>
          </inertial>
          <collision name="link_18_collision">
            <pose>0.100000 0.000000 0.000000 0.000000 1.570790 0.000000</pose>
            <geometry>
              <cylinder>
                <length>0.2</length>
                <radius>0.025</radius>
              </cylinder>
            </geometry>
          </collision>
          <visual name="link_18_vis">
            <pose>0.100000 0.000000 0.000000 0.000000 1.570790 0.000000</pose>
            <geometry>
              <cylinder>
                <length>0.2</length>
                <radius>00.025</radius>
              </cylinder>
            </geometry>
          </visual>
          <velocity_decay />
        </link>
    
        <link name="sphere_19">
          <pose>0.100000 0.000000 0.000000 0.000000 -0.000000 0.000000</pose>
          <inertial>
            <pose>0.000000 0.000000 0.000000 0.000000 -0.000000 0.000000</pose>
            <mass>0.100000</mass>
            <inertia>
              <ixx>0.010000</ixx>
              <ixy>0.000000</ixy>
              <ixz>0.000000</ixz>
              <iyy>0.010000</iyy>
              <iyz>0.000000</iyz>
              <izz>0.010000</izz>
            </inertia>
          </inertial>
          <collision name="sphere_19_collision">
            <pose>0.000000 0.000000 0.000000 0.000000 -0.000000 0.000000</pose>
            <geometry>
              <sphere>
                <radius>0.025</radius>
              </sphere>
            </geometry>
          </collision>
          <visual name="sphere_19_vis">
            <pose>0.000000 0.000000 0.000000 0.000000 -0.000000 0.000000</pose>
            <geometry>
              <sphere>
                <radius>0.025</radius>
              </sphere>
            </geometry>
          </visual>
          <velocity_decay />
        </link>
        <link name="link_19">
          <pose>0.100000 0.000000 0.000000 0.000000 -0.000000 0.000000</pose>
          <inertial>
            <pose>0.000000 0.000000 0.000000 0.000000 -0.000000 0.000000</pose>
            <mass>0.100000</mass>
            <inertia>
              <ixx>0.010000</ixx>
              <ixy>0.000000</ixy>
              <ixz>0.000000</ixz>
              <iyy>0.010000</iyy>
              <iyz>0.000000</iyz>
              <izz>0.010000</izz>
            </inertia>
          </inertial>
          <collision name="link_19_collision">
            <pose>0.100000 0.000000 0.000000 0.000000 1.570790 0.000000</pose>
            <geometry>
              <cylinder>
                <length>0.2</length>
                <radius>0.025</radius>
              </cylinder>
            </geometry>
          </collision>
          <visual name="link_19_vis">
            <pose>0.100000 0.000000 0.000000 0.000000 1.570790 0.000000</pose>
            <geometry>
              <cylinder>
                <length>0.2</length>
                <radius>00.025</radius>
              </cylinder>
            </geometry>
          </visual>
          <velocity_decay />
        </link>
    
        <link name="sphere_20">
          <pose>0.100000 0.000000 0.000000 0.000000 -0.000000 0.000000</pose>
          <inertial>
            <pose>0.000000 0.000000 0.000000 0.000000 -0.000000 0.000000</pose>
            <mass>0.100000</mass>
            <inertia>
              <ixx>0.010000</ixx>
              <ixy>0.000000</ixy>
              <ixz>0.000000</ixz>
              <iyy>0.010000</iyy>
              <iyz>0.000000</iyz>
              <izz>0.010000</izz>
            </inertia>
          </inertial>
          <collision name="sphere_20_collision">
            <pose>0.000000 0.000000 0.000000 0.000000 -0.000000 0.000000</pose>
            <geometry>
              <sphere>
                <radius>0.025</radius>
              </sphere>
            </geometry>
          </collision>
          <visual name="sphere_20_vis">
            <pose>0.000000 0.000000 0.000000 0.000000 -0.000000 0.000000</pose>
            <geometry>
              <sphere>
                <radius>0.025</radius>
              </sphere>
            </geometry>
          </visual>
          <velocity_decay />
        </link>
        <link name="link_20">
          <pose>0.100000 0.000000 0.000000 0.000000 -0.000000 0.000000</pose>
          <inertial>
            <pose>0.000000 0.000000 0.000000 0.000000 -0.000000 0.000000</pose>
            <mass>0.100000</mass>
            <inertia>
              <ixx>0.010000</ixx>
              <ixy>0.000000</ixy>
              <ixz>0.000000</ixz>
              <iyy>0.010000</iyy>
              <iyz>0.000000</iyz>
              <izz>0.010000</izz>
            </inertia>
          </inertial>
          <collision name="link_20_collision">
            <pose>0.100000 0.000000 0.000000 0.000000 1.570790 0.000000</pose>
            <geometry>
              <cylinder>
                <length>0.2</length>
                <radius>0.025</radius>
              </cylinder>
            </geometry>
          </collision>
          <visual name="link_20_vis">
            <pose>0.100000 0.000000 0.000000 0.000000 1.570790 0.000000</pose>
            <geometry>
              <cylinder>
                <length>0.2</length>
                <radius>00.025</radius>
              </cylinder>
            </geometry>
          </visual>
          <velocity_decay />
        </link>
    

    
        <joint name="joint_1_1" type="revolute">
          <child>sphere_1</child>
          <parent>sphere_0</parent>
          <axis>
            <xyz>0.000000 0.000000 1.000000</xyz>
            <limit>
              <lower>-0.700000</lower>
              <upper>0.700000</upper>
            </limit>
            <dynamics>
              <damping>4.0</damping>
              <friction>0.2</friction>
            </dynamics>
            <use_parent_model_frame>true</use_parent_model_frame>
          </axis>
        </joint>
        <joint name="joint_1_2" type="revolute">
          <child>link_1</child>
          <parent>sphere_1</parent>
          <axis>
            <xyz>0.000000 1.000000 0.000000</xyz>
            <limit>
              <lower>-0.700000</lower>
              <upper>0.700000</upper>
            </limit>
            <dynamics>
              <damping>4.0</damping>
              <friction>0.2</friction>
            </dynamics>
            <use_parent_model_frame>true</use_parent_model_frame>
          </axis>
        </joint>
    
        <joint name="joint_2_1" type="revolute">
          <child>sphere_2</child>
          <parent>sphere_1</parent>
          <axis>
            <xyz>0.000000 0.000000 1.000000</xyz>
            <limit>
              <lower>-0.700000</lower>
              <upper>0.700000</upper>
            </limit>
            <dynamics>
              <damping>4.0</damping>
              <friction>0.2</friction>
            </dynamics>
            <use_parent_model_frame>true</use_parent_model_frame>
          </axis>
        </joint>
        <joint name="joint_2_2" type="revolute">
          <child>link_2</child>
          <parent>sphere_2</parent>
          <axis>
            <xyz>0.000000 1.000000 0.000000</xyz>
            <limit>
              <lower>-0.700000</lower>
              <upper>0.700000</upper>
            </limit>
            <dynamics>
              <damping>4.0</damping>
              <friction>0.2</friction>
            </dynamics>
            <use_parent_model_frame>true</use_parent_model_frame>
          </axis>
        </joint>
    
        <joint name="joint_3_1" type="revolute">
          <child>sphere_3</child>
          <parent>sphere_2</parent>
          <axis>
            <xyz>0.000000 0.000000 1.000000</xyz>
            <limit>
              <lower>-0.700000</lower>
              <upper>0.700000</upper>
            </limit>
            <dynamics>
              <damping>4.0</damping>
              <friction>0.2</friction>
            </dynamics>
            <use_parent_model_frame>true</use_parent_model_frame>
          </axis>
        </joint>
        <joint name="joint_3_2" type="revolute">
          <child>link_3</child>
          <parent>sphere_3</parent>
          <axis>
            <xyz>0.000000 1.000000 0.000000</xyz>
            <limit>
              <lower>-0.700000</lower>
              <upper>0.700000</upper>
            </limit>
            <dynamics>
              <damping>4.0</damping>
              <friction>0.2</friction>
            </dynamics>
            <use_parent_model_frame>true</use_parent_model_frame>
          </axis>
        </joint>
    
        <joint name="joint_4_1" type="revolute">
          <child>sphere_4</child>
          <parent>sphere_3</parent>
          <axis>
            <xyz>0.000000 0.000000 1.000000</xyz>
            <limit>
              <lower>-0.700000</lower>
              <upper>0.700000</upper>
            </limit>
            <dynamics>
              <damping>4.0</damping>
              <friction>0.2</friction>
            </dynamics>
            <use_parent_model_frame>true</use_parent_model_frame>
          </axis>
        </joint>
        <joint name="joint_4_2" type="revolute">
          <child>link_4</child>
          <parent>sphere_4</parent>
          <axis>
            <xyz>0.000000 1.000000 0.000000</xyz>
            <limit>
              <lower>-0.700000</lower>
              <upper>0.700000</upper>
            </limit>
            <dynamics>
              <damping>4.0</damping>
              <friction>0.2</friction>
            </dynamics>
            <use_parent_model_frame>true</use_parent_model_frame>
          </axis>
        </joint>
    
        <joint name="joint_5_1" type="revolute">
          <child>sphere_5</child>
          <parent>sphere_4</parent>
          <axis>
            <xyz>0.000000 0.000000 1.000000</xyz>
            <limit>
              <lower>-0.700000</lower>
              <upper>0.700000</upper>
            </limit>
            <dynamics>
              <damping>4.0</damping>
              <friction>0.2</friction>
            </dynamics>
            <use_parent_model_frame>true</use_parent_model_frame>
          </axis>
        </joint>
        <joint name="joint_5_2" type="revolute">
          <child>link_5</child>
          <parent>sphere_5</parent>
          <axis>
            <xyz>0.000000 1.000000 0.000000</xyz>
            <limit>
              <lower>-0.700000</lower>
              <upper>0.700000</upper>
            </limit>
            <dynamics>
              <damping>4.0</damping>
              <friction>0.2</friction>
            </dynamics>
            <use_parent_model_frame>true</use_parent_model_frame>
          </axis>
        </joint>
    
        <joint name="joint_6_1" type="revolute">
          <child>sphere_6</child>
          <parent>sphere_5</parent>
          <axis>
            <xyz>0.000000 0.000000 1.000000</xyz>
            <limit>
              <lower>-0.700000</lower>
              <upper>0.700000</upper>
            </limit>
            <dynamics>
              <damping>4.0</damping>
              <friction>0.2</friction>
            </dynamics>
            <use_parent_model_frame>true</use_parent_model_frame>
          </axis>
        </joint>
        <joint name="joint_6_2" type="revolute">
          <child>link_6</child>
          <parent>sphere_6</parent>
          <axis>
            <xyz>0.000000 1.000000 0.000000</xyz>
            <limit>
              <lower>-0.700000</lower>
              <upper>0.700000</upper>
            </limit>
            <dynamics>
              <damping>4.0</damping>
              <friction>0.2</friction>
            </dynamics>
            <use_parent_model_frame>true</use_parent_model_frame>
          </axis>
        </joint>
    
        <joint name="joint_7_1" type="revolute">
          <child>sphere_7</child>
          <parent>sphere_6</parent>
          <axis>
            <xyz>0.000000 0.000000 1.000000</xyz>
            <limit>
              <lower>-0.700000</lower>
              <upper>0.700000</upper>
            </limit>
            <dynamics>
              <damping>4.0</damping>
              <friction>0.2</friction>
            </dynamics>
            <use_parent_model_frame>true</use_parent_model_frame>
          </axis>
        </joint>
        <joint name="joint_7_2" type="revolute">
          <child>link_7</child>
          <parent>sphere_7</parent>
          <axis>
            <xyz>0.000000 1.000000 0.000000</xyz>
            <limit>
              <lower>-0.700000</lower>
              <upper>0.700000</upper>
            </limit>
            <dynamics>
              <damping>4.0</damping>
              <friction>0.2</friction>
            </dynamics>
            <use_parent_model_frame>true</use_parent_model_frame>
          </axis>
        </joint>
    
        <joint name="joint_8_1" type="revolute">
          <child>sphere_8</child>
          <parent>sphere_7</parent>
          <axis>
            <xyz>0.000000 0.000000 1.000000</xyz>
            <limit>
              <lower>-0.700000</lower>
              <upper>0.700000</upper>
            </limit>
            <dynamics>
              <damping>4.0</damping>
              <friction>0.2</friction>
            </dynamics>
            <use_parent_model_frame>true</use_parent_model_frame>
          </axis>
        </joint>
        <joint name="joint_8_2" type="revolute">
          <child>link_8</child>
          <parent>sphere_8</parent>
          <axis>
            <xyz>0.000000 1.000000 0.000000</xyz>
            <limit>
              <lower>-0.700000</lower>
              <upper>0.700000</upper>
            </limit>
            <dynamics>
              <damping>4.0</damping>
              <friction>0.2</friction>
            </dynamics>
            <use_parent_model_frame>true</use_parent_model_frame>
          </axis>
        </joint>
    
        <joint name="joint_9_1" type="revolute">
          <child>sphere_9</child>
          <parent>sphere_8</parent>
          <axis>
            <xyz>0.000000 0.000000 1.000000</xyz>
            <limit>
              <lower>-0.700000</lower>
              <upper>0.700000</upper>
            </limit>
            <dynamics>
              <damping>4.0</damping>
              <friction>0.2</friction>
            </dynamics>
            <use_parent_model_frame>true</use_parent_model_frame>
          </axis>
        </joint>
        <joint name="joint_9_2" type="revolute">
          <child>link_9</child>
          <parent>sphere_9</parent>
          <axis>
            <xyz>0.000000 1.000000 0.000000</xyz>
            <limit>
              <lower>-0.700000</lower>
              <upper>0.700000</upper>
            </limit>
            <dynamics>
              <damping>4.0</damping>
              <friction>0.2</friction>
            </dynamics>
            <use_parent_model_frame>true</use_parent_model_frame>
          </axis>
        </joint>
    
        <joint name="joint_10_1" type="revolute">
          <child>sphere_10</child>
          <parent>sphere_9</parent>
          <axis>
            <xyz>0.000000 0.000000 1.000000</xyz>
            <limit>
              <lower>-0.700000</lower>
              <upper>0.700000</upper>
            </limit>
            <dynamics>
              <damping>4.0</damping>
              <friction>0.2</friction>
            </dynamics>
            <use_parent_model_frame>true</use_parent_model_frame>
          </axis>
        </joint>
        <joint name="joint_10_2" type="revolute">
          <child>link_10</child>
          <parent>sphere_10</parent>
          <axis>
            <xyz>0.000000 1.000000 0.000000</xyz>
            <limit>
              <lower>-0.700000</lower>
              <upper>0.700000</upper>
            </limit>
            <dynamics>
              <damping>4.0</damping>
              <friction>0.2</friction>
            </dynamics>
            <use_parent_model_frame>true</use_parent_model_frame>
          </axis>
        </joint>
    
        <joint name="joint_11_1" type="revolute">
          <child>sphere_11</child>
          <parent>sphere_10</parent>
          <axis>
            <xyz>0.000000 0.000000 1.000000</xyz>
            <limit>
              <lower>-0.700000</lower>
              <upper>0.700000</upper>
            </limit>
            <dynamics>
              <damping>4.0</damping>
              <friction>0.2</friction>
            </dynamics>
            <use_parent_model_frame>true</use_parent_model_frame>
          </axis>
        </joint>
        <joint name="joint_11_2" type="revolute">
          <child>link_11</child>
          <parent>sphere_11</parent>
          <axis>
            <xyz>0.000000 1.000000 0.000000</xyz>
            <limit>
              <lower>-0.700000</lower>
              <upper>0.700000</upper>
            </limit>
            <dynamics>
              <damping>4.0</damping>
              <friction>0.2</friction>
            </dynamics>
            <use_parent_model_frame>true</use_parent_model_frame>
          </axis>
        </joint>
    
        <joint name="joint_12_1" type="revolute">
          <child>sphere_12</child>
          <parent>sphere_11</parent>
          <axis>
            <xyz>0.000000 0.000000 1.000000</xyz>
            <limit>
              <lower>-0.700000</lower>
              <upper>0.700000</upper>
            </limit>
            <dynamics>
              <damping>4.0</damping>
              <friction>0.2</friction>
            </dynamics>
            <use_parent_model_frame>true</use_parent_model_frame>
          </axis>
        </joint>
        <joint name="joint_12_2" type="revolute">
          <child>link_12</child>
          <parent>sphere_12</parent>
          <axis>
            <xyz>0.000000 1.000000 0.000000</xyz>
            <limit>
              <lower>-0.700000</lower>
              <upper>0.700000</upper>
            </limit>
            <dynamics>
              <damping>4.0</damping>
              <friction>0.2</friction>
            </dynamics>
            <use_parent_model_frame>true</use_parent_model_frame>
          </axis>
        </joint>
    
        <joint name="joint_13_1" type="revolute">
          <child>sphere_13</child>
          <parent>sphere_12</parent>
          <axis>
            <xyz>0.000000 0.000000 1.000000</xyz>
            <limit>
              <lower>-0.700000</lower>
              <upper>0.700000</upper>
            </limit>
            <dynamics>
              <damping>4.0</damping>
              <friction>0.2</friction>
            </dynamics>
            <use_parent_model_frame>true</use_parent_model_frame>
          </axis>
        </joint>
        <joint name="joint_13_2" type="revolute">
          <child>link_13</child>
          <parent>sphere_13</parent>
          <axis>
            <xyz>0.000000 1.000000 0.000000</xyz>
            <limit>
              <lower>-0.700000</lower>
              <upper>0.700000</upper>
            </limit>
            <dynamics>
              <damping>4.0</damping>
              <friction>0.2</friction>
            </dynamics>
            <use_parent_model_frame>true</use_parent_model_frame>
          </axis>
        </joint>
    
        <joint name="joint_14_1" type="revolute">
          <child>sphere_14</child>
          <parent>sphere_13</parent>
          <axis>
            <xyz>0.000000 0.000000 1.000000</xyz>
            <limit>
              <lower>-0.700000</lower>
              <upper>0.700000</upper>
            </limit>
            <dynamics>
              <damping>4.0</damping>
              <friction>0.2</friction>
            </dynamics>
            <use_parent_model_frame>true</use_parent_model_frame>
          </axis>
        </joint>
        <joint name="joint_14_2" type="revolute">
          <child>link_14</child>
          <parent>sphere_14</parent>
          <axis>
            <xyz>0.000000 1.000000 0.000000</xyz>
            <limit>
              <lower>-0.700000</lower>
              <upper>0.700000</upper>
            </limit>
            <dynamics>
              <damping>4.0</damping>
              <friction>0.2</friction>
            </dynamics>
            <use_parent_model_frame>true</use_parent_model_frame>
          </axis>
        </joint>
    
        <joint name="joint_15_1" type="revolute">
          <child>sphere_15</child>
          <parent>sphere_14</parent>
          <axis>
            <xyz>0.000000 0.000000 1.000000</xyz>
            <limit>
              <lower>-0.700000</lower>
              <upper>0.700000</upper>
            </limit>
            <dynamics>
              <damping>4.0</damping>
              <friction>0.2</friction>
            </dynamics>
            <use_parent_model_frame>true</use_parent_model_frame>
          </axis>
        </joint>
        <joint name="joint_15_2" type="revolute">
          <child>link_15</child>
          <parent>sphere_15</parent>
          <axis>
            <xyz>0.000000 1.000000 0.000000</xyz>
            <limit>
              <lower>-0.700000</lower>
              <upper>0.700000</upper>
            </limit>
            <dynamics>
              <damping>4.0</damping>
              <friction>0.2</friction>
            </dynamics>
            <use_parent_model_frame>true</use_parent_model_frame>
          </axis>
        </joint>
    
        <joint name="joint_16_1" type="revolute">
          <child>sphere_16</child>
          <parent>sphere_15</parent>
          <axis>
            <xyz>0.000000 0.000000 1.000000</xyz>
            <limit>
              <lower>-0.700000</lower>
              <upper>0.700000</upper>
            </limit>
            <dynamics>
              <damping>4.0</damping>
              <friction>0.2</friction>
            </dynamics>
            <use_parent_model_frame>true</use_parent_model_frame>
          </axis>
        </joint>
        <joint name="joint_16_2" type="revolute">
          <child>link_16</child>
          <parent>sphere_16</parent>
          <axis>
            <xyz>0.000000 1.000000 0.000000</xyz>
            <limit>
              <lower>-0.700000</lower>
              <upper>0.700000</upper>
            </limit>
            <dynamics>
              <damping>4.0</damping>
              <friction>0.2</friction>
            </dynamics>
            <use_parent_model_frame>true</use_parent_model_frame>
          </axis>
        </joint>
    
        <joint name="joint_17_1" type="revolute">
          <child>sphere_17</child>
          <parent>sphere_16</parent>
          <axis>
            <xyz>0.000000 0.000000 1.000000</xyz>
            <limit>
              <lower>-0.700000</lower>
              <upper>0.700000</upper>
            </limit>
            <dynamics>
              <damping>4.0</damping>
              <friction>0.2</friction>
            </dynamics>
            <use_parent_model_frame>true</use_parent_model_frame>
          </axis>
        </joint>
        <joint name="joint_17_2" type="revolute">
          <child>link_17</child>
          <parent>sphere_17</parent>
          <axis>
            <xyz>0.000000 1.000000 0.000000</xyz>
            <limit>
              <lower>-0.700000</lower>
              <upper>0.700000</upper>
            </limit>
            <dynamics>
              <damping>4.0</damping>
              <friction>0.2</friction>
            </dynamics>
            <use_parent_model_frame>true</use_parent_model_frame>
          </axis>
        </joint>
    
        <joint name="joint_18_1" type="revolute">
          <child>sphere_18</child>
          <parent>sphere_17</parent>
          <axis>
            <xyz>0.000000 0.000000 1.000000</xyz>
            <limit>
              <lower>-0.700000</lower>
              <upper>0.700000</upper>
            </limit>
            <dynamics>
              <damping>4.0</damping>
              <friction>0.2</friction>
            </dynamics>
            <use_parent_model_frame>true</use_parent_model_frame>
          </axis>
        </joint>
        <joint name="joint_18_2" type="revolute">
          <child>link_18</child>
          <parent>sphere_18</parent>
          <axis>
            <xyz>0.000000 1.000000 0.000000</xyz>
            <limit>
              <lower>-0.700000</lower>
              <upper>0.700000</upper>
            </limit>
            <dynamics>
              <damping>4.0</damping>
              <friction>0.2</friction>
            </dynamics>
            <use_parent_model_frame>true</use_parent_model_frame>
          </axis>
        </joint>
    
        <joint name="joint_19_1" type="revolute">
          <child>sphere_19</child>
          <parent>sphere_18</parent>
          <axis>
            <xyz>0.000000 0.000000 1.000000</xyz>
            <limit>
              <lower>-0.700000</lower>
              <upper>0.700000</upper>
            </limit>
            <dynamics>
              <damping>4.0</damping>
              <friction>0.2</friction>
            </dynamics>
            <use_parent_model_frame>true</use_parent_model_frame>
          </axis>
        </joint>
        <joint name="joint_19_2" type="revolute">
          <child>link_19</child>
          <parent>sphere_19</parent>
          <axis>
            <xyz>0.000000 1.000000 0.000000</xyz>
            <limit>
              <lower>-0.700000</lower>
              <upper>0.700000</upper>
            </limit>
            <dynamics>
              <damping>4.0</damping>
              <friction>0.2</friction>
            </dynamics>
            <use_parent_model_frame>true</use_parent_model_frame>
          </axis>
        </joint>
    
        <joint name="joint_20_1" type="revolute">
          <child>sphere_20</child>
          <parent>sphere_19</parent>
          <axis>
            <xyz>0.000000 0.000000 1.000000</xyz>
            <limit>
              <lower>-0.700000</lower>
              <upper>0.700000</upper>
            </limit>
            <dynamics>
              <damping>4.0</damping>
              <friction>0.2</friction>
            </dynamics>
            <use_parent_model_frame>true</use_parent_model_frame>
          </axis>
        </joint>
        <joint name="joint_20_2" type="revolute">
          <child>link_20</child>
          <parent>sphere_20</parent>
          <axis>
            <xyz>0.000000 1.000000 0.000000</xyz>
            <limit>
              <lower>-0.700000</lower>
              <upper>0.700000</upper>
            </limit>
            <dynamics>
              <damping>4.0</damping>
              <friction>0.2</friction>
            </dynamics>
            <use_parent_model_frame>true</use_parent_model_frame>
          </axis>
        </joint>
    
</sdf>
