





<?xml version="1.0" ?>
<robot name="rope">
    
    <link name="link_0">
        <visual>
            <origin rpy="0 -1.5707 0" xyz="0.07500000000000001 0 0"/>
            <geometry>
                <cylinder length="0.2" radius="0.05"/>
            </geometry>
        </visual>
        <collision>
            <origin rpy="0 -1.5707 0" xyz="0.07500000000000001 0 0"/>
            <geometry>
                <box size="0.1 0.1 0.2"/>
            </geometry>
            <surface>
                <friction>
                    <ode>
                        <mu>0.0</mu>
                        <mu2>0.0</mu2>
                    </ode>
                </friction>
            </surface>
        </collision>
        <inertial>
            <mass value="0.5"/>
            <inertia ixx="3.333" ixy="0" ixz="0" iyy="0" iyz="0" izz="3.333"/>
            <origin rpy="0 0 0" xyz="0.17500000000000002 0 0"/>
        </inertial>
    </link>
    
    <link name="link_1">
        <visual>
            <origin rpy="0 -1.5707 0" xyz="0.07500000000000001 0 0"/>
            <geometry>
                <cylinder length="0.2" radius="0.05"/>
            </geometry>
        </visual>
        <collision>
            <origin rpy="0 -1.5707 0" xyz="0.07500000000000001 0 0"/>
            <geometry>
                <box size="0.1 0.1 0.2"/>
            </geometry>
            <surface>
                <friction>
                    <ode>
                        <mu>0.0</mu>
                        <mu2>0.0</mu2>
                    </ode>
                </friction>
            </surface>
        </collision>
        <inertial>
            <mass value="0.5"/>
            <inertia ixx="3.333" ixy="0" ixz="0" iyy="0" iyz="0" izz="3.333"/>
            <origin rpy="0 0 0" xyz="0.17500000000000002 0 0"/>
        </inertial>
    </link>
    
    <link name="link_2">
        <visual>
            <origin rpy="0 -1.5707 0" xyz="0.07500000000000001 0 0"/>
            <geometry>
                <cylinder length="0.2" radius="0.05"/>
            </geometry>
        </visual>
        <collision>
            <origin rpy="0 -1.5707 0" xyz="0.07500000000000001 0 0"/>
            <geometry>
                <box size="0.1 0.1 0.2"/>
            </geometry>
            <surface>
                <friction>
                    <ode>
                        <mu>0.0</mu>
                        <mu2>0.0</mu2>
                    </ode>
                </friction>
            </surface>
        </collision>
        <inertial>
            <mass value="0.5"/>
            <inertia ixx="3.333" ixy="0" ixz="0" iyy="0" iyz="0" izz="3.333"/>
            <origin rpy="0 0 0" xyz="0.17500000000000002 0 0"/>
        </inertial>
    </link>
    
    <link name="link_3">
        <visual>
            <origin rpy="0 -1.5707 0" xyz="0.07500000000000001 0 0"/>
            <geometry>
                <cylinder length="0.2" radius="0.05"/>
            </geometry>
        </visual>
        <collision>
            <origin rpy="0 -1.5707 0" xyz="0.07500000000000001 0 0"/>
            <geometry>
                <box size="0.1 0.1 0.2"/>
            </geometry>
            <surface>
                <friction>
                    <ode>
                        <mu>0.0</mu>
                        <mu2>0.0</mu2>
                    </ode>
                </friction>
            </surface>
        </collision>
        <inertial>
            <mass value="0.5"/>
            <inertia ixx="3.333" ixy="0" ixz="0" iyy="0" iyz="0" izz="3.333"/>
            <origin rpy="0 0 0" xyz="0.17500000000000002 0 0"/>
        </inertial>
    </link>
    
    <link name="link_4">
        <visual>
            <origin rpy="0 -1.5707 0" xyz="0.07500000000000001 0 0"/>
            <geometry>
                <cylinder length="0.2" radius="0.05"/>
            </geometry>
        </visual>
        <collision>
            <origin rpy="0 -1.5707 0" xyz="0.07500000000000001 0 0"/>
            <geometry>
                <box size="0.1 0.1 0.2"/>
            </geometry>
            <surface>
                <friction>
                    <ode>
                        <mu>0.0</mu>
                        <mu2>0.0</mu2>
                    </ode>
                </friction>
            </surface>
        </collision>
        <inertial>
            <mass value="0.5"/>
            <inertia ixx="3.333" ixy="0" ixz="0" iyy="0" iyz="0" izz="3.333"/>
            <origin rpy="0 0 0" xyz="0.17500000000000002 0 0"/>
        </inertial>
    </link>
    
    <link name="link_5">
        <visual>
            <origin rpy="0 -1.5707 0" xyz="0.07500000000000001 0 0"/>
            <geometry>
                <cylinder length="0.2" radius="0.05"/>
            </geometry>
        </visual>
        <collision>
            <origin rpy="0 -1.5707 0" xyz="0.07500000000000001 0 0"/>
            <geometry>
                <box size="0.1 0.1 0.2"/>
            </geometry>
            <surface>
                <friction>
                    <ode>
                        <mu>0.0</mu>
                        <mu2>0.0</mu2>
                    </ode>
                </friction>
            </surface>
        </collision>
        <inertial>
            <mass value="0.5"/>
            <inertia ixx="3.333" ixy="0" ixz="0" iyy="0" iyz="0" izz="3.333"/>
            <origin rpy="0 0 0" xyz="0.17500000000000002 0 0"/>
        </inertial>
    </link>
    
    <link name="link_6">
        <visual>
            <origin rpy="0 -1.5707 0" xyz="0.07500000000000001 0 0"/>
            <geometry>
                <cylinder length="0.2" radius="0.05"/>
            </geometry>
        </visual>
        <collision>
            <origin rpy="0 -1.5707 0" xyz="0.07500000000000001 0 0"/>
            <geometry>
                <box size="0.1 0.1 0.2"/>
            </geometry>
            <surface>
                <friction>
                    <ode>
                        <mu>0.0</mu>
                        <mu2>0.0</mu2>
                    </ode>
                </friction>
            </surface>
        </collision>
        <inertial>
            <mass value="0.5"/>
            <inertia ixx="3.333" ixy="0" ixz="0" iyy="0" iyz="0" izz="3.333"/>
            <origin rpy="0 0 0" xyz="0.17500000000000002 0 0"/>
        </inertial>
    </link>
    
    <link name="link_7">
        <visual>
            <origin rpy="0 -1.5707 0" xyz="0.07500000000000001 0 0"/>
            <geometry>
                <cylinder length="0.2" radius="0.05"/>
            </geometry>
        </visual>
        <collision>
            <origin rpy="0 -1.5707 0" xyz="0.07500000000000001 0 0"/>
            <geometry>
                <box size="0.1 0.1 0.2"/>
            </geometry>
            <surface>
                <friction>
                    <ode>
                        <mu>0.0</mu>
                        <mu2>0.0</mu2>
                    </ode>
                </friction>
            </surface>
        </collision>
        <inertial>
            <mass value="0.5"/>
            <inertia ixx="3.333" ixy="0" ixz="0" iyy="0" iyz="0" izz="3.333"/>
            <origin rpy="0 0 0" xyz="0.17500000000000002 0 0"/>
        </inertial>
    </link>
    
    <link name="link_8">
        <visual>
            <origin rpy="0 -1.5707 0" xyz="0.07500000000000001 0 0"/>
            <geometry>
                <cylinder length="0.2" radius="0.05"/>
            </geometry>
        </visual>
        <collision>
            <origin rpy="0 -1.5707 0" xyz="0.07500000000000001 0 0"/>
            <geometry>
                <box size="0.1 0.1 0.2"/>
            </geometry>
            <surface>
                <friction>
                    <ode>
                        <mu>0.0</mu>
                        <mu2>0.0</mu2>
                    </ode>
                </friction>
            </surface>
        </collision>
        <inertial>
            <mass value="0.5"/>
            <inertia ixx="3.333" ixy="0" ixz="0" iyy="0" iyz="0" izz="3.333"/>
            <origin rpy="0 0 0" xyz="0.17500000000000002 0 0"/>
        </inertial>
    </link>
    
    <link name="link_9">
        <visual>
            <origin rpy="0 -1.5707 0" xyz="0.07500000000000001 0 0"/>
            <geometry>
                <cylinder length="0.2" radius="0.05"/>
            </geometry>
        </visual>
        <collision>
            <origin rpy="0 -1.5707 0" xyz="0.07500000000000001 0 0"/>
            <geometry>
                <box size="0.1 0.1 0.2"/>
            </geometry>
            <surface>
                <friction>
                    <ode>
                        <mu>0.0</mu>
                        <mu2>0.0</mu2>
                    </ode>
                </friction>
            </surface>
        </collision>
        <inertial>
            <mass value="0.5"/>
            <inertia ixx="3.333" ixy="0" ixz="0" iyy="0" iyz="0" izz="3.333"/>
            <origin rpy="0 0 0" xyz="0.17500000000000002 0 0"/>
        </inertial>
    </link>
    
    <link name="link_10">
        <visual>
            <origin rpy="0 -1.5707 0" xyz="0.07500000000000001 0 0"/>
            <geometry>
                <cylinder length="0.2" radius="0.05"/>
            </geometry>
        </visual>
        <collision>
            <origin rpy="0 -1.5707 0" xyz="0.07500000000000001 0 0"/>
            <geometry>
                <box size="0.1 0.1 0.2"/>
            </geometry>
            <surface>
                <friction>
                    <ode>
                        <mu>0.0</mu>
                        <mu2>0.0</mu2>
                    </ode>
                </friction>
            </surface>
        </collision>
        <inertial>
            <mass value="0.5"/>
            <inertia ixx="3.333" ixy="0" ixz="0" iyy="0" iyz="0" izz="3.333"/>
            <origin rpy="0 0 0" xyz="0.17500000000000002 0 0"/>
        </inertial>
    </link>
    
    <link name="link_11">
        <visual>
            <origin rpy="0 -1.5707 0" xyz="0.07500000000000001 0 0"/>
            <geometry>
                <cylinder length="0.2" radius="0.05"/>
            </geometry>
        </visual>
        <collision>
            <origin rpy="0 -1.5707 0" xyz="0.07500000000000001 0 0"/>
            <geometry>
                <box size="0.1 0.1 0.2"/>
            </geometry>
            <surface>
                <friction>
                    <ode>
                        <mu>0.0</mu>
                        <mu2>0.0</mu2>
                    </ode>
                </friction>
            </surface>
        </collision>
        <inertial>
            <mass value="0.5"/>
            <inertia ixx="3.333" ixy="0" ixz="0" iyy="0" iyz="0" izz="3.333"/>
            <origin rpy="0 0 0" xyz="0.17500000000000002 0 0"/>
        </inertial>
    </link>
    
    <link name="link_12">
        <visual>
            <origin rpy="0 -1.5707 0" xyz="0.07500000000000001 0 0"/>
            <geometry>
                <cylinder length="0.2" radius="0.05"/>
            </geometry>
        </visual>
        <collision>
            <origin rpy="0 -1.5707 0" xyz="0.07500000000000001 0 0"/>
            <geometry>
                <box size="0.1 0.1 0.2"/>
            </geometry>
            <surface>
                <friction>
                    <ode>
                        <mu>0.0</mu>
                        <mu2>0.0</mu2>
                    </ode>
                </friction>
            </surface>
        </collision>
        <inertial>
            <mass value="0.5"/>
            <inertia ixx="3.333" ixy="0" ixz="0" iyy="0" iyz="0" izz="3.333"/>
            <origin rpy="0 0 0" xyz="0.17500000000000002 0 0"/>
        </inertial>
    </link>
    
    <link name="link_13">
        <visual>
            <origin rpy="0 -1.5707 0" xyz="0.07500000000000001 0 0"/>
            <geometry>
                <cylinder length="0.2" radius="0.05"/>
            </geometry>
        </visual>
        <collision>
            <origin rpy="0 -1.5707 0" xyz="0.07500000000000001 0 0"/>
            <geometry>
                <box size="0.1 0.1 0.2"/>
            </geometry>
            <surface>
                <friction>
                    <ode>
                        <mu>0.0</mu>
                        <mu2>0.0</mu2>
                    </ode>
                </friction>
            </surface>
        </collision>
        <inertial>
            <mass value="0.5"/>
            <inertia ixx="3.333" ixy="0" ixz="0" iyy="0" iyz="0" izz="3.333"/>
            <origin rpy="0 0 0" xyz="0.17500000000000002 0 0"/>
        </inertial>
    </link>
    
    <link name="link_14">
        <visual>
            <origin rpy="0 -1.5707 0" xyz="0.07500000000000001 0 0"/>
            <geometry>
                <cylinder length="0.2" radius="0.05"/>
            </geometry>
        </visual>
        <collision>
            <origin rpy="0 -1.5707 0" xyz="0.07500000000000001 0 0"/>
            <geometry>
                <box size="0.1 0.1 0.2"/>
            </geometry>
            <surface>
                <friction>
                    <ode>
                        <mu>0.0</mu>
                        <mu2>0.0</mu2>
                    </ode>
                </friction>
            </surface>
        </collision>
        <inertial>
            <mass value="0.5"/>
            <inertia ixx="3.333" ixy="0" ixz="0" iyy="0" iyz="0" izz="3.333"/>
            <origin rpy="0 0 0" xyz="0.17500000000000002 0 0"/>
        </inertial>
    </link>
    
    <link name="link_15">
        <visual>
            <origin rpy="0 -1.5707 0" xyz="0.07500000000000001 0 0"/>
            <geometry>
                <cylinder length="0.2" radius="0.05"/>
            </geometry>
        </visual>
        <collision>
            <origin rpy="0 -1.5707 0" xyz="0.07500000000000001 0 0"/>
            <geometry>
                <box size="0.1 0.1 0.2"/>
            </geometry>
            <surface>
                <friction>
                    <ode>
                        <mu>0.0</mu>
                        <mu2>0.0</mu2>
                    </ode>
                </friction>
            </surface>
        </collision>
        <inertial>
            <mass value="0.5"/>
            <inertia ixx="3.333" ixy="0" ixz="0" iyy="0" iyz="0" izz="3.333"/>
            <origin rpy="0 0 0" xyz="0.17500000000000002 0 0"/>
        </inertial>
    </link>
    
    <link name="link_16">
        <visual>
            <origin rpy="0 -1.5707 0" xyz="0.07500000000000001 0 0"/>
            <geometry>
                <cylinder length="0.2" radius="0.05"/>
            </geometry>
        </visual>
        <collision>
            <origin rpy="0 -1.5707 0" xyz="0.07500000000000001 0 0"/>
            <geometry>
                <box size="0.1 0.1 0.2"/>
            </geometry>
            <surface>
                <friction>
                    <ode>
                        <mu>0.0</mu>
                        <mu2>0.0</mu2>
                    </ode>
                </friction>
            </surface>
        </collision>
        <inertial>
            <mass value="0.5"/>
            <inertia ixx="3.333" ixy="0" ixz="0" iyy="0" iyz="0" izz="3.333"/>
            <origin rpy="0 0 0" xyz="0.17500000000000002 0 0"/>
        </inertial>
    </link>
    
    <link name="link_17">
        <visual>
            <origin rpy="0 -1.5707 0" xyz="0.07500000000000001 0 0"/>
            <geometry>
                <cylinder length="0.2" radius="0.05"/>
            </geometry>
        </visual>
        <collision>
            <origin rpy="0 -1.5707 0" xyz="0.07500000000000001 0 0"/>
            <geometry>
                <box size="0.1 0.1 0.2"/>
            </geometry>
            <surface>
                <friction>
                    <ode>
                        <mu>0.0</mu>
                        <mu2>0.0</mu2>
                    </ode>
                </friction>
            </surface>
        </collision>
        <inertial>
            <mass value="0.5"/>
            <inertia ixx="3.333" ixy="0" ixz="0" iyy="0" iyz="0" izz="3.333"/>
            <origin rpy="0 0 0" xyz="0.17500000000000002 0 0"/>
        </inertial>
    </link>
    
    <link name="link_18">
        <visual>
            <origin rpy="0 -1.5707 0" xyz="0.07500000000000001 0 0"/>
            <geometry>
                <cylinder length="0.2" radius="0.05"/>
            </geometry>
        </visual>
        <collision>
            <origin rpy="0 -1.5707 0" xyz="0.07500000000000001 0 0"/>
            <geometry>
                <box size="0.1 0.1 0.2"/>
            </geometry>
            <surface>
                <friction>
                    <ode>
                        <mu>0.0</mu>
                        <mu2>0.0</mu2>
                    </ode>
                </friction>
            </surface>
        </collision>
        <inertial>
            <mass value="0.5"/>
            <inertia ixx="3.333" ixy="0" ixz="0" iyy="0" iyz="0" izz="3.333"/>
            <origin rpy="0 0 0" xyz="0.17500000000000002 0 0"/>
        </inertial>
    </link>
    
    <link name="link_19">
        <visual>
            <origin rpy="0 -1.5707 0" xyz="0.07500000000000001 0 0"/>
            <geometry>
                <cylinder length="0.2" radius="0.05"/>
            </geometry>
        </visual>
        <collision>
            <origin rpy="0 -1.5707 0" xyz="0.07500000000000001 0 0"/>
            <geometry>
                <box size="0.1 0.1 0.2"/>
            </geometry>
            <surface>
                <friction>
                    <ode>
                        <mu>0.0</mu>
                        <mu2>0.0</mu2>
                    </ode>
                </friction>
            </surface>
        </collision>
        <inertial>
            <mass value="0.5"/>
            <inertia ixx="3.333" ixy="0" ixz="0" iyy="0" iyz="0" izz="3.333"/>
            <origin rpy="0 0 0" xyz="0.17500000000000002 0 0"/>
        </inertial>
    </link>
    
    <link name="link_20">
        <visual>
            <origin rpy="0 -1.5707 0" xyz="0.07500000000000001 0 0"/>
            <geometry>
                <cylinder length="0.2" radius="0.05"/>
            </geometry>
        </visual>
        <collision>
            <origin rpy="0 -1.5707 0" xyz="0.07500000000000001 0 0"/>
            <geometry>
                <box size="0.1 0.1 0.2"/>
            </geometry>
            <surface>
                <friction>
                    <ode>
                        <mu>0.0</mu>
                        <mu2>0.0</mu2>
                    </ode>
                </friction>
            </surface>
        </collision>
        <inertial>
            <mass value="0.5"/>
            <inertia ixx="3.333" ixy="0" ixz="0" iyy="0" iyz="0" izz="3.333"/>
            <origin rpy="0 0 0" xyz="0.17500000000000002 0 0"/>
        </inertial>
    </link>
    

    
    <joint name="joint_0" type="revolute">
        <parent link="link_0"/>
        <child link="link_1"/>
        <origin xyz="0.17500000000000002 0 0"/>
        <axis xyz="0 0 1"/>
        <limit lower="-2" upper="2" effort="10" velocity="2"/>
        <dynamics damping="1" friction="0.0"/>
    </joint>
    
    <joint name="joint_1" type="revolute">
        <parent link="link_1"/>
        <child link="link_2"/>
        <origin xyz="0.17500000000000002 0 0"/>
        <axis xyz="0 0 1"/>
        <limit lower="-2" upper="2" effort="10" velocity="2"/>
        <dynamics damping="1" friction="0.0"/>
    </joint>
    
    <joint name="joint_2" type="revolute">
        <parent link="link_2"/>
        <child link="link_3"/>
        <origin xyz="0.17500000000000002 0 0"/>
        <axis xyz="0 0 1"/>
        <limit lower="-2" upper="2" effort="10" velocity="2"/>
        <dynamics damping="1" friction="0.0"/>
    </joint>
    
    <joint name="joint_3" type="revolute">
        <parent link="link_3"/>
        <child link="link_4"/>
        <origin xyz="0.17500000000000002 0 0"/>
        <axis xyz="0 0 1"/>
        <limit lower="-2" upper="2" effort="10" velocity="2"/>
        <dynamics damping="1" friction="0.0"/>
    </joint>
    
    <joint name="joint_4" type="revolute">
        <parent link="link_4"/>
        <child link="link_5"/>
        <origin xyz="0.17500000000000002 0 0"/>
        <axis xyz="0 0 1"/>
        <limit lower="-2" upper="2" effort="10" velocity="2"/>
        <dynamics damping="1" friction="0.0"/>
    </joint>
    
    <joint name="joint_5" type="revolute">
        <parent link="link_5"/>
        <child link="link_6"/>
        <origin xyz="0.17500000000000002 0 0"/>
        <axis xyz="0 0 1"/>
        <limit lower="-2" upper="2" effort="10" velocity="2"/>
        <dynamics damping="1" friction="0.0"/>
    </joint>
    
    <joint name="joint_6" type="revolute">
        <parent link="link_6"/>
        <child link="link_7"/>
        <origin xyz="0.17500000000000002 0 0"/>
        <axis xyz="0 0 1"/>
        <limit lower="-2" upper="2" effort="10" velocity="2"/>
        <dynamics damping="1" friction="0.0"/>
    </joint>
    
    <joint name="joint_7" type="revolute">
        <parent link="link_7"/>
        <child link="link_8"/>
        <origin xyz="0.17500000000000002 0 0"/>
        <axis xyz="0 0 1"/>
        <limit lower="-2" upper="2" effort="10" velocity="2"/>
        <dynamics damping="1" friction="0.0"/>
    </joint>
    
    <joint name="joint_8" type="revolute">
        <parent link="link_8"/>
        <child link="link_9"/>
        <origin xyz="0.17500000000000002 0 0"/>
        <axis xyz="0 0 1"/>
        <limit lower="-2" upper="2" effort="10" velocity="2"/>
        <dynamics damping="1" friction="0.0"/>
    </joint>
    
    <joint name="joint_9" type="revolute">
        <parent link="link_9"/>
        <child link="link_10"/>
        <origin xyz="0.17500000000000002 0 0"/>
        <axis xyz="0 0 1"/>
        <limit lower="-2" upper="2" effort="10" velocity="2"/>
        <dynamics damping="1" friction="0.0"/>
    </joint>
    
    <joint name="joint_10" type="revolute">
        <parent link="link_10"/>
        <child link="link_11"/>
        <origin xyz="0.17500000000000002 0 0"/>
        <axis xyz="0 0 1"/>
        <limit lower="-2" upper="2" effort="10" velocity="2"/>
        <dynamics damping="1" friction="0.0"/>
    </joint>
    
    <joint name="joint_11" type="revolute">
        <parent link="link_11"/>
        <child link="link_12"/>
        <origin xyz="0.17500000000000002 0 0"/>
        <axis xyz="0 0 1"/>
        <limit lower="-2" upper="2" effort="10" velocity="2"/>
        <dynamics damping="1" friction="0.0"/>
    </joint>
    
    <joint name="joint_12" type="revolute">
        <parent link="link_12"/>
        <child link="link_13"/>
        <origin xyz="0.17500000000000002 0 0"/>
        <axis xyz="0 0 1"/>
        <limit lower="-2" upper="2" effort="10" velocity="2"/>
        <dynamics damping="1" friction="0.0"/>
    </joint>
    
    <joint name="joint_13" type="revolute">
        <parent link="link_13"/>
        <child link="link_14"/>
        <origin xyz="0.17500000000000002 0 0"/>
        <axis xyz="0 0 1"/>
        <limit lower="-2" upper="2" effort="10" velocity="2"/>
        <dynamics damping="1" friction="0.0"/>
    </joint>
    
    <joint name="joint_14" type="revolute">
        <parent link="link_14"/>
        <child link="link_15"/>
        <origin xyz="0.17500000000000002 0 0"/>
        <axis xyz="0 0 1"/>
        <limit lower="-2" upper="2" effort="10" velocity="2"/>
        <dynamics damping="1" friction="0.0"/>
    </joint>
    
    <joint name="joint_15" type="revolute">
        <parent link="link_15"/>
        <child link="link_16"/>
        <origin xyz="0.17500000000000002 0 0"/>
        <axis xyz="0 0 1"/>
        <limit lower="-2" upper="2" effort="10" velocity="2"/>
        <dynamics damping="1" friction="0.0"/>
    </joint>
    
    <joint name="joint_16" type="revolute">
        <parent link="link_16"/>
        <child link="link_17"/>
        <origin xyz="0.17500000000000002 0 0"/>
        <axis xyz="0 0 1"/>
        <limit lower="-2" upper="2" effort="10" velocity="2"/>
        <dynamics damping="1" friction="0.0"/>
    </joint>
    
    <joint name="joint_17" type="revolute">
        <parent link="link_17"/>
        <child link="link_18"/>
        <origin xyz="0.17500000000000002 0 0"/>
        <axis xyz="0 0 1"/>
        <limit lower="-2" upper="2" effort="10" velocity="2"/>
        <dynamics damping="1" friction="0.0"/>
    </joint>
    
    <joint name="joint_18" type="revolute">
        <parent link="link_18"/>
        <child link="link_19"/>
        <origin xyz="0.17500000000000002 0 0"/>
        <axis xyz="0 0 1"/>
        <limit lower="-2" upper="2" effort="10" velocity="2"/>
        <dynamics damping="1" friction="0.0"/>
    </joint>
    
    <joint name="joint_19" type="revolute">
        <parent link="link_19"/>
        <child link="link_20"/>
        <origin xyz="0.17500000000000002 0 0"/>
        <axis xyz="0 0 1"/>
        <limit lower="-2" upper="2" effort="10" velocity="2"/>
        <dynamics damping="1" friction="0.0"/>
    </joint>
    
    <gazebo>
        <plugin name="linkbot_model_plugin" filename="liblinkbot_model_plugin.so">
            <kP>600.0</kP>
            <kI>10.0</kI>
            <kD>1.0</kD>
            <action_scale>1</action_scale>
        </plugin>
    </gazebo>
</robot>
