<?xml version='1.0'?>
<sdf version='1.6'>
    <model name='car'>

        <link name="base">
            <inertial>
                <pose>0.001453 -0.000453 0.029787 0 0 0</pose>
                <inertia>
                    <ixx>0.003005</ixx>
                    <ixy>0</ixy>
                    <ixz>0</ixz>
                    <iyy>0.03005</iyy>
                    <iyz>0</iyz>
                    <izz>0.05476</izz>
                </inertia>
                <mass>2.0</mass>
            </inertial>
            <collision name="base_collision">
                <pose>0 0 0.047800 0 0 0</pose>
                <geometry>
                    <cylinder>
                        <radius>0.075</radius>
                        <length>0.04</length>
                    </cylinder>
                </geometry>
            </collision>
            <visual name="base_visual">
                <pose>0 0 0.03 0 0 0</pose>
                <geometry>
                    <cylinder>
                        <radius>0.075</radius>
                        <length>0.04</length>
                    </cylinder>
                </geometry>
            </visual>
            <collision name="front_wheel_collision">
                <pose>0.05 0 0.017000 0 1.570700 1.570700</pose>
                <geometry>
                    <sphere>
                        <radius>0.018000</radius>
                    </sphere>
                </geometry>
                <surface>
                    <friction>
                        <ode>
                            <mu>0</mu>
                        </ode>
                    </friction>
                </surface>
            </collision>
            <visual name="front_wheel_visual">
                <pose>0.05 0 0.017000 0 1.570700 1.570700</pose>
                <geometry>
                    <sphere>
                        <radius>0.018</radius>
                    </sphere>
                </geometry>
            </visual>
            <collision name="rear_wheel_collision">
                <pose>-0.05 0 0.017 0 1.5707 1.5707</pose>
                <geometry>
                    <sphere>
                        <radius>0.015000</radius>
                    </sphere>
                </geometry>
                <surface>
                    <friction>
                        <ode>
                            <mu>0</mu>
                        </ode>
                    </friction>
                </surface>
            </collision>
            <visual name="rear_wheel_visual">
                <pose>-0.05 0 0.017000 0 1.570700 1.570700</pose>
                <geometry>
                    <sphere>
                        <radius>0.018</radius>
                    </sphere>
                </geometry>
            </visual>
        </link>
        <link name="left_wheel">
            <pose>0 0.05 0.032000 0 0 0</pose>
            <inertial>
                <inertia>
                    <!-- having these inertias is what makes the model not spin all over the place -->
                    <ixx>0.001000</ixx>
                    <ixy>0</ixy>
                    <ixz>0</ixz>
                    <iyy>0.001000</iyy>
                    <iyz>0</iyz>
                    <izz>0.001000</izz>
                </inertia>
                <mass>0.010000</mass>
            </inertial>
            <collision name="collision">
                <pose>0 0 0 0 1.570700 1.570700</pose>
                <geometry>
                    <cylinder>
                        <radius>0.033000</radius>
                        <length>0.023000</length>
                    </cylinder>
                </geometry>
                <surface>
                    <friction>
                        <ode>
                            <mu>10</mu>
                        </ode>
                    </friction>
                </surface>
            </collision>
            <visual name="visual">
                <pose>0 0 0 0 1.570700 1.570700</pose>
                <geometry>
                    <cylinder>
                        <radius>0.033000</radius>
                        <length>0.023000</length>
                    </cylinder>
                </geometry>
            </visual>
        </link>
        <link name="right_wheel">
            <pose>0 -0.05 0.032000 0 0 0</pose>
            <inertial>
                <inertia>
                    <ixx>0.001000</ixx>
                    <ixy>0</ixy>
                    <ixz>0</ixz>
                    <iyy>0.001000</iyy>
                    <iyz>0</iyz>
                    <izz>0.001000</izz>
                </inertia>
                <mass>0.010000</mass>
            </inertial>
            <collision name="collision">
                <pose>0 0 0 0 1.570700 1.570700</pose>
                <geometry>
                    <cylinder>
                        <radius>0.033000</radius>
                        <length>0.023000</length>
                    </cylinder>
                </geometry>
                <surface>
                    <friction>
                        <ode>
                            <mu>10</mu>
                        </ode>
                    </friction>
                </surface>
            </collision>
            <visual name="visual">
                <pose>0 0 0 0 1.570700 1.570700</pose>
                <geometry>
                    <cylinder>
                        <radius>0.033000</radius>
                        <length>0.023000</length>
                    </cylinder>
                </geometry>
            </visual>
        </link>
        <joint name="left_wheel" type="revolute">
            <parent>base</parent>
            <child>left_wheel</child>
            <axis>
                <xyz>0 1 0</xyz>
                <use_parent_model_frame>true</use_parent_model_frame>
                <dynamics>
                    <friction>0.001</friction>
                    <damping>0.0002</damping>
                </dynamics>
            </axis>
        </joint>
        <joint name="right_wheel" type="revolute">
            <parent>base</parent>
            <child>right_wheel</child>
            <axis>
                <xyz>0 1 0</xyz>
                <use_parent_model_frame>true</use_parent_model_frame>
                <dynamics>
                    <friction>0.001</friction>
                    <damping>0.0002</damping>
                </dynamics>
            </axis>
        </joint>

        <plugin name="car_plugin" filename="libcar_plugin.so">
            <kP_vel>0.01</kP_vel>
            <kFF_vel>0.004</kFF_vel>
            <max_force>0.05</max_force>
        </plugin>
    </model>
</sdf>
