<?xml version='1.0'?>
<sdf version='1.6'>
    <model name='car'>
        <link name='base'>
            <pose>0 0 0.025 0 0 0</pose>
            <inertial>
                <pose frame=''>0 0 0 0 0 0</pose>
                <mass>0.5</mass>
                <inertia>
                    <ixx>0.00020833</ixx>
                    <ixy>0</ixy>
                    <ixz>0</ixz>
                    <izz>0.00020833</izz>
                    <iyz>0</iyz>
                    <iyy>0.00020833</iyy>
                </inertia>
            </inertial>
            <visual name='base_visual'>
                <pose>0 0 0 0 0 0</pose>
                <geometry>
                    <box>
                        <size>0.05 0.05 0.05</size>
                    </box>
                </geometry>
                <material>
                    <script>
                        <name>Gazebo/Yellow</name>
                        <uri>file://media/materials/scripts/gazebo.material</uri>
                    </script>
                </material>
            </visual>
            <collision name='base_visual'>
                <pose>0 0 0 0 0 0</pose>
                <geometry>
                    <box>
                        <size>0.05 0.05 0.05</size>
                    </box>
                </geometry>
            </collision>
            <collision name='caster_collision'>
                <pose>0.019 0 -0.017 0 0 0</pose>
                <geometry>
                    <sphere>
                        <radius>0.01</radius>
                    </sphere>
                </geometry>
            </collision>
            <visual name='caster_visual'>
                <pose>0.019 0 -0.017 0 0 0</pose>
                <geometry>
                    <sphere>
                        <radius>0.01</radius>
                    </sphere>
                </geometry>
            </visual>
        </link>
        <link name='right_wheel'>
            <pose>-0.02 -0.025 0.008 0 1.57079 1.57079</pose>
            <inertial>
                <mass>0.01</mass>
                <inertia>
                    <ixx>0.00000037</ixx>
                    <ixy>0</ixy>
                    <ixz>0</ixz>
                    <iyy>0.00000037</iyy>
                    <iyz>0</iyz>
                    <izz>0.00000050</izz>
                </inertia>
                <pose>0 0 0 0 0 0</pose>
            </inertial>
            <visual name='right_wheel_visual'>
                <pose>0 0 0 0 0 0</pose>
                <geometry>
                    <cylinder>
                        <radius>0.01</radius>
                        <length>0.012</length>
                    </cylinder>
                </geometry>
                <material>
                    <script>
                        <name>Gazebo/DarkGray</name>
                        <uri>file://media/materials/scripts/gazebo.material</uri>
                    </script>
                </material>
            </visual>
            <collision name='right_wheel_collision'>
                <pose>0 0 0 0 0 0</pose>
                <geometry>
                    <cylinder>
                        <radius>0.01</radius>
                        <length>0.012</length>
                    </cylinder>
                </geometry>
            </collision>
        </link>
        <link name='left_wheel'>
            <pose>-0.02 0.025 0.008 0 1.57079 1.57079</pose>
            <inertial>
                <mass>0.01</mass>
                <inertia>
                    <ixx>0.00000037</ixx>
                    <ixy>0</ixy>
                    <ixz>0</ixz>
                    <iyy>0.00000037</iyy>
                    <iyz>0</iyz>
                    <izz>0.00000050</izz>
                </inertia>
            </inertial>
            <visual name='left_wheel_visual'>
                <pose>0 0 0 0 0 0</pose>
                <geometry>
                    <cylinder>
                        <radius>0.01</radius>
                        <length>0.012</length>
                    </cylinder>
                </geometry>
                <material>
                    <script>
                        <name>Gazebo/DarkGray</name>
                        <uri>file://media/materials/scripts/gazebo.material</uri>
                    </script>
                </material>
            </visual>
            <collision name='left_wheel_collision'>
                <pose>0 0 0 0 0 0</pose>
                <geometry>
                    <cylinder>
                        <radius>0.01</radius>
                        <length>0.012</length>
                    </cylinder>
                </geometry>
            </collision>
        </link>
        <joint name='left_wheel_joint' type='revolute'>
            <parent>base</parent>
            <child>left_wheel</child>
            <pose>0 0 0 0 0 0</pose>
            <axis>
                <xyz>0 0 1</xyz>
                <limit>
                    <effort>0.016</effort> <!-- 16 kg-cm -->
                    <velocity>41.88</velocity> <!-- ~400 rpm -->
                </limit>
                <dynamics>
                    <damping>0.0058</damping>
                    <friction>0.0040</friction>
                </dynamics>
            </axis>
            <physics>
                <ode>
                    <implicit_spring_damper>true</implicit_spring_damper>
                    <limit>
                        <cfm>0.0</cfm>
                        <erp>0.0</erp>
                    </limit>
                    <suspension>
                        <cfm>0.0</cfm>
                        <erp>0.0</erp>
                    </suspension>
                </ode>
            </physics>
        </joint>
        <joint name='right_wheel_joint' type='revolute'>
            <parent>base</parent>
            <child>right_wheel</child>
            <pose>0 0 0 0 0 0</pose>
            <axis>
                <xyz>0 0 1</xyz>
                <use_parent_model_frame>0</use_parent_model_frame>
                <limit>
                    <effort>0.016</effort> <!-- 16 kg-cm -->
                    <velocity>41.88</velocity> <!-- ~400 rpm -->
                </limit>
                <dynamics>
                    <damping>0.0058</damping>
                    <friction>0.0040</friction>
                </dynamics>
            </axis>
            <physics>
                <ode>
                    <implicit_spring_damper>true</implicit_spring_damper>
                    <limit>
                        <cfm>0</cfm>
                        <erp>0.0</erp>
                    </limit>
                    <suspension>
                        <cfm>0</cfm>
                        <erp>0.0</erp>
                    </suspension>
                </ode>
            </physics>
        </joint>
        <plugin name="car_plugin" filename="libcar_plugin.so">
            <left_wheel_joint>left_wheel_joint</left_wheel_joint>
            <right_wheel_joint>right_wheel_joint</right_wheel_joint>
        </plugin>
    </model>
</sdf>
