
<sdf version="1.6">
    <model name="link_bot">
        <pose frame="">0 0 0.01 0 0 0</pose>

        
        <link name="link_1">
            <pose frame="">0.0 0 0 3.14159 -1.57079 3.14159</pose>
            <inertial>
                <pose frame="">0 0 -0.1 0 0 0</pose>
                <mass>0.05</mass>
                <inertia>
                    <ixx>0.0001669791666666667</ixx>
                    <ixy>0</ixy>
                    <ixz>0</ixz>
                    <iyy>0.0001669791666666667</iyy>
                    <iyz>0</iyz>
                    <izz>6.25e-07</izz>
                </inertia>
            </inertial>
            <collision name="link_1_collision">
                <pose frame="">0 0 -0.1 0 0 0</pose>
                <geometry>
                    <box>
                        <size>0.01 0.01 0.2</size>
                    </box>
                </geometry>
                <surface>
                    <friction>
                        <ode>
                            <mu>0.001</mu>
                            <mu2>0.001</mu2>
                        </ode>
                    </friction>
                </surface>
            </collision>
            <visual name="link_1_visual">
                <cast_shadows>0</cast_shadows>
                <pose frame="">0 0 -0.1 0 0 0</pose>
                <geometry>
                    <cylinder>
                        <length>0.2</length>
                        <radius>0.005</radius>
                    </cylinder>
                </geometry>
                <material>
                    <script>
                        <name>Gazebo/Orange</name>
                        <uri>file://media/materials/scripts/gazebo.material</uri>
                    </script>
                </material>
            </visual>
        </link>
        
        <link name="link_2">
            <pose frame="">0.2 0 0 3.14159 -1.57079 3.14159</pose>
            <inertial>
                <pose frame="">0 0 -0.1 0 0 0</pose>
                <mass>0.05</mass>
                <inertia>
                    <ixx>0.0001669791666666667</ixx>
                    <ixy>0</ixy>
                    <ixz>0</ixz>
                    <iyy>0.0001669791666666667</iyy>
                    <iyz>0</iyz>
                    <izz>6.25e-07</izz>
                </inertia>
            </inertial>
            <collision name="link_2_collision">
                <pose frame="">0 0 -0.1 0 0 0</pose>
                <geometry>
                    <box>
                        <size>0.01 0.01 0.2</size>
                    </box>
                </geometry>
                <surface>
                    <friction>
                        <ode>
                            <mu>0.001</mu>
                            <mu2>0.001</mu2>
                        </ode>
                    </friction>
                </surface>
            </collision>
            <visual name="link_2_visual">
                <cast_shadows>0</cast_shadows>
                <pose frame="">0 0 -0.1 0 0 0</pose>
                <geometry>
                    <cylinder>
                        <length>0.2</length>
                        <radius>0.005</radius>
                    </cylinder>
                </geometry>
                <material>
                    <script>
                        <name>Gazebo/Yellow</name>
                        <uri>file://media/materials/scripts/gazebo.material</uri>
                    </script>
                </material>
            </visual>
        </link>
        
        <link name="link_3">
            <pose frame="">0.4 0 0 3.14159 -1.57079 3.14159</pose>
            <inertial>
                <pose frame="">0 0 -0.1 0 0 0</pose>
                <mass>0.05</mass>
                <inertia>
                    <ixx>0.0001669791666666667</ixx>
                    <ixy>0</ixy>
                    <ixz>0</ixz>
                    <iyy>0.0001669791666666667</iyy>
                    <iyz>0</iyz>
                    <izz>6.25e-07</izz>
                </inertia>
            </inertial>
            <collision name="link_3_collision">
                <pose frame="">0 0 -0.1 0 0 0</pose>
                <geometry>
                    <box>
                        <size>0.01 0.01 0.2</size>
                    </box>
                </geometry>
                <surface>
                    <friction>
                        <ode>
                            <mu>0.001</mu>
                            <mu2>0.001</mu2>
                        </ode>
                    </friction>
                </surface>
            </collision>
            <visual name="link_3_visual">
                <cast_shadows>0</cast_shadows>
                <pose frame="">0 0 -0.1 0 0 0</pose>
                <geometry>
                    <cylinder>
                        <length>0.2</length>
                        <radius>0.005</radius>
                    </cylinder>
                </geometry>
                <material>
                    <script>
                        <name>Gazebo/Green</name>
                        <uri>file://media/materials/scripts/gazebo.material</uri>
                    </script>
                </material>
            </visual>
        </link>
        
        <link name="link_4">
            <pose frame="">0.6000000000000001 0 0 3.14159 -1.57079 3.14159</pose>
            <inertial>
                <pose frame="">0 0 -0.1 0 0 0</pose>
                <mass>0.05</mass>
                <inertia>
                    <ixx>0.0001669791666666667</ixx>
                    <ixy>0</ixy>
                    <ixz>0</ixz>
                    <iyy>0.0001669791666666667</iyy>
                    <iyz>0</iyz>
                    <izz>6.25e-07</izz>
                </inertia>
            </inertial>
            <collision name="link_4_collision">
                <pose frame="">0 0 -0.1 0 0 0</pose>
                <geometry>
                    <box>
                        <size>0.01 0.01 0.2</size>
                    </box>
                </geometry>
                <surface>
                    <friction>
                        <ode>
                            <mu>0.001</mu>
                            <mu2>0.001</mu2>
                        </ode>
                    </friction>
                </surface>
            </collision>
            <visual name="link_4_visual">
                <cast_shadows>0</cast_shadows>
                <pose frame="">0 0 -0.1 0 0 0</pose>
                <geometry>
                    <cylinder>
                        <length>0.2</length>
                        <radius>0.005</radius>
                    </cylinder>
                </geometry>
                <material>
                    <script>
                        <name>Gazebo/Blue</name>
                        <uri>file://media/materials/scripts/gazebo.material</uri>
                    </script>
                </material>
            </visual>
        </link>
        
        <link name="link_5">
            <pose frame="">0.8 0 0 3.14159 -1.57079 3.14159</pose>
            <inertial>
                <pose frame="">0 0 -0.1 0 0 0</pose>
                <mass>0.05</mass>
                <inertia>
                    <ixx>0.0001669791666666667</ixx>
                    <ixy>0</ixy>
                    <ixz>0</ixz>
                    <iyy>0.0001669791666666667</iyy>
                    <iyz>0</iyz>
                    <izz>6.25e-07</izz>
                </inertia>
            </inertial>
            <collision name="link_5_collision">
                <pose frame="">0 0 -0.1 0 0 0</pose>
                <geometry>
                    <box>
                        <size>0.01 0.01 0.2</size>
                    </box>
                </geometry>
                <surface>
                    <friction>
                        <ode>
                            <mu>0.001</mu>
                            <mu2>0.001</mu2>
                        </ode>
                    </friction>
                </surface>
            </collision>
            <visual name="link_5_visual">
                <cast_shadows>0</cast_shadows>
                <pose frame="">0 0 -0.1 0 0 0</pose>
                <geometry>
                    <cylinder>
                        <length>0.2</length>
                        <radius>0.005</radius>
                    </cylinder>
                </geometry>
                <material>
                    <script>
                        <name>Gazebo/Purple</name>
                        <uri>file://media/materials/scripts/gazebo.material</uri>
                    </script>
                </material>
            </visual>
        </link>
        
        <link name="link_6">
            <pose frame="">1.0 0 0 3.14159 -1.57079 3.14159</pose>
            <inertial>
                <pose frame="">0 0 -0.1 0 0 0</pose>
                <mass>0.05</mass>
                <inertia>
                    <ixx>0.0001669791666666667</ixx>
                    <ixy>0</ixy>
                    <ixz>0</ixz>
                    <iyy>0.0001669791666666667</iyy>
                    <iyz>0</iyz>
                    <izz>6.25e-07</izz>
                </inertia>
            </inertial>
            <collision name="link_6_collision">
                <pose frame="">0 0 -0.1 0 0 0</pose>
                <geometry>
                    <box>
                        <size>0.01 0.01 0.2</size>
                    </box>
                </geometry>
                <surface>
                    <friction>
                        <ode>
                            <mu>0.001</mu>
                            <mu2>0.001</mu2>
                        </ode>
                    </friction>
                </surface>
            </collision>
            <visual name="link_6_visual">
                <cast_shadows>0</cast_shadows>
                <pose frame="">0 0 -0.1 0 0 0</pose>
                <geometry>
                    <cylinder>
                        <length>0.2</length>
                        <radius>0.005</radius>
                    </cylinder>
                </geometry>
                <material>
                    <script>
                        <name>Gazebo/White</name>
                        <uri>file://media/materials/scripts/gazebo.material</uri>
                    </script>
                </material>
            </visual>
        </link>
        
        <link name="link_7">
            <pose frame="">1.2000000000000002 0 0 3.14159 -1.57079 3.14159</pose>
            <inertial>
                <pose frame="">0 0 -0.1 0 0 0</pose>
                <mass>0.05</mass>
                <inertia>
                    <ixx>0.0001669791666666667</ixx>
                    <ixy>0</ixy>
                    <ixz>0</ixz>
                    <iyy>0.0001669791666666667</iyy>
                    <iyz>0</iyz>
                    <izz>6.25e-07</izz>
                </inertia>
            </inertial>
            <collision name="link_7_collision">
                <pose frame="">0 0 -0.1 0 0 0</pose>
                <geometry>
                    <box>
                        <size>0.01 0.01 0.2</size>
                    </box>
                </geometry>
                <surface>
                    <friction>
                        <ode>
                            <mu>0.001</mu>
                            <mu2>0.001</mu2>
                        </ode>
                    </friction>
                </surface>
            </collision>
            <visual name="link_7_visual">
                <cast_shadows>0</cast_shadows>
                <pose frame="">0 0 -0.1 0 0 0</pose>
                <geometry>
                    <cylinder>
                        <length>0.2</length>
                        <radius>0.005</radius>
                    </cylinder>
                </geometry>
                <material>
                    <script>
                        <name>Gazebo/Black</name>
                        <uri>file://media/materials/scripts/gazebo.material</uri>
                    </script>
                </material>
            </visual>
        </link>
        
        <link name="link_8">
            <pose frame="">1.4000000000000001 0 0 3.14159 -1.57079 3.14159</pose>
            <inertial>
                <pose frame="">0 0 -0.1 0 0 0</pose>
                <mass>0.05</mass>
                <inertia>
                    <ixx>0.0001669791666666667</ixx>
                    <ixy>0</ixy>
                    <ixz>0</ixz>
                    <iyy>0.0001669791666666667</iyy>
                    <iyz>0</iyz>
                    <izz>6.25e-07</izz>
                </inertia>
            </inertial>
            <collision name="link_8_collision">
                <pose frame="">0 0 -0.1 0 0 0</pose>
                <geometry>
                    <box>
                        <size>0.01 0.01 0.2</size>
                    </box>
                </geometry>
                <surface>
                    <friction>
                        <ode>
                            <mu>0.001</mu>
                            <mu2>0.001</mu2>
                        </ode>
                    </friction>
                </surface>
            </collision>
            <visual name="link_8_visual">
                <cast_shadows>0</cast_shadows>
                <pose frame="">0 0 -0.1 0 0 0</pose>
                <geometry>
                    <cylinder>
                        <length>0.2</length>
                        <radius>0.005</radius>
                    </cylinder>
                </geometry>
                <material>
                    <script>
                        <name>Gazebo/Red</name>
                        <uri>file://media/materials/scripts/gazebo.material</uri>
                    </script>
                </material>
            </visual>
        </link>
        
        <link name="link_9">
            <pose frame="">1.6 0 0 3.14159 -1.57079 3.14159</pose>
            <inertial>
                <pose frame="">0 0 -0.1 0 0 0</pose>
                <mass>0.05</mass>
                <inertia>
                    <ixx>0.0001669791666666667</ixx>
                    <ixy>0</ixy>
                    <ixz>0</ixz>
                    <iyy>0.0001669791666666667</iyy>
                    <iyz>0</iyz>
                    <izz>6.25e-07</izz>
                </inertia>
            </inertial>
            <collision name="link_9_collision">
                <pose frame="">0 0 -0.1 0 0 0</pose>
                <geometry>
                    <box>
                        <size>0.01 0.01 0.2</size>
                    </box>
                </geometry>
                <surface>
                    <friction>
                        <ode>
                            <mu>0.001</mu>
                            <mu2>0.001</mu2>
                        </ode>
                    </friction>
                </surface>
            </collision>
            <visual name="link_9_visual">
                <cast_shadows>0</cast_shadows>
                <pose frame="">0 0 -0.1 0 0 0</pose>
                <geometry>
                    <cylinder>
                        <length>0.2</length>
                        <radius>0.005</radius>
                    </cylinder>
                </geometry>
                <material>
                    <script>
                        <name>Gazebo/Orange</name>
                        <uri>file://media/materials/scripts/gazebo.material</uri>
                    </script>
                </material>
            </visual>
        </link>
        
        <link name="link_10">
            <pose frame="">1.8 0 0 3.14159 -1.57079 3.14159</pose>
            <inertial>
                <pose frame="">0 0 -0.1 0 0 0</pose>
                <mass>0.05</mass>
                <inertia>
                    <ixx>0.0001669791666666667</ixx>
                    <ixy>0</ixy>
                    <ixz>0</ixz>
                    <iyy>0.0001669791666666667</iyy>
                    <iyz>0</iyz>
                    <izz>6.25e-07</izz>
                </inertia>
            </inertial>
            <collision name="link_10_collision">
                <pose frame="">0 0 -0.1 0 0 0</pose>
                <geometry>
                    <box>
                        <size>0.01 0.01 0.2</size>
                    </box>
                </geometry>
                <surface>
                    <friction>
                        <ode>
                            <mu>0.001</mu>
                            <mu2>0.001</mu2>
                        </ode>
                    </friction>
                </surface>
            </collision>
            <visual name="link_10_visual">
                <cast_shadows>0</cast_shadows>
                <pose frame="">0 0 -0.1 0 0 0</pose>
                <geometry>
                    <cylinder>
                        <length>0.2</length>
                        <radius>0.005</radius>
                    </cylinder>
                </geometry>
                <material>
                    <script>
                        <name>Gazebo/Yellow</name>
                        <uri>file://media/materials/scripts/gazebo.material</uri>
                    </script>
                </material>
            </visual>
        </link>
        

        
        <joint name="joint_1" type="revolute">
            <parent>link_1</parent>
            <child>link_2</child>
            <pose>0 0 0 0 0</pose>
            <axis>
                <xyz>0 0 1</xyz>
                <dynamics>
                    <damping>0.002</damping>
                    <friction>0.015</friction>
                    <spring_reference>0</spring_reference>
                    <spring_stiffness>0.0001</spring_stiffness>
                </dynamics>
                <use_parent_model_frame>1</use_parent_model_frame>
            </axis>
        </joint>
        
        <joint name="joint_2" type="revolute">
            <parent>link_2</parent>
            <child>link_3</child>
            <pose>0 0 0 0 0</pose>
            <axis>
                <xyz>0 0 1</xyz>
                <dynamics>
                    <damping>0.002</damping>
                    <friction>0.015</friction>
                    <spring_reference>0</spring_reference>
                    <spring_stiffness>0.0001</spring_stiffness>
                </dynamics>
                <use_parent_model_frame>1</use_parent_model_frame>
            </axis>
        </joint>
        
        <joint name="joint_3" type="revolute">
            <parent>link_3</parent>
            <child>link_4</child>
            <pose>0 0 0 0 0</pose>
            <axis>
                <xyz>0 0 1</xyz>
                <dynamics>
                    <damping>0.002</damping>
                    <friction>0.015</friction>
                    <spring_reference>0</spring_reference>
                    <spring_stiffness>0.0001</spring_stiffness>
                </dynamics>
                <use_parent_model_frame>1</use_parent_model_frame>
            </axis>
        </joint>
        
        <joint name="joint_4" type="revolute">
            <parent>link_4</parent>
            <child>link_5</child>
            <pose>0 0 0 0 0</pose>
            <axis>
                <xyz>0 0 1</xyz>
                <dynamics>
                    <damping>0.002</damping>
                    <friction>0.015</friction>
                    <spring_reference>0</spring_reference>
                    <spring_stiffness>0.0001</spring_stiffness>
                </dynamics>
                <use_parent_model_frame>1</use_parent_model_frame>
            </axis>
        </joint>
        
        <joint name="joint_5" type="revolute">
            <parent>link_5</parent>
            <child>link_6</child>
            <pose>0 0 0 0 0</pose>
            <axis>
                <xyz>0 0 1</xyz>
                <dynamics>
                    <damping>0.002</damping>
                    <friction>0.015</friction>
                    <spring_reference>0</spring_reference>
                    <spring_stiffness>0.0001</spring_stiffness>
                </dynamics>
                <use_parent_model_frame>1</use_parent_model_frame>
            </axis>
        </joint>
        
        <joint name="joint_6" type="revolute">
            <parent>link_6</parent>
            <child>link_7</child>
            <pose>0 0 0 0 0</pose>
            <axis>
                <xyz>0 0 1</xyz>
                <dynamics>
                    <damping>0.002</damping>
                    <friction>0.015</friction>
                    <spring_reference>0</spring_reference>
                    <spring_stiffness>0.0001</spring_stiffness>
                </dynamics>
                <use_parent_model_frame>1</use_parent_model_frame>
            </axis>
        </joint>
        
        <joint name="joint_7" type="revolute">
            <parent>link_7</parent>
            <child>link_8</child>
            <pose>0 0 0 0 0</pose>
            <axis>
                <xyz>0 0 1</xyz>
                <dynamics>
                    <damping>0.002</damping>
                    <friction>0.015</friction>
                    <spring_reference>0</spring_reference>
                    <spring_stiffness>0.0001</spring_stiffness>
                </dynamics>
                <use_parent_model_frame>1</use_parent_model_frame>
            </axis>
        </joint>
        
        <joint name="joint_8" type="revolute">
            <parent>link_8</parent>
            <child>link_9</child>
            <pose>0 0 0 0 0</pose>
            <axis>
                <xyz>0 0 1</xyz>
                <dynamics>
                    <damping>0.002</damping>
                    <friction>0.015</friction>
                    <spring_reference>0</spring_reference>
                    <spring_stiffness>0.0001</spring_stiffness>
                </dynamics>
                <use_parent_model_frame>1</use_parent_model_frame>
            </axis>
        </joint>
        
        <joint name="joint_9" type="revolute">
            <parent>link_9</parent>
            <child>link_10</child>
            <pose>0 0 0 0 0</pose>
            <axis>
                <xyz>0 0 1</xyz>
                <dynamics>
                    <damping>0.002</damping>
                    <friction>0.015</friction>
                    <spring_reference>0</spring_reference>
                    <spring_stiffness>0.0001</spring_stiffness>
                </dynamics>
                <use_parent_model_frame>1</use_parent_model_frame>
            </axis>
        </joint>
        

        <link name='head'>
            <pose frame=''>2.0 0 0 0 0 0</pose>
            <inertial>
                <pose frame=''>0 0 0 0 0 0</pose>
                <mass>0.1</mass>
                <inertia>
                    <ixx>0.00002333</ixx>
                    <ixy>0</ixy>
                    <ixz>0</ixz>
                    <iyy>0.00002333</iyy>
                    <iyz>0</iyz>
                    <izz>0.00002</izz>
                </inertia>
            </inertial>
            <collision name='head_collision'>
                <pose frame=''>0 0 0 0 0 0</pose>
                <geometry>
                    <cylinder>
                        <radius>0.02</radius>
                        <length>0.04</length>
                    </cylinder>
                </geometry>
                <surface>
                    <friction>
                        <ode>
                            <mu>0.05</mu>
                            <mu2>0.05</mu2>
                        </ode>
                    </friction>
                </surface>
            </collision>
            <visual name='head_visual'>
                <cast_shadows>0</cast_shadows>
                <pose frame=''>0 0 0 0 0 0</pose>
                <geometry>
                    <cylinder>
                        <radius>0.02</radius>
                        <length>0.01</length>
                    </cylinder>
                </geometry>
                <material>
                    <script>
                        <name>Gazebo/Red</name>
                        <uri>file://media/materials/scripts/gazebo.material</uri>
                    </script>
                </material>
            </visual>
            <sensor name='head_contact' type='contact'>
                <contact>
                    <collision>head_collision</collision>
                    <topic>__default_topic__</topic>
                </contact>
            </sensor>
        </link>

        <joint name="head_joint" type="fixed">
            <parent>head</parent>
            <child>link_10</child>
            <pose>0 0 -0.2 0 0 0</pose>
            <axis>
                <xyz>0 0 1</xyz>
                <use_parent_model_frame>1</use_parent_model_frame>
                <limit>
                    <effort>10</effort>
                    <velocity>5</velocity>
                </limit>
                <dynamics>
                    <damping>0</damping>
                    <friction>0</friction>
                </dynamics>
            </axis>
            <physics>
                <ode>
                    <limit>
                        <cfm>0</cfm>
                        <erp>0.2</erp>
                    </limit>
                </ode>
            </physics>
        </joint>

        <plugin name='tether_plugin' filename='libtether_plugin.so'>
            <num_links>10</num_links>
        </plugin>
        <plugin name='multi_link_bot_model_plugin' filename='libmulti_link_bot_model_plugin.so'>
            <kP_pos>50</kP_pos>
            <kI_pos>0.001</kI_pos>
            <kD_pos>0.0</kD_pos>
            <kP_vel>20.0</kP_vel>
            <kI_vel>0.0</kI_vel>
            <kD_vel>0.0</kD_vel>
            <max_force>1.0</max_force>
            <max_vel>0.15</max_vel>
            <max_vel_acc>0.01</max_vel_acc>
            <gripper1_link>head</gripper1_link>
            <num_links>0</num_links>
            <rope_length>2.0</rope_length>

            <B>1.0 0.1 0.0 1.1</B>
        </plugin>

        <joint type='revolute' name='world_joint'>
            <parent>world</parent>
            <child>link_1</child>
            <axis>
                <xyz>1 0 0</xyz>
                <dynamics>
                    <damping>0.001</damping>
                    <friction>0.001</friction>
                </dynamics>
            </axis>
        </joint>
    </model>
</sdf>
