
<sdf version="1.6">
    <model name="link_bot">
        <pose frame="">0 0 0.01 0 0 0</pose>

        
        <link name="link_1">
            <pose frame="">0.0 0 0 3.14159 -1.57079 3.14159</pose>
            <inertial>
                <pose frame="">0 0 0.05 0 0 0</pose>
                <mass>0.016666666666666666</mass>
                <inertia>
                    <ixx>1.3993055555555558e-05</ixx>
                    <ixy>0</ixy>
                    <ixz>0</ixz>
                    <iyy>1.3993055555555558e-05</iyy>
                    <iyz>0</iyz>
                    <izz>2.0833333333333333e-07</izz>
                </inertia>
            </inertial>
            <collision name="link_1_collision">
                <pose frame="">0 0 -0.05 0 0 0</pose>
                <geometry>
                    <box>
                        <size>0.01 0.01 0.1</size>
                    </box>
                </geometry>
                <surface>
                    <friction>
                        <ode>
                            <mu>0.001</mu>
                            <mu2>0.001</mu2>
                        </ode>
                    </friction>
                </surface>
            </collision>
            <visual name="link_1_visual">
                <cast_shadows>0</cast_shadows>
                <pose frame="">0 0 -0.05 0 0 0</pose>
                <geometry>
                    <cylinder>
                        <length>0.1</length>
                        <radius>0.005</radius>
                    </cylinder>
                </geometry>
                <material>
                    <script>
                        <name>Gazebo/Orange</name>
                        <uri>file://media/materials/scripts/gazebo.material</uri>
                    </script>
                </material>
            </visual>
        </link>
        
        <link name="link_2">
            <pose frame="">0.1 0 0 3.14159 -1.57079 3.14159</pose>
            <inertial>
                <pose frame="">0 0 0.05 0 0 0</pose>
                <mass>0.016666666666666666</mass>
                <inertia>
                    <ixx>1.3993055555555558e-05</ixx>
                    <ixy>0</ixy>
                    <ixz>0</ixz>
                    <iyy>1.3993055555555558e-05</iyy>
                    <iyz>0</iyz>
                    <izz>2.0833333333333333e-07</izz>
                </inertia>
            </inertial>
            <collision name="link_2_collision">
                <pose frame="">0 0 -0.05 0 0 0</pose>
                <geometry>
                    <box>
                        <size>0.01 0.01 0.1</size>
                    </box>
                </geometry>
                <surface>
                    <friction>
                        <ode>
                            <mu>0.001</mu>
                            <mu2>0.001</mu2>
                        </ode>
                    </friction>
                </surface>
            </collision>
            <visual name="link_2_visual">
                <cast_shadows>0</cast_shadows>
                <pose frame="">0 0 -0.05 0 0 0</pose>
                <geometry>
                    <cylinder>
                        <length>0.1</length>
                        <radius>0.005</radius>
                    </cylinder>
                </geometry>
                <material>
                    <script>
                        <name>Gazebo/Yellow</name>
                        <uri>file://media/materials/scripts/gazebo.material</uri>
                    </script>
                </material>
            </visual>
        </link>
        
        <link name="link_3">
            <pose frame="">0.2 0 0 3.14159 -1.57079 3.14159</pose>
            <inertial>
                <pose frame="">0 0 0.05 0 0 0</pose>
                <mass>0.016666666666666666</mass>
                <inertia>
                    <ixx>1.3993055555555558e-05</ixx>
                    <ixy>0</ixy>
                    <ixz>0</ixz>
                    <iyy>1.3993055555555558e-05</iyy>
                    <iyz>0</iyz>
                    <izz>2.0833333333333333e-07</izz>
                </inertia>
            </inertial>
            <collision name="link_3_collision">
                <pose frame="">0 0 -0.05 0 0 0</pose>
                <geometry>
                    <box>
                        <size>0.01 0.01 0.1</size>
                    </box>
                </geometry>
                <surface>
                    <friction>
                        <ode>
                            <mu>0.001</mu>
                            <mu2>0.001</mu2>
                        </ode>
                    </friction>
                </surface>
            </collision>
            <visual name="link_3_visual">
                <cast_shadows>0</cast_shadows>
                <pose frame="">0 0 -0.05 0 0 0</pose>
                <geometry>
                    <cylinder>
                        <length>0.1</length>
                        <radius>0.005</radius>
                    </cylinder>
                </geometry>
                <material>
                    <script>
                        <name>Gazebo/Green</name>
                        <uri>file://media/materials/scripts/gazebo.material</uri>
                    </script>
                </material>
            </visual>
        </link>
        
        <link name="link_4">
            <pose frame="">0.30000000000000004 0 0 3.14159 -1.57079 3.14159</pose>
            <inertial>
                <pose frame="">0 0 0.05 0 0 0</pose>
                <mass>0.016666666666666666</mass>
                <inertia>
                    <ixx>1.3993055555555558e-05</ixx>
                    <ixy>0</ixy>
                    <ixz>0</ixz>
                    <iyy>1.3993055555555558e-05</iyy>
                    <iyz>0</iyz>
                    <izz>2.0833333333333333e-07</izz>
                </inertia>
            </inertial>
            <collision name="link_4_collision">
                <pose frame="">0 0 -0.05 0 0 0</pose>
                <geometry>
                    <box>
                        <size>0.01 0.01 0.1</size>
                    </box>
                </geometry>
                <surface>
                    <friction>
                        <ode>
                            <mu>0.001</mu>
                            <mu2>0.001</mu2>
                        </ode>
                    </friction>
                </surface>
            </collision>
            <visual name="link_4_visual">
                <cast_shadows>0</cast_shadows>
                <pose frame="">0 0 -0.05 0 0 0</pose>
                <geometry>
                    <cylinder>
                        <length>0.1</length>
                        <radius>0.005</radius>
                    </cylinder>
                </geometry>
                <material>
                    <script>
                        <name>Gazebo/Blue</name>
                        <uri>file://media/materials/scripts/gazebo.material</uri>
                    </script>
                </material>
            </visual>
        </link>
        
        <link name="link_5">
            <pose frame="">0.4 0 0 3.14159 -1.57079 3.14159</pose>
            <inertial>
                <pose frame="">0 0 0.05 0 0 0</pose>
                <mass>0.016666666666666666</mass>
                <inertia>
                    <ixx>1.3993055555555558e-05</ixx>
                    <ixy>0</ixy>
                    <ixz>0</ixz>
                    <iyy>1.3993055555555558e-05</iyy>
                    <iyz>0</iyz>
                    <izz>2.0833333333333333e-07</izz>
                </inertia>
            </inertial>
            <collision name="link_5_collision">
                <pose frame="">0 0 -0.05 0 0 0</pose>
                <geometry>
                    <box>
                        <size>0.01 0.01 0.1</size>
                    </box>
                </geometry>
                <surface>
                    <friction>
                        <ode>
                            <mu>0.001</mu>
                            <mu2>0.001</mu2>
                        </ode>
                    </friction>
                </surface>
            </collision>
            <visual name="link_5_visual">
                <cast_shadows>0</cast_shadows>
                <pose frame="">0 0 -0.05 0 0 0</pose>
                <geometry>
                    <cylinder>
                        <length>0.1</length>
                        <radius>0.005</radius>
                    </cylinder>
                </geometry>
                <material>
                    <script>
                        <name>Gazebo/Purple</name>
                        <uri>file://media/materials/scripts/gazebo.material</uri>
                    </script>
                </material>
            </visual>
        </link>
        
        <link name="link_6">
            <pose frame="">0.5 0 0 3.14159 -1.57079 3.14159</pose>
            <inertial>
                <pose frame="">0 0 0.05 0 0 0</pose>
                <mass>0.016666666666666666</mass>
                <inertia>
                    <ixx>1.3993055555555558e-05</ixx>
                    <ixy>0</ixy>
                    <ixz>0</ixz>
                    <iyy>1.3993055555555558e-05</iyy>
                    <iyz>0</iyz>
                    <izz>2.0833333333333333e-07</izz>
                </inertia>
            </inertial>
            <collision name="link_6_collision">
                <pose frame="">0 0 -0.05 0 0 0</pose>
                <geometry>
                    <box>
                        <size>0.01 0.01 0.1</size>
                    </box>
                </geometry>
                <surface>
                    <friction>
                        <ode>
                            <mu>0.001</mu>
                            <mu2>0.001</mu2>
                        </ode>
                    </friction>
                </surface>
            </collision>
            <visual name="link_6_visual">
                <cast_shadows>0</cast_shadows>
                <pose frame="">0 0 -0.05 0 0 0</pose>
                <geometry>
                    <cylinder>
                        <length>0.1</length>
                        <radius>0.005</radius>
                    </cylinder>
                </geometry>
                <material>
                    <script>
                        <name>Gazebo/White</name>
                        <uri>file://media/materials/scripts/gazebo.material</uri>
                    </script>
                </material>
            </visual>
        </link>
        
        <link name="link_7">
            <pose frame="">0.6000000000000001 0 0 3.14159 -1.57079 3.14159</pose>
            <inertial>
                <pose frame="">0 0 0.05 0 0 0</pose>
                <mass>0.016666666666666666</mass>
                <inertia>
                    <ixx>1.3993055555555558e-05</ixx>
                    <ixy>0</ixy>
                    <ixz>0</ixz>
                    <iyy>1.3993055555555558e-05</iyy>
                    <iyz>0</iyz>
                    <izz>2.0833333333333333e-07</izz>
                </inertia>
            </inertial>
            <collision name="link_7_collision">
                <pose frame="">0 0 -0.05 0 0 0</pose>
                <geometry>
                    <box>
                        <size>0.01 0.01 0.1</size>
                    </box>
                </geometry>
                <surface>
                    <friction>
                        <ode>
                            <mu>0.001</mu>
                            <mu2>0.001</mu2>
                        </ode>
                    </friction>
                </surface>
            </collision>
            <visual name="link_7_visual">
                <cast_shadows>0</cast_shadows>
                <pose frame="">0 0 -0.05 0 0 0</pose>
                <geometry>
                    <cylinder>
                        <length>0.1</length>
                        <radius>0.005</radius>
                    </cylinder>
                </geometry>
                <material>
                    <script>
                        <name>Gazebo/Black</name>
                        <uri>file://media/materials/scripts/gazebo.material</uri>
                    </script>
                </material>
            </visual>
        </link>
        
        <link name="link_8">
            <pose frame="">0.7000000000000001 0 0 3.14159 -1.57079 3.14159</pose>
            <inertial>
                <pose frame="">0 0 0.05 0 0 0</pose>
                <mass>0.016666666666666666</mass>
                <inertia>
                    <ixx>1.3993055555555558e-05</ixx>
                    <ixy>0</ixy>
                    <ixz>0</ixz>
                    <iyy>1.3993055555555558e-05</iyy>
                    <iyz>0</iyz>
                    <izz>2.0833333333333333e-07</izz>
                </inertia>
            </inertial>
            <collision name="link_8_collision">
                <pose frame="">0 0 -0.05 0 0 0</pose>
                <geometry>
                    <box>
                        <size>0.01 0.01 0.1</size>
                    </box>
                </geometry>
                <surface>
                    <friction>
                        <ode>
                            <mu>0.001</mu>
                            <mu2>0.001</mu2>
                        </ode>
                    </friction>
                </surface>
            </collision>
            <visual name="link_8_visual">
                <cast_shadows>0</cast_shadows>
                <pose frame="">0 0 -0.05 0 0 0</pose>
                <geometry>
                    <cylinder>
                        <length>0.1</length>
                        <radius>0.005</radius>
                    </cylinder>
                </geometry>
                <material>
                    <script>
                        <name>Gazebo/Red</name>
                        <uri>file://media/materials/scripts/gazebo.material</uri>
                    </script>
                </material>
            </visual>
        </link>
        
        <link name="link_9">
            <pose frame="">0.8 0 0 3.14159 -1.57079 3.14159</pose>
            <inertial>
                <pose frame="">0 0 0.05 0 0 0</pose>
                <mass>0.016666666666666666</mass>
                <inertia>
                    <ixx>1.3993055555555558e-05</ixx>
                    <ixy>0</ixy>
                    <ixz>0</ixz>
                    <iyy>1.3993055555555558e-05</iyy>
                    <iyz>0</iyz>
                    <izz>2.0833333333333333e-07</izz>
                </inertia>
            </inertial>
            <collision name="link_9_collision">
                <pose frame="">0 0 -0.05 0 0 0</pose>
                <geometry>
                    <box>
                        <size>0.01 0.01 0.1</size>
                    </box>
                </geometry>
                <surface>
                    <friction>
                        <ode>
                            <mu>0.001</mu>
                            <mu2>0.001</mu2>
                        </ode>
                    </friction>
                </surface>
            </collision>
            <visual name="link_9_visual">
                <cast_shadows>0</cast_shadows>
                <pose frame="">0 0 -0.05 0 0 0</pose>
                <geometry>
                    <cylinder>
                        <length>0.1</length>
                        <radius>0.005</radius>
                    </cylinder>
                </geometry>
                <material>
                    <script>
                        <name>Gazebo/Orange</name>
                        <uri>file://media/materials/scripts/gazebo.material</uri>
                    </script>
                </material>
            </visual>
        </link>
        
        <link name="link_10">
            <pose frame="">0.9 0 0 3.14159 -1.57079 3.14159</pose>
            <inertial>
                <pose frame="">0 0 0.05 0 0 0</pose>
                <mass>0.016666666666666666</mass>
                <inertia>
                    <ixx>1.3993055555555558e-05</ixx>
                    <ixy>0</ixy>
                    <ixz>0</ixz>
                    <iyy>1.3993055555555558e-05</iyy>
                    <iyz>0</iyz>
                    <izz>2.0833333333333333e-07</izz>
                </inertia>
            </inertial>
            <collision name="link_10_collision">
                <pose frame="">0 0 -0.05 0 0 0</pose>
                <geometry>
                    <box>
                        <size>0.01 0.01 0.1</size>
                    </box>
                </geometry>
                <surface>
                    <friction>
                        <ode>
                            <mu>0.001</mu>
                            <mu2>0.001</mu2>
                        </ode>
                    </friction>
                </surface>
            </collision>
            <visual name="link_10_visual">
                <cast_shadows>0</cast_shadows>
                <pose frame="">0 0 -0.05 0 0 0</pose>
                <geometry>
                    <cylinder>
                        <length>0.1</length>
                        <radius>0.005</radius>
                    </cylinder>
                </geometry>
                <material>
                    <script>
                        <name>Gazebo/Yellow</name>
                        <uri>file://media/materials/scripts/gazebo.material</uri>
                    </script>
                </material>
            </visual>
        </link>
        
        <link name="link_11">
            <pose frame="">1.0 0 0 3.14159 -1.57079 3.14159</pose>
            <inertial>
                <pose frame="">0 0 0.05 0 0 0</pose>
                <mass>0.016666666666666666</mass>
                <inertia>
                    <ixx>1.3993055555555558e-05</ixx>
                    <ixy>0</ixy>
                    <ixz>0</ixz>
                    <iyy>1.3993055555555558e-05</iyy>
                    <iyz>0</iyz>
                    <izz>2.0833333333333333e-07</izz>
                </inertia>
            </inertial>
            <collision name="link_11_collision">
                <pose frame="">0 0 -0.05 0 0 0</pose>
                <geometry>
                    <box>
                        <size>0.01 0.01 0.1</size>
                    </box>
                </geometry>
                <surface>
                    <friction>
                        <ode>
                            <mu>0.001</mu>
                            <mu2>0.001</mu2>
                        </ode>
                    </friction>
                </surface>
            </collision>
            <visual name="link_11_visual">
                <cast_shadows>0</cast_shadows>
                <pose frame="">0 0 -0.05 0 0 0</pose>
                <geometry>
                    <cylinder>
                        <length>0.1</length>
                        <radius>0.005</radius>
                    </cylinder>
                </geometry>
                <material>
                    <script>
                        <name>Gazebo/Green</name>
                        <uri>file://media/materials/scripts/gazebo.material</uri>
                    </script>
                </material>
            </visual>
        </link>
        
        <link name="link_12">
            <pose frame="">1.1 0 0 3.14159 -1.57079 3.14159</pose>
            <inertial>
                <pose frame="">0 0 0.05 0 0 0</pose>
                <mass>0.016666666666666666</mass>
                <inertia>
                    <ixx>1.3993055555555558e-05</ixx>
                    <ixy>0</ixy>
                    <ixz>0</ixz>
                    <iyy>1.3993055555555558e-05</iyy>
                    <iyz>0</iyz>
                    <izz>2.0833333333333333e-07</izz>
                </inertia>
            </inertial>
            <collision name="link_12_collision">
                <pose frame="">0 0 -0.05 0 0 0</pose>
                <geometry>
                    <box>
                        <size>0.01 0.01 0.1</size>
                    </box>
                </geometry>
                <surface>
                    <friction>
                        <ode>
                            <mu>0.001</mu>
                            <mu2>0.001</mu2>
                        </ode>
                    </friction>
                </surface>
            </collision>
            <visual name="link_12_visual">
                <cast_shadows>0</cast_shadows>
                <pose frame="">0 0 -0.05 0 0 0</pose>
                <geometry>
                    <cylinder>
                        <length>0.1</length>
                        <radius>0.005</radius>
                    </cylinder>
                </geometry>
                <material>
                    <script>
                        <name>Gazebo/Blue</name>
                        <uri>file://media/materials/scripts/gazebo.material</uri>
                    </script>
                </material>
            </visual>
        </link>
        
        <link name="link_13">
            <pose frame="">1.2000000000000002 0 0 3.14159 -1.57079 3.14159</pose>
            <inertial>
                <pose frame="">0 0 0.05 0 0 0</pose>
                <mass>0.016666666666666666</mass>
                <inertia>
                    <ixx>1.3993055555555558e-05</ixx>
                    <ixy>0</ixy>
                    <ixz>0</ixz>
                    <iyy>1.3993055555555558e-05</iyy>
                    <iyz>0</iyz>
                    <izz>2.0833333333333333e-07</izz>
                </inertia>
            </inertial>
            <collision name="link_13_collision">
                <pose frame="">0 0 -0.05 0 0 0</pose>
                <geometry>
                    <box>
                        <size>0.01 0.01 0.1</size>
                    </box>
                </geometry>
                <surface>
                    <friction>
                        <ode>
                            <mu>0.001</mu>
                            <mu2>0.001</mu2>
                        </ode>
                    </friction>
                </surface>
            </collision>
            <visual name="link_13_visual">
                <cast_shadows>0</cast_shadows>
                <pose frame="">0 0 -0.05 0 0 0</pose>
                <geometry>
                    <cylinder>
                        <length>0.1</length>
                        <radius>0.005</radius>
                    </cylinder>
                </geometry>
                <material>
                    <script>
                        <name>Gazebo/Purple</name>
                        <uri>file://media/materials/scripts/gazebo.material</uri>
                    </script>
                </material>
            </visual>
        </link>
        
        <link name="link_14">
            <pose frame="">1.3 0 0 3.14159 -1.57079 3.14159</pose>
            <inertial>
                <pose frame="">0 0 0.05 0 0 0</pose>
                <mass>0.016666666666666666</mass>
                <inertia>
                    <ixx>1.3993055555555558e-05</ixx>
                    <ixy>0</ixy>
                    <ixz>0</ixz>
                    <iyy>1.3993055555555558e-05</iyy>
                    <iyz>0</iyz>
                    <izz>2.0833333333333333e-07</izz>
                </inertia>
            </inertial>
            <collision name="link_14_collision">
                <pose frame="">0 0 -0.05 0 0 0</pose>
                <geometry>
                    <box>
                        <size>0.01 0.01 0.1</size>
                    </box>
                </geometry>
                <surface>
                    <friction>
                        <ode>
                            <mu>0.001</mu>
                            <mu2>0.001</mu2>
                        </ode>
                    </friction>
                </surface>
            </collision>
            <visual name="link_14_visual">
                <cast_shadows>0</cast_shadows>
                <pose frame="">0 0 -0.05 0 0 0</pose>
                <geometry>
                    <cylinder>
                        <length>0.1</length>
                        <radius>0.005</radius>
                    </cylinder>
                </geometry>
                <material>
                    <script>
                        <name>Gazebo/White</name>
                        <uri>file://media/materials/scripts/gazebo.material</uri>
                    </script>
                </material>
            </visual>
        </link>
        
        <link name="link_15">
            <pose frame="">1.4000000000000001 0 0 3.14159 -1.57079 3.14159</pose>
            <inertial>
                <pose frame="">0 0 0.05 0 0 0</pose>
                <mass>0.016666666666666666</mass>
                <inertia>
                    <ixx>1.3993055555555558e-05</ixx>
                    <ixy>0</ixy>
                    <ixz>0</ixz>
                    <iyy>1.3993055555555558e-05</iyy>
                    <iyz>0</iyz>
                    <izz>2.0833333333333333e-07</izz>
                </inertia>
            </inertial>
            <collision name="link_15_collision">
                <pose frame="">0 0 -0.05 0 0 0</pose>
                <geometry>
                    <box>
                        <size>0.01 0.01 0.1</size>
                    </box>
                </geometry>
                <surface>
                    <friction>
                        <ode>
                            <mu>0.001</mu>
                            <mu2>0.001</mu2>
                        </ode>
                    </friction>
                </surface>
            </collision>
            <visual name="link_15_visual">
                <cast_shadows>0</cast_shadows>
                <pose frame="">0 0 -0.05 0 0 0</pose>
                <geometry>
                    <cylinder>
                        <length>0.1</length>
                        <radius>0.005</radius>
                    </cylinder>
                </geometry>
                <material>
                    <script>
                        <name>Gazebo/Black</name>
                        <uri>file://media/materials/scripts/gazebo.material</uri>
                    </script>
                </material>
            </visual>
        </link>
        
        <link name="link_16">
            <pose frame="">1.5 0 0 3.14159 -1.57079 3.14159</pose>
            <inertial>
                <pose frame="">0 0 0.05 0 0 0</pose>
                <mass>0.016666666666666666</mass>
                <inertia>
                    <ixx>1.3993055555555558e-05</ixx>
                    <ixy>0</ixy>
                    <ixz>0</ixz>
                    <iyy>1.3993055555555558e-05</iyy>
                    <iyz>0</iyz>
                    <izz>2.0833333333333333e-07</izz>
                </inertia>
            </inertial>
            <collision name="link_16_collision">
                <pose frame="">0 0 -0.05 0 0 0</pose>
                <geometry>
                    <box>
                        <size>0.01 0.01 0.1</size>
                    </box>
                </geometry>
                <surface>
                    <friction>
                        <ode>
                            <mu>0.001</mu>
                            <mu2>0.001</mu2>
                        </ode>
                    </friction>
                </surface>
            </collision>
            <visual name="link_16_visual">
                <cast_shadows>0</cast_shadows>
                <pose frame="">0 0 -0.05 0 0 0</pose>
                <geometry>
                    <cylinder>
                        <length>0.1</length>
                        <radius>0.005</radius>
                    </cylinder>
                </geometry>
                <material>
                    <script>
                        <name>Gazebo/Red</name>
                        <uri>file://media/materials/scripts/gazebo.material</uri>
                    </script>
                </material>
            </visual>
        </link>
        
        <link name="link_17">
            <pose frame="">1.6 0 0 3.14159 -1.57079 3.14159</pose>
            <inertial>
                <pose frame="">0 0 0.05 0 0 0</pose>
                <mass>0.016666666666666666</mass>
                <inertia>
                    <ixx>1.3993055555555558e-05</ixx>
                    <ixy>0</ixy>
                    <ixz>0</ixz>
                    <iyy>1.3993055555555558e-05</iyy>
                    <iyz>0</iyz>
                    <izz>2.0833333333333333e-07</izz>
                </inertia>
            </inertial>
            <collision name="link_17_collision">
                <pose frame="">0 0 -0.05 0 0 0</pose>
                <geometry>
                    <box>
                        <size>0.01 0.01 0.1</size>
                    </box>
                </geometry>
                <surface>
                    <friction>
                        <ode>
                            <mu>0.001</mu>
                            <mu2>0.001</mu2>
                        </ode>
                    </friction>
                </surface>
            </collision>
            <visual name="link_17_visual">
                <cast_shadows>0</cast_shadows>
                <pose frame="">0 0 -0.05 0 0 0</pose>
                <geometry>
                    <cylinder>
                        <length>0.1</length>
                        <radius>0.005</radius>
                    </cylinder>
                </geometry>
                <material>
                    <script>
                        <name>Gazebo/Orange</name>
                        <uri>file://media/materials/scripts/gazebo.material</uri>
                    </script>
                </material>
            </visual>
        </link>
        
        <link name="link_18">
            <pose frame="">1.7000000000000002 0 0 3.14159 -1.57079 3.14159</pose>
            <inertial>
                <pose frame="">0 0 0.05 0 0 0</pose>
                <mass>0.016666666666666666</mass>
                <inertia>
                    <ixx>1.3993055555555558e-05</ixx>
                    <ixy>0</ixy>
                    <ixz>0</ixz>
                    <iyy>1.3993055555555558e-05</iyy>
                    <iyz>0</iyz>
                    <izz>2.0833333333333333e-07</izz>
                </inertia>
            </inertial>
            <collision name="link_18_collision">
                <pose frame="">0 0 -0.05 0 0 0</pose>
                <geometry>
                    <box>
                        <size>0.01 0.01 0.1</size>
                    </box>
                </geometry>
                <surface>
                    <friction>
                        <ode>
                            <mu>0.001</mu>
                            <mu2>0.001</mu2>
                        </ode>
                    </friction>
                </surface>
            </collision>
            <visual name="link_18_visual">
                <cast_shadows>0</cast_shadows>
                <pose frame="">0 0 -0.05 0 0 0</pose>
                <geometry>
                    <cylinder>
                        <length>0.1</length>
                        <radius>0.005</radius>
                    </cylinder>
                </geometry>
                <material>
                    <script>
                        <name>Gazebo/Yellow</name>
                        <uri>file://media/materials/scripts/gazebo.material</uri>
                    </script>
                </material>
            </visual>
        </link>
        
        <link name="link_19">
            <pose frame="">1.8 0 0 3.14159 -1.57079 3.14159</pose>
            <inertial>
                <pose frame="">0 0 0.05 0 0 0</pose>
                <mass>0.016666666666666666</mass>
                <inertia>
                    <ixx>1.3993055555555558e-05</ixx>
                    <ixy>0</ixy>
                    <ixz>0</ixz>
                    <iyy>1.3993055555555558e-05</iyy>
                    <iyz>0</iyz>
                    <izz>2.0833333333333333e-07</izz>
                </inertia>
            </inertial>
            <collision name="link_19_collision">
                <pose frame="">0 0 -0.05 0 0 0</pose>
                <geometry>
                    <box>
                        <size>0.01 0.01 0.1</size>
                    </box>
                </geometry>
                <surface>
                    <friction>
                        <ode>
                            <mu>0.001</mu>
                            <mu2>0.001</mu2>
                        </ode>
                    </friction>
                </surface>
            </collision>
            <visual name="link_19_visual">
                <cast_shadows>0</cast_shadows>
                <pose frame="">0 0 -0.05 0 0 0</pose>
                <geometry>
                    <cylinder>
                        <length>0.1</length>
                        <radius>0.005</radius>
                    </cylinder>
                </geometry>
                <material>
                    <script>
                        <name>Gazebo/Green</name>
                        <uri>file://media/materials/scripts/gazebo.material</uri>
                    </script>
                </material>
            </visual>
        </link>
        
        <link name="link_20">
            <pose frame="">1.9000000000000001 0 0 3.14159 -1.57079 3.14159</pose>
            <inertial>
                <pose frame="">0 0 0.05 0 0 0</pose>
                <mass>0.016666666666666666</mass>
                <inertia>
                    <ixx>1.3993055555555558e-05</ixx>
                    <ixy>0</ixy>
                    <ixz>0</ixz>
                    <iyy>1.3993055555555558e-05</iyy>
                    <iyz>0</iyz>
                    <izz>2.0833333333333333e-07</izz>
                </inertia>
            </inertial>
            <collision name="link_20_collision">
                <pose frame="">0 0 -0.05 0 0 0</pose>
                <geometry>
                    <box>
                        <size>0.01 0.01 0.1</size>
                    </box>
                </geometry>
                <surface>
                    <friction>
                        <ode>
                            <mu>0.001</mu>
                            <mu2>0.001</mu2>
                        </ode>
                    </friction>
                </surface>
            </collision>
            <visual name="link_20_visual">
                <cast_shadows>0</cast_shadows>
                <pose frame="">0 0 -0.05 0 0 0</pose>
                <geometry>
                    <cylinder>
                        <length>0.1</length>
                        <radius>0.005</radius>
                    </cylinder>
                </geometry>
                <material>
                    <script>
                        <name>Gazebo/Blue</name>
                        <uri>file://media/materials/scripts/gazebo.material</uri>
                    </script>
                </material>
            </visual>
        </link>
        
        <link name="link_21">
            <pose frame="">2.0 0 0 3.14159 -1.57079 3.14159</pose>
            <inertial>
                <pose frame="">0 0 0.05 0 0 0</pose>
                <mass>0.016666666666666666</mass>
                <inertia>
                    <ixx>1.3993055555555558e-05</ixx>
                    <ixy>0</ixy>
                    <ixz>0</ixz>
                    <iyy>1.3993055555555558e-05</iyy>
                    <iyz>0</iyz>
                    <izz>2.0833333333333333e-07</izz>
                </inertia>
            </inertial>
            <collision name="link_21_collision">
                <pose frame="">0 0 -0.05 0 0 0</pose>
                <geometry>
                    <box>
                        <size>0.01 0.01 0.1</size>
                    </box>
                </geometry>
                <surface>
                    <friction>
                        <ode>
                            <mu>0.001</mu>
                            <mu2>0.001</mu2>
                        </ode>
                    </friction>
                </surface>
            </collision>
            <visual name="link_21_visual">
                <cast_shadows>0</cast_shadows>
                <pose frame="">0 0 -0.05 0 0 0</pose>
                <geometry>
                    <cylinder>
                        <length>0.1</length>
                        <radius>0.005</radius>
                    </cylinder>
                </geometry>
                <material>
                    <script>
                        <name>Gazebo/Purple</name>
                        <uri>file://media/materials/scripts/gazebo.material</uri>
                    </script>
                </material>
            </visual>
        </link>
        
        <link name="link_22">
            <pose frame="">2.1 0 0 3.14159 -1.57079 3.14159</pose>
            <inertial>
                <pose frame="">0 0 0.05 0 0 0</pose>
                <mass>0.016666666666666666</mass>
                <inertia>
                    <ixx>1.3993055555555558e-05</ixx>
                    <ixy>0</ixy>
                    <ixz>0</ixz>
                    <iyy>1.3993055555555558e-05</iyy>
                    <iyz>0</iyz>
                    <izz>2.0833333333333333e-07</izz>
                </inertia>
            </inertial>
            <collision name="link_22_collision">
                <pose frame="">0 0 -0.05 0 0 0</pose>
                <geometry>
                    <box>
                        <size>0.01 0.01 0.1</size>
                    </box>
                </geometry>
                <surface>
                    <friction>
                        <ode>
                            <mu>0.001</mu>
                            <mu2>0.001</mu2>
                        </ode>
                    </friction>
                </surface>
            </collision>
            <visual name="link_22_visual">
                <cast_shadows>0</cast_shadows>
                <pose frame="">0 0 -0.05 0 0 0</pose>
                <geometry>
                    <cylinder>
                        <length>0.1</length>
                        <radius>0.005</radius>
                    </cylinder>
                </geometry>
                <material>
                    <script>
                        <name>Gazebo/White</name>
                        <uri>file://media/materials/scripts/gazebo.material</uri>
                    </script>
                </material>
            </visual>
        </link>
        
        <link name="link_23">
            <pose frame="">2.2 0 0 3.14159 -1.57079 3.14159</pose>
            <inertial>
                <pose frame="">0 0 0.05 0 0 0</pose>
                <mass>0.016666666666666666</mass>
                <inertia>
                    <ixx>1.3993055555555558e-05</ixx>
                    <ixy>0</ixy>
                    <ixz>0</ixz>
                    <iyy>1.3993055555555558e-05</iyy>
                    <iyz>0</iyz>
                    <izz>2.0833333333333333e-07</izz>
                </inertia>
            </inertial>
            <collision name="link_23_collision">
                <pose frame="">0 0 -0.05 0 0 0</pose>
                <geometry>
                    <box>
                        <size>0.01 0.01 0.1</size>
                    </box>
                </geometry>
                <surface>
                    <friction>
                        <ode>
                            <mu>0.001</mu>
                            <mu2>0.001</mu2>
                        </ode>
                    </friction>
                </surface>
            </collision>
            <visual name="link_23_visual">
                <cast_shadows>0</cast_shadows>
                <pose frame="">0 0 -0.05 0 0 0</pose>
                <geometry>
                    <cylinder>
                        <length>0.1</length>
                        <radius>0.005</radius>
                    </cylinder>
                </geometry>
                <material>
                    <script>
                        <name>Gazebo/Black</name>
                        <uri>file://media/materials/scripts/gazebo.material</uri>
                    </script>
                </material>
            </visual>
        </link>
        
        <link name="link_24">
            <pose frame="">2.3000000000000003 0 0 3.14159 -1.57079 3.14159</pose>
            <inertial>
                <pose frame="">0 0 0.05 0 0 0</pose>
                <mass>0.016666666666666666</mass>
                <inertia>
                    <ixx>1.3993055555555558e-05</ixx>
                    <ixy>0</ixy>
                    <ixz>0</ixz>
                    <iyy>1.3993055555555558e-05</iyy>
                    <iyz>0</iyz>
                    <izz>2.0833333333333333e-07</izz>
                </inertia>
            </inertial>
            <collision name="link_24_collision">
                <pose frame="">0 0 -0.05 0 0 0</pose>
                <geometry>
                    <box>
                        <size>0.01 0.01 0.1</size>
                    </box>
                </geometry>
                <surface>
                    <friction>
                        <ode>
                            <mu>0.001</mu>
                            <mu2>0.001</mu2>
                        </ode>
                    </friction>
                </surface>
            </collision>
            <visual name="link_24_visual">
                <cast_shadows>0</cast_shadows>
                <pose frame="">0 0 -0.05 0 0 0</pose>
                <geometry>
                    <cylinder>
                        <length>0.1</length>
                        <radius>0.005</radius>
                    </cylinder>
                </geometry>
                <material>
                    <script>
                        <name>Gazebo/Red</name>
                        <uri>file://media/materials/scripts/gazebo.material</uri>
                    </script>
                </material>
            </visual>
        </link>
        
        <link name="link_25">
            <pose frame="">2.4000000000000004 0 0 3.14159 -1.57079 3.14159</pose>
            <inertial>
                <pose frame="">0 0 0.05 0 0 0</pose>
                <mass>0.016666666666666666</mass>
                <inertia>
                    <ixx>1.3993055555555558e-05</ixx>
                    <ixy>0</ixy>
                    <ixz>0</ixz>
                    <iyy>1.3993055555555558e-05</iyy>
                    <iyz>0</iyz>
                    <izz>2.0833333333333333e-07</izz>
                </inertia>
            </inertial>
            <collision name="link_25_collision">
                <pose frame="">0 0 -0.05 0 0 0</pose>
                <geometry>
                    <box>
                        <size>0.01 0.01 0.1</size>
                    </box>
                </geometry>
                <surface>
                    <friction>
                        <ode>
                            <mu>0.001</mu>
                            <mu2>0.001</mu2>
                        </ode>
                    </friction>
                </surface>
            </collision>
            <visual name="link_25_visual">
                <cast_shadows>0</cast_shadows>
                <pose frame="">0 0 -0.05 0 0 0</pose>
                <geometry>
                    <cylinder>
                        <length>0.1</length>
                        <radius>0.005</radius>
                    </cylinder>
                </geometry>
                <material>
                    <script>
                        <name>Gazebo/Orange</name>
                        <uri>file://media/materials/scripts/gazebo.material</uri>
                    </script>
                </material>
            </visual>
        </link>
        
        <link name="link_26">
            <pose frame="">2.5 0 0 3.14159 -1.57079 3.14159</pose>
            <inertial>
                <pose frame="">0 0 0.05 0 0 0</pose>
                <mass>0.016666666666666666</mass>
                <inertia>
                    <ixx>1.3993055555555558e-05</ixx>
                    <ixy>0</ixy>
                    <ixz>0</ixz>
                    <iyy>1.3993055555555558e-05</iyy>
                    <iyz>0</iyz>
                    <izz>2.0833333333333333e-07</izz>
                </inertia>
            </inertial>
            <collision name="link_26_collision">
                <pose frame="">0 0 -0.05 0 0 0</pose>
                <geometry>
                    <box>
                        <size>0.01 0.01 0.1</size>
                    </box>
                </geometry>
                <surface>
                    <friction>
                        <ode>
                            <mu>0.001</mu>
                            <mu2>0.001</mu2>
                        </ode>
                    </friction>
                </surface>
            </collision>
            <visual name="link_26_visual">
                <cast_shadows>0</cast_shadows>
                <pose frame="">0 0 -0.05 0 0 0</pose>
                <geometry>
                    <cylinder>
                        <length>0.1</length>
                        <radius>0.005</radius>
                    </cylinder>
                </geometry>
                <material>
                    <script>
                        <name>Gazebo/Yellow</name>
                        <uri>file://media/materials/scripts/gazebo.material</uri>
                    </script>
                </material>
            </visual>
        </link>
        
        <link name="link_27">
            <pose frame="">2.6 0 0 3.14159 -1.57079 3.14159</pose>
            <inertial>
                <pose frame="">0 0 0.05 0 0 0</pose>
                <mass>0.016666666666666666</mass>
                <inertia>
                    <ixx>1.3993055555555558e-05</ixx>
                    <ixy>0</ixy>
                    <ixz>0</ixz>
                    <iyy>1.3993055555555558e-05</iyy>
                    <iyz>0</iyz>
                    <izz>2.0833333333333333e-07</izz>
                </inertia>
            </inertial>
            <collision name="link_27_collision">
                <pose frame="">0 0 -0.05 0 0 0</pose>
                <geometry>
                    <box>
                        <size>0.01 0.01 0.1</size>
                    </box>
                </geometry>
                <surface>
                    <friction>
                        <ode>
                            <mu>0.001</mu>
                            <mu2>0.001</mu2>
                        </ode>
                    </friction>
                </surface>
            </collision>
            <visual name="link_27_visual">
                <cast_shadows>0</cast_shadows>
                <pose frame="">0 0 -0.05 0 0 0</pose>
                <geometry>
                    <cylinder>
                        <length>0.1</length>
                        <radius>0.005</radius>
                    </cylinder>
                </geometry>
                <material>
                    <script>
                        <name>Gazebo/Green</name>
                        <uri>file://media/materials/scripts/gazebo.material</uri>
                    </script>
                </material>
            </visual>
        </link>
        
        <link name="link_28">
            <pose frame="">2.7 0 0 3.14159 -1.57079 3.14159</pose>
            <inertial>
                <pose frame="">0 0 0.05 0 0 0</pose>
                <mass>0.016666666666666666</mass>
                <inertia>
                    <ixx>1.3993055555555558e-05</ixx>
                    <ixy>0</ixy>
                    <ixz>0</ixz>
                    <iyy>1.3993055555555558e-05</iyy>
                    <iyz>0</iyz>
                    <izz>2.0833333333333333e-07</izz>
                </inertia>
            </inertial>
            <collision name="link_28_collision">
                <pose frame="">0 0 -0.05 0 0 0</pose>
                <geometry>
                    <box>
                        <size>0.01 0.01 0.1</size>
                    </box>
                </geometry>
                <surface>
                    <friction>
                        <ode>
                            <mu>0.001</mu>
                            <mu2>0.001</mu2>
                        </ode>
                    </friction>
                </surface>
            </collision>
            <visual name="link_28_visual">
                <cast_shadows>0</cast_shadows>
                <pose frame="">0 0 -0.05 0 0 0</pose>
                <geometry>
                    <cylinder>
                        <length>0.1</length>
                        <radius>0.005</radius>
                    </cylinder>
                </geometry>
                <material>
                    <script>
                        <name>Gazebo/Blue</name>
                        <uri>file://media/materials/scripts/gazebo.material</uri>
                    </script>
                </material>
            </visual>
        </link>
        
        <link name="link_29">
            <pose frame="">2.8000000000000003 0 0 3.14159 -1.57079 3.14159</pose>
            <inertial>
                <pose frame="">0 0 0.05 0 0 0</pose>
                <mass>0.016666666666666666</mass>
                <inertia>
                    <ixx>1.3993055555555558e-05</ixx>
                    <ixy>0</ixy>
                    <ixz>0</ixz>
                    <iyy>1.3993055555555558e-05</iyy>
                    <iyz>0</iyz>
                    <izz>2.0833333333333333e-07</izz>
                </inertia>
            </inertial>
            <collision name="link_29_collision">
                <pose frame="">0 0 -0.05 0 0 0</pose>
                <geometry>
                    <box>
                        <size>0.01 0.01 0.1</size>
                    </box>
                </geometry>
                <surface>
                    <friction>
                        <ode>
                            <mu>0.001</mu>
                            <mu2>0.001</mu2>
                        </ode>
                    </friction>
                </surface>
            </collision>
            <visual name="link_29_visual">
                <cast_shadows>0</cast_shadows>
                <pose frame="">0 0 -0.05 0 0 0</pose>
                <geometry>
                    <cylinder>
                        <length>0.1</length>
                        <radius>0.005</radius>
                    </cylinder>
                </geometry>
                <material>
                    <script>
                        <name>Gazebo/Purple</name>
                        <uri>file://media/materials/scripts/gazebo.material</uri>
                    </script>
                </material>
            </visual>
        </link>
        
        <link name="link_30">
            <pose frame="">2.9000000000000004 0 0 3.14159 -1.57079 3.14159</pose>
            <inertial>
                <pose frame="">0 0 0.05 0 0 0</pose>
                <mass>0.016666666666666666</mass>
                <inertia>
                    <ixx>1.3993055555555558e-05</ixx>
                    <ixy>0</ixy>
                    <ixz>0</ixz>
                    <iyy>1.3993055555555558e-05</iyy>
                    <iyz>0</iyz>
                    <izz>2.0833333333333333e-07</izz>
                </inertia>
            </inertial>
            <collision name="link_30_collision">
                <pose frame="">0 0 -0.05 0 0 0</pose>
                <geometry>
                    <box>
                        <size>0.01 0.01 0.1</size>
                    </box>
                </geometry>
                <surface>
                    <friction>
                        <ode>
                            <mu>0.001</mu>
                            <mu2>0.001</mu2>
                        </ode>
                    </friction>
                </surface>
            </collision>
            <visual name="link_30_visual">
                <cast_shadows>0</cast_shadows>
                <pose frame="">0 0 -0.05 0 0 0</pose>
                <geometry>
                    <cylinder>
                        <length>0.1</length>
                        <radius>0.005</radius>
                    </cylinder>
                </geometry>
                <material>
                    <script>
                        <name>Gazebo/White</name>
                        <uri>file://media/materials/scripts/gazebo.material</uri>
                    </script>
                </material>
            </visual>
        </link>
        

        
        <joint name="joint_1" type="revolute">
            <parent>link_1</parent>
            <child>link_2</child>
            <pose>0 0 0 0 0</pose>
            <axis>
                <xyz>0 0 1</xyz>
                <dynamics>
                    <damping>0.002</damping>
                    <friction>0.02</friction>
                </dynamics>
                <use_parent_model_frame>1</use_parent_model_frame>
            </axis>
        </joint>
        
        <joint name="joint_2" type="revolute">
            <parent>link_2</parent>
            <child>link_3</child>
            <pose>0 0 0 0 0</pose>
            <axis>
                <xyz>0 0 1</xyz>
                <dynamics>
                    <damping>0.002</damping>
                    <friction>0.02</friction>
                </dynamics>
                <use_parent_model_frame>1</use_parent_model_frame>
            </axis>
        </joint>
        
        <joint name="joint_3" type="revolute">
            <parent>link_3</parent>
            <child>link_4</child>
            <pose>0 0 0 0 0</pose>
            <axis>
                <xyz>0 0 1</xyz>
                <dynamics>
                    <damping>0.002</damping>
                    <friction>0.02</friction>
                </dynamics>
                <use_parent_model_frame>1</use_parent_model_frame>
            </axis>
        </joint>
        
        <joint name="joint_4" type="revolute">
            <parent>link_4</parent>
            <child>link_5</child>
            <pose>0 0 0 0 0</pose>
            <axis>
                <xyz>0 0 1</xyz>
                <dynamics>
                    <damping>0.002</damping>
                    <friction>0.02</friction>
                </dynamics>
                <use_parent_model_frame>1</use_parent_model_frame>
            </axis>
        </joint>
        
        <joint name="joint_5" type="revolute">
            <parent>link_5</parent>
            <child>link_6</child>
            <pose>0 0 0 0 0</pose>
            <axis>
                <xyz>0 0 1</xyz>
                <dynamics>
                    <damping>0.002</damping>
                    <friction>0.02</friction>
                </dynamics>
                <use_parent_model_frame>1</use_parent_model_frame>
            </axis>
        </joint>
        
        <joint name="joint_6" type="revolute">
            <parent>link_6</parent>
            <child>link_7</child>
            <pose>0 0 0 0 0</pose>
            <axis>
                <xyz>0 0 1</xyz>
                <dynamics>
                    <damping>0.002</damping>
                    <friction>0.02</friction>
                </dynamics>
                <use_parent_model_frame>1</use_parent_model_frame>
            </axis>
        </joint>
        
        <joint name="joint_7" type="revolute">
            <parent>link_7</parent>
            <child>link_8</child>
            <pose>0 0 0 0 0</pose>
            <axis>
                <xyz>0 0 1</xyz>
                <dynamics>
                    <damping>0.002</damping>
                    <friction>0.02</friction>
                </dynamics>
                <use_parent_model_frame>1</use_parent_model_frame>
            </axis>
        </joint>
        
        <joint name="joint_8" type="revolute">
            <parent>link_8</parent>
            <child>link_9</child>
            <pose>0 0 0 0 0</pose>
            <axis>
                <xyz>0 0 1</xyz>
                <dynamics>
                    <damping>0.002</damping>
                    <friction>0.02</friction>
                </dynamics>
                <use_parent_model_frame>1</use_parent_model_frame>
            </axis>
        </joint>
        
        <joint name="joint_9" type="revolute">
            <parent>link_9</parent>
            <child>link_10</child>
            <pose>0 0 0 0 0</pose>
            <axis>
                <xyz>0 0 1</xyz>
                <dynamics>
                    <damping>0.002</damping>
                    <friction>0.02</friction>
                </dynamics>
                <use_parent_model_frame>1</use_parent_model_frame>
            </axis>
        </joint>
        
        <joint name="joint_10" type="revolute">
            <parent>link_10</parent>
            <child>link_11</child>
            <pose>0 0 0 0 0</pose>
            <axis>
                <xyz>0 0 1</xyz>
                <dynamics>
                    <damping>0.002</damping>
                    <friction>0.02</friction>
                </dynamics>
                <use_parent_model_frame>1</use_parent_model_frame>
            </axis>
        </joint>
        
        <joint name="joint_11" type="revolute">
            <parent>link_11</parent>
            <child>link_12</child>
            <pose>0 0 0 0 0</pose>
            <axis>
                <xyz>0 0 1</xyz>
                <dynamics>
                    <damping>0.002</damping>
                    <friction>0.02</friction>
                </dynamics>
                <use_parent_model_frame>1</use_parent_model_frame>
            </axis>
        </joint>
        
        <joint name="joint_12" type="revolute">
            <parent>link_12</parent>
            <child>link_13</child>
            <pose>0 0 0 0 0</pose>
            <axis>
                <xyz>0 0 1</xyz>
                <dynamics>
                    <damping>0.002</damping>
                    <friction>0.02</friction>
                </dynamics>
                <use_parent_model_frame>1</use_parent_model_frame>
            </axis>
        </joint>
        
        <joint name="joint_13" type="revolute">
            <parent>link_13</parent>
            <child>link_14</child>
            <pose>0 0 0 0 0</pose>
            <axis>
                <xyz>0 0 1</xyz>
                <dynamics>
                    <damping>0.002</damping>
                    <friction>0.02</friction>
                </dynamics>
                <use_parent_model_frame>1</use_parent_model_frame>
            </axis>
        </joint>
        
        <joint name="joint_14" type="revolute">
            <parent>link_14</parent>
            <child>link_15</child>
            <pose>0 0 0 0 0</pose>
            <axis>
                <xyz>0 0 1</xyz>
                <dynamics>
                    <damping>0.002</damping>
                    <friction>0.02</friction>
                </dynamics>
                <use_parent_model_frame>1</use_parent_model_frame>
            </axis>
        </joint>
        
        <joint name="joint_15" type="revolute">
            <parent>link_15</parent>
            <child>link_16</child>
            <pose>0 0 0 0 0</pose>
            <axis>
                <xyz>0 0 1</xyz>
                <dynamics>
                    <damping>0.002</damping>
                    <friction>0.02</friction>
                </dynamics>
                <use_parent_model_frame>1</use_parent_model_frame>
            </axis>
        </joint>
        
        <joint name="joint_16" type="revolute">
            <parent>link_16</parent>
            <child>link_17</child>
            <pose>0 0 0 0 0</pose>
            <axis>
                <xyz>0 0 1</xyz>
                <dynamics>
                    <damping>0.002</damping>
                    <friction>0.02</friction>
                </dynamics>
                <use_parent_model_frame>1</use_parent_model_frame>
            </axis>
        </joint>
        
        <joint name="joint_17" type="revolute">
            <parent>link_17</parent>
            <child>link_18</child>
            <pose>0 0 0 0 0</pose>
            <axis>
                <xyz>0 0 1</xyz>
                <dynamics>
                    <damping>0.002</damping>
                    <friction>0.02</friction>
                </dynamics>
                <use_parent_model_frame>1</use_parent_model_frame>
            </axis>
        </joint>
        
        <joint name="joint_18" type="revolute">
            <parent>link_18</parent>
            <child>link_19</child>
            <pose>0 0 0 0 0</pose>
            <axis>
                <xyz>0 0 1</xyz>
                <dynamics>
                    <damping>0.002</damping>
                    <friction>0.02</friction>
                </dynamics>
                <use_parent_model_frame>1</use_parent_model_frame>
            </axis>
        </joint>
        
        <joint name="joint_19" type="revolute">
            <parent>link_19</parent>
            <child>link_20</child>
            <pose>0 0 0 0 0</pose>
            <axis>
                <xyz>0 0 1</xyz>
                <dynamics>
                    <damping>0.002</damping>
                    <friction>0.02</friction>
                </dynamics>
                <use_parent_model_frame>1</use_parent_model_frame>
            </axis>
        </joint>
        
        <joint name="joint_20" type="revolute">
            <parent>link_20</parent>
            <child>link_21</child>
            <pose>0 0 0 0 0</pose>
            <axis>
                <xyz>0 0 1</xyz>
                <dynamics>
                    <damping>0.002</damping>
                    <friction>0.02</friction>
                </dynamics>
                <use_parent_model_frame>1</use_parent_model_frame>
            </axis>
        </joint>
        
        <joint name="joint_21" type="revolute">
            <parent>link_21</parent>
            <child>link_22</child>
            <pose>0 0 0 0 0</pose>
            <axis>
                <xyz>0 0 1</xyz>
                <dynamics>
                    <damping>0.002</damping>
                    <friction>0.02</friction>
                </dynamics>
                <use_parent_model_frame>1</use_parent_model_frame>
            </axis>
        </joint>
        
        <joint name="joint_22" type="revolute">
            <parent>link_22</parent>
            <child>link_23</child>
            <pose>0 0 0 0 0</pose>
            <axis>
                <xyz>0 0 1</xyz>
                <dynamics>
                    <damping>0.002</damping>
                    <friction>0.02</friction>
                </dynamics>
                <use_parent_model_frame>1</use_parent_model_frame>
            </axis>
        </joint>
        
        <joint name="joint_23" type="revolute">
            <parent>link_23</parent>
            <child>link_24</child>
            <pose>0 0 0 0 0</pose>
            <axis>
                <xyz>0 0 1</xyz>
                <dynamics>
                    <damping>0.002</damping>
                    <friction>0.02</friction>
                </dynamics>
                <use_parent_model_frame>1</use_parent_model_frame>
            </axis>
        </joint>
        
        <joint name="joint_24" type="revolute">
            <parent>link_24</parent>
            <child>link_25</child>
            <pose>0 0 0 0 0</pose>
            <axis>
                <xyz>0 0 1</xyz>
                <dynamics>
                    <damping>0.002</damping>
                    <friction>0.02</friction>
                </dynamics>
                <use_parent_model_frame>1</use_parent_model_frame>
            </axis>
        </joint>
        
        <joint name="joint_25" type="revolute">
            <parent>link_25</parent>
            <child>link_26</child>
            <pose>0 0 0 0 0</pose>
            <axis>
                <xyz>0 0 1</xyz>
                <dynamics>
                    <damping>0.002</damping>
                    <friction>0.02</friction>
                </dynamics>
                <use_parent_model_frame>1</use_parent_model_frame>
            </axis>
        </joint>
        
        <joint name="joint_26" type="revolute">
            <parent>link_26</parent>
            <child>link_27</child>
            <pose>0 0 0 0 0</pose>
            <axis>
                <xyz>0 0 1</xyz>
                <dynamics>
                    <damping>0.002</damping>
                    <friction>0.02</friction>
                </dynamics>
                <use_parent_model_frame>1</use_parent_model_frame>
            </axis>
        </joint>
        
        <joint name="joint_27" type="revolute">
            <parent>link_27</parent>
            <child>link_28</child>
            <pose>0 0 0 0 0</pose>
            <axis>
                <xyz>0 0 1</xyz>
                <dynamics>
                    <damping>0.002</damping>
                    <friction>0.02</friction>
                </dynamics>
                <use_parent_model_frame>1</use_parent_model_frame>
            </axis>
        </joint>
        
        <joint name="joint_28" type="revolute">
            <parent>link_28</parent>
            <child>link_29</child>
            <pose>0 0 0 0 0</pose>
            <axis>
                <xyz>0 0 1</xyz>
                <dynamics>
                    <damping>0.002</damping>
                    <friction>0.02</friction>
                </dynamics>
                <use_parent_model_frame>1</use_parent_model_frame>
            </axis>
        </joint>
        
        <joint name="joint_29" type="revolute">
            <parent>link_29</parent>
            <child>link_30</child>
            <pose>0 0 0 0 0</pose>
            <axis>
                <xyz>0 0 1</xyz>
                <dynamics>
                    <damping>0.002</damping>
                    <friction>0.02</friction>
                </dynamics>
                <use_parent_model_frame>1</use_parent_model_frame>
            </axis>
        </joint>
        

        <link name='head'>
            <pose frame=''>3.0 0 0 0 0 0</pose>
            <inertial>
                <pose frame=''>0 0 0 0 0 0</pose>
                <mass>0.1</mass>
                <inertia>
                    <ixx>0.00002333</ixx>
                    <ixy>0</ixy>
                    <ixz>0</ixz>
                    <iyy>0.00002333</iyy>
                    <iyz>0</iyz>
                    <izz>0.00002</izz>
                </inertia>
            </inertial>
            <collision name='head_collision'>
                <pose frame=''>0 0 0 0 0 0</pose>
                <geometry>
                    <cylinder>
                        <radius>0.02</radius>
                        <length>0.04</length>
                    </cylinder>
                </geometry>
                <surface>
                    <friction>
                        <ode>
                            <mu>0.05</mu>
                            <mu2>0.05</mu2>
                        </ode>
                    </friction>
                </surface>
            </collision>
            <visual name='head_visual'>
                <cast_shadows>0</cast_shadows>
                <pose frame=''>0 0 0 0 0 0</pose>
                <geometry>
                    <sphere>
                        <radius>0.02</radius>
                    </sphere>
                </geometry>
                <material>
                    <script>
                        <name>Gazebo/Red</name>
                        <uri>file://media/materials/scripts/gazebo.material</uri>
                    </script>
                </material>
            </visual>
            <sensor name='head_contact' type='contact'>
                <contact>
                    <collision>head_collision</collision>
                    <topic>__default_topic__</topic>
                </contact>
            </sensor>
        </link>

        <joint name="head_joint" type="revolute">
            <parent>head</parent>
            <child>link_30</child>
            <pose>0 0 -0.1 0 0 0</pose>
            <axis>
                <xyz>0 0 1</xyz>
                <use_parent_model_frame>1</use_parent_model_frame>
                <limit>
                    <effort>10</effort>
                    <velocity>5</velocity>
                </limit>
                <dynamics>
                    <damping>0</damping>
                    <friction>0</friction>
                </dynamics>
            </axis>
            <physics>
                <ode>
                    <limit>
                        <cfm>0</cfm>
                        <erp>0.2</erp>
                    </limit>
                </ode>
            </physics>
        </joint>

        <plugin name='multi_link_bot_model_plugin' filename='libmulti_link_bot_model_plugin.so'>
            <kP_pos>50</kP_pos>
            <kI_pos>0.001</kI_pos>
            <kD_pos>0.0</kD_pos>
            <kP_vel>20.0</kP_vel>
            <kI_vel>0.0</kI_vel>
            <kD_vel>0.0</kD_vel>
            <max_force>1.0</max_force>
            <max_vel>0.15</max_vel>
            <max_vel_acc>0.01</max_vel_acc>
            <gripper1_link>head</gripper1_link>
            <num_links>0</num_links>
            <rope_length>3.0</rope_length>
        </plugin>
        <plugin name="tether_plugin" filename="libtether_plugin.so">
            <linkName>link_1</linkName>
            <num_links>30</num_links>
            <kP_pos>50</kP_pos>
            <kI_pos>0.0</kI_pos>
            <kD_pos>0.0</kD_pos>
            <max_vel>1.0</max_vel>
            <kP_vel>100.0</kP_vel>
            <kI_vel>0.0</kI_vel>
            <kD_vel>0.0</kD_vel>
            <max_force>5.0</max_force>
        </plugin>

    </model>
</sdf>
