
<sdf version="1.6">
    <model name="link_bot">
        <pose frame="">0 0 0 0 0 0</pose>
        
        <link name="link_1">
        <pose frame="">0.03 0 0 3.14159 -1.57079 3.14159</pose>
        <inertial>
            <pose frame="">0 0 0 0 0 0</pose>
            <mass>0.02
            </mass>
            <inertia>
                <ixx>1.82e-06
                </ixx>
                <ixy>0</ixy>
                <ixz>0</ixz>
                <iyy>1.82e-06
                </iyy>
                <iyz>0</iyz>
                <izz>6.4e-07
                </izz>
            </inertia>
        </inertial>
        <collision name="link_1_collision">
            <pose frame="">0 0 0 0 0 0</pose>
            <geometry>
                <cylinder>
                    <length>0.03</length>
                    <radius>0.008</radius>
                </cylinder>
            </geometry>
            <surface>
                <friction>
                    <ode>
                        <mu>0.20</mu>
                        <mu2>0.20</mu2>
                    </ode>
                </friction>
                <contact>
                    <ode>
                        <kp>1e15</kp>
                        <kd>1e13</kd>
                    </ode>
                </contact>
            </surface>
        </collision>

        <collision name="link_1_collision_ball1">
            <pose frame="">0 0 0.015 0 0 0</pose>
            <geometry>
                <sphere>
                    <radius>0.008</radius>
                </sphere>
            </geometry>
            <surface>
                <friction>
                    <ode>
                        <mu>0.20</mu>
                        <mu2>0.20</mu2>
                    </ode>
                </friction>
                <contact>
                    <ode>
                        <kp>1e15</kp>
                        <kd>1e13</kd>
                    </ode>
                </contact>
            </surface>
        </collision>

        <collision name="link_1_collision_ball2">
            <pose frame="">0 0 -0.015 0 0 0</pose>
            <geometry>
                <sphere>
                    <radius>0.008</radius>
                </sphere>
            </geometry>
            <surface>
                <friction>
                    <ode>
                        <mu>0.20</mu>
                        <mu2>0.20</mu2>
                    </ode>
                </friction>
                <contact>
                    <ode>
                        <kp>1e15</kp>
                        <kd>1e13</kd>
                    </ode>
                </contact>
            </surface>
        </collision>



        <visual name="link_1_visual">
            <cast_shadows>0</cast_shadows>
            <pose frame="">0 0 0 0 0 0</pose>
            <geometry>
                <cylinder>
                    <length>0.03
                    </length>
                    <radius>0.008
                    </radius>
                </cylinder>
            </geometry>
            <material>
                <script>
                    <name>Gazebo/Orange </name>
                    <uri>file://media/materials/scripts/gazebo.material</uri>
                </script>
            </material>
        </visual>
        <self_collide>1</self_collide>
        </link>
        
        <link name="link_2">
        <pose frame="">0.06 0 0 3.14159 -1.57079 3.14159</pose>
        <inertial>
            <pose frame="">0 0 0 0 0 0</pose>
            <mass>0.02
            </mass>
            <inertia>
                <ixx>1.82e-06
                </ixx>
                <ixy>0</ixy>
                <ixz>0</ixz>
                <iyy>1.82e-06
                </iyy>
                <iyz>0</iyz>
                <izz>6.4e-07
                </izz>
            </inertia>
        </inertial>
        <collision name="link_2_collision">
            <pose frame="">0 0 0 0 0 0</pose>
            <geometry>
                <cylinder>
                    <length>0.03</length>
                    <radius>0.008</radius>
                </cylinder>
            </geometry>
            <surface>
                <friction>
                    <ode>
                        <mu>0.20</mu>
                        <mu2>0.20</mu2>
                    </ode>
                </friction>
                <contact>
                    <ode>
                        <kp>1e15</kp>
                        <kd>1e13</kd>
                    </ode>
                </contact>
            </surface>
        </collision>

        <collision name="link_2_collision_ball1">
            <pose frame="">0 0 0.015 0 0 0</pose>
            <geometry>
                <sphere>
                    <radius>0.008</radius>
                </sphere>
            </geometry>
            <surface>
                <friction>
                    <ode>
                        <mu>0.20</mu>
                        <mu2>0.20</mu2>
                    </ode>
                </friction>
                <contact>
                    <ode>
                        <kp>1e15</kp>
                        <kd>1e13</kd>
                    </ode>
                </contact>
            </surface>
        </collision>

        <collision name="link_2_collision_ball2">
            <pose frame="">0 0 -0.015 0 0 0</pose>
            <geometry>
                <sphere>
                    <radius>0.008</radius>
                </sphere>
            </geometry>
            <surface>
                <friction>
                    <ode>
                        <mu>0.20</mu>
                        <mu2>0.20</mu2>
                    </ode>
                </friction>
                <contact>
                    <ode>
                        <kp>1e15</kp>
                        <kd>1e13</kd>
                    </ode>
                </contact>
            </surface>
        </collision>



        <visual name="link_2_visual">
            <cast_shadows>0</cast_shadows>
            <pose frame="">0 0 0 0 0 0</pose>
            <geometry>
                <cylinder>
                    <length>0.03
                    </length>
                    <radius>0.008
                    </radius>
                </cylinder>
            </geometry>
            <material>
                <script>
                    <name>Gazebo/Yellow </name>
                    <uri>file://media/materials/scripts/gazebo.material</uri>
                </script>
            </material>
        </visual>
        <self_collide>1</self_collide>
        </link>
        
        <link name="link_3">
        <pose frame="">0.09 0 0 3.14159 -1.57079 3.14159</pose>
        <inertial>
            <pose frame="">0 0 0 0 0 0</pose>
            <mass>0.02
            </mass>
            <inertia>
                <ixx>1.82e-06
                </ixx>
                <ixy>0</ixy>
                <ixz>0</ixz>
                <iyy>1.82e-06
                </iyy>
                <iyz>0</iyz>
                <izz>6.4e-07
                </izz>
            </inertia>
        </inertial>
        <collision name="link_3_collision">
            <pose frame="">0 0 0 0 0 0</pose>
            <geometry>
                <cylinder>
                    <length>0.03</length>
                    <radius>0.008</radius>
                </cylinder>
            </geometry>
            <surface>
                <friction>
                    <ode>
                        <mu>0.20</mu>
                        <mu2>0.20</mu2>
                    </ode>
                </friction>
                <contact>
                    <ode>
                        <kp>1e15</kp>
                        <kd>1e13</kd>
                    </ode>
                </contact>
            </surface>
        </collision>

        <collision name="link_3_collision_ball1">
            <pose frame="">0 0 0.015 0 0 0</pose>
            <geometry>
                <sphere>
                    <radius>0.008</radius>
                </sphere>
            </geometry>
            <surface>
                <friction>
                    <ode>
                        <mu>0.20</mu>
                        <mu2>0.20</mu2>
                    </ode>
                </friction>
                <contact>
                    <ode>
                        <kp>1e15</kp>
                        <kd>1e13</kd>
                    </ode>
                </contact>
            </surface>
        </collision>

        <collision name="link_3_collision_ball2">
            <pose frame="">0 0 -0.015 0 0 0</pose>
            <geometry>
                <sphere>
                    <radius>0.008</radius>
                </sphere>
            </geometry>
            <surface>
                <friction>
                    <ode>
                        <mu>0.20</mu>
                        <mu2>0.20</mu2>
                    </ode>
                </friction>
                <contact>
                    <ode>
                        <kp>1e15</kp>
                        <kd>1e13</kd>
                    </ode>
                </contact>
            </surface>
        </collision>



        <visual name="link_3_visual">
            <cast_shadows>0</cast_shadows>
            <pose frame="">0 0 0 0 0 0</pose>
            <geometry>
                <cylinder>
                    <length>0.03
                    </length>
                    <radius>0.008
                    </radius>
                </cylinder>
            </geometry>
            <material>
                <script>
                    <name>Gazebo/Green </name>
                    <uri>file://media/materials/scripts/gazebo.material</uri>
                </script>
            </material>
        </visual>
        <self_collide>1</self_collide>
        </link>
        
        <link name="link_4">
        <pose frame="">0.12 0 0 3.14159 -1.57079 3.14159</pose>
        <inertial>
            <pose frame="">0 0 0 0 0 0</pose>
            <mass>0.02
            </mass>
            <inertia>
                <ixx>1.82e-06
                </ixx>
                <ixy>0</ixy>
                <ixz>0</ixz>
                <iyy>1.82e-06
                </iyy>
                <iyz>0</iyz>
                <izz>6.4e-07
                </izz>
            </inertia>
        </inertial>
        <collision name="link_4_collision">
            <pose frame="">0 0 0 0 0 0</pose>
            <geometry>
                <cylinder>
                    <length>0.03</length>
                    <radius>0.008</radius>
                </cylinder>
            </geometry>
            <surface>
                <friction>
                    <ode>
                        <mu>0.20</mu>
                        <mu2>0.20</mu2>
                    </ode>
                </friction>
                <contact>
                    <ode>
                        <kp>1e15</kp>
                        <kd>1e13</kd>
                    </ode>
                </contact>
            </surface>
        </collision>

        <collision name="link_4_collision_ball1">
            <pose frame="">0 0 0.015 0 0 0</pose>
            <geometry>
                <sphere>
                    <radius>0.008</radius>
                </sphere>
            </geometry>
            <surface>
                <friction>
                    <ode>
                        <mu>0.20</mu>
                        <mu2>0.20</mu2>
                    </ode>
                </friction>
                <contact>
                    <ode>
                        <kp>1e15</kp>
                        <kd>1e13</kd>
                    </ode>
                </contact>
            </surface>
        </collision>

        <collision name="link_4_collision_ball2">
            <pose frame="">0 0 -0.015 0 0 0</pose>
            <geometry>
                <sphere>
                    <radius>0.008</radius>
                </sphere>
            </geometry>
            <surface>
                <friction>
                    <ode>
                        <mu>0.20</mu>
                        <mu2>0.20</mu2>
                    </ode>
                </friction>
                <contact>
                    <ode>
                        <kp>1e15</kp>
                        <kd>1e13</kd>
                    </ode>
                </contact>
            </surface>
        </collision>



        <visual name="link_4_visual">
            <cast_shadows>0</cast_shadows>
            <pose frame="">0 0 0 0 0 0</pose>
            <geometry>
                <cylinder>
                    <length>0.03
                    </length>
                    <radius>0.008
                    </radius>
                </cylinder>
            </geometry>
            <material>
                <script>
                    <name>Gazebo/Blue </name>
                    <uri>file://media/materials/scripts/gazebo.material</uri>
                </script>
            </material>
        </visual>
        <self_collide>1</self_collide>
        </link>
        
        <link name="link_5">
        <pose frame="">0.15 0 0 3.14159 -1.57079 3.14159</pose>
        <inertial>
            <pose frame="">0 0 0 0 0 0</pose>
            <mass>0.02
            </mass>
            <inertia>
                <ixx>1.82e-06
                </ixx>
                <ixy>0</ixy>
                <ixz>0</ixz>
                <iyy>1.82e-06
                </iyy>
                <iyz>0</iyz>
                <izz>6.4e-07
                </izz>
            </inertia>
        </inertial>
        <collision name="link_5_collision">
            <pose frame="">0 0 0 0 0 0</pose>
            <geometry>
                <cylinder>
                    <length>0.03</length>
                    <radius>0.008</radius>
                </cylinder>
            </geometry>
            <surface>
                <friction>
                    <ode>
                        <mu>0.20</mu>
                        <mu2>0.20</mu2>
                    </ode>
                </friction>
                <contact>
                    <ode>
                        <kp>1e15</kp>
                        <kd>1e13</kd>
                    </ode>
                </contact>
            </surface>
        </collision>

        <collision name="link_5_collision_ball1">
            <pose frame="">0 0 0.015 0 0 0</pose>
            <geometry>
                <sphere>
                    <radius>0.008</radius>
                </sphere>
            </geometry>
            <surface>
                <friction>
                    <ode>
                        <mu>0.20</mu>
                        <mu2>0.20</mu2>
                    </ode>
                </friction>
                <contact>
                    <ode>
                        <kp>1e15</kp>
                        <kd>1e13</kd>
                    </ode>
                </contact>
            </surface>
        </collision>

        <collision name="link_5_collision_ball2">
            <pose frame="">0 0 -0.015 0 0 0</pose>
            <geometry>
                <sphere>
                    <radius>0.008</radius>
                </sphere>
            </geometry>
            <surface>
                <friction>
                    <ode>
                        <mu>0.20</mu>
                        <mu2>0.20</mu2>
                    </ode>
                </friction>
                <contact>
                    <ode>
                        <kp>1e15</kp>
                        <kd>1e13</kd>
                    </ode>
                </contact>
            </surface>
        </collision>



        <visual name="link_5_visual">
            <cast_shadows>0</cast_shadows>
            <pose frame="">0 0 0 0 0 0</pose>
            <geometry>
                <cylinder>
                    <length>0.03
                    </length>
                    <radius>0.008
                    </radius>
                </cylinder>
            </geometry>
            <material>
                <script>
                    <name>Gazebo/Purple </name>
                    <uri>file://media/materials/scripts/gazebo.material</uri>
                </script>
            </material>
        </visual>
        <self_collide>1</self_collide>
        </link>
        
        <link name="link_6">
        <pose frame="">0.18 0 0 3.14159 -1.57079 3.14159</pose>
        <inertial>
            <pose frame="">0 0 0 0 0 0</pose>
            <mass>0.02
            </mass>
            <inertia>
                <ixx>1.82e-06
                </ixx>
                <ixy>0</ixy>
                <ixz>0</ixz>
                <iyy>1.82e-06
                </iyy>
                <iyz>0</iyz>
                <izz>6.4e-07
                </izz>
            </inertia>
        </inertial>
        <collision name="link_6_collision">
            <pose frame="">0 0 0 0 0 0</pose>
            <geometry>
                <cylinder>
                    <length>0.03</length>
                    <radius>0.008</radius>
                </cylinder>
            </geometry>
            <surface>
                <friction>
                    <ode>
                        <mu>0.20</mu>
                        <mu2>0.20</mu2>
                    </ode>
                </friction>
                <contact>
                    <ode>
                        <kp>1e15</kp>
                        <kd>1e13</kd>
                    </ode>
                </contact>
            </surface>
        </collision>

        <collision name="link_6_collision_ball1">
            <pose frame="">0 0 0.015 0 0 0</pose>
            <geometry>
                <sphere>
                    <radius>0.008</radius>
                </sphere>
            </geometry>
            <surface>
                <friction>
                    <ode>
                        <mu>0.20</mu>
                        <mu2>0.20</mu2>
                    </ode>
                </friction>
                <contact>
                    <ode>
                        <kp>1e15</kp>
                        <kd>1e13</kd>
                    </ode>
                </contact>
            </surface>
        </collision>

        <collision name="link_6_collision_ball2">
            <pose frame="">0 0 -0.015 0 0 0</pose>
            <geometry>
                <sphere>
                    <radius>0.008</radius>
                </sphere>
            </geometry>
            <surface>
                <friction>
                    <ode>
                        <mu>0.20</mu>
                        <mu2>0.20</mu2>
                    </ode>
                </friction>
                <contact>
                    <ode>
                        <kp>1e15</kp>
                        <kd>1e13</kd>
                    </ode>
                </contact>
            </surface>
        </collision>



        <visual name="link_6_visual">
            <cast_shadows>0</cast_shadows>
            <pose frame="">0 0 0 0 0 0</pose>
            <geometry>
                <cylinder>
                    <length>0.03
                    </length>
                    <radius>0.008
                    </radius>
                </cylinder>
            </geometry>
            <material>
                <script>
                    <name>Gazebo/White </name>
                    <uri>file://media/materials/scripts/gazebo.material</uri>
                </script>
            </material>
        </visual>
        <self_collide>1</self_collide>
        </link>
        
        <link name="link_7">
        <pose frame="">0.21 0 0 3.14159 -1.57079 3.14159</pose>
        <inertial>
            <pose frame="">0 0 0 0 0 0</pose>
            <mass>0.02
            </mass>
            <inertia>
                <ixx>1.82e-06
                </ixx>
                <ixy>0</ixy>
                <ixz>0</ixz>
                <iyy>1.82e-06
                </iyy>
                <iyz>0</iyz>
                <izz>6.4e-07
                </izz>
            </inertia>
        </inertial>
        <collision name="link_7_collision">
            <pose frame="">0 0 0 0 0 0</pose>
            <geometry>
                <cylinder>
                    <length>0.03</length>
                    <radius>0.008</radius>
                </cylinder>
            </geometry>
            <surface>
                <friction>
                    <ode>
                        <mu>0.20</mu>
                        <mu2>0.20</mu2>
                    </ode>
                </friction>
                <contact>
                    <ode>
                        <kp>1e15</kp>
                        <kd>1e13</kd>
                    </ode>
                </contact>
            </surface>
        </collision>

        <collision name="link_7_collision_ball1">
            <pose frame="">0 0 0.015 0 0 0</pose>
            <geometry>
                <sphere>
                    <radius>0.008</radius>
                </sphere>
            </geometry>
            <surface>
                <friction>
                    <ode>
                        <mu>0.20</mu>
                        <mu2>0.20</mu2>
                    </ode>
                </friction>
                <contact>
                    <ode>
                        <kp>1e15</kp>
                        <kd>1e13</kd>
                    </ode>
                </contact>
            </surface>
        </collision>

        <collision name="link_7_collision_ball2">
            <pose frame="">0 0 -0.015 0 0 0</pose>
            <geometry>
                <sphere>
                    <radius>0.008</radius>
                </sphere>
            </geometry>
            <surface>
                <friction>
                    <ode>
                        <mu>0.20</mu>
                        <mu2>0.20</mu2>
                    </ode>
                </friction>
                <contact>
                    <ode>
                        <kp>1e15</kp>
                        <kd>1e13</kd>
                    </ode>
                </contact>
            </surface>
        </collision>



        <visual name="link_7_visual">
            <cast_shadows>0</cast_shadows>
            <pose frame="">0 0 0 0 0 0</pose>
            <geometry>
                <cylinder>
                    <length>0.03
                    </length>
                    <radius>0.008
                    </radius>
                </cylinder>
            </geometry>
            <material>
                <script>
                    <name>Gazebo/Black </name>
                    <uri>file://media/materials/scripts/gazebo.material</uri>
                </script>
            </material>
        </visual>
        <self_collide>1</self_collide>
        </link>
        
        <link name="link_8">
        <pose frame="">0.24 0 0 3.14159 -1.57079 3.14159</pose>
        <inertial>
            <pose frame="">0 0 0 0 0 0</pose>
            <mass>0.02
            </mass>
            <inertia>
                <ixx>1.82e-06
                </ixx>
                <ixy>0</ixy>
                <ixz>0</ixz>
                <iyy>1.82e-06
                </iyy>
                <iyz>0</iyz>
                <izz>6.4e-07
                </izz>
            </inertia>
        </inertial>
        <collision name="link_8_collision">
            <pose frame="">0 0 0 0 0 0</pose>
            <geometry>
                <cylinder>
                    <length>0.03</length>
                    <radius>0.008</radius>
                </cylinder>
            </geometry>
            <surface>
                <friction>
                    <ode>
                        <mu>0.20</mu>
                        <mu2>0.20</mu2>
                    </ode>
                </friction>
                <contact>
                    <ode>
                        <kp>1e15</kp>
                        <kd>1e13</kd>
                    </ode>
                </contact>
            </surface>
        </collision>

        <collision name="link_8_collision_ball1">
            <pose frame="">0 0 0.015 0 0 0</pose>
            <geometry>
                <sphere>
                    <radius>0.008</radius>
                </sphere>
            </geometry>
            <surface>
                <friction>
                    <ode>
                        <mu>0.20</mu>
                        <mu2>0.20</mu2>
                    </ode>
                </friction>
                <contact>
                    <ode>
                        <kp>1e15</kp>
                        <kd>1e13</kd>
                    </ode>
                </contact>
            </surface>
        </collision>

        <collision name="link_8_collision_ball2">
            <pose frame="">0 0 -0.015 0 0 0</pose>
            <geometry>
                <sphere>
                    <radius>0.008</radius>
                </sphere>
            </geometry>
            <surface>
                <friction>
                    <ode>
                        <mu>0.20</mu>
                        <mu2>0.20</mu2>
                    </ode>
                </friction>
                <contact>
                    <ode>
                        <kp>1e15</kp>
                        <kd>1e13</kd>
                    </ode>
                </contact>
            </surface>
        </collision>



        <visual name="link_8_visual">
            <cast_shadows>0</cast_shadows>
            <pose frame="">0 0 0 0 0 0</pose>
            <geometry>
                <cylinder>
                    <length>0.03
                    </length>
                    <radius>0.008
                    </radius>
                </cylinder>
            </geometry>
            <material>
                <script>
                    <name>Gazebo/Red </name>
                    <uri>file://media/materials/scripts/gazebo.material</uri>
                </script>
            </material>
        </visual>
        <self_collide>1</self_collide>
        </link>
        
        <link name="link_9">
        <pose frame="">0.27 0 0 3.14159 -1.57079 3.14159</pose>
        <inertial>
            <pose frame="">0 0 0 0 0 0</pose>
            <mass>0.02
            </mass>
            <inertia>
                <ixx>1.82e-06
                </ixx>
                <ixy>0</ixy>
                <ixz>0</ixz>
                <iyy>1.82e-06
                </iyy>
                <iyz>0</iyz>
                <izz>6.4e-07
                </izz>
            </inertia>
        </inertial>
        <collision name="link_9_collision">
            <pose frame="">0 0 0 0 0 0</pose>
            <geometry>
                <cylinder>
                    <length>0.03</length>
                    <radius>0.008</radius>
                </cylinder>
            </geometry>
            <surface>
                <friction>
                    <ode>
                        <mu>0.20</mu>
                        <mu2>0.20</mu2>
                    </ode>
                </friction>
                <contact>
                    <ode>
                        <kp>1e15</kp>
                        <kd>1e13</kd>
                    </ode>
                </contact>
            </surface>
        </collision>

        <collision name="link_9_collision_ball1">
            <pose frame="">0 0 0.015 0 0 0</pose>
            <geometry>
                <sphere>
                    <radius>0.008</radius>
                </sphere>
            </geometry>
            <surface>
                <friction>
                    <ode>
                        <mu>0.20</mu>
                        <mu2>0.20</mu2>
                    </ode>
                </friction>
                <contact>
                    <ode>
                        <kp>1e15</kp>
                        <kd>1e13</kd>
                    </ode>
                </contact>
            </surface>
        </collision>

        <collision name="link_9_collision_ball2">
            <pose frame="">0 0 -0.015 0 0 0</pose>
            <geometry>
                <sphere>
                    <radius>0.008</radius>
                </sphere>
            </geometry>
            <surface>
                <friction>
                    <ode>
                        <mu>0.20</mu>
                        <mu2>0.20</mu2>
                    </ode>
                </friction>
                <contact>
                    <ode>
                        <kp>1e15</kp>
                        <kd>1e13</kd>
                    </ode>
                </contact>
            </surface>
        </collision>



        <visual name="link_9_visual">
            <cast_shadows>0</cast_shadows>
            <pose frame="">0 0 0 0 0 0</pose>
            <geometry>
                <cylinder>
                    <length>0.03
                    </length>
                    <radius>0.008
                    </radius>
                </cylinder>
            </geometry>
            <material>
                <script>
                    <name>Gazebo/Orange </name>
                    <uri>file://media/materials/scripts/gazebo.material</uri>
                </script>
            </material>
        </visual>
        <self_collide>1</self_collide>
        </link>
        
        <link name="link_10">
        <pose frame="">0.3 0 0 3.14159 -1.57079 3.14159</pose>
        <inertial>
            <pose frame="">0 0 0 0 0 0</pose>
            <mass>0.02
            </mass>
            <inertia>
                <ixx>1.82e-06
                </ixx>
                <ixy>0</ixy>
                <ixz>0</ixz>
                <iyy>1.82e-06
                </iyy>
                <iyz>0</iyz>
                <izz>6.4e-07
                </izz>
            </inertia>
        </inertial>
        <collision name="link_10_collision">
            <pose frame="">0 0 0 0 0 0</pose>
            <geometry>
                <cylinder>
                    <length>0.03</length>
                    <radius>0.008</radius>
                </cylinder>
            </geometry>
            <surface>
                <friction>
                    <ode>
                        <mu>0.20</mu>
                        <mu2>0.20</mu2>
                    </ode>
                </friction>
                <contact>
                    <ode>
                        <kp>1e15</kp>
                        <kd>1e13</kd>
                    </ode>
                </contact>
            </surface>
        </collision>

        <collision name="link_10_collision_ball1">
            <pose frame="">0 0 0.015 0 0 0</pose>
            <geometry>
                <sphere>
                    <radius>0.008</radius>
                </sphere>
            </geometry>
            <surface>
                <friction>
                    <ode>
                        <mu>0.20</mu>
                        <mu2>0.20</mu2>
                    </ode>
                </friction>
                <contact>
                    <ode>
                        <kp>1e15</kp>
                        <kd>1e13</kd>
                    </ode>
                </contact>
            </surface>
        </collision>

        <collision name="link_10_collision_ball2">
            <pose frame="">0 0 -0.015 0 0 0</pose>
            <geometry>
                <sphere>
                    <radius>0.008</radius>
                </sphere>
            </geometry>
            <surface>
                <friction>
                    <ode>
                        <mu>0.20</mu>
                        <mu2>0.20</mu2>
                    </ode>
                </friction>
                <contact>
                    <ode>
                        <kp>1e15</kp>
                        <kd>1e13</kd>
                    </ode>
                </contact>
            </surface>
        </collision>



        <visual name="link_10_visual">
            <cast_shadows>0</cast_shadows>
            <pose frame="">0 0 0 0 0 0</pose>
            <geometry>
                <cylinder>
                    <length>0.03
                    </length>
                    <radius>0.008
                    </radius>
                </cylinder>
            </geometry>
            <material>
                <script>
                    <name>Gazebo/Yellow </name>
                    <uri>file://media/materials/scripts/gazebo.material</uri>
                </script>
            </material>
        </visual>
        <self_collide>1</self_collide>
        </link>
        
        
        <joint name="joint_1" type="universal">
            <child>link_2</child>
            <parent>link_1</parent>
            <pose>0 0 0.015 0 0 0 </pose>
            <axis>
                <xyz>0 0 1</xyz>
                <limit>
                    <lower>-2.0</lower>
                    <upper>2.0</upper>
                    <effort>10</effort>
                    <velocity>5</velocity>
                </limit>
                <dynamics>
                    <damping>0.001</damping>
                    <friction>0.01</friction>
                </dynamics>
                <use_parent_model_frame>1</use_parent_model_frame>
            </axis>
            <axis2>
                <xyz>0 1 0</xyz>
                <limit>
                    <lower>-2.0</lower>
                    <upper>2.0</upper>
                    <effort>10</effort>
                    <velocity>5</velocity>
                </limit>
                <dynamics>
                    <damping>0.001</damping>
                    <friction>0.01</friction>
                </dynamics>
                <use_parent_model_frame>1</use_parent_model_frame>
            </axis2>
            <physics>
                <ode>
                </ode>
            </physics>
        </joint>
        
        <joint name="joint_2" type="universal">
            <child>link_3</child>
            <parent>link_2</parent>
            <pose>0 0 0.015 0 0 0 </pose>
            <axis>
                <xyz>0 0 1</xyz>
                <limit>
                    <lower>-2.0</lower>
                    <upper>2.0</upper>
                    <effort>10</effort>
                    <velocity>5</velocity>
                </limit>
                <dynamics>
                    <damping>0.001</damping>
                    <friction>0.01</friction>
                </dynamics>
                <use_parent_model_frame>1</use_parent_model_frame>
            </axis>
            <axis2>
                <xyz>0 1 0</xyz>
                <limit>
                    <lower>-2.0</lower>
                    <upper>2.0</upper>
                    <effort>10</effort>
                    <velocity>5</velocity>
                </limit>
                <dynamics>
                    <damping>0.001</damping>
                    <friction>0.01</friction>
                </dynamics>
                <use_parent_model_frame>1</use_parent_model_frame>
            </axis2>
            <physics>
                <ode>
                </ode>
            </physics>
        </joint>
        
        <joint name="joint_3" type="universal">
            <child>link_4</child>
            <parent>link_3</parent>
            <pose>0 0 0.015 0 0 0 </pose>
            <axis>
                <xyz>0 0 1</xyz>
                <limit>
                    <lower>-2.0</lower>
                    <upper>2.0</upper>
                    <effort>10</effort>
                    <velocity>5</velocity>
                </limit>
                <dynamics>
                    <damping>0.001</damping>
                    <friction>0.01</friction>
                </dynamics>
                <use_parent_model_frame>1</use_parent_model_frame>
            </axis>
            <axis2>
                <xyz>0 1 0</xyz>
                <limit>
                    <lower>-2.0</lower>
                    <upper>2.0</upper>
                    <effort>10</effort>
                    <velocity>5</velocity>
                </limit>
                <dynamics>
                    <damping>0.001</damping>
                    <friction>0.01</friction>
                </dynamics>
                <use_parent_model_frame>1</use_parent_model_frame>
            </axis2>
            <physics>
                <ode>
                </ode>
            </physics>
        </joint>
        
        <joint name="joint_4" type="universal">
            <child>link_5</child>
            <parent>link_4</parent>
            <pose>0 0 0.015 0 0 0 </pose>
            <axis>
                <xyz>0 0 1</xyz>
                <limit>
                    <lower>-2.0</lower>
                    <upper>2.0</upper>
                    <effort>10</effort>
                    <velocity>5</velocity>
                </limit>
                <dynamics>
                    <damping>0.001</damping>
                    <friction>0.01</friction>
                </dynamics>
                <use_parent_model_frame>1</use_parent_model_frame>
            </axis>
            <axis2>
                <xyz>0 1 0</xyz>
                <limit>
                    <lower>-2.0</lower>
                    <upper>2.0</upper>
                    <effort>10</effort>
                    <velocity>5</velocity>
                </limit>
                <dynamics>
                    <damping>0.001</damping>
                    <friction>0.01</friction>
                </dynamics>
                <use_parent_model_frame>1</use_parent_model_frame>
            </axis2>
            <physics>
                <ode>
                </ode>
            </physics>
        </joint>
        
        <joint name="joint_5" type="universal">
            <child>link_6</child>
            <parent>link_5</parent>
            <pose>0 0 0.015 0 0 0 </pose>
            <axis>
                <xyz>0 0 1</xyz>
                <limit>
                    <lower>-2.0</lower>
                    <upper>2.0</upper>
                    <effort>10</effort>
                    <velocity>5</velocity>
                </limit>
                <dynamics>
                    <damping>0.001</damping>
                    <friction>0.01</friction>
                </dynamics>
                <use_parent_model_frame>1</use_parent_model_frame>
            </axis>
            <axis2>
                <xyz>0 1 0</xyz>
                <limit>
                    <lower>-2.0</lower>
                    <upper>2.0</upper>
                    <effort>10</effort>
                    <velocity>5</velocity>
                </limit>
                <dynamics>
                    <damping>0.001</damping>
                    <friction>0.01</friction>
                </dynamics>
                <use_parent_model_frame>1</use_parent_model_frame>
            </axis2>
            <physics>
                <ode>
                </ode>
            </physics>
        </joint>
        
        <joint name="joint_6" type="universal">
            <child>link_7</child>
            <parent>link_6</parent>
            <pose>0 0 0.015 0 0 0 </pose>
            <axis>
                <xyz>0 0 1</xyz>
                <limit>
                    <lower>-2.0</lower>
                    <upper>2.0</upper>
                    <effort>10</effort>
                    <velocity>5</velocity>
                </limit>
                <dynamics>
                    <damping>0.001</damping>
                    <friction>0.01</friction>
                </dynamics>
                <use_parent_model_frame>1</use_parent_model_frame>
            </axis>
            <axis2>
                <xyz>0 1 0</xyz>
                <limit>
                    <lower>-2.0</lower>
                    <upper>2.0</upper>
                    <effort>10</effort>
                    <velocity>5</velocity>
                </limit>
                <dynamics>
                    <damping>0.001</damping>
                    <friction>0.01</friction>
                </dynamics>
                <use_parent_model_frame>1</use_parent_model_frame>
            </axis2>
            <physics>
                <ode>
                </ode>
            </physics>
        </joint>
        
        <joint name="joint_7" type="universal">
            <child>link_8</child>
            <parent>link_7</parent>
            <pose>0 0 0.015 0 0 0 </pose>
            <axis>
                <xyz>0 0 1</xyz>
                <limit>
                    <lower>-2.0</lower>
                    <upper>2.0</upper>
                    <effort>10</effort>
                    <velocity>5</velocity>
                </limit>
                <dynamics>
                    <damping>0.001</damping>
                    <friction>0.01</friction>
                </dynamics>
                <use_parent_model_frame>1</use_parent_model_frame>
            </axis>
            <axis2>
                <xyz>0 1 0</xyz>
                <limit>
                    <lower>-2.0</lower>
                    <upper>2.0</upper>
                    <effort>10</effort>
                    <velocity>5</velocity>
                </limit>
                <dynamics>
                    <damping>0.001</damping>
                    <friction>0.01</friction>
                </dynamics>
                <use_parent_model_frame>1</use_parent_model_frame>
            </axis2>
            <physics>
                <ode>
                </ode>
            </physics>
        </joint>
        
        <joint name="joint_8" type="universal">
            <child>link_9</child>
            <parent>link_8</parent>
            <pose>0 0 0.015 0 0 0 </pose>
            <axis>
                <xyz>0 0 1</xyz>
                <limit>
                    <lower>-2.0</lower>
                    <upper>2.0</upper>
                    <effort>10</effort>
                    <velocity>5</velocity>
                </limit>
                <dynamics>
                    <damping>0.001</damping>
                    <friction>0.01</friction>
                </dynamics>
                <use_parent_model_frame>1</use_parent_model_frame>
            </axis>
            <axis2>
                <xyz>0 1 0</xyz>
                <limit>
                    <lower>-2.0</lower>
                    <upper>2.0</upper>
                    <effort>10</effort>
                    <velocity>5</velocity>
                </limit>
                <dynamics>
                    <damping>0.001</damping>
                    <friction>0.01</friction>
                </dynamics>
                <use_parent_model_frame>1</use_parent_model_frame>
            </axis2>
            <physics>
                <ode>
                </ode>
            </physics>
        </joint>
        
        <joint name="joint_9" type="universal">
            <child>link_10</child>
            <parent>link_9</parent>
            <pose>0 0 0.015 0 0 0 </pose>
            <axis>
                <xyz>0 0 1</xyz>
                <limit>
                    <lower>-2.0</lower>
                    <upper>2.0</upper>
                    <effort>10</effort>
                    <velocity>5</velocity>
                </limit>
                <dynamics>
                    <damping>0.001</damping>
                    <friction>0.01</friction>
                </dynamics>
                <use_parent_model_frame>1</use_parent_model_frame>
            </axis>
            <axis2>
                <xyz>0 1 0</xyz>
                <limit>
                    <lower>-2.0</lower>
                    <upper>2.0</upper>
                    <effort>10</effort>
                    <velocity>5</velocity>
                </limit>
                <dynamics>
                    <damping>0.001</damping>
                    <friction>0.01</friction>
                </dynamics>
                <use_parent_model_frame>1</use_parent_model_frame>
            </axis2>
            <physics>
                <ode>
                </ode>
            </physics>
        </joint>
        
        <link name='head'>
        <pose frame=''>0.315 0 0 0 0 0 </pose>
        <inertial>
            <pose frame=''>0 0 0 0 0 0</pose>
            <mass>0.1</mass>
            <inertia>
                <ixx>0.0001</ixx>
                <ixy>0</ixy>
                <ixz>0</ixz>
                <iyy>0.0001</iyy>
                <iyz>0</iyz>
                <izz>0.001</izz>
            </inertia>
        </inertial>
        <collision name='head_collision'>
            <pose frame=''>0 0 0 0 0 0</pose>
            <geometry>
                <sphere>
                    <radius>0.008 </radius>
                </sphere>
            </geometry>
            <surface>
                <friction>
                    <ode>
                        <mu>0.0</mu>
                        <mu2>0.0</mu2>
                    </ode>
                </friction>
                <contact>
                    <ode>
                    </ode>
                </contact>
            </surface>
        </collision>
        <visual name='head_visual'>
            <cast_shadows>0</cast_shadows>
            <pose frame=''>0 0 0 0 0 0</pose>
            <geometry>
                <sphere>
                    <radius>0.008
                    </radius>
                </sphere>
            </geometry>
            <material>
                <script>
                    <name>Gazebo/Red</name>
                    <uri>file://media/materials/scripts/gazebo.material</uri>
                </script>
            </material>
        </visual>
        <self_collide>1</self_collide>
        </link>
        <joint name="head_joint" type="universal">
            <child>head</child>
            <parent>link_10</parent>
            <pose>0 0 0 0 0 0</pose>
            <axis>
                <xyz>0 0 1</xyz>
                <dynamics>
                    <damping>0.001</damping>
                    <friction>0.01</friction>
                </dynamics>
            </axis>
            <axis2>
                <xyz>0 1 0</xyz>
                <dynamics>
                    <damping>0.001</damping>
                    <friction>0.01</friction>
                </dynamics>
            </axis2>
        </joint>
        <plugin name='rope_plugin' filename='librope_plugin.so'>
            <num_links>10</num_links>
            <rope_length>0.3</rope_length>
        </plugin>
        <plugin name='position_3d_plugin' filename='libposition_3d_plugin.so'>
            <name>gripper</name>
            <kP_pos>5</kP_pos>
            <kI_pos>0.0</kI_pos>
            <kD_pos>0.0</kD_pos>
            <kP_vel>200.0</kP_vel>
            <kI_vel>0.0</kI_vel>
            <kD_vel>0.0</kD_vel>
            <max_force>2.0</max_force>
            <max_vel>0.15</max_vel>
            <kP_rot>0.1</kP_rot>
            <kI_rot>0.0</kI_rot>
            <kD_rot>0.0</kD_rot>
            <kP_rot_vel>0.1</kP_rot_vel>
            <kI_rot_vel>0.0</kI_rot_vel>
            <kD_rot_vel>0.0</kD_rot_vel>
            <max_torque>0.1</max_torque>
            <max_rot_vel>6.0</max_rot_vel>
            <link>head</link>
        </plugin>
    </model>
</sdf>
