<sdf version='1.7'>
    <model name='victor'>
        <joint name='world_joint' type='fixed'>
            <pose relative_to='__model__'>0 0 0 0 -0 0</pose>
            <parent>world</parent>
            <child>victor_left_gripper_mounting_bracket</child>
        </joint>
        <link name='victor_left_gripper_mounting_bracket'>
            <pose relative_to='world_joint'>0 0 0 0 -0 0</pose>
            <inertial>
                <pose>0.007867 0.007867 0.057609 0 -0 0</pose>
                <mass>0.2</mass>
                <inertia>
                    <ixx>0.000532552</ixx>
                    <ixy>-1.2377e-05</ixy>
                    <ixz>-4.80803e-05</ixz>
                    <iyy>0.000532552</iyy>
                    <iyz>-4.80803e-05</iyz>
                    <izz>0.000358154</izz>
                </inertia>
            </inertial>
            <visual name='victor_left_gripper_mounting_bracket_visual'>
                <pose>0 0 0 0 -0 0</pose>
                <geometry>
                    <mesh>
                        <scale>1 1 1</scale>
                        <uri>
                            /home/peter/catkin_ws/src/kuka_iiwa_interface/victor_description/meshes/robotiq_3finger/kuka_to_palm_connectors_visual.stl
                        </uri>
                    </mesh>
                </geometry>
            </visual>
            <visual name='victor_left_gripper_mounting_bracket_fixed_joint_lump__victor_left_gripper_palm_visual_1'>
                <pose>0 0 0.02705 0 -0 0.785398</pose>
                <geometry>
                    <mesh>
                        <scale>1 1 1</scale>
                        <uri>
                            /home/peter/catkin_ws/src/kuka_iiwa_interface/victor_description/meshes/robotiq_3finger/palm_visual.stl
                        </uri>
                    </mesh>
                </geometry>
            </visual>
            <visual name='victor_left_gripper_mounting_bracket_fixed_joint_lump__victor_left_gripper_fingerA_base_visual_2'>
                <pose>0.015733 0.015733 0.088169 0 -0 0.785398</pose>
                <geometry>
                    <mesh>
                        <scale>1 1 1</scale>
                        <uri>
                            /home/peter/catkin_ws/src/kuka_iiwa_interface/victor_description/meshes/robotiq_3finger/finger_link1_base_visual.stl
                        </uri>
                    </mesh>
                </geometry>
            </visual>
            <self_collide>0</self_collide>
            <enable_wind>0</enable_wind>
            <kinematic>0</kinematic>
        </link>
        <joint name='victor_left_gripper_fingerA_joint_2' type='revolute'>
            <pose relative_to='victor_left_gripper_mounting_bracket'>0.031467 0.031467 0.109683 -0 0.610865 0.785398
            </pose>
            <parent>victor_left_gripper_mounting_bracket</parent>
            <child>victor_left_gripper_fingerA_prox</child>
            <axis>
                <xyz>0 -1 0</xyz>
                <limit>
                    <lower>0</lower>
                    <upper>1.22173</upper>
                    <effort>300</effort>
                    <velocity>10</velocity>
                </limit>
                <dynamics>
                    <damping>0.005</damping>
                    <friction>0</friction>
                    <spring_reference>0</spring_reference>
                    <spring_stiffness>0</spring_stiffness>
                </dynamics>
            </axis>
        </joint>
        <link name='victor_left_gripper_fingerA_prox'>
            <pose relative_to='victor_left_gripper_fingerA_joint_2'>0 0 0 0 -0 0</pose>
            <inertial>
                <pose>0.01 0 0.03 0 -0 0</pose>
                <mass>0.1</mass>
                <inertia>
                    <ixx>0.0001667</ixx>
                    <ixy>0</ixy>
                    <ixz>0</ixz>
                    <iyy>0.0001667</iyy>
                    <iyz>0</iyz>
                    <izz>0.0001667</izz>
                </inertia>
            </inertial>
            <visual name='victor_left_gripper_fingerA_prox_visual'>
                <pose>0 0 0 0 -0 0</pose>
                <geometry>
                    <mesh>
                        <scale>1 1 1</scale>
                        <uri>
                            /home/peter/catkin_ws/src/kuka_iiwa_interface/victor_description/meshes/robotiq_3finger/finger_link2_prox_visual.stl
                        </uri>
                    </mesh>
                </geometry>
            </visual>
            <self_collide>0</self_collide>
            <enable_wind>0</enable_wind>
            <kinematic>0</kinematic>
        </link>
        <joint name='victor_left_gripper_fingerA_joint_3' type='revolute'>
            <pose relative_to='victor_left_gripper_fingerA_prox'>0 0 0.05715 0 -0 0</pose>
            <parent>victor_left_gripper_fingerA_prox</parent>
            <child>victor_left_gripper_fingerA_med</child>
            <axis>
                <xyz>0 -1 0</xyz>
                <limit>
                    <lower>-1</lower>
                    <upper>1</upper>
                    <effort>300</effort>
                    <velocity>10</velocity>
                </limit>
                <dynamics>
                    <damping>0.005</damping>
                    <friction>0</friction>
                    <spring_reference>0</spring_reference>
                    <spring_stiffness>0</spring_stiffness>
                </dynamics>
            </axis>
        </joint>
        <link name='victor_left_gripper_fingerA_med'>
            <pose relative_to='victor_left_gripper_fingerA_joint_3'>0 0 0 0 -0 0</pose>
            <inertial>
                <pose>0.01 0 0.02 0 -0 0</pose>
                <mass>0.1</mass>
                <inertia>
                    <ixx>0.0001667</ixx>
                    <ixy>0</ixy>
                    <ixz>0</ixz>
                    <iyy>0.0001667</iyy>
                    <iyz>0</iyz>
                    <izz>0.0001667</izz>
                </inertia>
            </inertial>
            <visual name='victor_left_gripper_fingerA_med_visual'>
                <pose>0 0 0 0 -0 0</pose>
                <geometry>
                    <mesh>
                        <scale>1 1 1</scale>
                        <uri>
                            /home/peter/catkin_ws/src/kuka_iiwa_interface/victor_description/meshes/robotiq_3finger/finger_link3_med_visual.stl
                        </uri>
                    </mesh>
                </geometry>
            </visual>
            <self_collide>0</self_collide>
            <enable_wind>0</enable_wind>
            <kinematic>0</kinematic>
        </link>
        <joint name='victor_left_gripper_fingerA_joint_4' type='revolute'>
            <pose relative_to='victor_left_gripper_fingerA_med'>0 0 0.0381 0 -0.436332 0</pose>
            <parent>victor_left_gripper_fingerA_med</parent>
            <child>victor_left_gripper_fingerA_dist</child>
            <axis>
                <xyz>0 -1 0</xyz>
                <limit>
                    <lower>-1</lower>
                    <upper>1</upper>
                    <effort>300</effort>
                    <velocity>10</velocity>
                </limit>
                <dynamics>
                    <damping>0.005</damping>
                    <friction>0</friction>
                    <spring_reference>0</spring_reference>
                    <spring_stiffness>0</spring_stiffness>
                </dynamics>
            </axis>
        </joint>
        <link name='victor_left_gripper_fingerA_dist'>
            <pose relative_to='victor_left_gripper_fingerA_joint_4'>0 0 0 0 -0 0</pose>
            <inertial>
                <pose>0 0 0.01 0 -0 0</pose>
                <mass>0.1</mass>
                <inertia>
                    <ixx>0.0001667</ixx>
                    <ixy>0</ixy>
                    <ixz>0</ixz>
                    <iyy>0.0001667</iyy>
                    <iyz>0</iyz>
                    <izz>0.0001667</izz>
                </inertia>
            </inertial>
            <visual name='victor_left_gripper_fingerA_dist_visual'>
                <pose>0 0 0 0 -0 0</pose>
                <geometry>
                    <mesh>
                        <scale>1 1 1</scale>
                        <uri>
                            /home/peter/catkin_ws/src/kuka_iiwa_interface/victor_description/meshes/robotiq_3finger/finger_link4_dist_visual.stl
                        </uri>
                    </mesh>
                </geometry>
            </visual>
            <self_collide>0</self_collide>
            <enable_wind>0</enable_wind>
            <kinematic>0</kinematic>
        </link>
        <pose>0 0 0 0 -0 0</pose>
    </model>
</sdf>